File: myThesis/Viscosity/csv/peo_su8_all_100.csv
Filename,peo_su8_all_100
Instrument name,5333-0457
Operator,Osamu Katagiri
rundate,29/01/2020
Sample name,PEO_SU8_01_100_1
Geometry name,60mm 0.9969° cone plate, Peltier plate Steel
Procedure name,Sample
,Flow ramp
proceduresegments,Flow ramp
[step]
Flow ramp - 1
Stress,Shear rate,Viscosity,Step time,Temperature,Normal stress,Axial force,Gap,Normal stress coefficient,Time,Torque,Velocity
Pa,1/s,Pa.s,s,°C,Pa,N,µm,Pa.s²,s,µN.m,rad/s
,3.86000e-3,13034.2,,,,,,,,,
17683.9,4.42000e-3,13353.9,1.00000,1.00,707.355,1.00000,1000000,3.62070e7,1.00000,1000000,1.00000
17683.9,5.15000e-3,12722.1,1.00000,1.00,707.355,1.00000,1000000,2.66700e7,1.00000,1000000,1.00000
17683.9,5.90000e-3,13034.2,1.00000,1.00,707.355,1.00000,1000000,2.03205e7,1.00000,1000000,1.00000
17683.9,6.62000e-3,17309.3,1.00000,1.00,707.355,1.00000,1000000,1.61407e7,1.00000,1000000,1.00000
17683.9,6.63000e-3,12265.7,1.00000,1.00,707.355,1.00000,1000000,1.60920e7,1.00000,1000000,1.00000
17683.9,6.76000e-3,12659.5,1.00000,1.00,707.355,1.00000,1000000,1.54790e7,1.00000,1000000,1.00000
17683.9,7.71000e-3,16426.3,1.00000,1.00,707.355,1.00000,1000000,1.18995e7,1.00000,1000000,1.00000
17683.9,7.88000e-3,11475.7,1.00000,1.00,707.355,1.00000,1000000,1.13916e7,1.00000,1000000,1.00000
17683.9,7.98000e-3,12496.3,1.00000,1.00,707.355,1.00000,1000000,1.11079e7,1.00000,1000000,1.00000
17683.9,8.98000e-3,15683.9,1.00000,1.00,707.355,1.00000,1000000,8771720,1.00000,1000000,1.00000
17683.9,9.17000e-3,10383.8,1.00000,1.00,707.355,1.00000,1000000,8411990,1.00000,1000000,1.00000
17683.9,9.47000e-3,12316.3,1.00000,1.00,707.355,1.00000,1000000,7887470,1.00000,1000000,1.00000
17683.9,0.0104535,15053.6,1.00000,1.00,707.355,1.00000,1000000,6473130,1.00000,1000000,1.00000
17683.9,0.0106730,9370.53,1.00000,1.00,707.355,1.00000,1000000,6209610,1.00000,1000000,1.00000
17683.9,0.0109913,12011.0,1.00000,1.00,707.355,1.00000,1000000,5855170,1.00000,1000000,1.00000
17683.9,0.0121717,14600.8,1.00000,1.00,707.355,1.00000,1000000,4774580,1.00000,1000000,1.00000
17683.9,0.0124252,8448.49,1.00000,1.00,707.355,1.00000,1000000,4581740,1.00000,1000000,1.00000
17683.9,0.0125626,11459.5,1.00000,1.00,707.355,1.00000,1000000,4482070,1.00000,1000000,1.00000
17683.9,0.0141723,14100.0,1.00000,1.00,707.355,1.00000,1000000,3521740,1.00000,1000000,1.00000
17683.9,0.0142420,10791.6,1.00000,1.00,707.355,1.00000,1000000,3487350,1.00000,1000000,1.00000
17683.9,0.0144650,7569.30,1.00000,1.00,707.355,1.00000,1000000,3380650,1.00000,1000000,1.00000
17683.9,0.0160229,10103.6,1.00000,1.00,707.355,1.00000,1000000,2755210,1.00000,1000000,1.00000
17683.9,0.0165016,13334.1,1.00000,1.00,707.355,1.00000,1000000,2597680,1.00000,1000000,1.00000
17683.9,0.0168395,6757.22,1.00000,1.00,707.355,1.00000,1000000,2494480,1.00000,1000000,1.00000
17683.9,0.0179582,9425.39,1.00000,1.00,707.355,1.00000,1000000,2193370,1.00000,1000000,1.00000
17683.9,0.0192139,12478.4,1.00000,1.00,707.355,1.00000,1000000,1916050,1.00000,1000000,1.00000
17683.9,0.0196035,5956.67,1.00000,1.00,707.355,1.00000,1000000,1840650,1.00000,1000000,1.00000
17683.9,0.0201669,8750.45,1.00000,1.00,707.355,1.00000,1000000,1739240,1.00000,1000000,1.00000
17683.9,0.0223719,11385.9,1.00000,1.00,707.355,1.00000,1000000,1413290,1.00000,1000000,1.00000
17683.9,0.0226246,8111.21,1.00000,1.00,707.355,1.00000,1000000,1381900,1.00000,1000000,1.00000
17683.9,0.0228210,5203.88,1.00000,1.00,707.355,1.00000,1000000,1358210,1.00000,1000000,1.00000
17683.9,0.0253330,7520.07,1.00000,1.00,707.355,1.00000,1000000,1102210,1.00000,1000000,1.00000
17683.9,0.0260490,10298.7,1.00000,1.00,707.355,1.00000,1000000,1042450,1.00000,1000000,1.00000
17683.9,0.0265672,4653.95,1.00000,1.00,707.355,1.00000,1000000,1002180,1.00000,1000000,1.00000
17683.9,0.0283447,6968.17,1.00000,1.00,707.355,1.00000,1000000,880428,1.00000,1000000,1.00000
17683.9,0.0303305,9162.18,1.00000,1.00,707.355,1.00000,1000000,768915,1.00000,1000000,1.00000
17683.9,0.0309280,4109.98,1.00000,1.00,707.355,1.00000,1000000,739493,1.00000,1000000,1.00000
17683.9,0.0317252,6451.17,1.00000,1.00,707.355,1.00000,1000000,702795,1.00000,1000000,1.00000
17683.9,0.0353157,7871.46,1.00000,1.00,707.355,1.00000,1000000,567155,1.00000,1000000,1.00000
17683.9,0.0355634,5964.09,1.00000,1.00,707.355,1.00000,1000000,559282,1.00000,1000000,1.00000
17683.9,0.0360040,3587.34,1.00000,1.00,707.355,1.00000,1000000,545678,1.00000,1000000,1.00000
17683.9,0.0397983,5517.68,1.00000,1.00,707.355,1.00000,1000000,446590,1.00000,1000000,1.00000
17683.9,0.0411203,6703.81,1.00000,1.00,707.355,1.00000,1000000,418336,1.00000,1000000,1.00000
17683.9,0.0419136,3159.49,1.00000,1.00,707.355,1.00000,1000000,402650,1.00000,1000000,1.00000
17683.9,0.0445692,5099.03,1.00000,1.00,707.355,1.00000,1000000,356097,1.00000,1000000,1.00000
17683.9,0.0478789,5794.70,1.00000,1.00,707.355,1.00000,1000000,308567,1.00000,1000000,1.00000
17683.9,0.0487924,2745.32,1.00000,1.00,707.355,1.00000,1000000,297121,1.00000,1000000,1.00000
17683.9,0.0498516,4715.16,1.00000,1.00,707.355,1.00000,1000000,284629,1.00000,1000000,1.00000
17683.9,0.0557484,5004.51,1.00000,1.00,707.355,1.00000,1000000,227600,1.00000,1000000,1.00000
17683.9,0.0558649,4353.43,1.00000,1.00,707.355,1.00000,1000000,226652,1.00000,1000000,1.00000
17683.9,0.0568005,2400.54,1.00000,1.00,707.355,1.00000,1000000,219247,1.00000,1000000,1.00000
17683.9,0.0624710,4025.77,1.00000,1.00,707.355,1.00000,1000000,181251,1.00000,1000000,1.00000
17683.9,0.0649114,4386.67,1.00000,1.00,707.355,1.00000,1000000,167879,1.00000,1000000,1.00000
17683.9,0.0661244,2137.21,1.00000,1.00,707.355,1.00000,1000000,161776,1.00000,1000000,1.00000
17683.9,0.0698791,3721.14,1.00000,1.00,707.355,1.00000,1000000,144858,1.00000,1000000,1.00000
17683.9,0.0755804,3855.18,1.00000,1.00,707.355,1.00000,1000000,123828,1.00000,1000000,1.00000
17683.9,0.0769772,1868.79,1.00000,1.00,707.355,1.00000,1000000,119375,1.00000,1000000,1.00000
17683.9,0.0782145,3438.67,1.00000,1.00,707.355,1.00000,1000000,115628,1.00000,1000000,1.00000
17683.9,0.0875269,3178.81,1.00000,1.00,707.355,1.00000,1000000,92332.5,1.00000,1000000,1.00000
17683.9,0.0880029,3382.18,1.00000,1.00,707.355,1.00000,1000000,91336.4,1.00000,1000000,1.00000
17683.9,0.0896136,1669.80,1.00000,1.00,707.355,1.00000,1000000,88082.5,1.00000,1000000,1.00000
17683.9,0.0980224,2937.15,1.00000,1.00,707.355,1.00000,1000000,73618.5,1.00000,1000000,1.00000
17683.9,0.102467,2985.40,1.00000,1.00,707.355,1.00000,1000000,67370.5,1.00000,1000000,1.00000
17683.9,0.104323,1473.30,1.00000,1.00,707.355,1.00000,1000000,64994.6,1.00000,1000000,1.00000
17683.9,0.109817,2712.29,1.00000,1.00,707.355,1.00000,1000000,58654.1,1.00000,1000000,1.00000
17683.9,0.119309,2625.98,1.00000,1.00,707.355,1.00000,1000000,49692.5,1.00000,1000000,1.00000
17683.9,0.121446,1301.10,1.00000,1.00,707.355,1.00000,1000000,47959.1,1.00000,1000000,1.00000
17683.9,0.122855,2507.74,1.00000,1.00,707.355,1.00000,1000000,46865.4,1.00000,1000000,1.00000
17683.9,0.137492,2318.52,1.00000,1.00,707.355,1.00000,1000000,37418.2,1.00000,1000000,1.00000
17683.9,0.138919,2303.79,1.00000,1.00,707.355,1.00000,1000000,36653.4,1.00000,1000000,1.00000
17683.9,0.141381,1152.13,1.00000,1.00,707.355,1.00000,1000000,35388.0,1.00000,1000000,1.00000
17683.9,0.153965,2142.18,1.00000,1.00,707.355,1.00000,1000000,29839.6,1.00000,1000000,1.00000
17683.9,0.161752,2024.67,1.00000,1.00,707.355,1.00000,1000000,27035.7,1.00000,1000000,1.00000
17683.9,0.164589,1025.74,1.00000,1.00,707.355,1.00000,1000000,26111.7,1.00000,1000000,1.00000
17683.9,0.172444,1978.14,1.00000,1.00,707.355,1.00000,1000000,23787.1,1.00000,1000000,1.00000
17683.9,0.188338,1784.02,1.00000,1.00,707.355,1.00000,1000000,19941.7,1.00000,1000000,1.00000
17683.9,0.191611,926.481,1.00000,1.00,707.355,1.00000,1000000,19266.2,1.00000,1000000,1.00000
17683.9,0.192965,1827.47,1.00000,1.00,707.355,1.00000,1000000,18996.8,1.00000,1000000,1.00000
17683.9,0.215912,1686.85,1.00000,1.00,707.355,1.00000,1000000,15173.4,1.00000,1000000,1.00000
17683.9,0.219294,1569.24,1.00000,1.00,707.355,1.00000,1000000,14709.0,1.00000,1000000,1.00000
17683.9,0.223064,824.850,1.00000,1.00,707.355,1.00000,1000000,14216.0,1.00000,1000000,1.00000
17683.9,0.241787,1554.64,1.00000,1.00,707.355,1.00000,1000000,12099.6,1.00000,1000000,1.00000
17683.9,0.255338,1379.11,1.00000,1.00,707.355,1.00000,1000000,10849.4,1.00000,1000000,1.00000
17683.9,0.259683,739.012,1.00000,1.00,707.355,1.00000,1000000,10489.4,1.00000,1000000,1.00000
17683.9,0.270848,1431.15,1.00000,1.00,707.355,1.00000,1000000,9642.43,1.00000,1000000,1.00000
17683.9,0.297305,1230.13,1.00000,1.00,707.355,1.00000,1000000,8002.64,1.00000,1000000,1.00000
17683.9,0.302312,661.511,1.00000,1.00,707.355,1.00000,1000000,7739.75,1.00000,1000000,1.00000
17683.9,0.302979,1318.58,1.00000,1.00,707.355,1.00000,1000000,7705.71,1.00000,1000000,1.00000
17683.9,0.339021,1215.30,1.00000,1.00,707.355,1.00000,1000000,6154.38,1.00000,1000000,1.00000
17683.9,0.346171,1084.87,1.00000,1.00,707.355,1.00000,1000000,5902.78,1.00000,1000000,1.00000
17683.9,0.351940,592.138,1.00000,1.00,707.355,1.00000,1000000,5710.84,1.00000,1000000,1.00000
17683.9,0.379171,1121.84,1.00000,1.00,707.355,1.00000,1000000,4920.03,1.00000,1000000,1.00000
17683.9,0.403069,957.599,1.00000,1.00,707.355,1.00000,1000000,4353.90,1.00000,1000000,1.00000
17683.9,0.409717,532.432,1.00000,1.00,707.355,1.00000,1000000,4213.76,1.00000,1000000,1.00000
17683.9,0.424663,1036.42,1.00000,1.00,707.355,1.00000,1000000,3922.37,1.00000,1000000,1.00000
17683.9,0.469318,854.155,1.00000,1.00,707.355,1.00000,1000000,3211.46,1.00000,1000000,1.00000
17683.9,0.475522,959.455,1.00000,1.00,707.355,1.00000,1000000,3128.21,1.00000,1000000,1.00000
17683.9,0.476980,479.178,1.00000,1.00,707.355,1.00000,1000000,3109.12,1.00000,1000000,1.00000
,0.532015,890.165,,,,,,,,,
17683.9,0.546456,761.220,1.00000,1.00,707.355,1.00000,1000000,2368.79,1.00000,1000000,1.00000
17683.9,0.555278,426.614,1.00000,1.00,707.355,1.00000,1000000,2294.12,1.00000,1000000,1.00000
17683.9,0.595183,825.364,1.00000,1.00,707.355,1.00000,1000000,1996.81,1.00000,1000000,1.00000
17683.9,0.636273,679.583,1.00000,1.00,707.355,1.00000,1000000,1747.23,1.00000,1000000,1.00000
17683.9,0.646427,379.133,1.00000,1.00,707.355,1.00000,1000000,1692.77,1.00000,1000000,1.00000
17683.9,0.666556,763.644,1.00000,1.00,707.355,1.00000,1000000,1592.08,1.00000,1000000,1.00000
17683.9,0.740853,607.230,1.00000,1.00,707.355,1.00000,1000000,1288.76,1.00000,1000000,1.00000
17683.9,0.746683,705.232,1.00000,1.00,707.355,1.00000,1000000,1268.72,1.00000,1000000,1.00000
17683.9,0.752553,342.135,1.00000,1.00,707.355,1.00000,1000000,1249.00,1.00000,1000000,1.00000
17683.9,0.835246,651.309,1.00000,1.00,707.355,1.00000,1000000,1013.93,1.00000,1000000,1.00000
17683.9,0.862621,533.193,1.00000,1.00,707.355,1.00000,1000000,950.599,1.00000,1000000,1.00000
17683.9,0.876086,304.604,1.00000,1.00,707.355,1.00000,1000000,921.604,1.00000,1000000,1.00000
17683.9,0.934449,600.108,1.00000,1.00,707.355,1.00000,1000000,810.077,1.00000,1000000,1.00000
17683.9,1.00440,476.426,1.00000,1.00,707.355,1.00000,1000000,701.171,1.00000,1000000,1.00000
17683.9,1.01990,270.702,1.00000,1.00,707.355,1.00000,1000000,680.021,1.00000,1000000,1.00000
17683.9,1.04640,551.547,1.00000,1.00,707.355,1.00000,1000000,646.014,1.00000,1000000,1.00000
17683.9,1.16949,422.741,1.00000,1.00,707.355,1.00000,1000000,517.183,1.00000,1000000,1.00000
17683.9,1.17203,507.315,1.00000,1.00,707.355,1.00000,1000000,514.944,1.00000,1000000,1.00000
17683.9,1.18734,244.286,1.00000,1.00,707.355,1.00000,1000000,501.750,1.00000,1000000,1.00000
17683.9,1.31107,467.767,1.00000,1.00,707.355,1.00000,1000000,411.515,1.00000,1000000,1.00000
17683.9,1.36171,377.733,1.00000,1.00,707.355,1.00000,1000000,381.477,1.00000,1000000,1.00000
17683.9,1.38224,217.488,1.00000,1.00,707.355,1.00000,1000000,370.229,1.00000,1000000,1.00000
17683.9,1.46661,430.060,1.00000,1.00,707.355,1.00000,1000000,328.858,1.00000,1000000,1.00000
17683.9,1.58552,337.223,1.00000,1.00,707.355,1.00000,1000000,281.381,1.00000,1000000,1.00000
17683.9,1.60913,193.108,1.00000,1.00,707.355,1.00000,1000000,273.184,1.00000,1000000,1.00000
17683.9,1.64076,394.811,1.00000,1.00,707.355,1.00000,1000000,262.753,1.00000,1000000,1.00000
17683.9,1.83791,363.666,1.00000,1.00,707.355,1.00000,1000000,209.406,1.00000,1000000,1.00000
17683.9,1.84613,298.441,1.00000,1.00,707.355,1.00000,1000000,207.545,1.00000,1000000,1.00000
17683.9,1.87327,171.461,1.00000,1.00,707.355,1.00000,1000000,201.575,1.00000,1000000,1.00000
17683.9,2.05778,335.722,1.00000,1.00,707.355,1.00000,1000000,167.047,1.00000,1000000,1.00000
17683.9,2.14956,265.275,1.00000,1.00,707.355,1.00000,1000000,153.087,1.00000,1000000,1.00000
17683.9,2.18082,155.288,1.00000,1.00,707.355,1.00000,1000000,148.730,1.00000,1000000,1.00000
17683.9,2.30184,309.675,1.00000,1.00,707.355,1.00000,1000000,133.502,1.00000,1000000,1.00000
17683.9,2.50287,238.692,1.00000,1.00,707.355,1.00000,1000000,112.917,1.00000,1000000,1.00000
17683.9,2.53881,138.253,1.00000,1.00,707.355,1.00000,1000000,109.743,1.00000,1000000,1.00000
17683.9,2.57527,286.998,1.00000,1.00,707.355,1.00000,1000000,106.658,1.00000,1000000,1.00000
17683.9,2.88436,262.873,1.00000,1.00,707.355,1.00000,1000000,85.0234,1.00000,1000000,1.00000
17683.9,2.91424,211.981,1.00000,1.00,707.355,1.00000,1000000,83.2889,1.00000,1000000,1.00000
17683.9,2.95568,127.030,1.00000,1.00,707.355,1.00000,1000000,80.9698,1.00000,1000000,1.00000
17683.9,3.23019,237.922,1.00000,1.00,707.355,1.00000,1000000,67.7925,1.00000,1000000,1.00000
17683.9,3.39323,185.648,1.00000,1.00,707.355,1.00000,1000000,61.4343,1.00000,1000000,1.00000
17683.9,3.44098,116.193,1.00000,1.00,707.355,1.00000,1000000,59.7411,1.00000,1000000,1.00000
17683.9,3.61412,212.700,1.00000,1.00,707.355,1.00000,1000000,54.1542,1.00000,1000000,1.00000
17683.9,3.95095,164.298,1.00000,1.00,707.355,1.00000,1000000,45.3142,1.00000,1000000,1.00000
17683.9,4.00603,107.726,1.00000,1.00,707.355,1.00000,1000000,44.0767,1.00000,1000000,1.00000
17683.9,4.04322,187.922,1.00000,1.00,707.355,1.00000,1000000,43.2696,1.00000,1000000,1.00000
17683.9,4.52283,162.155,1.00000,1.00,707.355,1.00000,1000000,34.5794,1.00000,1000000,1.00000
17683.9,4.60034,143.512,1.00000,1.00,707.355,1.00000,1000000,33.4239,1.00000,1000000,1.00000
17683.9,4.66374,97.6522,1.00000,1.00,707.355,1.00000,1000000,32.5214,1.00000,1000000,1.00000
17683.9,5.06539,139.401,1.00000,1.00,707.355,1.00000,1000000,27.5684,1.00000,1000000,1.00000
17683.9,5.35647,128.121,1.00000,1.00,707.355,1.00000,1000000,24.6536,1.00000,1000000,1.00000
17683.9,5.42918,85.3111,1.00000,1.00,707.355,1.00000,1000000,23.9977,1.00000,1000000,1.00000
17683.9,5.67285,120.638,1.00000,1.00,707.355,1.00000,1000000,21.9804,1.00000,1000000,1.00000
17683.9,6.23687,115.082,1.00000,1.00,707.355,1.00000,1000000,18.1846,1.00000,1000000,1.00000
17683.9,6.32010,73.1991,1.00000,1.00,707.355,1.00000,1000000,17.7088,1.00000,1000000,1.00000
17683.9,6.34492,103.458,1.00000,1.00,707.355,1.00000,1000000,17.5705,1.00000,1000000,1.00000
17683.9,7.09803,86.4177,1.00000,1.00,707.355,1.00000,1000000,14.0398,1.00000,1000000,1.00000
17683.9,7.26198,102.740,1.00000,1.00,707.355,1.00000,1000000,13.4130,1.00000,1000000,1.00000
17683.9,7.35760,65.4047,1.00000,1.00,707.355,1.00000,1000000,13.0667,1.00000,1000000,1.00000
17683.9,7.94880,71.8166,1.00000,1.00,707.355,1.00000,1000000,11.1953,1.00000,1000000,1.00000
17683.9,8.45557,89.1176,1.00000,1.00,707.355,1.00000,1000000,9.89354,1.00000,1000000,1.00000
17683.9,8.56599,61.6855,1.00000,1.00,707.355,1.00000,1000000,9.64012,1.00000,1000000,1.00000
17683.9,8.90242,59.7317,1.00000,1.00,707.355,1.00000,1000000,8.92527,1.00000,1000000,1.00000
17683.9,9.84535,78.4570,1.00000,1.00,707.355,1.00000,1000000,7.29752,1.00000,1000000,1.00000
17683.9,9.95811,50.0733,1.00000,1.00,707.355,1.00000,1000000,7.13319,1.00000,1000000,1.00000
17683.9,9.97208,54.7213,1.00000,1.00,707.355,1.00000,1000000,7.11322,1.00000,1000000,1.00000
17683.9,11.1404,41.4925,1.00000,1.00,707.355,1.00000,1000000,5.69949,1.00000,1000000,1.00000
17683.9,11.4636,70.9657,1.00000,1.00,707.355,1.00000,1000000,5.38264,1.00000,1000000,1.00000
17683.9,11.6085,47.1642,1.00000,1.00,707.355,1.00000,1000000,5.24911,1.00000,1000000,1.00000
17683.9,12.4772,35.7847,1.00000,1.00,707.355,1.00000,1000000,4.54363,1.00000,1000000,1.00000
17683.9,13.3477,60.2806,1.00000,1.00,707.355,1.00000,1000000,3.97031,1.00000,1000000,1.00000
17683.9,13.5151,44.4422,1.00000,1.00,707.355,1.00000,1000000,3.87257,1.00000,1000000,1.00000
17683.9,13.9708,31.1120,1.00000,1.00,707.355,1.00000,1000000,3.62406,1.00000,1000000,1.00000
17683.9,15.5416,54.0983,1.00000,1.00,707.355,1.00000,1000000,2.92851,1.00000,1000000,1.00000
17683.9,15.6305,27.9924,1.00000,1.00,707.355,1.00000,1000000,2.89529,1.00000,1000000,1.00000
17683.9,15.7331,38.4429,1.00000,1.00,707.355,1.00000,1000000,2.85765,1.00000,1000000,1.00000
17683.9,17.4854,24.3269,1.00000,1.00,707.355,1.00000,1000000,2.31359,1.00000,1000000,1.00000
17683.9,18.0961,47.3368,1.00000,1.00,707.355,1.00000,1000000,2.16007,1.00000,1000000,1.00000
17683.9,18.3165,35.3857,1.00000,1.00,707.355,1.00000,1000000,2.10840,1.00000,1000000,1.00000
17683.9,19.5608,21.1069,1.00000,1.00,707.355,1.00000,1000000,1.84869,1.00000,1000000,1.00000
17683.9,21.0704,41.8929,1.00000,1.00,707.355,1.00000,1000000,1.59328,1.00000,1000000,1.00000
17683.9,21.3227,30.9974,1.00000,1.00,707.355,1.00000,1000000,1.55580,1.00000,1000000,1.00000
17683.9,21.9089,18.4090,1.00000,1.00,707.355,1.00000,1000000,1.47366,1.00000,1000000,1.00000
17683.9,24.5317,16.2113,1.00000,1.00,707.355,1.00000,1000000,1.17539,1.00000,1000000,1.00000
17683.9,24.5336,36.5292,1.00000,1.00,707.355,1.00000,1000000,1.17521,1.00000,1000000,1.00000
17683.9,24.8231,27.7967,1.00000,1.00,707.355,1.00000,1000000,1.14796,1.00000,1000000,1.00000
17683.9,27.4470,14.0275,1.00000,1.00,707.355,1.00000,1000000,0.938962,1.00000,1000000,1.00000
17683.9,28.5659,32.5831,1.00000,1.00,707.355,1.00000,1000000,0.866846,1.00000,1000000,1.00000
17683.9,28.8986,25.2201,1.00000,1.00,707.355,1.00000,1000000,0.847001,1.00000,1000000,1.00000
17683.9,30.6997,12.7719,1.00000,1.00,707.355,1.00000,1000000,0.750532,1.00000,1000000,1.00000
17683.9,33.2611,28.5855,1.00000,1.00,707.355,1.00000,1000000,0.639388,1.00000,1000000,1.00000
17683.9,33.6419,22.1922,1.00000,1.00,707.355,1.00000,1000000,0.624995,1.00000,1000000,1.00000
17683.9,34.3848,11.6380,1.00000,1.00,707.355,1.00000,1000000,0.598280,1.00000,1000000,1.00000
17683.9,38.5112,10.4470,1.00000,1.00,707.355,1.00000,1000000,0.476940,1.00000,1000000,1.00000
17683.9,38.7280,25.1221,1.00000,1.00,707.355,1.00000,1000000,0.471615,1.00000,1000000,1.00000
17683.9,39.1651,20.0446,1.00000,1.00,707.355,1.00000,1000000,0.461147,1.00000,1000000,1.00000
17683.9,43.0759,9.54448,1.00000,1.00,707.355,1.00000,1000000,0.381214,1.00000,1000000,1.00000
17683.9,45.0934,22.0783,1.00000,1.00,707.355,1.00000,1000000,0.347866,1.00000,1000000,1.00000
11.6118,45.5941,17.8297,0.0327840,20.00,27793.7,39.2925,20.0195,13.3699,0.0327840,656.630,-2.75026e-4
222.721,48.1893,8.58870,28.5082,19.99,25378.5,35.8780,20.0255,10.9286,28.5082,12594.6,1.06183e-4
244.084,52.5051,19.4202,33.2923,20.00,25031.5,35.3875,20.0022,9.07996,33.2923,13802.6,1.24573e-4
269.242,53.0783,15.8453,40.6324,19.99,24471.7,34.5961,19.9987,8.68622,40.6324,15225.3,1.49695e-4
290.574,53.9127,7.49232,47.9724,20.00,23901.7,33.7903,20.0023,8.22332,47.9724,16431.5,1.68611e-4
311.912,60.3816,6.91888,55.3124,20.00,23293.1,32.9299,19.9863,6.38879,55.3124,17638.2,1.85474e-4
334.970,61.1350,17.1120,62.7180,19.99,22670.8,32.0501,20.0035,6.06579,62.7180,18942.1,2.03632e-4
360.481,61.7920,14.2348,70.1236,20.00,22017.5,31.1266,19.9972,5.76639,70.1236,20384.7,2.24496e-4
384.890,67.6005,6.27747,77.4636,20.00,21319.2,30.1393,19.9901,4.66521,77.4636,21765.0,2.47060e-4
411.298,71.1832,15.0387,84.8036,20.00,20550.0,29.0519,20.0001,4.05562,84.8036,23258.3,2.78483e-4
435.230,71.9361,12.7764,92.1436,20.00,19669.6,27.8072,19.9915,3.80103,92.1436,24611.7,3.05341e-4
455.814,75.6452,5.68689,99.4837,20.00,18762.3,26.5246,20.0021,3.27886,99.4837,25775.7,3.41731e-4
472.171,82.8831,13.2282,106.889,20.00,17802.7,25.1679,19.9917,2.59151,106.889,26700.6,3.87342e-4
481.437,83.7439,11.3034,114.295,20.00,16901.0,23.8933,19.9971,2.40994,114.295,27224.6,4.35459e-4
482.155,84.6097,5.26158,121.635,20.00,16131.7,22.8057,19.9940,2.25341,121.635,27265.2,4.88726e-4
475.482,94.5740,4.86280,128.975,20.00,15488.2,21.8959,19.9936,1.73164,128.975,26887.9,5.42709e-4
465.541,96.5060,11.6560,136.315,20.00,15086.9,21.3286,19.9957,1.61991,136.315,26325.7,5.95839e-4
454.854,97.4926,10.2188,143.655,20.00,14821.0,20.9527,20.0073,1.55932,143.655,25721.4,6.51253e-4
445.015,112.368,10.2437,151.061,20.00,14588.7,20.6243,19.9962,1.15540,151.061,25165.0,7.09889e-4
436.465,113.496,9.08961,158.466,20.00,14391.2,20.3451,20.0098,1.11721,158.466,24681.5,7.74354e-4
428.929,130.837,9.00260,165.806,20.00,14250.5,20.1462,20.0035,0.832471,165.806,24255.4,8.46228e-4
422.758,132.127,8.08523,173.146,20.00,14136.1,19.9844,20.0100,0.809739,173.146,23906.4,9.24888e-4
417.748,152.342,7.89117,180.486,20.00,14078.6,19.9032,20.0098,0.606626,180.486,23623.1,1.00854e-3
413.116,153.816,7.19184,187.826,20.00,13986.1,19.7723,20.0020,0.591143,187.826,23361.2,1.10715e-3
409.381,177.381,6.97757,195.232,20.00,13913.7,19.6701,20.0182,0.442211,195.232,23150.0,1.20855e-3
405.580,179.063,6.35695,202.637,20.00,13820.7,19.5385,20.0124,0.431039,202.637,22935.0,1.32574e-3
402.264,206.536,6.11614,209.977,19.99,13735.2,19.4177,20.0109,0.321992,209.977,22747.5,1.44499e-3
400.359,208.460,5.72628,217.317,20.00,13709.8,19.3818,20.0164,0.315490,217.317,22639.8,1.58791e-3
398.760,240.482,5.27751,224.657,20.00,13638.7,19.2812,20.0136,0.235835,224.657,22549.3,1.73423e-3
396.863,242.675,5.03425,231.997,20.00,13568.7,19.1823,20.0151,0.230403,231.997,22442.1,1.90649e-3
395.917,280.009,4.66244,239.403,20.00,13530.6,19.1284,20.0160,0.172573,239.403,22388.6,2.08271e-3
394.120,282.513,4.50224,246.809,20.00,13484.6,19.0634,20.0162,0.168951,246.809,22286.9,2.27990e-3
392.001,326.032,4.08682,254.149,20.00,13467.8,19.0396,20.0202,0.126700,254.149,22167.1,2.50001e-3
390.751,328.888,4.00837,261.489,20.00,13437.0,18.9961,20.0149,0.124224,261.489,22096.5,2.74211e-3
389.699,379.619,3.52645,268.829,20.00,13394.8,18.9365,20.0149,0.0929484,268.829,22037.0,2.99491e-3
388.456,382.869,3.51761,276.169,20.00,13411.6,18.9601,20.0227,0.0914911,276.169,21966.7,3.28322e-3
387.417,442.014,3.04025,283.574,20.00,13406.7,18.9533,20.0153,0.0686198,283.574,21907.9,3.60112e-3
384.596,445.713,3.10366,290.980,20.00,13414.2,18.9638,20.0148,0.0675232,290.980,21748.4,3.93725e-3
384.266,514.665,2.68592,298.320,20.00,13413.3,18.9626,20.0167,0.0506391,298.320,21729.7,4.31559e-3
384.165,518.881,2.77317,305.660,20.00,13425.0,18.9792,20.0192,0.0498631,305.660,21724.0,4.72804e-3
385.666,599.256,2.33184,313.000,20.00,13462.1,19.0316,20.0281,0.0374877,313.000,21808.9,5.16819e-3
386.489,604.056,2.46675,320.340,20.00,13471.8,19.0454,20.0235,0.0369209,320.340,21855.5,5.66849e-3
386.221,697.751,2.02620,327.746,20.00,13466.5,19.0378,20.0171,0.0276601,327.746,21840.3,6.21167e-3
385.042,703.220,2.21204,335.151,20.00,13497.5,19.0817,20.0185,0.0272943,335.151,21773.6,6.80361e-3
384.381,812.435,1.79005,342.491,20.00,13557.6,19.1667,20.0140,0.0205403,342.491,21736.2,7.45415e-3
385.223,818.661,1.98006,349.831,20.00,13632.1,19.2719,20.0306,0.0203401,349.831,21783.8,8.15303e-3
387.120,945.969,1.52985,357.171,20.00,13714.1,19.3879,20.0289,0.0153255,357.171,21891.1,8.93718e-3
389.888,953.045,1.76127,364.511,20.00,13744.3,19.4305,20.0264,0.0151320,364.511,22047.6,9.77361e-3
394.107,1101.45,1.32008,371.917,20.00,13758.7,19.4510,20.0251,0.0113409,371.917,22286.2,0.0107142
397.041,1109.49,1.56665,379.322,20.00,13685.9,19.3479,20.0142,0.0111180,379.322,22452.2,0.0117527
395.588,1282.49,1.11741,386.662,20.00,13657.9,19.3085,20.0184,8.30381e-3,386.662,22370.0,0.0128693
394.543,1291.62,1.39983,394.002,20.00,13627.5,19.2654,20.0263,8.16857e-3,394.002,22310.9,0.0140942
395.053,1493.28,0.993231,401.342,20.00,13574.4,19.1903,20.0137,6.08748e-3,401.342,22339.7,0.0154273
396.082,1503.66,1.25755,408.683,20.00,13547.0,19.1516,20.0178,5.99162e-3,408.683,22397.9,0.0168871
398.995,1738.72,0.870609,416.088,20.00,13458.5,19.0265,20.0184,4.45181e-3,416.088,22562.6,0.0185146
397.420,1750.51,1.12770,423.494,20.00,13497.4,19.0816,20.0114,4.40476e-3,423.494,22473.6,0.0202955
401.375,2024.50,0.776562,430.834,20.00,13606.3,19.2355,20.0148,3.31975e-3,430.834,22697.2,0.0222143
400.199,2037.84,0.997686,438.174,20.00,13838.2,19.5633,20.0128,3.33227e-3,438.174,22630.7,0.0243184
408.897,2357.25,0.689057,445.514,20.00,13916.4,19.6738,20.0209,2.50446e-3,445.514,23122.6,0.0266390
410.141,2372.36,0.889044,452.854,20.00,13755.4,19.4463,20.0176,2.44407e-3,452.854,23192.9,0.0291675
400.981,2744.70,0.615695,460.259,20.00,13590.5,19.2131,20.0180,1.80403e-3,460.259,22674.9,0.0319839
407.838,2761.73,0.777389,467.665,20.00,13990.8,19.7790,20.0299,1.83434e-3,467.665,23062.7,0.0350177
415.649,3195.82,0.545841,475.005,20.00,14106.6,19.9427,20.0153,1.38120e-3,475.005,23504.4,0.0383583
415.991,3214.95,0.671843,482.345,20.00,13736.6,19.4196,20.0202,1.32901e-3,482.345,23523.7,0.0420114
414.604,3665.62,0.569428,489.685,20.00,13577.0,19.1941,20.0140,1.01044e-3,489.685,23445.3,0.0459898
421.021,3721.10,0.498484,497.025,20.00,13555.1,19.1631,20.0193,9.78949e-4,497.025,23808.2,0.0503718
415.923,4009.14,0.442187,504.431,20.00,13200.4,18.6617,20.0150,8.21269e-4,504.431,23519.9,0.0552100
415.926,4185.42,0.440580,511.836,20.00,13299.7,18.8020,20.0167,7.59214e-4,511.836,23520.1,0.0604838
417.997,4476.97,0.355072,519.176,20.00,13225.7,18.6974,20.0137,6.59859e-4,519.176,23637.2,0.0662428
411.815,4485.17,0.354147,526.516,20.00,12951.4,18.3096,20.0107,6.43812e-4,526.516,23287.6,0.0725504
406.763,4975.53,0.296330,533.856,20.00,12754.6,18.0315,20.0165,5.15216e-4,533.856,23001.9,0.0794237
407.958,5175.45,0.292533,541.196,20.00,12931.5,18.2814,20.0391,4.82783e-4,541.196,23069.5,0.0869654
410.938,5699.94,0.233151,548.602,20.00,13185.5,18.6405,20.0103,4.05840e-4,548.602,23238.0,0.0953062
416.975,5793.32,0.260654,556.007,20.00,13412.1,18.9609,20.0255,3.99614e-4,556.007,23579.4,0.104454
421.102,6321.49,0.194016,563.347,20.00,13671.2,19.3272,20.0346,3.42112e-4,563.347,23812.8,0.114357
426.057,6745.52,0.228076,570.688,20.00,13437.7,18.9971,20.0140,2.95321e-4,570.688,24092.9,0.125235
417.896,7360.50,0.198972,578.028,20.00,13071.3,18.4791,20.0097,2.41270e-4,578.028,23631.5,0.137158
408.553,7854.23,0.215876,585.368,20.00,12822.5,18.1274,20.0098,2.07858e-4,585.368,23103.1,0.150183
401.995,8570.59,0.209831,592.773,20.00,12731.0,17.9980,20.0308,1.73316e-4,592.773,22732.3,0.164568
411.996,9145.17,0.201671,600.179,20.00,13152.5,18.5939,20.0289,1.57262e-4,600.179,23297.8,0.180347
420.305,9978.50,0.202406,607.519,20.00,13507.2,19.0954,20.0250,1.35655e-4,607.519,23767.7,0.197458
411.771,10648.3,0.199744,614.859,20.00,13025.7,18.4146,20.0167,1.14879e-4,614.859,23285.1,0.216267
395.599,11617.6,0.194191,622.199,20.00,12598.6,17.8109,20.0197,9.33450e-5,622.199,22370.6,0.236821
402.920,12398.5,0.183053,629.539,20.00,13089.0,18.5042,20.0347,8.51470e-5,629.539,22784.6,0.259256
412.675,13525.3,0.179070,636.944,20.00,13199.5,18.6604,20.0147,7.21547e-5,636.944,23336.2,0.284172
393.210,14436.3,0.177082,644.350,20.00,12613.5,17.8318,20.0196,6.05232e-5,644.350,22235.5,0.311412
400.290,15422.4,0.160996,651.690,20.00,13084.6,18.4979,20.0303,5.50119e-5,651.690,22635.9,0.340966
401.602,16014.6,0.169929,659.030,20.00,12916.4,18.2601,20.0184,5.03626e-5,659.030,22710.0,0.373408