File: myThesis/Viscosity/csv/peo_su8_all_025.csv
Filename,peo_su8_all_025
Instrument name,5333-0457
Operator,Osamu Katagiri
rundate,28/01/2020
Sample name,PEO_SU8_01_025
Geometry name,60mm 0.9969° cone plate, Peltier plate Steel
Procedure name,Sample
,Flow ramp
proceduresegments,Flow ramp
[step]
Flow ramp - 1
Stress,Shear rate,Viscosity,Step time,Temperature,Normal stress,Axial force,Gap,Normal stress coefficient,Time,Torque,Velocity
Pa,1/s,Pa.s,s,°C,Pa,N,µm,Pa.s²,s,µN.m,rad/s
,6.01000e-3,30.2489,,,,,,,,,
17683.9,6.81000e-3,30.0000,1.00000,1.00,707.355,1.00000,1000000,1.52526e7,1.00000,1000000,1.00000
17683.9,7.38000e-3,22.7615,1.00000,1.00,707.355,1.00000,1000000,1.29875e7,1.00000,1000000,1.00000
17683.9,7.75000e-3,29.5027,1.00000,1.00,707.355,1.00000,1000000,1.17770e7,1.00000,1000000,1.00000
17683.9,8.24000e-3,21.9635,1.00000,1.00,707.355,1.00000,1000000,1.04180e7,1.00000,1000000,1.00000
17683.9,8.86000e-3,27.7220,1.00000,1.00,707.355,1.00000,1000000,9010940,1.00000,1000000,1.00000
17683.9,9.22000e-3,20.4903,1.00000,1.00,707.355,1.00000,1000000,8321000,1.00000,1000000,1.00000
17683.9,0.0101153,25.3831,1.00000,1.00,707.355,1.00000,1000000,6913210,1.00000,1000000,1.00000
17683.9,0.0103111,19.0181,1.00000,1.00,707.355,1.00000,1000000,6653160,1.00000,1000000,1.00000
17683.9,0.0115370,17.1805,1.00000,1.00,707.355,1.00000,1000000,5314370,1.00000,1000000,1.00000
17683.9,0.0115535,23.4141,1.00000,1.00,707.355,1.00000,1000000,5299200,1.00000,1000000,1.00000
17683.9,0.0129267,15.3739,1.00000,1.00,707.355,1.00000,1000000,4233140,1.00000,1000000,1.00000
17683.9,0.0131962,21.7179,1.00000,1.00,707.355,1.00000,1000000,4062000,1.00000,1000000,1.00000
17683.9,0.0144762,13.7327,1.00000,1.00,707.355,1.00000,1000000,3375430,1.00000,1000000,1.00000
17683.9,0.0150722,19.8856,1.00000,1.00,707.355,1.00000,1000000,3113750,1.00000,1000000,1.00000
17683.9,0.0161837,12.3072,1.00000,1.00,707.355,1.00000,1000000,2700730,1.00000,1000000,1.00000
17683.9,0.0172148,18.2079,1.00000,1.00,707.355,1.00000,1000000,2386900,1.00000,1000000,1.00000
17683.9,0.0181075,11.0474,1.00000,1.00,707.355,1.00000,1000000,2157350,1.00000,1000000,1.00000
17683.9,0.0196626,16.9097,1.00000,1.00,707.355,1.00000,1000000,1829600,1.00000,1000000,1.00000
17683.9,0.0202864,9.93591,1.00000,1.00,707.355,1.00000,1000000,1718810,1.00000,1000000,1.00000
17683.9,0.0224584,15.6847,1.00000,1.00,707.355,1.00000,1000000,1402430,1.00000,1000000,1.00000
17683.9,0.0227202,8.99211,1.00000,1.00,707.355,1.00000,1000000,1370290,1.00000,1000000,1.00000
17683.9,0.0254093,8.18237,1.00000,1.00,707.355,1.00000,1000000,1095600,1.00000,1000000,1.00000
17683.9,0.0256514,14.4591,1.00000,1.00,707.355,1.00000,1000000,1075020,1.00000,1000000,1.00000
17683.9,0.0284293,7.44653,1.00000,1.00,707.355,1.00000,1000000,875196,1.00000,1000000,1.00000
17683.9,0.0292983,13.3293,1.00000,1.00,707.355,1.00000,1000000,824049,1.00000,1000000,1.00000
17683.9,0.0318065,6.74768,1.00000,1.00,707.355,1.00000,1000000,699207,1.00000,1000000,1.00000
17683.9,0.0334638,12.2877,1.00000,1.00,707.355,1.00000,1000000,631665,1.00000,1000000,1.00000
17683.9,0.0356264,6.08544,1.00000,1.00,707.355,1.00000,1000000,557306,1.00000,1000000,1.00000
17683.9,0.0382214,11.3275,1.00000,1.00,707.355,1.00000,1000000,484200,1.00000,1000000,1.00000
17683.9,0.0398924,5.42238,1.00000,1.00,707.355,1.00000,1000000,444485,1.00000,1000000,1.00000
17683.9,0.0436562,10.5199,1.00000,1.00,707.355,1.00000,1000000,371147,1.00000,1000000,1.00000
17683.9,0.0446307,4.81222,1.00000,1.00,707.355,1.00000,1000000,355116,1.00000,1000000,1.00000
17683.9,0.0498644,9.83028,1.00000,1.00,707.355,1.00000,1000000,284483,1.00000,1000000,1.00000
17683.9,0.0498955,4.23359,1.00000,1.00,707.355,1.00000,1000000,284129,1.00000,1000000,1.00000
17683.9,0.0559257,3.70931,1.00000,1.00,707.355,1.00000,1000000,226159,1.00000,1000000,1.00000
17683.9,0.0569546,9.11817,1.00000,1.00,707.355,1.00000,1000000,218062,1.00000,1000000,1.00000
17683.9,0.0625331,3.27317,1.00000,1.00,707.355,1.00000,1000000,180891,1.00000,1000000,1.00000
17683.9,0.0650530,8.46807,1.00000,1.00,707.355,1.00000,1000000,167149,1.00000,1000000,1.00000
17683.9,0.0699676,2.93709,1.00000,1.00,707.355,1.00000,1000000,144492,1.00000,1000000,1.00000
17683.9,0.0743028,7.85463,1.00000,1.00,707.355,1.00000,1000000,128123,1.00000,1000000,1.00000
17683.9,0.0782798,2.65941,1.00000,1.00,707.355,1.00000,1000000,115435,1.00000,1000000,1.00000
17683.9,0.0848668,7.24086,1.00000,1.00,707.355,1.00000,1000000,98211.4,1.00000,1000000,1.00000
17683.9,0.0875856,2.42911,1.00000,1.00,707.355,1.00000,1000000,92208.8,1.00000,1000000,1.00000
17683.9,0.0969341,6.72461,1.00000,1.00,707.355,1.00000,1000000,75280.8,1.00000,1000000,1.00000
17683.9,0.0981052,2.22746,1.00000,1.00,707.355,1.00000,1000000,73494.3,1.00000,1000000,1.00000
17683.9,0.109884,2.04740,1.00000,1.00,707.355,1.00000,1000000,58582.6,1.00000,1000000,1.00000
17683.9,0.110719,6.28378,1.00000,1.00,707.355,1.00000,1000000,57702.3,1.00000,1000000,1.00000
17683.9,0.122936,1.87753,1.00000,1.00,707.355,1.00000,1000000,46803.6,1.00000,1000000,1.00000
17683.9,0.126462,5.82858,1.00000,1.00,707.355,1.00000,1000000,44230.1,1.00000,1000000,1.00000
17683.9,0.137546,1.71068,1.00000,1.00,707.355,1.00000,1000000,37388.8,1.00000,1000000,1.00000
17683.9,0.144444,5.41302,1.00000,1.00,707.355,1.00000,1000000,33903.0,1.00000,1000000,1.00000
17683.9,0.154044,1.56758,1.00000,1.00,707.355,1.00000,1000000,29809.0,1.00000,1000000,1.00000
17683.9,0.164979,4.98697,1.00000,1.00,707.355,1.00000,1000000,25988.4,1.00000,1000000,1.00000
17683.9,0.172542,1.45437,1.00000,1.00,707.355,1.00000,1000000,23760.1,1.00000,1000000,1.00000
17683.9,0.188435,4.60011,1.00000,1.00,707.355,1.00000,1000000,19921.2,1.00000,1000000,1.00000
17683.9,0.192978,1.30745,1.00000,1.00,707.355,1.00000,1000000,18994.2,1.00000,1000000,1.00000
17683.9,0.215229,4.26688,1.00000,1.00,707.355,1.00000,1000000,15269.9,1.00000,1000000,1.00000
17683.9,0.215977,1.18133,1.00000,1.00,707.355,1.00000,1000000,15164.3,1.00000,1000000,1.00000
17683.9,0.241835,1.05254,1.00000,1.00,707.355,1.00000,1000000,12094.8,1.00000,1000000,1.00000
17683.9,0.245833,3.96266,1.00000,1.00,707.355,1.00000,1000000,11704.6,1.00000,1000000,1.00000
17683.9,0.270873,0.934253,1.00000,1.00,707.355,1.00000,1000000,9640.65,1.00000,1000000,1.00000
17683.9,0.280792,3.70289,1.00000,1.00,707.355,1.00000,1000000,8971.56,1.00000,1000000,1.00000
17683.9,0.303006,0.823563,1.00000,1.00,707.355,1.00000,1000000,7704.34,1.00000,1000000,1.00000
17683.9,0.320717,3.43465,1.00000,1.00,707.355,1.00000,1000000,6876.91,1.00000,1000000,1.00000
17683.9,0.339022,0.746494,1.00000,1.00,707.355,1.00000,1000000,6154.34,1.00000,1000000,1.00000
17683.9,0.366320,3.18977,1.00000,1.00,707.355,1.00000,1000000,5271.28,1.00000,1000000,1.00000
17683.9,0.379260,0.668797,1.00000,1.00,707.355,1.00000,1000000,4917.72,1.00000,1000000,1.00000
17683.9,0.418407,2.95870,1.00000,1.00,707.355,1.00000,1000000,4040.54,1.00000,1000000,1.00000
17683.9,0.424661,0.609387,1.00000,1.00,707.355,1.00000,1000000,3922.41,1.00000,1000000,1.00000
17683.9,0.475677,0.554909,1.00000,1.00,707.355,1.00000,1000000,3126.17,1.00000,1000000,1.00000
17683.9,0.477893,2.72750,1.00000,1.00,707.355,1.00000,1000000,3097.25,1.00000,1000000,1.00000
17683.9,0.532154,0.507453,1.00000,1.00,707.355,1.00000,1000000,2497.83,1.00000,1000000,1.00000
17683.9,0.545837,2.51437,1.00000,1.00,707.355,1.00000,1000000,2374.17,1.00000,1000000,1.00000
17683.9,0.595340,0.463378,1.00000,1.00,707.355,1.00000,1000000,1995.76,1.00000,1000000,1.00000
17683.9,0.623441,2.31790,1.00000,1.00,707.355,1.00000,1000000,1819.90,1.00000,1000000,1.00000
17683.9,0.666668,0.428940,1.00000,1.00,707.355,1.00000,1000000,1591.54,1.00000,1000000,1.00000
17683.9,0.712078,2.13678,1.00000,1.00,707.355,1.00000,1000000,1395.03,1.00000,1000000,1.00000
17683.9,0.746650,0.395675,1.00000,1.00,707.355,1.00000,1000000,1268.83,1.00000,1000000,1.00000
17683.9,0.813329,1.98443,1.00000,1.00,707.355,1.00000,1000000,1069.31,1.00000,1000000,1.00000
17683.9,0.835293,0.369983,1.00000,1.00,707.355,1.00000,1000000,1013.82,1.00000,1000000,1.00000
17683.9,0.928962,1.82824,1.00000,1.00,707.355,1.00000,1000000,819.675,1.00000,1000000,1.00000
17683.9,0.934260,0.344170,1.00000,1.00,707.355,1.00000,1000000,810.405,1.00000,1000000,1.00000
17683.9,1.04655,0.320592,1.00000,1.00,707.355,1.00000,1000000,645.829,1.00000,1000000,1.00000
17683.9,1.06104,1.68642,1.00000,1.00,707.355,1.00000,1000000,628.310,1.00000,1000000,1.00000
17683.9,1.17199,0.293603,1.00000,1.00,707.355,1.00000,1000000,514.979,1.00000,1000000,1.00000
17683.9,1.21192,1.57586,1.00000,1.00,707.355,1.00000,1000000,481.604,1.00000,1000000,1.00000
17683.9,1.31095,0.267610,1.00000,1.00,707.355,1.00000,1000000,411.590,1.00000,1000000,1.00000
17683.9,1.38423,1.45183,1.00000,1.00,707.355,1.00000,1000000,369.165,1.00000,1000000,1.00000
17683.9,1.46669,0.241020,1.00000,1.00,707.355,1.00000,1000000,328.822,1.00000,1000000,1.00000
17683.9,1.58100,1.32934,1.00000,1.00,707.355,1.00000,1000000,282.992,1.00000,1000000,1.00000
17683.9,1.64081,0.218481,1.00000,1.00,707.355,1.00000,1000000,262.737,1.00000,1000000,1.00000
17683.9,1.80581,1.23456,1.00000,1.00,707.355,1.00000,1000000,216.917,1.00000,1000000,1.00000
17683.9,1.83766,0.199350,1.00000,1.00,707.355,1.00000,1000000,209.463,1.00000,1000000,1.00000
17683.9,2.05772,0.184498,1.00000,1.00,707.355,1.00000,1000000,167.057,1.00000,1000000,1.00000
17683.9,2.06267,1.17082,1.00000,1.00,707.355,1.00000,1000000,166.256,1.00000,1000000,1.00000
17683.9,2.30195,0.173523,1.00000,1.00,707.355,1.00000,1000000,133.489,1.00000,1000000,1.00000
17683.9,2.35614,1.12484,1.00000,1.00,707.355,1.00000,1000000,127.419,1.00000,1000000,1.00000
17683.9,2.57555,0.163620,1.00000,1.00,707.355,1.00000,1000000,106.634,1.00000,1000000,1.00000
17683.9,2.69139,1.08668,1.00000,1.00,707.355,1.00000,1000000,97.6527,1.00000,1000000,1.00000
17683.9,2.88425,0.155186,1.00000,1.00,707.355,1.00000,1000000,85.0299,1.00000,1000000,1.00000
17683.9,3.07434,1.05045,1.00000,1.00,707.355,1.00000,1000000,74.8400,1.00000,1000000,1.00000
17683.9,3.22992,0.148075,1.00000,1.00,707.355,1.00000,1000000,67.8038,1.00000,1000000,1.00000
17683.9,3.51168,1.00114,1.00000,1.00,707.355,1.00000,1000000,57.3598,1.00000,1000000,1.00000
17683.9,3.61322,0.137965,1.00000,1.00,707.355,1.00000,1000000,54.1812,1.00000,1000000,1.00000
17683.9,4.01112,0.941299,1.00000,1.00,707.355,1.00000,1000000,43.9649,1.00000,1000000,1.00000
17683.9,4.04230,0.127390,1.00000,1.00,707.355,1.00000,1000000,43.2893,1.00000,1000000,1.00000
17683.9,4.52219,0.117830,1.00000,1.00,707.355,1.00000,1000000,34.5892,1.00000,1000000,1.00000
17683.9,4.58125,0.854476,1.00000,1.00,707.355,1.00000,1000000,33.7031,1.00000,1000000,1.00000
17683.9,5.06433,0.108185,1.00000,1.00,707.355,1.00000,1000000,27.5800,1.00000,1000000,1.00000
,5.20040,0.745107,,,,,,,,,
17683.9,5.67134,0.0980740,1.00000,1.00,707.355,1.00000,1000000,21.9921,1.00000,1000000,1.00000
17683.9,5.90345,0.661210,1.00000,1.00,707.355,1.00000,1000000,20.2967,1.00000,1000000,1.00000
17683.9,6.34469,0.0910553,1.00000,1.00,707.355,1.00000,1000000,17.5718,1.00000,1000000,1.00000
17683.9,6.74337,0.635634,1.00000,1.00,707.355,1.00000,1000000,15.5555,1.00000,1000000,1.00000
17683.9,7.09793,0.0848599,1.00000,1.00,707.355,1.00000,1000000,14.0402,1.00000,1000000,1.00000
17683.9,7.70350,0.637989,1.00000,1.00,707.355,1.00000,1000000,11.9196,1.00000,1000000,1.00000
17683.9,7.94884,0.0788018,1.00000,1.00,707.355,1.00000,1000000,11.1952,1.00000,1000000,1.00000
17683.9,8.69369,0.613396,1.00000,1.00,707.355,1.00000,1000000,9.35900,1.00000,1000000,1.00000
17683.9,8.90163,0.0726856,1.00000,1.00,707.355,1.00000,1000000,8.92686,1.00000,1000000,1.00000
17683.9,9.45859,0.513870,1.00000,1.00,707.355,1.00000,1000000,7.90651,1.00000,1000000,1.00000
17683.9,9.95862,0.0679026,1.00000,1.00,707.355,1.00000,1000000,7.13246,1.00000,1000000,1.00000
17683.9,10.0456,0.448097,1.00000,1.00,707.355,1.00000,1000000,7.00948,1.00000,1000000,1.00000
17683.9,10.6683,0.379258,1.00000,1.00,707.355,1.00000,1000000,6.21509,1.00000,1000000,1.00000
17683.9,11.1404,0.0636664,1.00000,1.00,707.355,1.00000,1000000,5.69949,1.00000,1000000,1.00000
17683.9,11.4670,0.312950,1.00000,1.00,707.355,1.00000,1000000,5.37945,1.00000,1000000,1.00000
17683.9,12.4766,0.0600880,1.00000,1.00,707.355,1.00000,1000000,4.54407,1.00000,1000000,1.00000
17683.9,12.7838,0.285238,1.00000,1.00,707.355,1.00000,1000000,4.32830,1.00000,1000000,1.00000
17683.9,13.9720,0.0573554,1.00000,1.00,707.355,1.00000,1000000,3.62343,1.00000,1000000,1.00000
17683.9,14.5135,0.264412,1.00000,1.00,707.355,1.00000,1000000,3.35810,1.00000,1000000,1.00000
17683.9,15.6304,0.0550206,1.00000,1.00,707.355,1.00000,1000000,2.89533,1.00000,1000000,1.00000
17683.9,15.8869,0.225926,1.00000,1.00,707.355,1.00000,1000000,2.80259,1.00000,1000000,1.00000
17683.9,16.6690,0.191824,1.00000,1.00,707.355,1.00000,1000000,2.54577,1.00000,1000000,1.00000
17683.9,17.4861,0.0524923,1.00000,1.00,707.355,1.00000,1000000,2.31341,1.00000,1000000,1.00000
17683.9,17.8057,0.146092,1.00000,1.00,707.355,1.00000,1000000,2.23110,1.00000,1000000,1.00000
17683.9,18.0822,0.166601,1.00000,1.00,707.355,1.00000,1000000,2.16339,1.00000,1000000,1.00000
17683.9,19.5617,0.0501726,1.00000,1.00,707.355,1.00000,1000000,1.84852,1.00000,1000000,1.00000
17683.9,20.1073,0.189668,1.00000,1.00,707.355,1.00000,1000000,1.74957,1.00000,1000000,1.00000
17683.9,21.6132,0.158475,1.00000,1.00,707.355,1.00000,1000000,1.51426,1.00000,1000000,1.00000
17683.9,21.9072,0.0480071,1.00000,1.00,707.355,1.00000,1000000,1.47389,1.00000,1000000,1.00000
17683.9,22.5405,0.134828,1.00000,1.00,707.355,1.00000,1000000,1.39223,1.00000,1000000,1.00000
17683.9,24.5265,0.119166,1.00000,1.00,707.355,1.00000,1000000,1.17589,1.00000,1000000,1.00000
17683.9,24.5332,0.0457361,1.00000,1.00,707.355,1.00000,1000000,1.17525,1.00000,1000000,1.00000
17683.9,26.5254,0.103383,1.00000,1.00,707.355,1.00000,1000000,1.00534,1.00000,1000000,1.00000
17683.9,27.1650,0.0866744,1.00000,1.00,707.355,1.00000,1000000,0.958557,1.00000,1000000,1.00000
17683.9,27.4455,0.0438522,1.00000,1.00,707.355,1.00000,1000000,0.939064,1.00000,1000000,1.00000
17683.9,27.8200,0.0726659,1.00000,1.00,707.355,1.00000,1000000,0.913952,1.00000,1000000,1.00000
17683.9,30.0878,0.0635096,1.00000,1.00,707.355,1.00000,1000000,0.781370,1.00000,1000000,1.00000
17683.9,30.7038,0.0424103,1.00000,1.00,707.355,1.00000,1000000,0.750332,1.00000,1000000,1.00000
17683.9,32.7310,0.0502168,1.00000,1.00,707.355,1.00000,1000000,0.660266,1.00000,1000000,1.00000
17683.9,34.3850,0.0410869,1.00000,1.00,707.355,1.00000,1000000,0.598273,1.00000,1000000,1.00000
17683.9,34.9662,0.0398441,1.00000,1.00,707.355,1.00000,1000000,0.578550,1.00000,1000000,1.00000
17683.9,38.5071,0.0398199,1.00000,1.00,707.355,1.00000,1000000,0.477041,1.00000,1000000,1.00000
17683.9,39.2173,0.0359328,1.00000,1.00,707.355,1.00000,1000000,0.459920,1.00000,1000000,1.00000
17683.9,43.0777,0.0389368,1.00000,1.00,707.355,1.00000,1000000,0.381182,1.00000,1000000,1.00000
17683.9,44.7928,0.0330842,1.00000,1.00,707.355,1.00000,1000000,0.352550,1.00000,1000000,1.00000
17683.9,48.1914,0.0381891,1.00000,1.00,707.355,1.00000,1000000,0.304578,1.00000,1000000,1.00000
17683.9,51.1679,0.0324380,1.00000,1.00,707.355,1.00000,1000000,0.270173,1.00000,1000000,1.00000
17683.9,53.9121,0.0374578,1.00000,1.00,707.355,1.00000,1000000,0.243369,1.00000,1000000,1.00000
17683.9,58.4511,0.0320011,1.00000,1.00,707.355,1.00000,1000000,0.207039,1.00000,1000000,1.00000
17683.9,60.3770,0.0367535,1.00000,1.00,707.355,1.00000,1000000,0.194041,1.00000,1000000,1.00000
17683.9,66.7715,0.0316871,1.00000,1.00,707.355,1.00000,1000000,0.158656,1.00000,1000000,1.00000
17683.9,67.6140,0.0360579,1.00000,1.00,707.355,1.00000,1000000,0.154726,1.00000,1000000,1.00000
17683.9,75.6401,0.0352718,1.00000,1.00,707.355,1.00000,1000000,0.123633,1.00000,1000000,1.00000
17683.9,76.2778,0.0316676,1.00000,1.00,707.355,1.00000,1000000,0.121574,1.00000,1000000,1.00000
17683.9,84.6189,0.0345564,1.00000,1.00,707.355,1.00000,1000000,0.0987877,1.00000,1000000,1.00000
17683.9,87.1377,0.0316676,1.00000,1.00,707.355,1.00000,1000000,0.0931591,1.00000,1000000,1.00000
17683.9,94.5620,0.0338743,1.00000,1.00,707.355,1.00000,1000000,0.0791051,1.00000,1000000,1.00000
17683.9,99.5437,0.0316676,1.00000,1.00,707.355,1.00000,1000000,0.0713855,1.00000,1000000,1.00000
17683.9,113.715,0.0315507,1.00000,1.00,707.355,1.00000,1000000,0.0547019,1.00000,1000000,1.00000
17683.9,129.902,0.0312603,1.00000,1.00,707.355,1.00000,1000000,0.0419185,1.00000,1000000,1.00000
17683.9,148.395,0.0311257,1.00000,1.00,707.355,1.00000,1000000,0.0321217,1.00000,1000000,1.00000
17683.9,169.519,0.0308392,1.00000,1.00,707.355,1.00000,1000000,0.0246151,1.00000,1000000,1.00000
17683.9,193.654,0.0308202,1.00000,1.00,707.355,1.00000,1000000,0.0188619,1.00000,1000000,1.00000
17683.9,221.226,0.0308773,1.00000,1.00,707.355,1.00000,1000000,0.0144532,1.00000,1000000,1.00000
17683.9,252.725,0.0310299,1.00000,1.00,707.355,1.00000,1000000,0.0110749,1.00000,1000000,1.00000
17683.9,288.702,0.0308392,1.00000,1.00,707.355,1.00000,1000000,8.48668e-3,1.00000,1000000,1.00000
17683.9,329.802,0.0307065,1.00000,1.00,707.355,1.00000,1000000,6.50326e-3,1.00000,1000000,1.00000
17683.9,376.750,0.0304614,1.00000,1.00,707.355,1.00000,1000000,4.98346e-3,1.00000,1000000,1.00000
17683.9,430.397,0.0307444,1.00000,1.00,707.355,1.00000,1000000,3.81856e-3,1.00000,1000000,1.00000
17683.9,491.677,0.0308202,1.00000,1.00,707.355,1.00000,1000000,2.92602e-3,1.00000,1000000,1.00000
17683.9,561.673,0.0307065,1.00000,1.00,707.355,1.00000,1000000,2.24218e-3,1.00000,1000000,1.00000
17683.9,641.627,0.0304239,1.00000,1.00,707.355,1.00000,1000000,1.71819e-3,1.00000,1000000,1.00000
17683.9,732.976,0.0304051,1.00000,1.00,707.355,1.00000,1000000,1.31661e-3,1.00000,1000000,1.00000
17683.9,837.331,0.0304051,1.00000,1.00,707.355,1.00000,1000000,1.00889e-3,1.00000,1000000,1.00000
17683.9,956.544,0.0304051,1.00000,1.00,707.355,1.00000,1000000,7.73086e-4,1.00000,1000000,1.00000
17683.9,1092.73,0.0304051,1.00000,1.00,707.355,1.00000,1000000,5.92396e-4,1.00000,1000000,1.00000
17683.9,1248.30,0.0304051,1.00000,1.00,707.355,1.00000,1000000,4.53941e-4,1.00000,1000000,1.00000
17683.9,1426.02,0.0302929,1.00000,1.00,707.355,1.00000,1000000,3.47845e-4,1.00000,1000000,1.00000
17683.9,1629.01,0.0300511,1.00000,1.00,707.355,1.00000,1000000,2.66557e-4,1.00000,1000000,1.00000
17683.9,1860.97,0.0303303,1.00000,1.00,707.355,1.00000,1000000,2.04248e-4,1.00000,1000000,1.00000
17683.9,2125.94,0.0304051,1.00000,1.00,707.355,1.00000,1000000,1.56508e-4,1.00000,1000000,1.00000
17683.9,2428.62,0.0304614,1.00000,1.00,707.355,1.00000,1000000,1.19927e-4,1.00000,1000000,1.00000
17683.9,2774.44,0.0307444,1.00000,1.00,707.355,1.00000,1000000,9.18940e-5,1.00000,1000000,1.00000
17683.9,3169.44,0.0307065,1.00000,1.00,707.355,1.00000,1000000,7.04162e-5,1.00000,1000000,1.00000
17683.9,3428.72,0.0304051,1.00000,1.00,707.355,1.00000,1000000,6.01691e-5,1.00000,1000000,1.00000