File: myThesis/Viscosity/csv/psb_thfdmf_00_6.csv
Filename,psb_thfdmf_00_6
Instrument name,5333-0457
Operator,Osamu Katagiri
rundate,11/12/2019
Sample name,OSKT 6_PSB_THFDMF
Geometry name,60mm 0.9969° cone plate, Peltier plate Steel
Procedure name,Sample
,Flow ramp
proceduresegments,Flow ramp
[step]
Flow ramp - 1
Stress,Shear rate,Viscosity,Step time,Temperature,Normal stress,Axial force,Gap,Normal stress coefficient,Time,Torque,Velocity
Pa,1/s,Pa.s,s,°C,Pa,N,µm,Pa.s²,s,µN.m,rad/s
8.01506e-5,6.30331e-3,0.0127156,3.59091,20.00,-27.3491,-0.0386638,20.0303,-688344,3.59091,4.53241e-3,1.09677e-4
-5.17063e-4,7.36468e-3,-0.0702085,10.5094,20.00,-29.2338,-0.0413283,20.0279,-538985,10.5094,-0.0292392,1.28145e-4
-2.96842e-4,8.20604e-3,-0.0361736,17.5637,20.00,-30.1716,-0.0426541,20.0293,-448055,17.5637,-0.0167860,1.42785e-4
-3.40625e-4,9.19263e-3,-0.0370542,24.5760,20.00,-31.2073,-0.0441183,20.0189,-369298,24.5760,-0.0192619,1.59951e-4
-4.96704e-5,0.0103519,-4.79817e-3,31.5228,20.00,-32.3186,-0.0456893,20.0135,-301585,31.5228,-2.80880e-3,1.80123e-4
-3.24717e-4,0.0115151,-0.0281992,38.4697,20.00,-33.5579,-0.0474414,20.0122,-253080,38.4697,-0.0183623,2.00363e-4
2.38702e-4,0.0128831,0.0185283,45.4820,20.00,-34.3162,-0.0485133,20.0153,-206757,45.4820,0.0134983,2.24165e-4
4.82923e-4,0.0144595,0.0333983,52.4944,20.00,-35.2967,-0.0498995,20.0258,-168821,52.4944,0.0273087,2.51595e-4
5.56282e-4,0.0161833,0.0327070,59.4412,20.00,-35.8366,-0.0506628,20.0298,-136834,59.4412,0.0314570,2.81589e-4
5.83933e-4,0.0181078,0.0316919,66.3880,20.00,-36.7089,-0.0518959,20.0296,-111954,66.3880,0.0330206,3.15075e-4
7.09497e-4,0.0202737,0.0314199,73.4004,20.00,-37.0813,-0.0524225,20.0328,-90217.2,73.4004,0.0401211,3.52762e-4
7.85207e-4,0.0227202,0.0313773,80.4127,20.00,-38.1749,-0.0539685,20.0223,-73952.5,80.4127,0.0444024,3.95331e-4
7.25786e-4,0.0254207,0.0314952,87.3595,20.00,-38.5486,-0.0544968,20.0324,-59653.2,87.3595,0.0410422,4.42319e-4
6.49151e-4,0.0284181,0.0316367,94.3063,20.00,-39.4249,-0.0557357,20.0278,-48818.2,94.3063,0.0367086,4.94473e-4
9.46439e-4,0.0318151,0.0317123,101.253,20.00,-39.3978,-0.0556973,20.0172,-38922.9,101.253,0.0535199,5.53582e-4
1.01957e-3,0.0356217,0.0316717,108.266,20.00,-40.3785,-0.0570837,20.0268,-31821.5,108.266,0.0576555,6.19817e-4
1.30878e-3,0.0398862,0.0314177,115.278,20.00,-41.7803,-0.0590656,20.0144,-26261.9,115.278,0.0740100,6.94019e-4
1.44367e-3,0.0446291,0.0310042,122.225,20.00,-43.4218,-0.0613862,20.0122,-21800.8,122.225,0.0816377,7.76544e-4
1.76889e-3,0.0499221,0.0303287,129.171,20.00,-43.7462,-0.0618447,20.0093,-17553.1,129.171,0.100028,8.68643e-4
1.90067e-3,0.0559127,0.0295389,136.184,20.00,-44.6690,-0.0631493,20.0096,-14288.4,136.184,0.107481,9.72879e-4
2.17209e-3,0.0625255,0.0282192,143.196,20.00,-46.4343,-0.0656449,20.0200,-11877.5,143.196,0.122829,1.08794e-3
2.38021e-3,0.0699789,0.0264127,150.143,20.00,-46.9789,-0.0664149,20.0290,-9593.33,150.143,0.134598,1.21763e-3
2.52182e-3,0.0782793,0.0243050,157.090,20.00,-47.6311,-0.0673368,20.0281,-7773.14,157.090,0.142606,1.36206e-3
2.70912e-3,0.0875910,0.0217735,164.037,20.00,-48.4979,-0.0685623,20.0260,-6321.27,164.037,0.153197,1.52408e-3
2.88057e-3,0.0981125,0.0173305,171.049,20.00,-49.7625,-0.0703501,20.0334,-5169.56,171.049,0.162892,1.70715e-3
2.90417e-3,0.109860,0.0146525,178.061,20.00,-50.3728,-0.0712128,20.0279,-4173.69,178.061,0.164227,1.91155e-3
3.07246e-3,0.122940,0.0128654,185.008,20.00,-50.8003,-0.0718173,20.0274,-3361.09,185.008,0.173744,2.13915e-3
3.10979e-3,0.137577,0.0116193,191.955,20.00,-52.6776,-0.0744712,20.0318,-2783.13,191.955,0.175855,2.39384e-3
3.01344e-3,0.154035,0.0106008,198.967,20.00,-53.7849,-0.0760367,20.0174,-2266.83,198.967,0.170406,2.68021e-3
2.52727e-3,0.172602,9.71957e-3,205.980,20.00,-54.8778,-0.0775817,20.0201,-1842.07,205.980,0.142913,3.00327e-3
1.89673e-3,0.193069,8.83375e-3,212.926,20.00,-55.8317,-0.0789302,20.0304,-1497.81,212.926,0.107258,3.35939e-3
1.26151e-3,0.215968,7.85106e-3,219.873,20.00,-56.7865,-0.0802800,20.0220,-1217.49,219.873,0.0713368,3.75784e-3
6.76474e-4,0.241889,6.99488e-3,226.886,20.00,-57.6007,-0.0814310,20.0184,-984.455,226.886,0.0382537,4.20886e-3
1.06084e-4,0.270953,6.36899e-3,233.898,19.99,-58.1503,-0.0822080,20.0293,-792.069,233.898,5.99892e-3,4.71458e-3
3.60979e-4,0.302925,5.86576e-3,240.845,20.00,-59.3324,-0.0838792,20.0233,-646.579,240.845,0.0204129,5.27088e-3
9.35212e-4,0.338976,5.53720e-3,247.792,20.00,-59.7177,-0.0844239,20.0287,-519.715,247.792,0.0528850,5.89817e-3
1.76296e-3,0.379207,5.32163e-3,254.738,20.00,-60.7329,-0.0858591,20.0277,-422.349,254.738,0.0996928,6.59818e-3
2.66147e-3,0.424734,5.19150e-3,261.751,20.01,-61.8364,-0.0874192,20.0255,-342.776,261.751,0.150503,7.39035e-3
3.21328e-3,0.475669,5.09020e-3,268.763,20.00,-63.1925,-0.0893363,20.0301,-279.291,268.763,0.181707,8.27662e-3
2.94909e-3,0.532161,5.00068e-3,275.710,20.00,-64.6332,-0.0913730,20.0273,-228.229,275.710,0.166767,9.25958e-3
2.12032e-3,0.595347,4.98082e-3,282.657,19.99,-64.9041,-0.0917561,20.0219,-183.119,282.657,0.119901,0.0103590
2.42944e-3,0.666699,5.00059e-3,289.669,20.00,-66.1657,-0.0935396,20.0153,-148.858,289.669,0.137382,0.0116005
3.93702e-3,0.746508,4.97076e-3,296.681,20.00,-67.0886,-0.0948443,20.0200,-120.387,296.681,0.222633,0.0129892
5.01615e-3,0.835210,5.33062e-3,303.628,20.00,-67.6668,-0.0956617,20.0193,-97.0028,303.628,0.283657,0.0145326
8.24606e-3,0.934497,5.67664e-3,310.575,20.00,-69.8123,-0.0986949,20.0314,-79.9423,310.575,0.466304,0.0162602
0.0122960,1.04636,5.73988e-3,317.587,20.00,-71.2950,-0.100791,20.0315,-65.1172,317.587,0.695325,0.0182067
0.0166060,1.17181,5.62938e-3,324.600,20.00,-72.4658,-0.102446,20.0357,-52.7740,324.600,0.939045,0.0203894
0.0175653,1.31119,5.35221e-3,331.547,20.00,-72.4977,-0.102491,20.0244,-42.1687,331.547,0.993296,0.0228147
0.0153941,1.46674,5.04156e-3,338.493,20.00,-74.3212,-0.105069,20.0308,-34.5466,338.493,0.870517,0.0255212
0.0150650,1.64069,4.84746e-3,345.440,20.00,-75.6686,-0.106974,20.0312,-28.1101,345.440,0.851908,0.0285480
0.0114677,1.83791,4.81644e-3,352.453,20.00,-78.0764,-0.110378,20.0165,-23.1138,352.453,0.648484,0.0319796
5.10659e-3,2.05811,4.77586e-3,359.465,20.00,-80.7912,-0.114216,20.0205,-19.0733,359.465,0.288771,0.0358111
3.42219e-3,2.30196,4.66367e-3,366.412,20.00,-82.2224,-0.116239,20.0300,-15.5166,366.412,0.193520,0.0400540
0.0101426,2.57526,4.60221e-3,373.359,20.00,-83.7995,-0.118469,20.0304,-12.6357,373.359,0.573550,0.0448094
9.82685e-3,2.88454,4.36361e-3,380.371,20.00,-86.9457,-0.122917,20.0111,-10.4495,380.371,0.555695,0.0501909
0.0104092,3.22963,4.07807e-3,387.383,20.00,-89.9812,-0.127208,20.0289,-8.62674,387.383,0.588627,0.0561954
8.66785e-3,3.61379,3.74305e-3,394.330,20.00,-93.5906,-0.132311,20.0255,-7.16650,394.330,0.490155,0.0628797
8.73092e-3,4.04225,3.46859e-3,401.277,20.00,-96.3153,-0.136163,20.0283,-5.89451,401.277,0.493722,0.0703351
0.0118132,4.52204,3.27797e-3,408.224,19.99,-98.8962,-0.139811,20.0273,-4.83627,408.224,0.668023,0.0786834
0.0161120,5.06459,3.10412e-3,415.236,20.00,-100.639,-0.142275,20.0229,-3.92354,415.236,0.911115,0.0881237
0.0177265,5.67142,2.98753e-3,422.248,20.00,-103.391,-0.146166,20.0078,-3.21441,422.248,1.00241,0.0986825
0.0210945,6.34476,3.02612e-3,429.195,20.00,-105.905,-0.149719,20.0224,-2.63078,429.195,1.19286,0.110399
0.0329224,7.09780,3.15794e-3,436.142,20.00,-107.303,-0.151696,20.0178,-2.12992,436.142,1.86172,0.123501
0.0257816,7.94909,3.11701e-3,443.154,20.00,-112.293,-0.158751,20.0226,-1.77713,443.154,1.45792,0.138314
0.0290071,8.90205,3.11149e-3,450.167,20.00,-114.616,-0.162035,20.0230,-1.44632,450.167,1.64031,0.154895
0.0275882,9.95855,3.10507e-3,457.114,20.00,-119.971,-0.169605,20.0123,-1.20972,457.114,1.56008,0.173278
0.0349710,11.1406,3.15367e-3,464.060,20.00,-123.366,-0.174405,20.0220,-0.993983,464.060,1.97756,0.193846
0.0447277,12.4766,3.21643e-3,471.073,20.00,-124.239,-0.175639,20.0297,-0.798115,471.073,2.52929,0.217092
0.0456393,13.9726,3.24617e-3,478.085,20.00,-127.215,-0.179846,20.0300,-0.651602,478.085,2.58084,0.243123
0.0470732,15.6305,3.24395e-3,485.032,20.00,-132.147,-0.186819,20.0237,-0.540895,485.032,2.66193,0.271970
0.0554308,17.4862,3.24383e-3,491.979,20.00,-134.623,-0.190318,20.0270,-0.440280,491.979,3.13454,0.304258
0.0653896,19.5622,3.23218e-3,498.926,20.00,-136.542,-0.193031,20.0259,-0.356804,498.926,3.69770,0.340382
0.0673155,21.9076,3.16419e-3,505.938,20.00,-144.717,-0.204588,20.0273,-0.301528,505.938,3.80660,0.381192
0.0807354,24.5336,3.15696e-3,512.950,20.00,-147.532,-0.208569,20.0184,-0.245112,512.950,4.56548,0.426884
0.0851205,27.4462,3.14803e-3,519.897,20.00,-152.881,-0.216130,20.0288,-0.202950,519.897,4.81345,0.477562
0.0989784,30.7039,3.16619e-3,526.844,20.00,-155.326,-0.219587,20.0154,-0.164762,526.844,5.59709,0.534247
0.107958,34.3855,3.16106e-3,533.856,20.00,-160.457,-0.226841,20.0153,-0.135709,533.856,6.10490,0.598306
0.119882,38.5079,3.13770e-3,540.869,20.00,-163.634,-0.231331,20.0164,-0.110350,540.869,6.77918,0.670036
0.135225,43.0786,3.12922e-3,547.815,20.00,-165.703,-0.234257,20.0161,-0.0892909,547.815,7.64680,0.749566
0.150463,48.1924,3.12553e-3,554.762,20.00,-168.099,-0.237645,20.0218,-0.0723783,554.762,8.50846,0.838546
0.167316,53.9130,3.11497e-3,561.709,20.00,-173.819,-0.245730,20.0265,-0.0598011,561.709,9.46148,0.938085
0.187133,60.3777,3.10776e-3,568.721,20.00,-177.719,-0.251244,20.0381,-0.0487507,568.721,10.5821,1.05057
0.209983,67.6148,3.09302e-3,575.734,20.00,-182.444,-0.257925,20.0357,-0.0399068,575.734,11.8742,1.17650
0.233552,75.6419,3.09250e-3,582.681,20.00,-187.293,-0.264780,20.0227,-0.0327339,582.681,13.2070,1.31617
0.261423,84.6204,3.07507e-3,589.627,20.00,-191.419,-0.270612,20.0293,-0.0267322,589.627,14.7831,1.47239
0.290272,94.5634,3.06960e-3,596.509,20.00,-197.821,-0.279663,20.0317,-0.0221221,596.509,16.4145,1.64540