File: myThesis/Viscosity/csv/psb_thfdmf_01_9.csv
Filename,psb_thfdmf_01_9
Instrument name,5333-0457
Operator,Osamu Katagiri
rundate,19/12/2019
Sample name,PSB_THFDMF_01_9
Geometry name,60.0mm 0.996944° cone plate, Peltier plate Steel
Procedure name,Sample
,Flow ramp
proceduresegments,Flow ramp
[step]
Flow ramp - 1
Stress,Shear rate,Viscosity,Step time,Temperature,Normal stress,Axial force,Gap,Normal stress coefficient,Time,Torque,Velocity
Pa,1/s,Pa.s,s,°C,Pa,N,µm,Pa.s²,s,µN.m,rad/s
0.0101421,6.35183e-3,1.59671,4.58755,20.03,-9.36854,-0.0132445,20.0299,-232206,4.58755,0.573520,1.10522e-4
0.0105866,6.86647e-3,1.54723,11.1412,20.03,-10.3665,-0.0146552,20.0123,-219869,11.1412,0.598661,1.19476e-4
0.0119633,7.54129e-3,1.56673,18.5467,20.02,-10.5418,-0.0149031,20.0330,-185363,18.5467,0.676509,1.31218e-4
0.0131703,8.25081e-3,1.56556,25.9523,20.02,-10.3041,-0.0145671,20.0250,-151362,25.9523,0.744763,1.43564e-4
0.0140178,9.04240e-3,1.57083,33.2923,20.02,-9.71159,-0.0137294,20.0356,-118774,33.2923,0.792688,1.57337e-4
0.0154110,9.91795e-3,1.56390,40.6324,20.02,-8.49088,-0.0120037,20.0285,-86319.5,40.6324,0.871474,1.72572e-4
0.0170561,0.0108803,1.55391,47.9724,20.01,-5.91410,-8.36086e-3,20.0238,-49957.9,47.9724,0.964500,1.89317e-4
0.0184805,0.0119065,1.55158,55.3124,20.01,-2.94645,-4.16544e-3,20.0243,-20784.2,55.3124,1.04505,2.07172e-4
0.0201868,0.0130585,1.54884,62.7180,20.01,-0.574416,-8.12062e-4,20.0241,-3368.51,62.7180,1.14154,2.27218e-4
0.0219845,0.0142898,1.54055,70.1236,20.00,0.609537,8.61713e-4,20.0326,2985.01,70.1236,1.24319,2.48643e-4
0.0241100,0.0156501,1.53554,77.4636,20.00,2.28246,3.22676e-3,20.0146,9319.00,77.4636,1.36339,2.72311e-4
0.0261817,0.0171599,1.52955,84.8036,20.01,2.72543,3.85298e-3,20.0232,9255.57,84.8036,1.48054,2.98582e-4
0.0286618,0.0187692,1.52286,92.1436,20.00,3.61472,5.11020e-3,20.0176,10260.9,92.1436,1.62079,3.26583e-4
0.0311799,0.0205629,1.51760,99.4837,20.00,3.48337,4.92450e-3,20.0272,8238.14,99.4837,1.76318,3.57794e-4
0.0339283,0.0225511,1.51368,106.889,20.00,4.08994,5.78201e-3,20.0282,8042.28,106.889,1.91860,3.92389e-4
0.0374422,0.0247268,1.50849,114.295,20.00,4.02376,5.68846e-3,20.0267,6581.07,114.295,2.11731,4.30245e-4
0.0407649,0.0270598,1.50496,121.635,20.00,4.14856,5.86489e-3,20.0280,5665.64,121.635,2.30520,4.70839e-4
0.0445195,0.0296574,1.50354,128.975,20.00,4.02810,5.69459e-3,20.0204,4579.68,128.975,2.51752,5.16037e-4
0.0486636,0.0324763,1.49837,136.315,20.00,5.27223,7.45344e-3,20.0299,4998.76,136.315,2.75186,5.65086e-4
0.0532641,0.0355684,1.49610,143.655,20.00,4.86579,6.87885e-3,20.0197,3846.13,143.655,3.01201,6.18890e-4
0.0580385,0.0389962,1.49420,151.061,20.00,4.55405,6.43814e-3,20.0256,2994.70,151.061,3.28200,6.78532e-4
0.0639238,0.0427569,1.49279,158.466,20.00,5.49234,7.76461e-3,20.0243,3004.32,158.466,3.61481,7.43968e-4
0.0698465,0.0468223,1.49160,165.806,20.00,4.65291,6.57790e-3,20.0229,2122.36,165.806,3.94972,8.14707e-4
0.0764871,0.0512855,1.49264,173.146,20.00,5.30885,7.50521e-3,20.0271,2018.42,173.146,4.32524,8.92367e-4
0.0837739,0.0561681,1.49226,180.486,20.00,6.10554,8.63150e-3,20.0253,1935.29,180.486,4.73731,9.77322e-4
0.0917689,0.0614434,1.49281,187.826,20.01,4.22763,5.97668e-3,20.0189,1119.82,187.826,5.18941,1.06911e-3
0.100582,0.0673626,1.49305,195.232,20.00,4.67855,6.61415e-3,20.0256,1031.04,195.232,5.68777,1.17211e-3
0.110313,0.0738118,1.49385,202.637,20.00,4.36862,6.17599e-3,20.0350,801.849,202.637,6.23804,1.28432e-3
0.120729,0.0808863,1.49374,209.977,20.00,4.87239,6.88819e-3,20.0153,744.720,209.977,6.82706,1.40742e-3
0.132477,0.0885852,1.49387,217.317,20.00,5.59772,7.91359e-3,20.0115,713.327,217.317,7.49139,1.54138e-3
0.144879,0.0970407,1.49356,224.657,20.00,4.42500,6.25569e-3,20.0195,469.900,224.657,8.19273,1.68850e-3
0.158731,0.106259,1.49345,231.997,20.00,4.71897,6.67129e-3,20.0034,417.942,231.997,8.97604,1.84890e-3
0.173955,0.116515,1.49337,239.403,20.00,4.88268,6.90273e-3,20.0072,359.660,239.403,9.83690,2.02736e-3
0.190628,0.127770,1.49585,246.809,20.00,4.61673,6.52674e-3,20.0153,282.796,246.809,10.7798,2.22320e-3
0.209116,0.139866,1.49433,254.149,20.00,4.27317,6.04105e-3,20.0166,218.438,254.149,11.8252,2.43366e-3
0.230663,0.153234,1.49355,261.489,20.00,4.47665,6.32872e-3,20.0089,190.654,261.489,13.0437,2.66626e-3
0.249475,0.167842,1.49267,268.829,20.00,3.60470,5.09603e-3,20.0052,127.959,268.829,14.1075,2.92044e-3
0.273732,0.183825,1.49162,276.169,20.00,4.93662,6.97899e-3,20.0143,146.090,276.169,15.4792,3.19855e-3
0.299772,0.201524,1.48840,283.574,20.00,3.45033,4.87779e-3,20.0231,84.9583,283.574,16.9517,3.50652e-3
0.329051,0.220870,1.48867,290.980,20.00,4.18485,5.91619e-3,20.0212,85.7840,290.980,18.6074,3.84313e-3
0.360253,0.241908,1.48824,298.320,20.00,4.11324,5.81496e-3,20.0271,70.2886,298.320,20.3718,4.20919e-3
0.394206,0.264968,1.48866,305.660,20.00,3.72507,5.26619e-3,20.0269,53.0574,305.660,22.2918,4.61044e-3
0.431538,0.290222,1.48868,313.000,20.00,3.53469,4.99705e-3,20.0328,41.9653,313.000,24.4029,5.04985e-3
0.473579,0.317923,1.48870,320.340,20.00,4.55351,6.43737e-3,20.0218,45.0508,320.340,26.7803,5.53185e-3
0.519044,0.348375,1.48977,327.746,20.00,3.24067,4.58138e-3,20.0278,26.7018,327.746,29.3512,6.06171e-3
0.568802,0.381921,1.49038,335.151,20.00,3.65910,5.17293e-3,20.0301,25.0858,335.151,32.1650,6.64541e-3
0.624663,0.418355,1.49057,342.491,20.00,3.60600,5.09787e-3,20.0293,20.6033,342.491,35.3239,7.27935e-3
0.682575,0.458121,1.49079,349.831,19.99,4.04183,5.71401e-3,20.0307,19.2583,349.831,38.5987,7.97129e-3
0.747959,0.501812,1.49091,357.171,20.00,2.60222,3.67880e-3,20.0385,10.3338,357.171,42.2961,8.73150e-3
0.819425,0.549577,1.49049,364.511,20.00,2.38447,3.37097e-3,20.0263,7.89469,364.511,46.3374,9.56262e-3
0.897566,0.602410,1.49086,371.917,20.00,3.15915,4.46614e-3,20.0252,8.70534,371.917,50.7562,0.0104819
0.984550,0.660313,1.49090,379.322,20.00,3.23103,4.56776e-3,20.0306,7.41038,379.322,55.6750,0.0114894
1.07883,0.723197,1.49039,386.662,20.00,3.39221,4.79562e-3,20.0295,6.48589,386.662,61.0066,0.0125836
1.18076,0.792077,1.49022,394.002,20.00,2.55601,3.61347e-3,20.0284,4.07406,394.002,66.7705,0.0137821
1.29126,0.867481,1.48997,401.342,20.00,1.78452,2.52281e-3,20.0374,2.37138,401.342,73.0190,0.0150941
1.41478,0.950096,1.48973,408.683,20.00,3.22168,4.55454e-3,20.0347,3.56901,408.683,80.0040,0.0165316
1.55157,1.04149,1.48967,416.088,20.00,1.50435,2.12673e-3,20.0230,1.38688,416.088,87.7391,0.0181219
1.70165,1.14159,1.49016,423.494,20.00,2.37132,3.35237e-3,20.0260,1.81956,423.494,96.2259,0.0198637
1.86343,1.25028,1.49061,430.834,20.00,2.79317,3.94876e-3,20.0276,1.78682,430.834,105.374,0.0217549
2.04157,1.36933,1.49095,438.174,20.00,1.50905,2.13337e-3,20.0312,0.804801,438.174,115.448,0.0238263
2.23669,1.49974,1.49115,445.514,20.00,2.88342,4.07634e-3,20.0301,1.28196,445.514,126.482,0.0260955
2.44985,1.64259,1.49143,452.854,20.00,1.50548,2.12833e-3,20.0146,0.557981,452.854,138.536,0.0285809
2.68557,1.80046,1.49161,460.259,20.00,-2.69835e-3,-3.81470e-6,20.0275,-8.32400e-4,460.259,151.865,0.0313279
2.94411,1.97352,1.49181,467.665,20.00,1.72130,2.43344e-3,20.0209,0.441953,467.665,166.485,0.0343391
3.22443,2.16145,1.49203,475.005,20.01,0.474764,6.71182e-4,20.0211,0.101622,475.005,182.337,0.0376091
3.53290,2.36729,1.49230,482.345,20.00,1.87656,2.65292e-3,20.0299,0.334857,482.345,199.781,0.0411907
3.86979,2.59270,1.49260,489.685,20.00,2.18176,3.08439e-3,20.0282,0.324564,489.685,218.831,0.0451130
4.23938,2.83960,1.49280,497.025,20.00,1.07756,1.52336e-3,20.0250,0.133636,497.025,239.731,0.0494090
4.64809,3.11256,1.49275,504.431,20.00,1.63330,2.30903e-3,20.0250,0.168590,504.431,262.843,0.0541584
5.09289,3.41169,1.49255,511.836,20.00,-1.05520,-1.49175e-3,20.0206,-0.0906556,511.836,287.996,0.0593633
5.57539,3.73658,1.49241,519.176,20.00,-2.82565,-3.99467e-3,20.0186,-0.202381,519.176,315.281,0.0650163
6.10420,4.09246,1.49201,526.516,20.00,2.49578,3.52832e-3,20.0413,0.149018,526.516,345.184,0.0712086
6.68833,4.48206,1.49180,533.856,20.00,-3.83117,-5.41619e-3,20.0237,-0.190711,533.856,378.216,0.0779878
7.32121,4.90909,1.49189,541.196,20.00,-2.51269,-3.55223e-3,20.0243,-0.104265,541.196,414.005,0.0854179
8.02671,5.38083,1.49218,548.602,20.00,-1.67984,-2.37482e-3,20.0273,-0.0580188,548.602,453.900,0.0936263
8.80295,5.89794,1.49241,556.007,20.00,0.298071,4.21388e-4,20.0296,8.56879e-3,556.007,497.795,0.102624
9.64431,6.45961,1.49289,563.347,20.00,1.31564,1.85994e-3,20.0226,0.0315300,563.347,545.373,0.112397
10.5654,7.07474,1.49309,570.688,20.00,3.30615,4.67396e-3,20.0264,0.0660543,570.688,597.458,0.123100
11.5742,7.74840,1.49293,578.028,20.00,4.79405,6.77742e-3,20.0240,0.0798505,578.028,654.504,0.134822
12.6678,8.48630,1.49240,585.368,20.00,3.15687,4.46292e-3,20.0196,0.0438349,585.368,716.344,0.147661
13.8764,9.30219,1.49164,592.773,20.00,-2.36782,-3.34743e-3,20.0160,-0.0273640,592.773,784.691,0.161858
15.1959,10.1960,1.49066,600.179,20.00,4.65585,6.58206e-3,20.0273,0.0447858,600.179,859.308,0.177410
16.6345,11.1671,1.48952,607.519,20.00,0.361916,5.11646e-4,20.0127,2.90222e-3,607.519,940.661,0.194306
18.2095,12.2304,1.48814,614.859,20.00,0.231383,3.27110e-4,20.0209,1.54687e-3,614.859,1029.73,0.212808
19.9188,13.3951,1.48689,622.199,20.00,-1.62609,-2.29883e-3,20.0299,-9.06266e-3,622.199,1126.38,0.233074
21.7831,14.6706,1.48526,629.539,20.00,-3.92566,-5.54977e-3,20.0205,-0.0182398,629.539,1231.81,0.255267
23.8655,16.0809,1.48317,636.944,20.00,6.09003,8.60957e-3,20.0168,0.0235505,636.944,1349.56,0.279806
26.1121,17.6264,1.48116,644.350,20.00,-1.80471,-2.55135e-3,20.0264,-5.80875e-3,644.350,1476.61,0.306698
28.5419,19.3048,1.47888,651.690,20.00,-1.36951,-1.93610e-3,20.0269,-3.67479e-3,651.690,1614.01,0.335903
31.2292,21.1431,1.47629,659.030,20.00,3.70787,5.24187e-3,20.0256,8.29446e-3,659.030,1765.97,0.367889
34.1186,23.1566,1.47354,666.370,20.00,-6.26749,-8.86045e-3,20.0280,-0.0116881,666.370,1929.36,0.402924
37.3099,25.3617,1.47089,673.710,20.00,6.29331,8.89696e-3,20.0253,9.78412e-3,673.710,2109.82,0.441293
40.8006,27.7996,1.46739,681.116,20.00,0.343968,4.86274e-4,20.0241,4.45082e-4,681.116,2307.22,0.483712
44.6470,30.4713,1.46412,688.521,20.00,-2.52772,-3.57349e-3,20.0279,-2.72238e-3,688.521,2524.73,0.530199
48.7124,33.3730,1.46046,695.861,20.00,7.30033,0.0103206,20.0243,6.55468e-3,695.861,2754.62,0.580689
53.2589,36.5509,1.45653,703.201,20.00,-4.08462,-5.77450e-3,20.0252,-3.05742e-3,703.201,3011.72,0.635984
58.1563,40.0317,1.45237,710.541,20.00,-2.50392,-3.53983e-3,20.0274,-1.56247e-3,710.541,3288.66,0.696550
63.4855,43.8436,1.44837,717.881,20.00,3.52886,4.98881e-3,20.0229,1.83578e-3,717.881,3590.02,0.762878
69.4133,48.0584,1.44353,725.287,20.00,-3.29828,-4.66283e-3,20.0268,-1.42807e-3,725.287,3925.23,0.836214
75.8326,52.6770,1.43833,732.693,20.00,4.06226,5.74289e-3,20.0068,1.46395e-3,732.693,4288.23,0.916578
82.6762,57.6932,1.43258,740.033,20.00,0.826369,1.16825e-3,20.0236,2.48270e-4,740.033,4675.23,1.00386
90.1630,63.1871,1.42609,747.373,20.00,0.279520,3.95162e-4,20.0212,7.00093e-5,747.373,5098.60,1.09945
98.2166,69.2042,1.41899,754.713,20.00,1.53700,2.17288e-3,20.0180,3.20928e-4,754.713,5554.02,1.20415
107.009,75.7943,1.41180,762.053,20.00,-2.95098,-4.17185e-3,20.0234,-5.13680e-4,762.053,6051.24,1.31882
116.651,83.0804,1.40448,769.458,20.00,0.453085,6.40535e-4,20.0180,6.56421e-5,769.458,6596.45,1.44560
127.210,91.0647,1.39703,776.864,20.00,0.638978,9.03334e-4,20.0250,7.70523e-5,776.864,7193.54,1.58452
138.685,99.7366,1.38937,784.204,20.00,-4.28175,-6.05318e-3,20.0150,-4.30439e-4,784.204,7842.44,1.73541
150.984,109.234,1.38154,791.544,20.00,10.4187,0.0147291,20.0123,8.73165e-4,791.544,8537.97,1.90067
164.312,119.636,1.37388,798.884,20.00,-1.33751,-1.89086e-3,20.0206,-9.34492e-5,798.884,9291.64,2.08166
178.838,131.029,1.36570,806.224,20.00,10.4125,0.0147203,20.0200,6.06487e-4,806.224,10113.0,2.27989
195.119,143.624,1.35658,813.629,20.00,16.6098,0.0234815,20.0119,8.05210e-4,813.629,11033.7,2.49906
212.441,157.427,1.34754,821.035,20.00,13.6361,0.0192776,20.0115,5.50214e-4,821.035,12013.2,2.73923
230.507,172.419,1.33879,828.375,20.00,28.3090,0.0400209,20.0115,9.52262e-4,828.375,13034.9,3.00008
250.874,188.837,1.32958,835.715,20.00,30.4190,0.0430039,20.0172,8.53042e-4,835.715,14186.6,3.28576
273.199,206.819,1.31997,843.055,20.00,37.1912,0.0525778,20.0117,8.69476e-4,843.055,15449.0,3.59865
297.271,226.514,1.31092,850.395,20.00,60.8408,0.0860116,20.0086,1.18578e-3,850.395,16810.3,3.94134
323.106,248.289,1.30153,857.801,20.00,49.8116,0.0704194,20.0145,8.08008e-4,857.801,18271.2,4.32022
351.488,272.151,1.29153,865.206,20.00,86.4206,0.122174,20.0054,1.16681e-3,865.206,19876.2,4.73541
382.074,298.067,1.28083,872.546,20.00,101.928,0.144098,20.0029,1.14727e-3,872.546,21605.8,5.18635
414.997,326.451,1.26956,879.886,20.00,105.764,0.149520,20.0060,9.92434e-4,879.886,23467.5,5.68023
450.042,357.537,1.25745,887.226,20.00,153.395,0.216858,20.0066,1.19997e-3,887.226,25449.3,6.22113
487.531,391.584,1.24442,894.566,20.00,154.665,0.218653,20.0026,1.00866e-3,894.566,27569.2,6.81355
528.352,429.227,1.23041,901.972,20.00,190.764,0.269686,20.0014,1.03543e-3,901.972,29877.6,7.46854
572.372,470.477,1.21603,909.378,20.00,231.199,0.326849,19.9965,1.04450e-3,909.378,32366.9,8.18628
619.165,515.280,1.20155,916.718,20.00,225.163,0.318317,19.9941,8.48028e-4,916.718,35013.0,8.96586
670.015,564.347,1.18662,924.058,20.00,306.547,0.433371,19.9892,9.62509e-4,924.058,37888.5,9.81961
724.647,618.089,1.17140,931.398,20.00,295.280,0.417442,19.9895,7.72915e-4,931.398,40977.8,10.7547
782.712,676.947,1.15553,938.738,20.01,350.537,0.495561,19.9866,7.64935e-4,938.738,44261.3,11.7789
846.188,742.023,1.13881,946.143,20.01,411.172,0.581281,19.9797,7.46773e-4,946.143,47850.8,12.9112
912.639,813.333,1.12175,953.549,20.01,434.574,0.614364,19.9902,6.56941e-4,953.549,51608.5,14.1520
983.613,890.784,1.10448,960.889,20.01,519.277,0.734110,19.9745,6.54416e-4,960.889,55622.0,15.4996
1061.10,975.611,1.08648,968.229,20.01,579.058,0.818624,19.9784,6.08372e-4,968.229,60003.8,16.9756
1142.90,1068.52,1.06834,975.569,20.01,637.494,0.901236,19.9783,5.58359e-4,975.569,64629.7,18.5921
1229.12,1170.27,1.05007,982.909,20.01,743.405,1.05096,19.9613,5.42821e-4,982.909,69505.0,20.3626
1322.97,1282.77,1.03024,990.315,20.01,796.825,1.12649,19.9735,4.84248e-4,990.315,74812.1,22.3201
1423.81,1406.04,1.01103,997.720,20.01,916.841,1.29615,19.9527,4.63764e-4,997.720,80514.7,24.4651
1523.38,1539.94,0.991571,1005.06,20.01,1023.35,1.44672,19.9513,4.31536e-4,1005.06,86145.1,26.7948
1642.77,1686.58,0.972277,1012.40,20.01,1100.31,1.55553,19.9528,3.86815e-4,1012.40,92896.6,29.3464
1759.84,1847.18,0.952284,1019.74,20.02,1270.90,1.79669,19.9420,3.72468e-4,1019.74,99516.4,32.1409
1890.91,2023.09,0.932356,1027.08,20.02,1364.53,1.92906,19.9464,3.33390e-4,1027.08,106928,35.2017
2023.65,2217.57,0.910664,1034.49,20.02,1522.30,2.15211,19.9349,3.09562e-4,1034.49,114435,38.5856
2162.37,2430.68,0.889051,1041.89,20.02,1704.99,2.41037,19.9253,2.88579e-4,1041.89,122279,42.2938
2306.49,2662.15,0.866575,1049.23,20.02,1813.54,2.56383,19.9299,2.55895e-4,1049.23,130429,46.3213
1738.57,2916.48,0.596121,1056.57,20.03,1816.28,2.56771,19.9144,2.13534e-4,1056.57,98313.9,50.7466
528.773,3193.06,0.165601,1063.91,19.98,945.834,1.33714,19.9451,9.27685e-5,1063.91,29901.4,55.5591
204.923,3497.91,0.0585843,1071.25,19.97,1081.21,1.52852,20.0082,8.83674e-5,1071.25,11588.1,60.8635
42.5201,3833.61,0.0110914,1078.66,19.99,602.150,0.851269,20.0733,4.09720e-5,1078.66,2404.45,66.7048
45.9992,4202.12,0.0109467,1086.06,20.00,792.535,1.12042,20.0934,4.48830e-5,1086.06,2601.20,73.1167
45.2760,4602.25,9.83781e-3,1093.40,19.98,211.530,0.299043,20.1099,9.98693e-6,1093.40,2560.30,80.0789
53.4613,5040.48,0.0106064,1100.74,19.97,449.093,0.634891,20.1052,1.76764e-5,1100.74,3023.17,87.7042
62.9748,5520.54,0.0114074,1108.08,19.98,1301.24,1.83959,20.1057,4.26969e-5,1108.08,3561.14,96.0571
69.3167,6046.18,0.0114645,1115.42,19.98,-217.983,-0.308167,20.1021,-5.96295e-6,1115.42,3919.77,105.203
81.4277,6627.43,0.0122865,1122.83,19.99,1275.98,1.80388,20.0969,2.90506e-5,1122.83,4604.63,115.317
88.7463,7264.36,0.0122167,1130.23,19.99,1836.16,2.59582,20.0889,3.47950e-5,1130.23,5018.49,126.400
94.1998,7956.12,0.0118399,1137.57,19.99,-357.004,-0.504703,20.0800,-5.63990e-6,1137.57,5326.87,138.436
99.8795,8713.77,0.0114623,1144.91,19.99,-680.641,-0.962234,20.0774,-8.96408e-6,1144.91,5648.05,151.619
99.9970,9543.77,0.0104777,1152.25,19.99,-369.071,-0.521761,20.0824,-4.05200e-6,1152.25,5654.70,166.061
76.6626,10452.5,7.33440e-3,1159.59,19.99,1511.52,2.13686,20.0768,1.38349e-5,1159.59,4335.17,181.873
78.8334,11457.1,6.88076e-3,1167.00,19.99,2002.16,2.83049,20.0673,1.52529e-5,1167.00,4457.92,199.353
89.2338,12558.2,7.10562e-3,1174.41,20.00,2144.83,3.03218,20.0666,1.35999e-5,1174.41,5046.05,218.512
97.6407,13754.1,7.09905e-3,1181.75,20.00,1882.39,2.66116,20.0702,9.95056e-6,1181.75,5521.45,239.320
109.906,15063.7,7.29605e-3,1189.09,20.00,1819.84,2.57274,20.0653,8.01988e-6,1189.09,6215.03,262.109
122.504,16484.8,7.43133e-3,1196.36,20.00,1874.70,2.65029,20.0584,6.89865e-6,1196.36,6927.44,286.835