File: 09_characterizationRheology/csv/peo_su8_all_050.csv
Filename,peo_su8_all_050
Instrument name,5333-0457
Operator,Osamu Katagiri
rundate,29/01/2020
Sample name,PEO_SU8_01_050_1
Geometry name,60mm 0.9969° cone plate, Peltier plate Steel
Procedure name,Sample
,Flow ramp
proceduresegments,Flow ramp
[step]
Flow ramp - 1
Stress,Shear rate,Viscosity,Step time,Temperature,Normal stress,Axial force,Gap,Normal stress coefficient,Time,Torque,Velocity
Pa,1/s,Pa.s,s,°C,Pa,N,µm,Pa.s²,s,µN.m,rad/s
,5.91000e-3,575.091,,,,,,,,,
17683.9,7.10000e-3,504.525,1.00000,1.00,707.355,1.00000,1000000,1.40320e7,1.00000,1000000,1.00000
17683.9,7.19000e-3,364.695,1.00000,1.00,707.355,1.00000,1000000,1.36830e7,1.00000,1000000,1.00000
17683.9,7.45000e-3,604.204,1.00000,1.00,707.355,1.00000,1000000,1.27446e7,1.00000,1000000,1.00000
17683.9,8.24000e-3,578.744,1.00000,1.00,707.355,1.00000,1000000,1.04180e7,1.00000,1000000,1.00000
17683.9,8.27000e-3,538.328,1.00000,1.00,707.355,1.00000,1000000,1.03425e7,1.00000,1000000,1.00000
17683.9,8.37000e-3,340.712,1.00000,1.00,707.355,1.00000,1000000,1.00969e7,1.00000,1000000,1.00000
17683.9,9.23000e-3,553.618,1.00000,1.00,707.355,1.00000,1000000,8302980,1.00000,1000000,1.00000
17683.9,9.63000e-3,551.644,1.00000,1.00,707.355,1.00000,1000000,7627550,1.00000,1000000,1.00000
17683.9,9.74000e-3,297.373,1.00000,1.00,707.355,1.00000,1000000,7456240,1.00000,1000000,1.00000
17683.9,0.0103160,497.937,1.00000,1.00,707.355,1.00000,1000000,6646840,1.00000,1000000,1.00000
17683.9,0.0112085,553.722,1.00000,1.00,707.355,1.00000,1000000,5630440,1.00000,1000000,1.00000
17683.9,0.0113445,253.267,1.00000,1.00,707.355,1.00000,1000000,5496260,1.00000,1000000,1.00000
17683.9,0.0115334,443.081,1.00000,1.00,707.355,1.00000,1000000,5317690,1.00000,1000000,1.00000
17683.9,0.0129169,394.321,1.00000,1.00,707.355,1.00000,1000000,4239560,1.00000,1000000,1.00000
17683.9,0.0130488,546.484,1.00000,1.00,707.355,1.00000,1000000,4154290,1.00000,1000000,1.00000
17683.9,0.0132082,217.867,1.00000,1.00,707.355,1.00000,1000000,4054620,1.00000,1000000,1.00000
17683.9,0.0144718,351.760,1.00000,1.00,707.355,1.00000,1000000,3377480,1.00000,1000000,1.00000
17683.9,0.0151914,500.276,1.00000,1.00,707.355,1.00000,1000000,3065080,1.00000,1000000,1.00000
17683.9,0.0153781,186.735,1.00000,1.00,707.355,1.00000,1000000,2991110,1.00000,1000000,1.00000
17683.9,0.0161916,315.089,1.00000,1.00,707.355,1.00000,1000000,2698100,1.00000,1000000,1.00000
17683.9,0.0176857,432.457,1.00000,1.00,707.355,1.00000,1000000,2261480,1.00000,1000000,1.00000
17683.9,0.0179045,161.072,1.00000,1.00,707.355,1.00000,1000000,2206550,1.00000,1000000,1.00000
17683.9,0.0181128,282.886,1.00000,1.00,707.355,1.00000,1000000,2156090,1.00000,1000000,1.00000
17683.9,0.0202839,253.910,1.00000,1.00,707.355,1.00000,1000000,1719230,1.00000,1000000,1.00000
17683.9,0.0205896,375.593,1.00000,1.00,707.355,1.00000,1000000,1668560,1.00000,1000000,1.00000
17683.9,0.0208459,138.809,1.00000,1.00,707.355,1.00000,1000000,1627780,1.00000,1000000,1.00000
17683.9,0.0227253,228.282,1.00000,1.00,707.355,1.00000,1000000,1369680,1.00000,1000000,1.00000
17683.9,0.0239703,324.372,1.00000,1.00,707.355,1.00000,1000000,1231090,1.00000,1000000,1.00000
17683.9,0.0242706,120.168,1.00000,1.00,707.355,1.00000,1000000,1200820,1.00000,1000000,1.00000
17683.9,0.0254109,206.158,1.00000,1.00,707.355,1.00000,1000000,1095460,1.00000,1000000,1.00000
17683.9,0.0279061,279.347,1.00000,1.00,707.355,1.00000,1000000,908321,1.00000,1000000,1.00000
17683.9,0.0282579,101.697,1.00000,1.00,707.355,1.00000,1000000,885845,1.00000,1000000,1.00000
17683.9,0.0284309,186.152,1.00000,1.00,707.355,1.00000,1000000,875097,1.00000,1000000,1.00000
17683.9,0.0318048,168.205,1.00000,1.00,707.355,1.00000,1000000,699282,1.00000,1000000,1.00000
17683.9,0.0324881,243.301,1.00000,1.00,707.355,1.00000,1000000,670176,1.00000,1000000,1.00000
17683.9,0.0329002,85.7539,1.00000,1.00,707.355,1.00000,1000000,653492,1.00000,1000000,1.00000
17683.9,0.0356148,152.189,1.00000,1.00,707.355,1.00000,1000000,557669,1.00000,1000000,1.00000
17683.9,0.0378225,211.707,1.00000,1.00,707.355,1.00000,1000000,494467,1.00000,1000000,1.00000
17683.9,0.0383052,73.2342,1.00000,1.00,707.355,1.00000,1000000,482083,1.00000,1000000,1.00000
17683.9,0.0398845,138.092,1.00000,1.00,707.355,1.00000,1000000,444661,1.00000,1000000,1.00000
17683.9,0.0440327,181.125,1.00000,1.00,707.355,1.00000,1000000,364827,1.00000,1000000,1.00000
17683.9,0.0445982,63.9767,1.00000,1.00,707.355,1.00000,1000000,355634,1.00000,1000000,1.00000
17683.9,0.0446185,125.385,1.00000,1.00,707.355,1.00000,1000000,355310,1.00000,1000000,1.00000
17683.9,0.0499210,113.737,1.00000,1.00,707.355,1.00000,1000000,283838,1.00000,1000000,1.00000
17683.9,0.0512626,156.719,1.00000,1.00,707.355,1.00000,1000000,269176,1.00000,1000000,1.00000
17683.9,0.0519250,55.9402,1.00000,1.00,707.355,1.00000,1000000,262352,1.00000,1000000,1.00000
17683.9,0.0559144,102.997,1.00000,1.00,707.355,1.00000,1000000,226251,1.00000,1000000,1.00000
17683.9,0.0596797,136.240,1.00000,1.00,707.355,1.00000,1000000,198602,1.00000,1000000,1.00000
17683.9,0.0604555,48.8245,1.00000,1.00,707.355,1.00000,1000000,193538,1.00000,1000000,1.00000
17683.9,0.0625330,93.4779,1.00000,1.00,707.355,1.00000,1000000,180892,1.00000,1000000,1.00000
17683.9,0.0694787,118.771,1.00000,1.00,707.355,1.00000,1000000,146533,1.00000,1000000,1.00000
17683.9,0.0699636,84.6802,1.00000,1.00,707.355,1.00000,1000000,144508,1.00000,1000000,1.00000
17683.9,0.0703874,42.5753,1.00000,1.00,707.355,1.00000,1000000,142774,1.00000,1000000,1.00000
17683.9,0.0782652,76.6682,1.00000,1.00,707.355,1.00000,1000000,115478,1.00000,1000000,1.00000
17683.9,0.0808867,101.614,1.00000,1.00,707.355,1.00000,1000000,108114,1.00000,1000000,1.00000
17683.9,0.0819509,37.5322,1.00000,1.00,707.355,1.00000,1000000,105325,1.00000,1000000,1.00000
17683.9,0.0876009,69.4890,1.00000,1.00,707.355,1.00000,1000000,92176.6,1.00000,1000000,1.00000
17683.9,0.0941679,88.3359,1.00000,1.00,707.355,1.00000,1000000,79768.6,1.00000,1000000,1.00000
17683.9,0.0954142,32.7581,1.00000,1.00,707.355,1.00000,1000000,77698.3,1.00000,1000000,1.00000
17683.9,0.0980929,62.8787,1.00000,1.00,707.355,1.00000,1000000,73512.7,1.00000,1000000,1.00000
17683.9,0.109630,76.6485,1.00000,1.00,707.355,1.00000,1000000,58854.4,1.00000,1000000,1.00000
17683.9,0.109898,56.6555,1.00000,1.00,707.355,1.00000,1000000,58567.7,1.00000,1000000,1.00000
17683.9,0.111089,28.5912,1.00000,1.00,707.355,1.00000,1000000,57318.6,1.00000,1000000,1.00000
17683.9,0.122923,50.8414,1.00000,1.00,707.355,1.00000,1000000,46813.5,1.00000,1000000,1.00000
17683.9,0.127630,67.1355,1.00000,1.00,707.355,1.00000,1000000,43424.2,1.00000,1000000,1.00000
17683.9,0.129340,24.8189,1.00000,1.00,707.355,1.00000,1000000,42283.6,1.00000,1000000,1.00000
17683.9,0.137546,45.5799,1.00000,1.00,707.355,1.00000,1000000,37388.8,1.00000,1000000,1.00000
17683.9,0.148586,58.4175,1.00000,1.00,707.355,1.00000,1000000,32039.2,1.00000,1000000,1.00000
17683.9,0.150588,21.5443,1.00000,1.00,707.355,1.00000,1000000,31193.0,1.00000,1000000,1.00000
17683.9,0.154042,40.9013,1.00000,1.00,707.355,1.00000,1000000,29809.8,1.00000,1000000,1.00000
17683.9,0.172529,36.5215,1.00000,1.00,707.355,1.00000,1000000,23763.7,1.00000,1000000,1.00000
17683.9,0.172983,50.7362,1.00000,1.00,707.355,1.00000,1000000,23639.1,1.00000,1000000,1.00000
17683.9,0.175327,18.8039,1.00000,1.00,707.355,1.00000,1000000,23011.2,1.00000,1000000,1.00000
17683.9,0.193019,32.6062,1.00000,1.00,707.355,1.00000,1000000,18986.2,1.00000,1000000,1.00000
17683.9,0.201386,44.0648,1.00000,1.00,707.355,1.00000,1000000,17441.3,1.00000,1000000,1.00000
17683.9,0.204131,16.4269,1.00000,1.00,707.355,1.00000,1000000,16975.4,1.00000,1000000,1.00000
17683.9,0.215944,29.2767,1.00000,1.00,707.355,1.00000,1000000,15168.9,1.00000,1000000,1.00000
17683.9,0.234453,38.5596,1.00000,1.00,707.355,1.00000,1000000,12868.4,1.00000,1000000,1.00000
17683.9,0.237667,14.4549,1.00000,1.00,707.355,1.00000,1000000,12522.8,1.00000,1000000,1.00000
17683.9,0.241840,26.2197,1.00000,1.00,707.355,1.00000,1000000,12094.3,1.00000,1000000,1.00000
17683.9,0.270843,23.4744,1.00000,1.00,707.355,1.00000,1000000,9642.78,1.00000,1000000,1.00000
17683.9,0.272949,34.1248,1.00000,1.00,707.355,1.00000,1000000,9494.55,1.00000,1000000,1.00000
17683.9,0.276712,12.5250,1.00000,1.00,707.355,1.00000,1000000,9238.08,1.00000,1000000,1.00000
17683.9,0.303025,21.1859,1.00000,1.00,707.355,1.00000,1000000,7703.37,1.00000,1000000,1.00000
17683.9,0.317765,29.7494,1.00000,1.00,707.355,1.00000,1000000,7005.28,1.00000,1000000,1.00000
17683.9,0.322171,10.8134,1.00000,1.00,707.355,1.00000,1000000,6814.98,1.00000,1000000,1.00000
17683.9,0.338980,18.9811,1.00000,1.00,707.355,1.00000,1000000,6155.87,1.00000,1000000,1.00000
17683.9,0.369940,26.2784,1.00000,1.00,707.355,1.00000,1000000,5168.62,1.00000,1000000,1.00000
17683.9,0.375099,9.40377,1.00000,1.00,707.355,1.00000,1000000,5027.43,1.00000,1000000,1.00000
17683.9,0.379251,16.8932,1.00000,1.00,707.355,1.00000,1000000,4917.95,1.00000,1000000,1.00000
17683.9,0.424762,15.0013,1.00000,1.00,707.355,1.00000,1000000,3920.54,1.00000,1000000,1.00000
17683.9,0.430682,23.1253,1.00000,1.00,707.355,1.00000,1000000,3813.50,1.00000,1000000,1.00000
17683.9,0.436722,8.07468,1.00000,1.00,707.355,1.00000,1000000,3708.75,1.00000,1000000,1.00000
17683.9,0.475624,13.3173,1.00000,1.00,707.355,1.00000,1000000,3126.87,1.00000,1000000,1.00000
17683.9,0.501398,20.0846,1.00000,1.00,707.355,1.00000,1000000,2813.66,1.00000,1000000,1.00000
,0.508468,6.94603,,,,,,,,,
17683.9,0.532114,11.8298,1.00000,1.00,707.355,1.00000,1000000,2498.21,1.00000,1000000,1.00000
17683.9,0.583725,17.4273,1.00000,1.00,707.355,1.00000,1000000,2075.97,1.00000,1000000,1.00000
17683.9,0.592002,5.88906,1.00000,1.00,707.355,1.00000,1000000,2018.33,1.00000,1000000,1.00000
17683.9,0.595300,10.5995,1.00000,1.00,707.355,1.00000,1000000,1996.02,1.00000,1000000,1.00000
17683.9,0.666677,9.55801,1.00000,1.00,707.355,1.00000,1000000,1591.50,1.00000,1000000,1.00000
17683.9,0.679569,14.4003,1.00000,1.00,707.355,1.00000,1000000,1531.69,1.00000,1000000,1.00000
17683.9,0.689259,5.05214,1.00000,1.00,707.355,1.00000,1000000,1488.92,1.00000,1000000,1.00000
17683.9,0.746625,8.62331,1.00000,1.00,707.355,1.00000,1000000,1268.92,1.00000,1000000,1.00000
17683.9,0.791150,12.4716,1.00000,1.00,707.355,1.00000,1000000,1130.11,1.00000,1000000,1.00000
17683.9,0.802493,4.32238,1.00000,1.00,707.355,1.00000,1000000,1098.39,1.00000,1000000,1.00000
17683.9,0.835246,7.77361,1.00000,1.00,707.355,1.00000,1000000,1013.93,1.00000,1000000,1.00000
17683.9,0.921053,11.5465,1.00000,1.00,707.355,1.00000,1000000,833.812,1.00000,1000000,1.00000
17683.9,0.934331,3.69133,1.00000,1.00,707.355,1.00000,1000000,810.282,1.00000,1000000,1.00000
17683.9,0.934357,7.00938,1.00000,1.00,707.355,1.00000,1000000,810.237,1.00000,1000000,1.00000
17683.9,1.04649,6.30255,1.00000,1.00,707.355,1.00000,1000000,645.903,1.00000,1000000,1.00000
17683.9,1.07228,10.4418,1.00000,1.00,707.355,1.00000,1000000,615.207,1.00000,1000000,1.00000
17683.9,1.08783,3.19270,1.00000,1.00,707.355,1.00000,1000000,597.744,1.00000,1000000,1.00000
17683.9,1.17190,5.63462,1.00000,1.00,707.355,1.00000,1000000,515.058,1.00000,1000000,1.00000
17683.9,1.24835,9.09445,1.00000,1.00,707.355,1.00000,1000000,453.905,1.00000,1000000,1.00000
17683.9,1.26654,2.75142,1.00000,1.00,707.355,1.00000,1000000,440.961,1.00000,1000000,1.00000
17683.9,1.31103,5.06512,1.00000,1.00,707.355,1.00000,1000000,411.540,1.00000,1000000,1.00000
17683.9,1.45332,8.05606,1.00000,1.00,707.355,1.00000,1000000,334.900,1.00000,1000000,1.00000
17683.9,1.46665,4.54550,1.00000,1.00,707.355,1.00000,1000000,328.840,1.00000,1000000,1.00000
17683.9,1.47461,2.69951,1.00000,1.00,707.355,1.00000,1000000,325.299,1.00000,1000000,1.00000
17683.9,1.64081,4.02939,1.00000,1.00,707.355,1.00000,1000000,262.737,1.00000,1000000,1.00000
17683.9,1.69194,7.46553,1.00000,1.00,707.355,1.00000,1000000,247.097,1.00000,1000000,1.00000
17683.9,1.71687,3.37432,1.00000,1.00,707.355,1.00000,1000000,239.973,1.00000,1000000,1.00000
17683.9,1.83751,3.54425,1.00000,1.00,707.355,1.00000,1000000,209.497,1.00000,1000000,1.00000
17683.9,1.95789,3.22654,1.00000,1.00,707.355,1.00000,1000000,184.527,1.00000,1000000,1.00000
17683.9,1.96975,6.65678,1.00000,1.00,707.355,1.00000,1000000,182.312,1.00000,1000000,1.00000
17683.9,2.05786,3.08757,1.00000,1.00,707.355,1.00000,1000000,167.034,1.00000,1000000,1.00000
17683.9,2.11260,2.41089,1.00000,1.00,707.355,1.00000,1000000,158.490,1.00000,1000000,1.00000
17683.9,2.29317,5.89672,1.00000,1.00,707.355,1.00000,1000000,134.513,1.00000,1000000,1.00000
17683.9,2.30205,2.67074,1.00000,1.00,707.355,1.00000,1000000,133.477,1.00000,1000000,1.00000
17683.9,2.32732,1.82936,1.00000,1.00,707.355,1.00000,1000000,130.595,1.00000,1000000,1.00000
17683.9,2.57539,2.30127,1.00000,1.00,707.355,1.00000,1000000,106.648,1.00000,1000000,1.00000
17683.9,2.63575,2.22700,1.00000,1.00,707.355,1.00000,1000000,101.819,1.00000,1000000,1.00000
17683.9,2.66970,5.16001,1.00000,1.00,707.355,1.00000,1000000,99.2459,1.00000,1000000,1.00000
17683.9,2.88420,1.97717,1.00000,1.00,707.355,1.00000,1000000,85.0329,1.00000,1000000,1.00000
17683.9,2.98506,2.61753,1.00000,1.00,707.355,1.00000,1000000,79.3837,1.00000,1000000,1.00000
17683.9,3.10805,4.17257,1.00000,1.00,707.355,1.00000,1000000,73.2254,1.00000,1000000,1.00000
17683.9,3.22990,1.70840,1.00000,1.00,707.355,1.00000,1000000,67.8047,1.00000,1000000,1.00000
17683.9,3.47545,2.79418,1.00000,1.00,707.355,1.00000,1000000,58.5619,1.00000,1000000,1.00000
17683.9,3.56871,3.42987,1.00000,1.00,707.355,1.00000,1000000,55.5412,1.00000,1000000,1.00000
17683.9,3.61325,1.48986,1.00000,1.00,707.355,1.00000,1000000,54.1803,1.00000,1000000,1.00000
17683.9,3.98593,2.70980,1.00000,1.00,707.355,1.00000,1000000,44.5224,1.00000,1000000,1.00000
17683.9,4.04231,1.30765,1.00000,1.00,707.355,1.00000,1000000,43.2891,1.00000,1000000,1.00000
17683.9,4.04642,2.69218,1.00000,1.00,707.355,1.00000,1000000,43.2012,1.00000,1000000,1.00000
17683.9,4.42127,2.11047,1.00000,1.00,707.355,1.00000,1000000,36.1862,1.00000,1000000,1.00000
17683.9,4.52218,1.16085,1.00000,1.00,707.355,1.00000,1000000,34.5893,1.00000,1000000,1.00000
17683.9,4.71118,2.47216,1.00000,1.00,707.355,1.00000,1000000,31.8697,1.00000,1000000,1.00000
17683.9,4.93816,1.69641,1.00000,1.00,707.355,1.00000,1000000,29.0073,1.00000,1000000,1.00000
17683.9,5.06408,1.03996,1.00000,1.00,707.355,1.00000,1000000,27.5827,1.00000,1000000,1.00000
17683.9,5.48516,2.10550,1.00000,1.00,707.355,1.00000,1000000,23.5103,1.00000,1000000,1.00000
17683.9,5.51549,1.32024,1.00000,1.00,707.355,1.00000,1000000,23.2525,1.00000,1000000,1.00000
17683.9,5.67135,0.925291,1.00000,1.00,707.355,1.00000,1000000,21.9920,1.00000,1000000,1.00000
17683.9,6.20303,1.24529,1.00000,1.00,707.355,1.00000,1000000,18.3836,1.00000,1000000,1.00000
17683.9,6.34457,0.820486,1.00000,1.00,707.355,1.00000,1000000,17.5725,1.00000,1000000,1.00000
17683.9,6.38628,1.87812,1.00000,1.00,707.355,1.00000,1000000,17.3437,1.00000,1000000,1.00000
17683.9,7.09783,0.709827,1.00000,1.00,707.355,1.00000,1000000,14.0406,1.00000,1000000,1.00000
17683.9,7.12241,1.42116,1.00000,1.00,707.355,1.00000,1000000,13.9439,1.00000,1000000,1.00000
17683.9,7.43545,1.87641,1.00000,1.00,707.355,1.00000,1000000,12.7945,1.00000,1000000,1.00000
17683.9,7.94914,0.610222,1.00000,1.00,707.355,1.00000,1000000,11.1943,1.00000,1000000,1.00000
17683.9,8.29187,1.35847,1.00000,1.00,707.355,1.00000,1000000,10.2880,1.00000,1000000,1.00000
17683.9,8.65698,1.67529,1.00000,1.00,707.355,1.00000,1000000,9.43854,1.00000,1000000,1.00000
17683.9,8.90133,0.549355,1.00000,1.00,707.355,1.00000,1000000,8.92746,1.00000,1000000,1.00000
17683.9,9.65334,1.03925,1.00000,1.00,707.355,1.00000,1000000,7.59071,1.00000,1000000,1.00000
17683.9,9.87228,1.35616,1.00000,1.00,707.355,1.00000,1000000,7.25776,1.00000,1000000,1.00000
17683.9,9.95832,0.521411,1.00000,1.00,707.355,1.00000,1000000,7.13289,1.00000,1000000,1.00000
17683.9,11.1403,0.488568,1.00000,1.00,707.355,1.00000,1000000,5.69959,1.00000,1000000,1.00000
17683.9,11.2384,1.11306,1.00000,1.00,707.355,1.00000,1000000,5.60052,1.00000,1000000,1.00000
17683.9,11.2582,1.10381,1.00000,1.00,707.355,1.00000,1000000,5.58084,1.00000,1000000,1.00000
17683.9,12.4761,0.456779,1.00000,1.00,707.355,1.00000,1000000,4.54444,1.00000,1000000,1.00000
17683.9,13.0836,1.33694,1.00000,1.00,707.355,1.00000,1000000,4.13222,1.00000,1000000,1.00000
17683.9,13.1077,1.01544,1.00000,1.00,707.355,1.00000,1000000,4.11704,1.00000,1000000,1.00000
17683.9,13.9723,0.424485,1.00000,1.00,707.355,1.00000,1000000,3.62328,1.00000,1000000,1.00000
17683.9,15.2319,1.18095,1.00000,1.00,707.355,1.00000,1000000,3.04880,1.00000,1000000,1.00000
17683.9,15.2611,0.769339,1.00000,1.00,707.355,1.00000,1000000,3.03715,1.00000,1000000,1.00000
17683.9,15.6304,0.373551,1.00000,1.00,707.355,1.00000,1000000,2.89533,1.00000,1000000,1.00000
17683.9,17.4860,0.303890,1.00000,1.00,707.355,1.00000,1000000,2.31343,1.00000,1000000,1.00000
17683.9,17.5243,0.675278,1.00000,1.00,707.355,1.00000,1000000,2.30333,1.00000,1000000,1.00000
17683.9,17.7329,1.19211,1.00000,1.00,707.355,1.00000,1000000,2.24946,1.00000,1000000,1.00000
17683.9,19.5342,0.901755,1.00000,1.00,707.355,1.00000,1000000,1.85373,1.00000,1000000,1.00000
17683.9,19.5622,0.262355,1.00000,1.00,707.355,1.00000,1000000,1.84843,1.00000,1000000,1.00000
17683.9,19.6697,0.714606,1.00000,1.00,707.355,1.00000,1000000,1.82828,1.00000,1000000,1.00000
17683.9,19.9894,0.539625,1.00000,1.00,707.355,1.00000,1000000,1.77026,1.00000,1000000,1.00000
17683.9,20.1231,0.514774,1.00000,1.00,707.355,1.00000,1000000,1.74682,1.00000,1000000,1.00000
17683.9,20.2676,0.393009,1.00000,1.00,707.355,1.00000,1000000,1.72200,1.00000,1000000,1.00000
17683.9,20.5496,0.284263,1.00000,1.00,707.355,1.00000,1000000,1.67506,1.00000,1000000,1.00000
17683.9,21.8935,0.158369,1.00000,1.00,707.355,1.00000,1000000,1.47573,1.00000,1000000,1.00000
17683.9,21.9059,0.223345,1.00000,1.00,707.355,1.00000,1000000,1.47406,1.00000,1000000,1.00000
17683.9,22.1653,0.193813,1.00000,1.00,707.355,1.00000,1000000,1.43976,1.00000,1000000,1.00000
17683.9,23.2676,0.414940,1.00000,1.00,707.355,1.00000,1000000,1.30658,1.00000,1000000,1.00000
17683.9,24.5346,0.200665,1.00000,1.00,707.355,1.00000,1000000,1.17511,1.00000,1000000,1.00000
17683.9,25.4004,0.195249,1.00000,1.00,707.355,1.00000,1000000,1.09637,1.00000,1000000,1.00000
17683.9,26.3511,0.354425,1.00000,1.00,707.355,1.00000,1000000,1.01869,1.00000,1000000,1.00000
17683.9,27.4435,0.176096,1.00000,1.00,707.355,1.00000,1000000,0.939201,1.00000,1000000,1.00000
17683.9,28.7647,0.264750,1.00000,1.00,707.355,1.00000,1000000,0.854905,1.00000,1000000,1.00000
17683.9,30.0504,0.310606,1.00000,1.00,707.355,1.00000,1000000,0.783316,1.00000,1000000,1.00000
17683.9,30.7066,0.159605,1.00000,1.00,707.355,1.00000,1000000,0.750195,1.00000,1000000,1.00000
17683.9,31.3961,0.217262,1.00000,1.00,707.355,1.00000,1000000,0.717606,1.00000,1000000,1.00000
17683.9,32.1277,0.164204,1.00000,1.00,707.355,1.00000,1000000,0.685296,1.00000,1000000,1.00000
17683.9,34.3826,0.141009,1.00000,1.00,707.355,1.00000,1000000,0.598357,1.00000,1000000,1.00000
17683.9,34.7450,0.126260,1.00000,1.00,707.355,1.00000,1000000,0.585940,1.00000,1000000,1.00000
17683.9,34.9872,0.251666,1.00000,1.00,707.355,1.00000,1000000,0.577855,1.00000,1000000,1.00000
17683.9,38.5056,0.127881,1.00000,1.00,707.355,1.00000,1000000,0.477078,1.00000,1000000,1.00000
17683.9,39.8029,0.209903,1.00000,1.00,707.355,1.00000,1000000,0.446486,1.00000,1000000,1.00000
17683.9,40.0789,0.168503,1.00000,1.00,707.355,1.00000,1000000,0.440358,1.00000,1000000,1.00000
17683.9,40.7351,0.224487,1.00000,1.00,707.355,1.00000,1000000,0.426285,1.00000,1000000,1.00000
17683.9,43.0793,0.110341,1.00000,1.00,707.355,1.00000,1000000,0.381154,1.00000,1000000,1.00000
17683.9,44.0486,0.110763,1.00000,1.00,707.355,1.00000,1000000,0.364564,1.00000,1000000,1.00000
17683.9,45.1096,0.0851927,1.00000,1.00,707.355,1.00000,1000000,0.347616,1.00000,1000000,1.00000
17683.9,47.4273,0.188437,1.00000,1.00,707.355,1.00000,1000000,0.314471,1.00000,1000000,1.00000
17683.9,48.1928,0.0985216,1.00000,1.00,707.355,1.00000,1000000,0.304560,1.00000,1000000,1.00000
17683.9,52.3553,0.0971123,1.00000,1.00,707.355,1.00000,1000000,0.258057,1.00000,1000000,1.00000
17683.9,53.9120,0.0827312,1.00000,1.00,707.355,1.00000,1000000,0.243370,1.00000,1000000,1.00000
17683.9,55.2188,0.156749,1.00000,1.00,707.355,1.00000,1000000,0.231987,1.00000,1000000,1.00000
17683.9,57.7496,0.0951093,1.00000,1.00,707.355,1.00000,1000000,0.212100,1.00000,1000000,1.00000
17683.9,60.3807,0.0691663,1.00000,1.00,707.355,1.00000,1000000,0.194018,1.00000,1000000,1.00000
17683.9,64.2905,0.136438,1.00000,1.00,707.355,1.00000,1000000,0.171137,1.00000,1000000,1.00000
17683.9,65.9173,0.0663760,1.00000,1.00,707.355,1.00000,1000000,0.162794,1.00000,1000000,1.00000
17683.9,67.6104,0.0592490,1.00000,1.00,707.355,1.00000,1000000,0.154743,1.00000,1000000,1.00000
17683.9,74.8524,0.117474,1.00000,1.00,707.355,1.00000,1000000,0.126248,1.00000,1000000,1.00000
17683.9,75.1660,0.0612581,1.00000,1.00,707.355,1.00000,1000000,0.125197,1.00000,1000000,1.00000
17683.9,75.6406,0.0519483,1.00000,1.00,707.355,1.00000,1000000,0.123631,1.00000,1000000,1.00000
17683.9,83.0321,0.100825,1.00000,1.00,707.355,1.00000,1000000,0.102600,1.00000,1000000,1.00000
17683.9,84.6177,0.0462281,1.00000,1.00,707.355,1.00000,1000000,0.0987905,1.00000,1000000,1.00000
17683.9,85.7123,0.0492744,1.00000,1.00,707.355,1.00000,1000000,0.0962834,1.00000,1000000,1.00000
17683.9,86.5490,0.0781767,1.00000,1.00,707.355,1.00000,1000000,0.0944308,1.00000,1000000,1.00000
17683.9,88.9760,0.0624576,1.00000,1.00,707.355,1.00000,1000000,0.0893494,1.00000,1000000,1.00000
17683.9,91.4710,0.0498991,1.00000,1.00,707.355,1.00000,1000000,0.0845417,1.00000,1000000,1.00000
17683.9,94.5639,0.0448778,1.00000,1.00,707.355,1.00000,1000000,0.0791019,1.00000,1000000,1.00000
17683.9,94.6885,0.0384978,1.00000,1.00,707.355,1.00000,1000000,0.0788938,1.00000,1000000,1.00000
17683.9,97.7384,0.0422210,1.00000,1.00,707.355,1.00000,1000000,0.0740469,1.00000,1000000,1.00000
17683.9,98.6991,0.0291147,1.00000,1.00,707.355,1.00000,1000000,0.0726125,1.00000,1000000,1.00000
17683.9,108.730,0.0239347,1.00000,1.00,707.355,1.00000,1000000,0.0598327,1.00000,1000000,1.00000
17683.9,111.452,0.0339615,1.00000,1.00,707.355,1.00000,1000000,0.0569458,1.00000,1000000,1.00000
17683.9,126.593,0.0210805,1.00000,1.00,707.355,1.00000,1000000,0.0441386,1.00000,1000000,1.00000
17683.9,129.752,0.0296905,1.00000,1.00,707.355,1.00000,1000000,0.0420155,1.00000,1000000,1.00000
17683.9,147.390,0.0201824,1.00000,1.00,707.355,1.00000,1000000,0.0325613,1.00000,1000000,1.00000
-6.45311,151.056,0.0271800,0.921630,19.98,6309.75,8.92019,20.0137,0.276526,0.921630,-364.915,-2.00516e-4
29.2710,171.604,0.0192003,12.7140,19.98,5828.66,8.24008,20.0149,0.197931,12.7140,1655.24,1.28963e-4
51.4334,175.859,0.0277740,18.5467,19.99,5681.32,8.03177,20.0249,0.183704,18.5467,2908.49,1.13419e-4
66.7102,197.780,0.0232101,25.9523,19.99,5561.66,7.86261,20.0215,0.142180,25.9523,3772.37,1.32048e-4
78.2275,199.796,0.0190270,33.2923,19.99,5393.62,7.62504,20.0194,0.135116,33.2923,4423.66,1.49410e-4
88.8380,222.435,0.0187686,40.6324,20.00,5243.47,7.41278,20.0258,0.105977,40.6324,5023.67,1.65284e-4
98.8630,232.620,0.0182992,47.9724,20.00,5133.75,7.25767,20.0134,0.0948726,47.9724,5590.57,1.82679e-4
108.448,258.957,0.0179070,55.3124,20.00,5001.62,7.07087,20.0113,0.0745857,55.3124,6132.61,2.00875e-4
118.316,270.836,0.0159570,62.7180,20.00,4870.29,6.88521,20.0058,0.0663960,62.7180,6690.63,2.22418e-4
126.206,301.477,0.0152485,70.1236,20.00,4728.12,6.68422,20.0135,0.0520212,70.1236,7136.77,2.49761e-4
126.977,315.330,0.0140033,77.4636,20.00,4561.44,6.44858,20.0194,0.0458745,77.4636,7180.39,2.84267e-4
125.290,350.978,0.0142374,84.8036,20.00,4432.06,6.26568,20.0191,0.0359788,84.8036,7084.96,3.09785e-4
123.969,367.134,0.0133824,92.1436,20.00,4296.76,6.07440,20.0162,0.0318781,92.1436,7010.28,3.38805e-4
122.751,402.998,0.0135739,99.4837,20.00,4196.72,5.93297,20.0156,0.0258407,99.4837,6941.42,3.70455e-4
121.340,427.448,0.0130468,106.889,20.00,4101.03,5.79769,20.0165,0.0224453,106.889,6861.59,4.05485e-4
120.010,462.728,0.0114913,114.295,20.00,3977.77,5.62344,20.0081,0.0185775,114.295,6786.41,4.45516e-4
118.671,497.671,0.0128588,121.635,20.00,3928.88,5.55432,20.0187,0.0158629,121.635,6710.67,4.86833e-4
117.541,538.705,0.0103919,128.975,20.00,3848.59,5.44081,20.0099,0.0132617,128.975,6646.80,5.33447e-4
116.672,579.431,0.0119263,136.315,20.00,3802.18,5.37521,20.0225,0.0113248,136.315,6597.64,5.83164e-4
115.492,627.157,0.0101792,143.655,20.00,3742.73,5.29116,20.0206,9.51560e-3,143.655,6530.92,6.38773e-4
114.477,674.622,0.0131061,151.061,20.00,3667.06,5.18418,20.0141,8.05743e-3,151.061,6473.55,7.00485e-4
113.211,730.133,0.0101696,158.466,20.00,3620.81,5.11880,20.0221,6.79206e-3,158.466,6401.94,7.66417e-4
112.365,785.453,0.0136027,165.806,20.00,3573.30,5.05163,20.0152,5.79200e-3,165.806,6354.12,8.39556e-4
111.285,850.017,0.0117203,173.146,20.00,3521.46,4.97834,20.0156,4.87379e-3,173.146,6293.01,9.19427e-4
110.283,914.490,0.0116590,180.486,20.00,3495.31,4.94138,20.0192,4.17953e-3,180.486,6236.35,1.00398e-3
109.531,949.393,0.0100461,187.826,20.00,3447.11,4.87324,20.0223,3.82440e-3,187.826,6193.81,1.10113e-3
108.544,1060.39,8.19000e-3,195.232,20.00,3409.77,4.82045,20.0153,3.03245e-3,195.232,6138.03,1.20621e-3
107.243,1064.73,0.0107841,202.637,20.00,3337.15,4.71779,20.0205,2.94372e-3,202.637,6064.43,1.32194e-3
106.508,1234.50,7.42000e-3,209.977,19.99,3332.05,4.71057,20.0266,2.18640e-3,209.977,6022.90,1.44634e-3
106.117,1239.65,9.77000e-3,217.317,20.00,3312.35,4.68272,20.0207,2.15545e-3,217.317,6000.80,1.58461e-3
105.101,1437.19,6.88000e-3,224.657,20.00,3250.45,4.59522,20.0112,1.57368e-3,224.657,5943.32,1.73531e-3
104.159,1443.30,8.79000e-3,231.997,20.00,3208.06,4.53529,20.0223,1.54003e-3,231.997,5890.03,1.90095e-3
103.301,1673.17,6.74000e-3,239.403,20.00,3164.94,4.47433,20.0275,1.13054e-3,239.403,5841.54,2.08287e-3
102.672,1680.41,8.02000e-3,246.809,20.00,3139.11,4.43782,20.0269,1.11167e-3,246.809,5805.97,2.28158e-3
102.317,1947.90,6.60000e-3,254.149,20.00,3135.82,4.43315,20.0193,8.26451e-4,254.149,5785.89,2.49860e-3
101.565,1956.48,7.25000e-3,261.489,20.00,3063.78,4.33131,20.0324,8.00399e-4,261.489,5743.36,2.73752e-3
101.059,2267.73,6.21000e-3,268.829,20.00,3054.77,4.31858,20.0345,5.94013e-4,268.829,5714.73,2.99598e-3
100.827,2277.90,6.64000e-3,276.169,20.00,3038.49,4.29556,20.0351,5.85583e-4,276.169,5701.62,3.28128e-3
100.633,2640.08,5.98000e-3,283.574,20.00,3004.20,4.24709,20.0326,4.31018e-4,283.574,5690.68,3.59550e-3
100.693,2652.12,6.29000e-3,290.980,20.00,3025.86,4.27771,20.0195,4.30193e-4,290.980,5694.04,3.94027e-3
100.425,3073.57,5.87000e-3,298.320,20.00,3000.55,4.24192,20.0227,3.17625e-4,298.320,5678.89,4.31533e-3
100.406,3087.82,5.91000e-3,305.660,20.00,3014.16,4.26116,20.0263,3.16127e-4,305.660,5677.84,4.72537e-3
100.356,3578.23,5.81000e-3,313.000,20.00,3024.58,4.27590,20.0271,2.36226e-4,313.000,5674.99,5.17334e-3
100.789,3595.11,5.53000e-3,320.340,20.00,3025.26,4.27687,20.0223,2.34066e-4,320.340,5699.50,5.66563e-3
100.755,4165.75,5.78000e-3,327.746,20.00,3006.97,4.25101,20.0300,1.73278e-4,327.746,5697.54,6.20943e-3
101.377,4185.73,5.49000e-3,335.151,20.00,3008.17,4.25270,20.0162,1.71696e-4,335.151,5732.74,6.80402e-3
102.070,4849.75,5.36000e-3,342.491,20.00,3023.80,4.27480,20.0172,1.28563e-4,342.491,5771.92,7.45105e-3
102.029,4873.38,4.89000e-3,349.831,20.00,3002.27,4.24435,20.0236,1.26412e-4,349.831,5769.58,8.15954e-3
101.609,5646.05,5.08000e-3,357.171,20.00,2957.18,4.18062,20.0278,9.27659e-5,357.171,5745.85,8.93675e-3
99.6647,5674.00,4.21000e-3,364.511,20.00,2833.74,4.00610,20.0178,8.80199e-5,364.511,5635.90,9.78770e-3
96.2830,6573.09,4.89000e-3,371.917,20.00,2636.98,3.72795,20.0298,6.10335e-5,371.917,5444.67,0.0107259
93.3609,6606.15,4.08000e-3,379.322,20.00,2498.56,3.53225,20.0119,5.72523e-5,379.322,5279.43,0.0117550
90.0681,7652.36,4.75000e-3,386.662,20.00,2598.99,3.67423,20.0222,4.43827e-5,386.662,5093.23,0.0128697
91.1619,7691.44,4.06000e-3,394.002,20.00,2854.50,4.03545,20.0278,4.82519e-5,394.002,5155.09,0.0140857
95.9021,8908.83,4.67000e-3,401.342,20.00,3022.57,4.27306,20.0223,3.80834e-5,401.342,5423.13,0.0154214
99.6324,8955.02,3.89000e-3,408.683,20.00,3050.66,4.31277,20.0253,3.80417e-5,408.683,5634.08,0.0168918
100.411,10371.6,4.57000e-3,416.088,20.00,3052.76,4.31574,20.0228,2.83793e-5,416.088,5678.10,0.0185150
99.5231,10426.2,3.82000e-3,423.494,20.00,3051.76,4.31433,20.0285,2.80736e-5,423.494,5627.90,0.0202906
100.204,12074.6,4.40000e-3,430.834,19.99,3073.92,4.34565,20.0285,2.10837e-5,430.834,5666.42,0.0222167
100.620,12139.1,3.76000e-3,438.174,20.00,3000.83,4.24233,20.0255,2.03643e-5,438.174,5689.95,0.0243301
101.621,14057.1,4.18000e-3,445.514,20.00,3206.56,4.53317,20.0269,1.62274e-5,445.514,5746.55,0.0266340
107.808,14133.3,3.65000e-3,452.854,20.01,3400.77,4.80773,20.0262,1.70251e-5,452.854,6096.41,0.0291657
109.462,15786.5,3.53000e-3,460.259,20.00,3411.84,4.82338,20.0249,1.36904e-5,460.259,6189.93,0.0319691
109.557,15809.5,3.77000e-3,467.665,20.00,3283.97,4.64260,20.0213,1.31390e-5,467.665,6195.32,0.0350348