File: 09_characterizationRheology/csv/peo_su8_01_050_0.csv
Filename,peo_su8_01_050_0
Instrument name,5333-0457
Operator,Osamu Katagiri
rundate,29/01/2020
Sample name,PEO_SU8_01_050_0
Geometry name,60mm 0.9969° cone plate, Peltier plate Steel
Procedure name,Sample
,Flow ramp
proceduresegments,Flow ramp
[step]
Flow ramp - 1
Stress,Shear rate,Viscosity,Step time,Temperature,Normal stress,Axial force,Gap,Normal stress coefficient,Time,Torque,Velocity
Pa,1/s,Pa.s,s,°C,Pa,N,µm,Pa.s²,s,µN.m,rad/s
43.6470,7.18799e-3,364.695,6.81578,20.06,4760.41,6.72987,20.0234,9.21360e7,6.81578,2468.18,1.13294e-4
89.5486,8.36886e-3,340.712,18.5467,20.04,4214.91,5.95869,20.0127,6.01804e7,18.5467,5063.85,1.15884e-4
100.423,9.74374e-3,297.373,25.9523,20.03,3955.42,5.59184,20.0204,4.16621e7,25.9523,5678.79,1.44429e-4
99.9167,0.0113445,253.267,33.2923,20.03,3714.50,5.25125,20.0069,2.88623e7,33.2923,5650.15,1.66092e-4
97.5546,0.0132082,217.867,40.6324,20.02,3516.00,4.97063,20.0123,2.01540e7,40.6324,5516.58,1.80338e-4
95.6295,0.0153781,186.735,47.9724,20.02,3353.05,4.74026,20.0124,1.41786e7,47.9724,5407.72,1.96945e-4
93.4414,0.0179045,161.072,55.3124,20.01,3215.64,4.54601,20.0175,1.00310e7,55.3124,5283.99,2.15793e-4
91.8402,0.0208459,138.809,62.7180,20.00,3111.62,4.39894,20.0184,7160500,62.7180,5193.44,2.35702e-4
89.6256,0.0242706,120.168,70.1236,20.01,2974.82,4.20556,20.0137,5050100,70.1236,5068.21,2.59218e-4
88.3151,0.0282579,101.697,77.4636,20.01,2908.57,4.11190,20.0193,3642500,77.4636,4994.10,2.83472e-4
86.8858,0.0329002,85.7539,84.8036,20.00,2821.49,3.98879,20.0133,2606640,84.8036,4913.28,3.09710e-4
85.3678,0.0383052,73.2342,92.1436,20.00,2744.28,3.87964,20.0287,1870310,92.1436,4827.44,3.38358e-4
83.9953,0.0445982,63.9767,99.4837,20.00,2658.96,3.75902,20.0259,1336830,99.4837,4749.82,3.71053e-4
82.5239,0.0519250,55.9402,106.889,20.00,2600.42,3.67625,20.0265,964472,106.889,4666.62,4.06092e-4
81.0027,0.0604555,48.8245,114.295,20.00,2528.33,3.57434,20.0177,691771,114.295,4580.60,4.45685e-4
78.9424,0.0703874,42.5753,121.635,20.00,2450.37,3.46413,20.0230,494586,121.635,4464.09,4.87980e-4
76.6520,0.0819509,37.5322,128.975,20.00,2401.38,3.39487,20.0193,357563,128.975,4334.57,5.34712e-4
74.0572,0.0954142,32.7581,136.315,20.00,2343.85,3.31354,20.0135,257456,136.315,4187.83,5.85599e-4
72.1460,0.111089,28.5912,143.655,20.00,2300.15,3.25176,20.0167,186385,143.655,4079.76,6.39533e-4
71.1745,0.129340,24.8189,151.061,20.00,2269.04,3.20778,20.0260,135637,151.061,4024.83,6.99987e-4
70.6081,0.150588,21.5443,158.466,20.00,2233.10,3.15697,20.0259,98475.3,158.466,3992.79,7.66079e-4
70.1534,0.175327,18.8039,165.806,20.00,2202.74,3.11406,20.0253,71658.0,165.806,3967.08,8.39583e-4
69.5974,0.204131,16.4269,173.146,20.00,2170.12,3.06793,20.0179,52079.4,173.146,3935.64,9.18123e-4
69.4552,0.237667,14.4549,180.486,20.00,2146.82,3.03500,20.0219,38006.7,180.486,3927.60,1.00344e-3
69.2491,0.276712,12.5250,187.826,20.00,2123.83,3.00250,20.0159,27737.4,187.826,3915.94,1.10029e-3
68.8930,0.322171,10.8134,195.232,20.00,2085.93,2.94891,20.0093,20096.8,195.232,3895.80,1.20482e-3
68.5175,0.375099,9.40377,202.637,20.00,2053.79,2.90347,20.0210,14597.0,202.637,3874.57,1.32144e-3
68.2638,0.436722,8.07468,209.977,20.00,2023.87,2.86118,20.0156,10611.4,209.977,3860.23,1.44635e-3
67.8832,0.508468,6.94603,217.317,20.00,1985.52,2.80696,20.0116,7679.74,217.317,3838.70,1.58398e-3
67.3571,0.592002,5.88906,224.657,20.00,1959.32,2.76992,20.0254,5590.60,224.657,3808.96,1.73545e-3
66.8095,0.689259,5.05214,231.997,20.00,1920.70,2.71533,20.0233,4042.93,231.997,3777.99,1.89999e-3
66.5478,0.802493,4.32238,239.403,20.00,1903.40,2.69087,20.0169,2955.61,239.403,3763.19,2.08200e-3
66.0071,0.934331,3.69133,246.809,20.00,1868.71,2.64182,20.0257,2140.62,246.809,3732.62,2.28217e-3
65.8028,1.08783,3.19270,254.149,20.00,1849.29,2.61437,20.0205,1562.74,254.149,3721.06,2.49837e-3
65.1889,1.26654,2.75142,261.489,20.00,1814.76,2.56555,20.0266,1131.31,261.489,3686.35,2.73689e-3
64.8457,1.47461,2.69951,268.829,20.00,1790.82,2.53171,20.0211,823.562,268.829,3666.94,2.99593e-3
64.4163,1.71687,3.37432,276.169,20.00,1760.42,2.48873,20.0153,597.229,276.169,3642.66,3.28156e-3
63.9930,1.95789,3.22654,283.574,20.00,1736.92,2.45552,20.0221,453.111,283.574,3618.72,3.59562e-3
63.5440,2.11260,2.41089,290.980,20.00,1700.27,2.40370,20.0162,380.962,290.980,3593.33,3.94105e-3
63.0844,2.32732,1.82936,298.320,20.00,1679.83,2.37480,20.0205,310.137,298.320,3567.34,4.31588e-3
62.2398,2.63575,2.22700,305.660,20.00,1641.46,2.32056,20.0263,236.277,305.660,3519.58,4.72659e-3
61.5037,2.98506,2.61753,313.000,20.00,1613.21,2.28063,20.0276,181.045,313.000,3477.95,5.17443e-3
60.8213,3.47545,2.79418,320.340,20.00,1590.58,2.24864,20.0140,131.684,320.340,3439.36,5.66604e-3
60.3844,4.04642,2.69218,327.746,20.00,1560.87,2.20663,20.0317,95.3292,327.746,3414.66,6.21143e-3
59.2699,4.71118,2.47216,335.151,20.00,1530.73,2.16403,20.0269,68.9668,335.151,3351.63,6.80641e-3
58.1413,5.48516,2.10550,342.491,20.00,1502.78,2.12450,20.0265,49.9478,342.491,3287.81,7.45167e-3
57.4674,6.38628,1.87812,349.831,20.00,1481.96,2.09508,20.0306,36.3364,349.831,3249.70,8.16139e-3
56.0729,7.43545,1.87641,357.171,20.00,1453.66,2.05507,20.0224,26.2935,357.171,3170.85,8.93678e-3
54.5376,8.65698,1.67529,364.511,20.00,1392.97,1.96926,20.0202,18.5870,364.511,3084.03,9.78620e-3
53.3101,9.87228,1.35616,371.917,20.00,1354.60,1.91502,20.0216,13.8988,371.917,3014.61,0.0107235
52.2507,11.2582,1.10381,379.322,20.00,1316.39,1.86100,20.0216,10.3860,379.322,2954.71,0.0117522
51.0265,13.1077,1.01544,386.662,20.00,1267.79,1.79230,20.0312,7.37891,386.662,2885.48,0.0128686
49.7552,15.2611,0.769339,394.002,20.00,1232.27,1.74209,20.0200,5.29095,394.002,2813.59,0.0140918
48.4489,17.5243,0.675278,401.342,20.00,1188.70,1.68048,20.0167,3.87071,401.342,2739.72,0.0154288
48.0121,20.1231,0.514774,408.683,20.00,1161.79,1.64245,20.0195,2.86906,408.683,2715.02,0.0168939
47.3837,23.2676,0.414940,416.088,20.00,1130.28,1.59789,20.0215,2.08777,416.088,2679.48,0.0185141
46.3955,26.3511,0.354425,423.494,20.00,1081.50,1.52893,20.0255,1.55750,423.494,2623.60,0.0202895
46.0521,30.0504,0.310606,430.834,20.00,1069.17,1.51151,20.0296,1.18399,430.834,2604.18,0.0222164
46.6086,34.9872,0.251666,438.174,20.00,1106.15,1.56378,20.0334,0.903639,438.174,2635.65,0.0243269
54.2782,40.7351,0.224487,445.514,20.00,1359.31,1.92168,20.0241,0.819181,445.514,3069.36,0.0266219
77.5293,47.4273,0.188437,452.854,20.00,1908.91,2.69866,20.0232,0.848650,452.854,4384.18,0.0291478
89.9826,55.2188,0.156749,460.259,20.00,2134.71,3.01787,20.0191,0.700106,460.259,5088.39,0.0319617
88.1465,64.2905,0.136438,467.665,20.00,2017.21,2.85176,20.0304,0.488043,467.665,4984.57,0.0350538
51.3442,74.8524,0.117474,475.005,20.00,1203.94,1.70204,20.0284,0.214880,475.005,2903.45,0.0383935
48.8795,83.0321,0.100825,482.345,20.00,1216.63,1.71998,20.0271,0.176469,482.345,2764.07,0.0419843
75.7866,86.5490,0.0781767,489.685,20.00,1741.65,2.46220,20.0269,0.232507,489.685,4285.63,0.0459815
95.7869,88.9760,0.0624576,497.025,20.00,2170.25,3.06812,20.0295,0.274134,497.025,5416.62,0.0503443
112.004,91.4710,0.0498991,504.431,20.00,2551.38,3.60693,20.0159,0.304935,504.431,6333.67,0.0551831
128.911,94.6885,0.0384978,511.836,20.00,2931.39,4.14416,20.0322,0.326949,511.836,7289.74,0.0604724
139.521,98.6991,0.0291147,519.176,20.00,3171.06,4.48299,20.0068,0.325521,519.176,7889.73,0.0662280
145.636,108.730,0.0239347,526.516,20.00,3319.01,4.69215,20.0128,0.280742,526.516,8235.55,0.0725280
149.829,126.593,0.0210805,533.856,20.00,3440.55,4.86397,20.0229,0.214688,533.856,8472.60,0.0794230
149.967,147.390,0.0201824,541.196,20.00,3428.12,4.84639,20.0111,0.157804,541.196,8480.41,0.0869728
147.209,171.604,0.0192003,548.602,20.00,3090.37,4.36891,20.0112,0.104943,548.602,8324.45,0.0953262
140.523,199.796,0.0190270,556.007,20.00,2790.63,3.94516,20.0144,0.0699081,556.007,7946.39,0.104444
149.496,232.620,0.0182992,563.347,20.00,2958.59,4.18261,20.0291,0.0546754,563.347,8453.79,0.114350
165.157,270.836,0.0159570,570.688,20.00,3211.94,4.54077,20.0202,0.0437881,570.688,9339.38,0.125227
179.521,315.330,0.0140033,578.028,20.00,3402.66,4.81040,20.0179,0.0342207,578.028,10151.7,0.137128
178.177,367.134,0.0133824,585.368,20.00,3404.71,4.81330,20.0071,0.0252599,585.368,10075.7,0.150174
162.502,427.448,0.0130468,592.773,20.00,2904.85,4.10663,20.0291,0.0158985,592.773,9189.29,0.164591
140.481,497.671,0.0128588,600.179,20.00,2319.15,3.27862,20.0116,9.36361e-3,600.179,7944.03,0.180351
132.534,579.431,0.0119263,607.519,20.00,2190.44,3.09667,20.0273,6.52422e-3,607.519,7494.64,0.197469
146.489,674.622,0.0131061,614.859,20.00,2638.53,3.73013,20.0245,5.79750e-3,614.859,8283.76,0.216219
145.969,785.453,0.0136027,622.199,20.00,2738.24,3.87109,20.0203,4.43845e-3,622.199,8254.35,0.236810
116.645,914.490,0.0116590,629.539,20.00,1784.81,2.52322,20.0209,2.13419e-3,629.539,6596.14,0.259290
118.554,1064.73,0.0107841,636.944,20.00,1949.86,2.75655,20.0263,1.71999e-3,636.944,6704.08,0.284118
122.373,1239.65,9.76895e-3,644.350,20.00,2000.95,2.82877,20.0262,1.30209e-3,644.350,6920.04,0.311424
91.6271,1443.30,8.79335e-3,651.690,20.00,1415.35,2.00090,20.0315,6.79438e-4,651.690,5181.39,0.340960
101.908,1680.41,8.02361e-3,659.030,20.00,1723.48,2.43651,20.0222,6.10343e-4,659.030,5762.75,0.373364
81.9019,1956.48,7.24857e-3,666.370,20.00,1170.26,1.65442,20.0210,3.05727e-4,666.370,4631.44,0.408877
87.5155,2277.90,6.63809e-3,673.710,20.00,1447.04,2.04571,20.0275,2.78877e-4,673.710,4948.88,0.447645
74.3871,2652.12,6.28650e-3,681.116,20.00,1068.97,1.51122,20.0280,1.51977e-4,681.116,4206.49,0.490633
83.9051,3087.82,5.90512e-3,688.521,20.00,1363.07,1.92700,20.0339,1.42960e-4,688.521,4744.72,0.537686
71.3649,3595.11,5.52680e-3,695.861,20.00,1093.28,1.54559,20.0283,8.45881e-5,695.861,4035.59,0.588683
70.5209,4185.73,5.48684e-3,703.201,20.00,1042.99,1.47450,20.0234,5.95306e-5,703.201,3987.86,0.644706
73.8636,4873.38,4.88543e-3,710.541,20.00,1105.41,1.56274,20.0285,4.65440e-5,710.541,4176.89,0.706001
71.6880,5674.00,4.21019e-3,717.881,20.00,1091.40,1.54294,20.0243,3.39006e-5,717.881,4053.86,0.772976
68.3066,6606.15,4.07864e-3,725.287,20.00,1004.17,1.41962,20.0256,2.30098e-5,725.287,3862.65,0.847146
64.0730,7691.44,4.06018e-3,732.693,20.00,971.631,1.37361,20.0308,1.64243e-5,732.693,3623.24,0.928396
62.3099,8955.02,3.89427e-3,740.033,20.00,971.814,1.37387,20.0218,1.21185e-5,740.033,3523.54,1.01646
63.9895,10426.2,3.82079e-3,747.373,20.00,1003.24,1.41830,20.0200,9.22901e-6,747.373,3618.52,1.11311
61.9217,12139.1,3.75551e-3,754.713,20.00,909.893,1.28633,20.0244,6.17476e-6,754.713,3501.59,1.21900
61.3187,14133.3,3.65470e-3,762.053,20.00,828.525,1.17130,20.0286,4.14780e-6,762.053,3467.49,1.33458
58.4660,15786.5,3.53281e-3,769.458,20.00,716.546,1.01299,20.0269,2.87521e-6,769.458,3306.17,1.46275