File: 09_characterizationRheology/csv/ps_thf_01_4.csv
Filename,ps_thf_01_4,,,,,,,,,,
Instrument name,5333-0457,,,,,,,,,,
Operator,Osamu Katagiri,,,,,,,,,,
rundate,18/12/2019,,,,,,,,,,
Sample name,PS_THF_01_4,,,,,,,,,,
Geometry name,60.0mm 0.996944° cone plate, Peltier plate Steel ,,,,,,,,,
Procedure name,Sample,,,,,,,,,,
,Flow ramp,,,,,,,,,,
proceduresegments,Flow ramp,,,,,,,,,,
[step],,,,,,,,,,,
Flow ramp - 1,,,,,,,,,,,
Stress,Shear rate,Viscosity,Step time,Temperature,Normal stress,Axial force,Gap,Normal stress coefficient,Time,Torque,Velocity
Pa,1/s,Pa.s,s,°C,Pa,N,µm,Pa.s²,s,µN.m,rad/s
0.0407158,0.019678045,7.670387021,4.39094,20.01,-21.0942,-0.0298212,20.0323,-489809,4.39094,2.30242,1.14E-04
0.0425113,0.022071918,7.646963621,11.1412,20.01,-25.1579,-0.0355662,20.0149,-532138,11.1412,2.40396,1.20E-04
0.0463362,0.025083093,7.626149602,18.5467,20,-20.3389,-0.0287534,20.018,-358196,18.5467,2.62025,1.31E-04
0.0507378,0.028505068,7.605392236,25.9523,20.01,-22.9838,-0.0324926,20.0257,-337401,25.9523,2.86915,1.44E-04
0.0560628,0.032393889,7.584691369,33.2923,20.01,-22.0402,-0.0311586,20.0295,-268860,33.2923,3.17028,1.58E-04
0.0606207,0.036421203,7.564192857,40.6324,20.01,-22.0996,-0.0312425,20.0273,-224959,40.6324,3.42802,1.72E-04
0.0661705,0.041389987,7.543604129,47.9724,20.01,-24.9167,-0.0352251,20.0269,-211231,47.9724,3.74185,1.89E-04
0.0715978,4.70E-02,7.523071441,55.3124,20,-23.8148,-0.0336674,20.0302,-168219,55.3124,4.04876,2.07E-04
0.0788169,0.053453641,7.50259464,62.718,20.01,-27.7242,-0.0391941,20.0289,-163090,62.718,4.45699,2.27E-04
0.0858174,6.07E-02,7.482173574,70.1236,20,-23.7827,-0.033622,20.0264,-116408,70.1236,4.85286,2.49E-04
0.09376,6.83E-02,7.461952128,77.4636,20,-26.0515,-0.0368295,20.0098,-106267,77.4636,5.302,2.72E-04
0.102395,0.078872427,7.44E+00,84.8036,20.01,-22.8749,-0.0323387,20.0073,-77856.3,84.8036,5.79031,2.98E-04
0.111949,8.78E-02,7.439989943,92.1436,20,-22.0835,-0.0312198,20.0202,-62624,92.1436,6.33056,3.27E-04
0.121728,0.101921053,7.42E+00,99.4837,20,-21.1615,-0.0299164,20.0301,-49986.4,99.4837,6.88354,3.58E-04
0.133922,0.114659961,7.42E+00,106.889,20,-27.0854,-0.0382911,20.0287,-53221.6,106.889,7.57312,3.93E-04
0.145855,0.128991079,7.416302725,114.295,20,-27.324,-0.0386284,20.0299,-44688.7,114.295,8.24788,4.30E-04
0.160644,0.145113415,7.414728169,121.635,20,-25.2417,-0.0356846,20.0326,-34417.1,121.635,9.08421,4.71E-04
0.175465,0.16325085,7.413153948,128.975,20.01,-25.869,-0.0365715,20.0269,-29424.5,128.975,9.92229,5.16E-04
0.192334,0.183655246,7.411580061,136.315,20,-20.1648,-0.0285073,20.0299,-19112.7,136.315,10.8762,5.65E-04
0.210883,0.206609946,7.410006508,143.655,20,-25.358,-0.035849,20.0283,-20037.3,143.655,11.9251,6.19E-04
0.231221,0.231782481,7.4163968,151.061,20,-25.9459,-0.0366801,20.0177,-17060.6,151.061,13.0752,6.79E-04
0.254188,0.26163973,7.425355743,158.466,20,-29.2188,-0.041307,20.0219,-15990.4,158.466,14.374,7.44E-04
0.278852,0.289898299,7.426629454,165.806,20,-26.5047,-0.0374701,20.0276,-12092.2,165.806,15.7687,8.15E-04
0.306207,0.32738382,7.443218365,173.146,20,-22.7009,-0.0320927,20.0315,-8633.01,173.146,17.3156,8.92E-04
0.336337,0.365057373,7.458020933,180.486,20,-26.5485,-0.037532,20.0304,-8415.67,180.486,19.0194,9.77E-04
0.369696,0.413133686,7.47498451,187.826,20,-24.4227,-0.0345268,20.0296,-6470.4,187.826,20.9058,1.07E-03
0.406468,0.470051016,7.491914363,195.232,20,-26.7315,-0.0377908,20.0287,-5894.35,195.232,22.9852,1.17E-03
0.447408,0.529114394,7.509027506,202.637,20,-30.4282,-0.0430168,20.0277,-5581.55,202.637,25.3003,1.28E-03
0.491603,0.602010359,7.526034462,209.977,20,-28.0514,-0.0396568,20.0293,-4289.26,209.977,27.7995,1.41E-03
0.540779,0.695393304,7.551243016,217.317,20,-26.1848,-0.0370179,20.0272,-3336.53,217.317,30.5803,1.54E-03
0.594712,0.791398105,7.581204024,224.657,20,-26.4264,-0.0373594,20.0289,-2806.8,224.657,33.6302,1.69E-03
0.654273,0.89701969,7.605539044,231.997,20,-27.4644,-0.0388269,20.019,-2431.55,231.997,36.9983,1.85E-03
0.720535,1.021205292,7.641799049,239.403,20,-27.9708,-0.0395428,20.0253,-2060.07,239.403,40.7453,2.03E-03
0.795091,1.143723592,7.668885404,246.809,20,-28.0037,-0.0395893,20.0279,-1717,246.809,44.9613,2.22E-03
0.875778,1.314082755,7.694646704,254.149,20,-29.5865,-0.0418269,20.0267,-1511.88,254.149,49.5241,2.43E-03
0.966017,1.514407868,7.741884856,261.489,20,-30.6904,-0.0433876,20.0311,-1306.91,261.489,54.627,2.67E-03
1.06391,1.708893785,7.79001733,268.829,20,-29.5364,-0.0417561,20.0257,-1048.68,268.829,60.163,2.92E-03
1.17679,1.932051301,7.825859765,276.169,20,-24.3456,-0.0344178,20.0333,-720.668,276.169,66.5461,3.20E-03
1.30115,2.205046733,7.87014441,283.574,20,-34.5219,-0.0488042,20.0282,-850.101,283.574,73.5784,3.51E-03
1.43984,2.543051573,7.925116267,290.98,20,-25.8537,-0.0365498,20.0259,-529.836,290.98,81.4208,3.84E-03
1.59095,2.853231014,7.968077666,298.32,20,-27.3229,-0.0386268,20.0302,-466.855,298.32,89.9661,4.21E-03
1.75904,3.250159766,8.026057691,305.66,20,-29.21,-0.0412946,20.0254,-416.085,305.66,99.4714,4.61E-03
1.9458,3.687243568,8.075878966,313,20,-29.2043,-0.0412867,20.0292,-346.785,313,110.032,5.05E-03
2.15349,4.192360888,8.123081305,320.34,20,-30.0659,-0.0425047,20.0092,-297.598,320.34,121.777,5.53E-03
2.38435,4.730759537,8.173583736,327.746,20,-33.4952,-0.0473528,20.0297,-275.917,327.746,134.832,6.06E-03
2.63956,5.361947045,8.218473908,335.151,20,-26.5292,-0.0375047,20.0088,-181.865,335.151,149.264,6.65E-03
2.91896,6.095968077,8.263565047,342.491,20,-33.5758,-0.0474667,20.0049,-191.895,342.491,165.063,7.28E-03
3.22466,6.931969115,8.289672623,349.831,20,-32.7056,-0.0462364,20.011,-155.819,349.831,182.35,7.97E-03
3.55719,7.837279049,8.321508624,357.171,20,-28.6977,-0.0405704,20.0205,-113.993,357.171,201.155,8.73E-03
3.91914,8.739150566,8.338057876,364.511,20,-29.971,-0.0423705,20.0251,-99.2474,364.511,221.622,9.56E-03
4.31034,9.890054981,8.357023134,371.917,20,-28.7176,-0.0405986,20.032,-79.1337,371.917,243.744,0.0104819
4.73434,11.32840887,8.369880625,379.322,20.01,-31.9822,-0.0452138,20.0225,-73.3605,379.322,267.721,0.0114887
5.18576,12.85638888,8.353071843,386.662,20,-33.1317,-0.0468389,20.0305,-63.3444,386.662,293.248,0.0125839
5.66833,14.24254612,8.348553766,394.002,20,-35.794,-0.0506026,20.0261,-57.0566,394.002,320.537,0.0137816
6.18183,16.20028228,8.321860678,401.342,20,-34.334,-0.0485385,20.0223,-45.6209,401.342,349.574,0.0150948
6.72806,18.32670671,8.282532163,408.683,20,-31.2714,-0.0442089,20.002,-34.6434,408.683,380.463,0.0165315
7.31822,20.53180284,8.242554543,416.088,20,-25.75,-0.0364033,20.016,-23.7431,416.088,413.835,0.0181204
7.94757,23.09435421,8.182270447,423.494,20,-16.2896,-0.0230289,20.03,-12.5,423.494,449.424,0.0198632
8.60339,26.44898301,8.110591755,430.834,20,-15.6802,-0.0221674,20.0259,-10.0313,430.834,486.511,0.0217543
9.28507,29.60385433,8.039873536,438.174,20,-24.3931,-0.034485,20.0291,-13.0091,438.174,525.058,0.0238264
10.0142,33.33134943,7.96258863,445.514,20,-36.1152,-0.0510567,20.0259,-16.0578,445.514,566.291,0.0260945
10.7965,37.63680165,7.880385939,452.854,20,-42.6988,-0.060364,20.0239,-15.8255,452.854,610.526,0.028581
11.6412,42.43702555,7.801832506,460.259,20,-40.369,-0.0570703,20.0105,-12.4537,460.259,658.293,0.0313273
12.5427,47.78037722,7.726835818,467.665,20,-29.2821,-0.0413966,20.0151,-7.51849,467.665,709.275,0.0343387
13.4908,53.85840076,7.640279854,475.005,20,-34.4648,-0.0487234,20.0055,-7.37729,475.005,762.885,0.0376086
14.5141,60.6219281,7.557406376,482.345,20,-39.386,-0.0556806,20.0176,-7.02835,482.345,820.755,0.0411901
15.64,67.84153803,7.486175302,489.685,20,-29.2952,-0.0414151,20.019,-4.35819,489.685,884.423,0.0451121
16.8854,76.81633341,7.423392363,497.025,20,-26.5075,-0.0374741,20.0307,-3.28754,497.025,954.846,0.049408
18.2787,86.70176526,7.35724367,504.431,20,-33.39,-0.047204,20.0318,-3.44661,504.431,1033.64,0.0541577
19.8365,99.73988523,7.28883577,511.836,20,-37.406,-0.0528814,20.0213,-3.21376,511.836,1121.73,0.0593625
21.5531,112.3073234,7.244545081,519.176,20,-31.758,-0.0448968,20.011,-2.27462,519.176,1218.8,0.065016
23.4573,127.553502,7.206830539,526.516,20,-23.3945,-0.0330732,20.016,-1.39693,526.516,1326.48,0.0712062
25.5679,144.8694116,7.169312336,533.856,20,-15.7904,-0.0223232,20.0297,-0.786027,533.856,1445.83,0.0779878
27.9339,163.8469971,7.131054895,541.196,20,-41.8808,-0.0592076,20.0196,-1.738,541.196,1579.62,0.0854143
30.5824,188.9398079,7.103576349,548.602,20,-48.4067,-0.0684334,20.0131,-1.67194,548.602,1729.4,0.0936249
33.53,218.1921811,7.084036241,556.007,20,-10.9113,-0.0154255,20.0354,-0.313679,556.007,1896.07,0.102623
36.6863,242.8495276,7.082668944,563.347,20,-61.4098,-0.086816,20.0085,-1.47179,563.347,2074.56,0.112394
40.096,277.4617808,7.063322688,570.688,20,-29.0955,-0.0411329,20.0232,-0.581331,570.688,2267.37,0.123098
43.9001,317.0071632,7.044029277,578.028,20,-10.8282,-0.015308,20.0128,-0.180361,578.028,2482.49,0.13482
48.0513,352.8313408,7.042669702,585.368,20,9.34148,0.0132062,20.0292,0.129717,585.368,2717.24,0.147658
52.6309,409.6451084,7.023229347,592.773,20,14.6124,0.0206579,20.0256,0.168882,592.773,2976.21,0.161852
57.5657,460.8458284,7.021738245,600.179,20,-5.47793,-7.74E-03,20.0295,-0.0526944,600.179,3255.26,0.177409
62.8145,512.9248498,7.020382972,607.519,20,-31.3641,-0.0443399,20.0206,-0.251521,607.519,3552.08,0.194302
68.5378,586.0297265,7.00120685,614.859,20,-6.76673,-9.57E-03,20.0146,-0.0452391,614.859,3875.72,0.212805
74.9241,676.7610578,6.981948334,622.199,20,15.6723,0.0221562,20.0241,0.0873503,622.199,4236.86,0.233068
82.0818,753.2401131,6.980600741,629.539,20,-6.80393,-9.62E-03,20.0238,-0.0316139,629.539,4641.62,0.255264
89.8014,851.4311565,6.961667664,636.944,20,-22.4664,-0.0317611,20.0217,-0.0868819,636.944,5078.15,0.279802
98.1286,967.5881494,6.942718929,644.35,20,41.4841,0.0586467,20.0248,0.13353,644.35,5549.04,0.30669
107.408,1099.591928,6.923821771,651.69,20,-6.3243,-8.94E-03,20.024,-0.0169704,651.69,6073.8,0.335898
117.333,1249.604399,6.904976048,659.03,20,18.4742,0.0261173,20.0179,0.0413278,659.03,6635.05,0.367883
128.037,1404.959288,6.886314546,666.37,20,46.656,0.0659584,20.0246,0.087011,666.37,7240.32,0.402916
139.686,1596.63168,6.867570912,673.71,20,27.3383,0.0386486,20.0099,0.0425044,673.71,7899.08,0.441283
152.513,1823.922897,6.84454339,681.116,20,57.586,0.0814103,20.0229,0.0745165,681.116,8624.38,0.483705
166.807,2092.544644,6.79121533,688.521,20,93.4377,0.132094,20.0203,0.100637,688.521,9432.74,0.53019
181.266,2342.146267,6.732001074,695.861,20,55.2896,0.0781638,20.0151,0.049644,695.861,10250.3,0.58068
197.143,2628.664312,6.663762952,703.201,20,115.494,0.163276,20.016,0.0864519,703.201,11148.2,0.635976
214.584,2942.974619,6.59154529,710.541,20,129.763,0.183448,20.0218,0.0809768,710.541,12134.4,0.696535
232.574,3317.77933,6.500305285,717.881,20,148.533,0.209984,20.0156,0.0772724,717.881,13151.7,0.762866
250.462,3715.178923,6.421077711,725.287,20,176.324,0.249272,20.0157,0.0763446,725.287,14163.3,0.836209