File: 09_characterizationRheology/csv/ps_thf_00_0.csv
Filename,ps_thf_00_0,,,,,,,,,,
Instrument name,5333-0457,,,,,,,,,,
Operator,Osamu Katagiri,,,,,,,,,,
rundate,11/12/2019,,,,,,,,,,
Sample name,OSKT 0_PS_THF,,,,,,,,,,
Geometry name,60mm 0.9969° cone plate, Peltier plate Steel ,,,,,,,,,
Procedure name,Sample,,,,,,,,,,
,Flow ramp,,,,,,,,,,
proceduresegments,Flow ramp,,,,,,,,,,
[step],,,,,,,,,,,
Flow ramp - 1,,,,,,,,,,,
Stress,Shear rate,Viscosity,Step time,Temperature,Normal stress,Axial force,Gap,Normal stress coefficient,Time,Torque,Velocity
Pa,1/s,Pa.s,s,°C,Pa,N,µm,Pa.s²,s,µN.m,rad/s
-0.04119,0.012600774,0.030406264,3.47463,19.95,-85.6626,-0.121103,20.0072,-2135710,3.47463,-2.32924,1.10E-04
-9.98E-03,0.013897761,0.032783319,10.5513,19.96,-84.9926,-0.120155,20.0142,-1573190,10.5513,-0.564337,1.28E-04
-0.0100061,0.015317519,0.034361162,17.5637,19.97,-85.3621,-0.120678,20.0247,-1261550,17.5637,-0.565834,1.43E-04
-9.65E-03,0.01700434,0.033477656,24.576,19.98,-85.5642,-0.120964,20.0206,-1006410,24.576,-0.545602,1.60E-04
-9.72E-03,0.018710707,0.031453951,31.5228,19.99,-85.4215,-0.120762,20.0226,-802542,31.5228,-0.549914,1.80E-04
-9.79E-03,0.020024574,0.024193386,38.4697,19.99,-85.0538,-0.120242,20.0307,-638188,38.4697,-0.553818,2.01E-04
-9.89E-03,0.021089353,0.018961907,45.482,19.99,-85.7936,-0.121288,20.0246,-513621,45.482,-0.559058,2.25E-04
-0.0100904,0.02221075,0.014861662,52.4944,19.99,-85.1188,-0.120334,20.0278,-406150,52.4944,-0.570599,2.52E-04
-0.0100723,0.023391776,0.011648037,59.4412,20,-84.796,-0.119878,20.0285,-323534,59.4412,-0.569578,2.82E-04
-9.77E-03,0.024632298,0.009149972,66.388,19.99,-84.8835,-0.120001,20.0272,-258627,66.388,-0.552659,3.15E-04
-9.71E-03,0.026523771,0.007124918,73.4004,20,-84.8766,-0.119992,20.0206,-206278,73.4004,-0.548898,3.53E-04
-9.75E-03,0.029703872,0.005967501,80.4127,20,-84.9486,-0.120093,20.029,-164524,80.4127,-0.551359,3.95E-04
-9.80E-03,0.032879045,0.005199159,87.3595,20,-84.8345,-0.119932,20.0357,-131329,87.3595,-0.554421,4.42E-04
-9.76E-03,0.03649909,0.005049458,94.3063,20,-85.2273,-0.120487,20.0251,-105402,94.3063,-0.552148,4.95E-04
-9.74E-03,0.040872877,0.004954791,101.253,20,-84.1729,-0.118997,20.0276,-83180.8,101.253,-0.550554,5.54E-04
-9.81E-03,0.045622033,0.004537117,108.266,20,-84.8102,-0.119898,20.0261,-66834.5,108.266,-0.555004,6.20E-04
-9.81E-03,0.051211716,0.004085539,115.278,20,-84.8544,-0.11996,20.0238,-53311.9,115.278,-0.55472,6.94E-04
-9.85E-03,0.056556091,0.004159147,122.225,20,-85.1076,-0.120318,20.0284,-42723.5,122.225,-0.557207,7.77E-04
-9.88E-03,0.062164718,0.004422015,129.171,20,-84.9755,-0.120131,20.0296,-34089,129.171,-0.558691,8.69E-04
-9.85E-03,0.066284487,0.005132322,136.184,20,-84.6387,-0.119655,20.0212,-27078.5,136.184,-0.557129,9.73E-04
-9.83E-03,0.068380373,0.006330345,143.196,20,-85.6903,-0.121142,20.0194,-21911.9,143.196,-0.556017,1.09E-03
-9.80E-03,0.070534422,0.007823161,150.143,20,-86.4047,-0.122152,20.0223,-17651.6,150.143,-0.554129,1.22E-03
-9.87E-03,0.072760508,0.00965865,157.09,20,-85.8199,-0.121325,20.01,-14002.1,157.09,-0.557958,1.36E-03
-9.88E-03,0.075052535,0.011936345,164.037,20,-85.87,-0.121396,20.0251,-11189.6,164.037,-0.558614,1.52E-03
-0.0100339,0.07965984,0.013980901,171.049,20,-86.4229,-0.122178,20.0223,-8978.66,171.049,-0.567406,1.71E-03
-0.0100886,0.08862243,0.014422601,178.061,20,-86.5121,-0.122304,20.0335,-7160.79,178.061,-0.570495,1.91E-03
-9.85E-03,0.098728334,0.014380093,185.008,20,-85.9821,-0.121554,20.0246,-5691.06,185.008,-0.557251,2.14E-03
-9.53E-03,0.10985042,0.013372023,191.955,20,-86.2204,-0.121891,20.0289,-4557.84,191.955,-0.539133,2.39E-03
-9.00E-03,0.122377538,0.012176707,198.967,20,-86.3029,-0.122008,20.0319,-3635.42,198.967,-0.509125,2.68E-03
-8.32E-03,0.136616212,0.010208729,205.98,20,-86.3063,-0.122013,20.0302,-2901.03,205.98,-0.470387,3.00E-03
-7.55E-03,0.153948934,0.008439227,212.926,20,-86.7769,-0.122678,20.0312,-2329.42,212.926,-0.426715,3.36E-03
-6.89E-03,0.172603664,0.007540816,219.873,20,-86.8648,-0.122802,20.0279,-1863.16,219.873,-0.389731,3.76E-03
-5.85E-03,0.189943845,0.006950062,226.886,20,-86.3848,-0.122124,20.0177,-1475.71,226.886,-0.330574,4.21E-03
-4.48E-03,0.418630089,0.002866167,233.898,20,-87.0304,-0.123036,20.0149,-1187.48,233.898,-0.253199,4.71E-03
-3.35E-03,0.480413619,0.00283246,240.845,20,-86.999,-0.122992,20.0148,-947.242,240.845,-0.189431,5.27E-03
-2.69E-03,0.532872513,0.0026465,247.792,20,-87.7322,-0.124028,20.0236,-763.473,247.792,-0.151901,5.90E-03
-1.99E-03,0.596393915,0.002239754,254.738,20,-88.1878,-0.124673,20.0307,-613.479,254.738,-0.112739,6.60E-03
-1.65E-03,0.669326437,0.001867497,261.751,20,-88.1813,-0.124663,20.03,-488.725,261.751,-0.0930633,7.39E-03
-2.20E-03,0.713900924,0.001654111,268.763,20,-88.088,-0.124532,20.0251,-389.254,268.763,-0.124344,8.28E-03
-3.68E-03,0.840189214,0.001250693,275.71,20,-87.2397,-0.123332,20.0238,-307.937,275.71,-0.208195,9.26E-03
-4.80E-03,0.912608092,0.001214347,282.657,20,-87.0663,-0.123087,20.0291,-245.526,282.657,-0.27159,0.0103616
-5.15E-03,1.047186925,0.001226666,289.669,20,-86.9218,-0.122883,20.0281,-195.692,289.669,-0.291361,0.0115965
-5.48E-03,1.167299761,0.00117532,296.681,20,-86.7232,-0.122602,20.0198,-155.462,296.681,-0.309879,0.0129958
-6.41E-03,1.296452563,0.001116069,303.628,20,-86.1333,-0.121768,20.0122,-123.462,303.628,-0.362359,0.0145334
-6.35E-03,1.444516819,0.000975757,310.575,20,-85.901,-0.12144,20.0079,-98.3781,310.575,-0.359125,0.0162592
-5.25E-03,1.62623123,0.000815037,317.587,20,-86.179,-0.121833,20.0145,-78.7019,317.587,-0.296607,0.0182078
-1.81E-03,1.790684861,0.000764454,324.6,20,-85.9997,-0.121579,20.018,-62.6434,324.6,-0.102089,0.0203873
2.21E-03,1.965635477,0.000773903,331.547,20,-85.7225,-0.121187,20.0105,-49.893,331.547,0.125033,0.0228074
2.54E-03,2.180048658,0.00085187,338.493,20,-85.6989,-0.121154,20.0046,-39.8315,338.493,0.143867,0.0255225
3.61E-03,2.33596884,0.001096221,345.44,20,-85.277,-0.120557,20.0159,-31.6746,345.44,0.203868,0.0285501
3.63E-03,2.492989144,0.00139259,352.453,20,-85.268,-0.120545,20.0152,-25.2506,352.453,0.205119,0.0319746
1.65E-03,2.70097324,0.001482726,359.465,20,-84.3672,-0.119271,20.0307,-19.9163,359.465,0.0930805,0.0358122
1.63E-04,3.007467489,0.001314506,366.412,20,-84.1411,-0.118952,20.0315,-15.8783,366.412,9.24E-03,0.0400545
1.88E-03,3.318394573,0.001203109,373.359,20,-84.4309,-0.119361,20.0289,-12.7304,373.359,0.106096,0.0448104
5.79E-03,3.628600919,0.001186443,380.371,20,-84.2845,-0.119154,20.0245,-10.1321,380.371,0.327202,0.0501849
3.58E-03,4.053879788,0.001175506,387.383,20,-84.4288,-0.119358,20.0253,-8.09025,387.383,0.202469,0.0562099
4.02E-03,4.516195034,0.001230795,394.33,20,-83.9131,-0.118629,20.0283,-6.4283,394.33,0.227582,0.0628659
4.60E-03,5.009760763,0.001288865,401.277,20,-83.8299,-0.118512,20.0303,-5.12916,401.277,0.259861,0.0703436
3.70E-03,5.56693684,0.001253239,408.224,20,-83.754,-0.118404,20.0271,-4.09573,408.224,0.209462,0.0786839
6.69E-03,6.201944734,0.00119452,415.236,20,-83.7687,-0.118425,20.0177,-3.26608,415.236,0.378409,0.0881203
-1.51E-03,6.982433991,0.001159425,422.248,20,-83.7753,-0.118434,20.0124,-2.60349,422.248,-0.0853609,0.0987026
-2.20E-03,7.764929843,0.001141057,429.195,20,-83.8346,-0.118518,20.0371,-2.08254,429.195,-0.124239,0.110399
1.68E-03,8.582232883,0.001164156,436.142,20,-84.1608,-0.11898,20.0228,-1.67084,436.142,0.0949782,0.123491
3.71E-03,9.517022289,0.001219968,443.154,20,-82.972,-0.117299,20.0319,-1.31305,443.154,0.209639,0.138316
5.15E-03,10.51091459,0.001227255,450.167,20,-82.679,-0.116885,20.0138,-1.04332,450.167,0.291499,0.154895
5.56E-03,11.70957104,0.001175106,457.114,20,-82.831,-0.1171,20.029,-0.835206,457.114,0.31418,0.17328
4.39E-03,12.92030716,0.001149134,464.06,20,-82.6715,-0.116874,20.011,-0.665949,464.06,0.248118,0.193868
9.24E-04,14.25156516,0.001176168,471.073,20,-83.2959,-0.117757,20.0266,-0.535173,471.073,0.052262,0.217077
6.68E-03,15.74801876,0.001204014,478.085,20,-82.743,-0.116975,20.0279,-0.423836,478.085,0.377907,0.243117
6.85E-03,17.55506022,0.001225382,485.032,20,-82.3114,-0.116365,20.0187,-0.336888,485.032,0.387456,0.271979
3.88E-03,19.11556082,0.001239381,491.979,20,-82.5655,-0.116724,20.0291,-0.269998,491.979,0.219387,0.304276
7.92E-03,21.07057646,0.001219157,498.926,20,-81.9525,-0.115858,20.02,-0.214171,498.926,0.448002,0.340369
9.31E-03,23.3932621,0.001183568,505.938,20,-81.5748,-0.115324,20.0217,-0.169952,505.938,0.526407,0.381209
6.02E-03,25.56157455,0.001169044,512.95,20,-82.1527,-0.116141,20.0175,-0.13649,512.95,0.340582,0.426883
0.0111382,28.22399341,0.001185043,519.897,20,-81.4607,-0.115162,20.027,-0.108136,519.897,0.629848,0.477571
8.96E-03,31.44467906,0.00120288,526.844,20,-81.4214,-0.115107,20.022,-0.0863687,526.844,0.506451,0.534244
0.0107611,36.65101963,0.001188968,533.856,20,-81.2282,-0.114834,20.0282,-0.0686983,533.856,0.608523,0.598313
0.0143565,40.48664721,0.001190467,540.869,20,-80.6656,-0.114038,20.0318,-0.0543962,540.869,0.81184,0.670052
0.0134841,44.7236835,0.001191968,547.815,20,-80.4488,-0.113732,20.0265,-0.043351,547.815,0.762509,0.749564
0.0157688,49.09776332,0.001193376,554.762,20,-80.2918,-0.11351,20.0289,-0.0345706,554.762,0.891702,0.838554
0.0177847,57.40522289,0.00117962,561.709,20,-79.6195,-0.112559,20.0259,-0.0273921,561.709,1.0057,0.938093
0.0204467,62.2403937,0.001180828,568.721,20,-79.6043,-0.112538,20.0286,-0.0218362,568.721,1.15624,1.05058
0.0211485,71.87184798,0.001167033,575.734,20,-79.6287,-0.112572,20.0296,-0.017417,575.734,1.19592,1.17651
0.0252074,76.01044886,0.001167861,582.681,20,-79.4596,-0.112333,20.0281,-0.0138873,582.681,1.42545,1.31617