File: 09_characterizationRheology/csv/ps_thf_01_3.csv
Filename,ps_thf_01_3,,,,,,,,,,
Instrument name,5333-0457,,,,,,,,,,
Operator,Osamu Katagiri,,,,,,,,,,
rundate,18/12/2019,,,,,,,,,,
Sample name,PS_THF_01_3,,,,,,,,,,
Geometry name,60.0mm 0.996944° cone plate, Peltier plate Steel ,,,,,,,,,
Procedure name,Sample,,,,,,,,,,
,Flow ramp,,,,,,,,,,
proceduresegments,Flow ramp,,,,,,,,,,
[step],,,,,,,,,,,
Flow ramp - 1,,,,,,,,,,,
Stress,Shear rate,Viscosity,Step time,Temperature,Normal stress,Axial force,Gap,Normal stress coefficient,Time,Torque,Velocity
Pa,1/s,Pa.s,s,°C,Pa,N,µm,Pa.s²,s,µN.m,rad/s
-0.99648,0.007975413,5.901967464,5.12444,20,9.23447,0.0130549,20.0285,3333.37,5.12444,-56.3496,-9.16E-04
0.0283476,0.009310062,5.874257785,11.1412,20,2.63547,3.73E-03,20.0322,55840.6,11.1412,1.60302,1.20E-04
0.0308267,0.011025956,5.838037106,18.5467,20,1.09032,1.54E-03,20.0262,19194.9,18.5467,1.74321,1.31E-04
0.0342322,0.013093986,5.79112817,25.9523,20,-1.4427,-2.04E-03,20.0195,-21115.8,25.9523,1.93579,1.44E-04
0.0367232,0.015502569,5.738265882,33.2923,20,1.08382,1.53E-03,20.0249,13240.5,33.2923,2.07665,1.57E-04
0.039966,0.018192345,5.684815908,40.6324,20,-0.995883,-1.41E-03,20.0325,-10161.7,40.6324,2.26002,1.72E-04
0.0433615,0.021612939,5.625423963,47.9724,20,-3.19041,-4.51E-03,20.0296,-27044.3,47.9724,2.45204,1.89E-04
0.0468368,2.55E-02,5.574006113,55.3124,20,-1.26919,-1.79E-03,20.028,-8979.93,55.3124,2.64856,2.07E-04
0.0512815,0.030109851,5.524165529,62.718,20,-1.39987,-1.98E-03,20.0334,-8221.64,62.718,2.8999,2.27E-04
0.0554655,3.56E-02,5.488740874,70.1236,20,-4.1344,-5.84E-03,20.0224,-20242.8,70.1236,3.1365,2.49E-04
0.0595292,4.17E-02,5.466799445,77.4636,20,-4.67667,-6.61E-03,20.0104,-19081.2,77.4636,3.3663,2.72E-04
0.0648116,0.049774628,5.45E+00,84.8036,20,-5.84149,-8.26E-03,20.0179,-19846.6,84.8036,3.66501,2.99E-04
0.0700237,6.02E-02,5.433162674,92.1436,20,-4.97445,-7.03E-03,20.0253,-14097.1,92.1436,3.95975,3.27E-04
0.0752861,0.071723482,5.42E+00,99.4837,20,-3.77889,-5.34E-03,20.0274,-8941.39,99.4837,4.25733,3.58E-04
0.0817734,0.082691379,5.41E+00,106.889,20,-6.0148,-8.50E-03,20.03,-11836.9,106.889,4.62418,3.92E-04
0.0886388,0.098714976,5.402231429,114.295,20,-5.9379,-8.39E-03,20.0342,-9725.74,114.295,5.0124,4.30E-04
0.0965648,0.116873987,5.391939916,121.635,20,-5.03656,-7.12E-03,20.0289,-6873.96,121.635,5.46061,4.71E-04
0.104516,0.136230271,5.38482651,128.975,20,-7.46738,-0.0105568,20.0255,-8494.87,128.975,5.91023,5.16E-04
0.11387,0.159461039,5.381485844,136.315,20,-5.38045,-7.61E-03,20.0155,-5097.36,136.315,6.43922,5.65E-04
0.124715,0.185585083,5.375477868,143.655,20,-6.17425,-8.73E-03,20.0193,-4876.38,143.655,7.05246,6.19E-04
0.135748,0.220812399,5.367477665,151.061,20,-6.61554,-9.35E-03,20.0255,-4349.82,151.061,7.67636,6.79E-04
0.148539,0.257863706,5.364813578,158.466,20,-7.35772,-0.0104017,20.0305,-4025.69,158.466,8.39967,7.44E-04
0.162171,0.300108776,5.358824215,165.806,20,-6.39113,-9.04E-03,20.0273,-2914.95,165.806,9.17058,8.15E-04
0.177069,0.357909553,5.350184716,173.146,20,-4.74533,-6.71E-03,20.0267,-1804.36,173.146,10.013,8.92E-04
0.193635,0.433328436,5.341559145,180.486,20,-4.99796,-7.07E-03,20.0257,-1584.49,180.486,10.9498,9.77E-04
0.210944,0.503680975,5.340233369,187.826,20,-8.29481,-0.0117265,20.0345,-2197.17,187.826,11.9286,1.07E-03
0.231003,0.597890612,5.33294748,195.232,20,-3.55808,-5.03E-03,20.0277,-784.651,195.232,13.0629,1.17E-03
0.252447,0.702232605,5.33294748,202.637,20,-4.59066,-6.49E-03,20.03,-841.957,202.637,14.2756,1.28E-03
0.276155,0.816533566,5.33294748,209.977,20,-3.63149,-5.13E-03,20.02,-555.442,209.977,15.6162,1.41E-03
0.301691,0.97831716,5.341559145,217.317,20,-3.51036,-4.96E-03,20.0198,-447.182,217.317,17.0602,1.54E-03
0.32968,1.14905,5.341559145,224.657,20,-3.71837,-5.26E-03,20.0327,-394.865,224.657,18.643,1.69E-03
0.360752,1.336078512,5.341559145,231.997,20,-2.28555,-3.23E-03,20.0262,-202.354,231.997,20.4,1.85E-03
0.394554,1.600801963,5.350184716,239.403,20,-2.22666,-3.15E-03,20.0312,-164.075,239.403,22.3115,2.03E-03
0.432426,1.880168897,5.350184716,246.809,20,-2.68596,-3.80E-03,20.0317,-164.554,246.809,24.4531,2.22E-03
0.473077,2.180323912,5.349520716,254.149,20,0.107307,1.52E-04,20.0268,5.4828,254.149,26.7519,2.43E-03
0.516993,2.594187778,5.341559145,261.489,20,-3.24601,-4.59E-03,20.0326,-138.266,261.489,29.2353,2.67E-03
0.566167,3.046917285,5.341559145,268.829,20,-0.744214,-1.05E-03,20.0257,-26.4232,268.829,32.016,2.92E-03
0.619479,3.578655725,5.341559145,276.169,20,2.06501,2.92E-03,20.0324,61.1009,276.169,35.0307,3.20E-03
0.677679,4.203191487,5.341559145,283.574,20,-1.93022,-2.73E-03,20.0282,-47.5351,283.574,38.3219,3.51E-03
0.741673,5.088890143,5.33294748,290.98,20,0.628474,8.88E-04,20.0303,12.8857,290.98,41.9406,3.84E-03
0.811066,6.054851088,5.325010575,298.32,20,-0.184692,-2.61E-04,20.0264,-3.15568,298.32,45.8647,4.21E-03
0.886565,6.951226134,5.3243497,305.66,20,2.24324,3.17E-03,20.0223,31.947,305.66,50.134,4.61E-03
0.969399,8.331805309,5.31576578,313,20,-0.332908,-4.71E-04,20.011,-3.95208,313,54.8182,5.05E-03
1.05986,9.913328649,5.307854446,320.34,20,1.81777,2.57E-03,20.0223,17.9905,320.34,59.9336,5.53E-03
1.16124,11.49591802,5.3071957,327.746,20,3.30476,4.67E-03,20.0194,27.2225,327.746,65.6665,6.06E-03
1.27121,13.50214954,5.3071957,335.151,20,0.965574,1.37E-03,20.015,6.62064,335.151,71.8851,6.64E-03
1.39121,16.02762237,5.299954886,342.491,20,2.13352,3.02E-03,20.0139,12.192,342.491,78.6709,7.28E-03
1.5241,18.62976852,5.298639436,349.831,20,-0.166623,-2.36E-04,20.022,-0.793845,349.831,86.186,7.97E-03
1.66939,21.88097724,5.298639436,357.171,20,2.95512,4.18E-03,20.0287,11.7368,357.171,94.4016,8.73E-03
1.83084,25.47942689,5.298028802,364.511,20,4.66438,6.59E-03,20.0271,15.4422,364.511,103.531,9.56E-03
2.00963,30.19056629,5.290096966,371.917,20,1.51496,2.14E-03,20.0262,4.17497,371.917,113.642,0.0104815
2.20535,35.45932914,5.290096966,379.322,20,2.50975,3.55E-03,20.0215,5.7559,379.322,124.71,0.0114897
2.41583,41.89558855,5.284191018,386.662,20,-0.0373914,-5.29E-05,20.0159,-0.071498,386.662,136.612,0.0125831
2.64639,48.85940658,5.277917324,394.002,20,2.15742,3.05E-03,20.0103,3.4387,394.002,149.65,0.0137822
2.89989,57.47518118,5.273053322,401.342,20,8.64974,0.0122283,20.0232,11.4942,401.342,163.985,0.0150942
3.17616,67.74916181,5.267820179,408.683,19.99,10.0026,0.0141408,20.0305,11.0811,408.683,179.607,0.0165315
3.48356,79.08026818,5.261519275,416.088,20,8.28643,0.0117147,20.0256,7.63923,416.088,196.991,0.0181221
3.82079,92.89615789,5.248437526,423.494,20,9.05941,0.0128074,20.0328,6.95196,423.494,216.06,0.019863
4.18719,109.6002701,5.234580765,430.834,20,6.02444,8.52E-03,20.0261,3.85406,430.834,236.78,0.0217544
4.5832,131.9128798,5.214532923,438.174,20,1.66671,2.36E-03,20.0206,0.888864,438.174,259.174,0.0238265
5.01244,155.5491635,5.177718906,445.514,20,-0.267811,-3.79E-04,20.0253,-0.11907,445.514,283.447,0.0260952
5.48193,185.7874162,5.103137218,452.854,20,0.582602,8.24E-04,20.0192,0.215946,452.854,309.996,0.0285799
6.01263,220.2778092,5.045824051,460.259,20,9.14186,0.012924,20.0267,2.82019,460.259,340.006,0.0313276
6.59725,259.5488373,4.976826476,467.665,20,-1.93409,-2.73E-03,20.0223,-0.496607,467.665,373.066,0.0343384
7.21567,301.920894,4.926228036,475.005,20,4.66226,6.59E-03,20.0296,0.997964,475.005,408.037,0.0376088
7.89461,355.8827146,4.844419388,482.345,20,3.71408,5.25E-03,20.0275,0.662742,482.345,446.43,0.041191
8.64432,409.6437838,4.74378615,489.685,20,6.33119,8.95E-03,20.0303,0.941858,489.685,488.825,0.0451126
9.45369,447.4331706,4.616380449,497.025,20,8.3282,0.0117737,20.0285,1.03286,497.025,534.594,0.0494087
10.352,481.654627,4.493029382,504.431,20,0.779159,1.10E-03,20.0186,0.0804249,504.431,585.394,0.0541585
11.3282,536.887445,4.400965985,511.836,20,1.85396,2.62E-03,20.0233,0.159281,511.836,640.593,0.0593631
12.3907,634.0842217,4.475045261,519.176,20,5.289,7.48E-03,20.0236,0.378824,519.176,700.675,0.0650154
13.5468,738.9827502,4.517433057,526.516,20,4.47569,6.33E-03,20.0318,0.267239,526.516,766.051,0.071208
14.8227,885.4377038,4.513029834,533.856,20,1.41495,2.00E-03,20.0271,0.0704347,533.856,838.204,0.0779875
16.1974,1037.493104,4.400781548,541.196,20,-8.70756,-0.01231,20.0213,-0.361351,541.196,915.94,0.0854146
17.7216,1231.804605,4.348029689,548.602,20,-11.0472,-0.0156176,20.0233,-0.381558,548.602,1002.13,0.0936256
19.4144,1437.477572,4.291888199,556.007,20,-7.58423,-0.010722,20.0301,-0.218034,556.007,1097.86,0.102622
21.2487,1717.70035,4.21706593,563.347,20,-19.1441,-0.0270644,20.0268,-0.458802,563.347,1201.58,0.112397
23.2641,2023.662245,4.146892228,570.688,20,-0.914691,-1.29E-03,20.0301,-0.0182749,570.688,1315.55,0.1231
25.4822,2375.72347,4.04648514,578.028,20,2.42345,3.43E-03,20.0283,0.0403657,578.028,1440.98,0.134822
27.9042,2711.795432,3.975882765,585.368,20,17.2342,0.0243643,20.0283,0.239312,585.368,1577.95,0.14766