File: 09_characterizationRheology/csv/ps_thf_00_1.csv
Filename,ps_thf_00_1,,,,,,,,,,
Instrument name,5333-0457,,,,,,,,,,
Operator,Osamu Katagiri,,,,,,,,,,
rundate,11/12/2019,,,,,,,,,,
Sample name,OSKT 1_PS_THF,,,,,,,,,,
Geometry name,60mm 0.9969° cone plate, Peltier plate Steel ,,,,,,,,,
Procedure name,Sample,,,,,,,,,,
,Flow ramp,,,,,,,,,,
proceduresegments,Flow ramp,,,,,,,,,,
[step],,,,,,,,,,,
Flow ramp - 1,,,,,,,,,,,
Stress,Shear rate,Viscosity,Step time,Temperature,Normal stress,Axial force,Gap,Normal stress coefficient,Time,Torque,Velocity
Pa,1/s,Pa.s,s,°C,Pa,N,µm,Pa.s²,s,µN.m,rad/s
6.04E-03,0.00733794,0.047175285,3.97681,20,-37.3015,-0.0527337,20.0201,-867905,3.97681,0.341745,1.14E-04
6.47E-03,0.008411183,0.045492101,10.5513,20,-38.0459,-0.0537862,20.0215,-699297,10.5513,0.365721,1.28E-04
6.85E-03,0.00955962,0.043647009,17.5637,20,-39.3275,-0.0555979,20.0271,-580662,17.5637,0.387398,1.43E-04
6.94E-03,0.010830381,0.041769162,24.576,20,-40.0916,-0.0566781,20.0335,-472599,24.576,0.392667,1.60E-04
6.97E-03,0.012370213,0.039613261,31.5228,20,-40.348,-0.0570406,20.0261,-378771,31.5228,0.39439,1.80E-04
7.01E-03,0.013982949,0.03779373,38.4697,20,-40.7396,-0.0575943,20.0311,-306065,38.4697,0.396465,2.01E-04
7.19E-03,0.015897229,0.035945897,45.482,20,-37.4843,-0.0529922,20.0307,-225434,45.482,0.406653,2.24E-04
7.42E-03,0.018189078,0.03402177,52.4944,20,-37.2961,-0.0527261,20.0279,-177575,52.4944,0.419689,2.52E-04
7.20E-03,0.020507054,0.032343689,59.4412,20,-38.098,-0.0538597,20.0307,-145319,59.4412,0.407227,2.82E-04
7.53E-03,0.023336992,0.030556561,66.388,20,-38.5523,-0.0545021,20.0303,-117787,66.388,0.425671,3.15E-04
7.47E-03,0.026288684,0.029050546,73.4004,20,-39.5093,-0.0558549,20.0237,-96099,73.4004,0.422628,3.53E-04
7.40E-03,0.029985875,0.02754439,80.4127,20,-40.459,-0.0571976,20.0272,-78415.5,80.4127,0.4183,3.95E-04
7.42E-03,0.033835283,0.026279163,87.3595,20,-40.9801,-0.0579342,20.0302,-63476.8,87.3595,0.419693,4.42E-04
7.56E-03,0.038568762,0.024895527,94.3063,20,-41.9937,-0.0593671,20.0245,-51930.3,94.3063,0.427392,4.95E-04
7.62E-03,0.043984199,2.35E-02,101.253,20,-42.5707,-0.0601829,20.0313,-41999.8,101.253,0.430783,5.54E-04
7.68E-03,0.049580196,2.24E-02,108.266,20,-42.8334,-0.0605543,20.026,-33753.6,108.266,0.434261,6.20E-04
7.81E-03,0.056478511,2.13E-02,115.278,20,-43.892,-0.0620508,20.0134,-27576.3,115.278,0.441706,6.94E-04
7.76E-03,6.30E-02,2.04E-02,122.225,20,-44.5194,-0.0629378,20.0248,-22357.2,122.225,0.439009,7.76E-04
7.89E-03,7.23E-02,1.94E-02,129.171,20,-45.5558,-0.064403,20.0256,-18279.8,129.171,0.446139,8.69E-04
7.73E-03,8.16E-02,1.86E-02,136.184,20,-46.3659,-0.0655483,20.0117,-14832.9,136.184,0.437284,9.73E-04
7.98E-03,9.31E-02,1.77E-02,143.196,20,-47.7086,-0.0674464,20.0169,-12196.1,143.196,0.451513,1.09E-03
8.23E-03,1.07E-01,1.66E-02,150.143,20,-48.4049,-0.0684308,20.0119,-9889.82,150.143,0.465549,1.22E-03
8.45E-03,1.21E-01,1.58E-02,157.09,20,-49.6059,-0.0701287,20.0112,-8092.45,157.09,0.477955,1.36E-03
8.52E-03,1.39E-01,1.49E-02,164.037,20,-50.7254,-0.0717114,20.0202,-6610.71,164.037,0.48192,1.52E-03
8.59E-03,1.56E-01,1.43E-02,171.049,20,-52.1298,-0.0736967,20.0073,-5416.54,171.049,0.485884,1.71E-03
8.64E-03,1.78E-01,1.37E-02,178.061,20,-53.5289,-0.0756747,20.0102,-4433.34,178.061,0.488405,1.91E-03
8.59E-03,2.04E-01,1.31E-02,185.008,20,-54.6627,-0.0772776,20.0185,-3614.96,185.008,0.485992,2.14E-03
8.42E-03,2.30E-01,1.25E-02,191.955,20,-55.1285,-0.0779361,20.0193,-2914.44,191.955,0.476071,2.39E-03
8.64E-03,2.62E-01,1.17E-02,198.967,20,-56.4679,-0.0798297,20.0263,-2379.74,198.967,0.488791,2.68E-03
9.25E-03,2.98E-01,1.09E-02,205.98,20,-57.5378,-0.0813422,20.026,-1932.92,205.98,0.523303,3.00E-03
9.69E-03,3.31E-01,1.02E-02,212.926,20,-59.2733,-0.0837957,20.0302,-1590.97,212.926,0.547712,3.36E-03
9.70E-03,3.64E-01,9.47E-03,219.873,20,-60.3874,-0.0853707,20.0333,-1295.13,219.873,0.54855,3.76E-03
9.86E-03,3.93E-01,8.84E-03,226.886,20,-61.1848,-0.0864979,20.0239,-1045.8,226.886,0.557582,4.21E-03
9.77E-03,4.21E-01,8.23E-03,233.898,20,-63.4147,-0.0896504,20.0338,-864.092,233.898,0.552211,4.71E-03
9.48E-03,4.50E-01,7.65E-03,240.845,20,-64.8024,-0.0916123,20.0335,-705.724,240.845,0.536126,5.27E-03
8.39E-03,4.83E-01,7.08E-03,247.792,20,-67.0401,-0.0947757,20.0235,-583.389,247.792,0.47454,5.90E-03
8.00E-03,5.38E-01,6.58E-03,254.738,20,-68.0957,-0.0962681,20.0321,-473.331,254.738,0.45223,6.60E-03
7.19E-03,6.08E-01,6.31E-03,261.751,20,-69.9509,-0.0988907,20.0325,-387.685,261.751,0.40654,7.39E-03
6.16E-03,6.97E-01,6.43E-03,268.763,20,-71.646,-0.101287,20.0245,-316.584,268.763,0.348187,8.28E-03
4.16E-03,7.77E-01,6.79E-03,275.71,20,-73.4768,-0.103875,20.0179,-259.43,275.71,0.235381,9.26E-03
3.70E-03,8.92E-01,7.30E-03,282.657,20,-75.5653,-0.106828,20.0172,-213.241,282.657,0.209021,0.010358
5.45E-03,1.01E+00,7.50E-03,289.669,20,-77.3706,-0.10938,20.0318,-174.064,289.669,0.307999,0.0116006
8.16E-03,1.15E+00,7.17E-03,296.681,20,-79.5187,-0.112417,20.0264,-142.697,296.681,0.461544,0.012989
0.0111816,1.24E+00,6.69E-03,303.628,20,-82.1839,-0.116185,20.0245,-117.791,303.628,0.632302,0.014534
0.0136578,1.31E+00,6.22E-03,310.575,20,-84.0981,-0.118891,20.0326,-96.3315,310.575,0.772333,0.0162576
0.0148658,1.41E+00,5.80E-03,317.587,20,-85.8856,-0.121418,20.0309,-78.4256,317.587,0.840641,0.0182087
0.0159845,1.53E+00,5.42E-03,324.6,20,-87.8306,-0.124168,20.0194,-63.9411,324.6,0.9039,0.020393
0.0150167,1.72E+00,5.03E-03,331.547,20,-90.419,-0.127827,20.029,-52.5988,331.547,0.849176,0.0228134
9.30E-03,1.95E+00,4.81E-03,338.493,20,-93.1701,-0.131716,20.0103,-43.3038,338.493,0.525844,0.0255225
4.85E-03,2.23E+00,4.97E-03,345.44,20,-95.6847,-0.135271,20.0133,-35.5359,345.44,0.274026,0.0285519
8.29E-03,2.52E+00,5.03E-03,352.453,20,-97.5516,-0.13791,20.0319,-28.8949,352.453,0.468544,0.0319709
0.0119281,2.87E+00,5.11E-03,359.465,20,-98.1681,-0.138782,20.0288,-23.1793,359.465,0.674521,0.0358083
0.0126693,3.25E+00,5.17E-03,366.412,20,-100.401,-0.141939,20.0256,-18.9453,366.412,0.716434,0.0400559
0.0155982,3.76E+00,5.22E-03,373.359,20,-104.497,-0.147729,20.0165,-15.7538,373.359,0.882056,0.0448133
0.0161022,4.31E+00,5.35E-03,380.371,20,-106.97,-0.151226,20.0278,-12.8575,380.371,0.910558,0.0501882
0.0124253,4.94E+00,5.39E-03,387.383,20,-109.891,-0.155354,20.0228,-10.5354,387.383,0.702636,0.0561957
0.0274851,5.54E+00,5.35E-03,394.33,20,-112.331,-0.158804,20.0268,-8.60321,394.33,1.55425,0.0628735
0.0246679,6.34E+00,5.27E-03,401.277,20,-113.623,-0.160631,20.0316,-6.95358,401.277,1.39494,0.0703359
0.0294127,7.203449384,5.19E-03,408.224,20,-115.573,-0.163388,20.03,-5.65119,408.224,1.66325,0.0786878
0.0304425,8.182450399,5.16E-03,415.236,20,-117.95,-0.166747,20.0137,-4.59877,415.236,1.72148,0.0881203
0.0350552,9.279171596,5.12E-03,422.248,20,-119.975,-0.169611,20.0191,-3.73002,422.248,1.98232,0.0986822
0.0382057,10.55034861,5.10E-03,429.195,20,-121.002,-0.171063,20.0302,-3.00584,429.195,2.16048,0.110398
0.0427606,11.9193668,5.11E-03,436.142,20,-124.539,-0.176062,20.0116,-2.47185,436.142,2.41805,0.123506
0.0416014,13.6767737,5.10E-03,443.154,20,-127.408,-0.180119,20.0357,-2.01641,443.154,2.35251,0.138311
0.0465587,15.46640666,5.08E-03,450.167,20,-131.185,-0.185458,20.0141,-1.65554,450.167,2.63283,0.154889
0.0579642,17.63522733,5.05E-03,457.114,20,-133.417,-0.188614,20.0305,-1.34521,457.114,3.2778,0.173284
0.0623403,20.39464697,5.07E-03,464.06,20,-134.647,-0.190353,20.0244,-1.08489,464.06,3.52526,0.193845
0.071192,23.15948328,5.06E-03,471.073,20,-136.415,-0.192852,20.0276,-0.876301,471.073,4.02581,0.217096
0.0728976,26.23195859,5.06E-03,478.085,20,-140.434,-0.198534,20.0262,-0.719344,478.085,4.12226,0.243117
0.0853005,29.94283918,5.04E-03,485.032,20,-144.723,-0.204597,20.0331,-0.592364,485.032,4.82363,0.271971
0.0964066,33.65165892,0.005034983,491.979,20,-144.914,-0.204868,20.0277,-0.473945,491.979,5.45166,0.304256
0.10376,39.31930649,0.005013444,498.926,20,-147.808,-0.208959,20.0252,-0.386246,498.926,5.86747,0.340381
0.118528,44.53564043,0.005014089,505.938,20,-151.445,-0.214101,20.0284,-0.315552,505.938,6.70259,0.38119
0.131835,50.44400438,0.005014735,512.95,20,-151.964,-0.214835,20.0271,-0.252477,512.95,7.45509,0.426883
0.146577,57.13620716,0.00501538,519.897,20,-155.412,-0.219709,20.0301,-0.206313,519.897,8.28872,0.477559
0.163006,64.71623751,0.005016026,526.844,20,-155.712,-0.220133,20.029,-0.16517,526.844,9.21778,0.53425
0.184667,73.30187994,0.005016671,533.856,20,-158.446,-0.223997,20.0331,-0.134008,533.856,10.4427,0.598307
0.202586,84.10599615,0.004996969,540.869,20,-160.935,-0.227517,20.0317,-0.108533,540.869,11.4559,0.670028
0.227294,92.22262056,0.004995592,547.815,20,-163.207,-0.230729,20.0279,-0.0879467,547.815,12.8532,0.749564