File: 09_characterizationRheology/csv/psb_thfdmf_01_6.csv
Filename,psb_thfdmf_01_6,,,,,,,,,,
Instrument name,5333-0457,,,,,,,,,,
Operator,Osamu Katagiri,,,,,,,,,,
rundate,19/12/2019,,,,,,,,,,
Sample name,PSB_THFDMF_01_6,,,,,,,,,,
Geometry name,60.0mm 0.996944° cone plate, Peltier plate Steel ,,,,,,,,,
Procedure name,Sample,,,,,,,,,,
,Flow ramp,,,,,,,,,,
proceduresegments,Flow ramp,,,,,,,,,,
[step],,,,,,,,,,,
Flow ramp - 1,,,,,,,,,,,
Stress,Shear rate,Viscosity,Step time,Temperature,Normal stress,Axial force,Gap,Normal stress coefficient,Time,Torque,Velocity
Pa,1/s,Pa.s,s,°C,Pa,N,µm,Pa.s²,s,µN.m,rad/s
-1.87656,0.007132638,0.360318982,1.14691,19.98,61.1354,0.0864281,20.0348,14.3283,1.14691,-106.117,0.0359416
1.35767,8.01E-03,0.357968115,11.4939,19.98,62.6721,0.0886006,20.03,1065560,11.4939,76.7743,1.33E-04
1.35767,9.03E-03,0.349651407,11.4939,19.98,62.6721,0.0886006,20.03,1065560,11.4939,76.7743,1.33E-04
1.49671,1.02E-02,0.339623098,18.5467,19.99,63.9196,0.0903642,20.0328,1121570,18.5467,84.6368,1.31E-04
1.35721,1.14E-02,0.329632442,25.9523,19.99,62.202,0.0879361,20.0205,909997,25.9523,76.7485,1.44E-04
1.31071,1.28E-02,0.320419866,33.2923,20,61.8606,0.0874534,20.0239,770159,33.2923,74.1188,1.56E-04
1.37322,0.014840789,0.310821069,40.6324,19.99,62.5321,0.0884027,20.0298,623586,40.6324,77.6535,1.74E-04
1.22142,0.016956484,0.303569249,47.9724,20,59.6036,0.0842626,20.0322,504045,47.9724,69.0699,1.89E-04
1.16978,0.018937767,0.295979732,55.3124,20,59.9146,0.0847023,20.0302,417732,55.3124,66.1495,2.08E-04
0.913573,0.021117658,0.287658977,62.718,20,57.4848,0.0812672,20.0277,339364,62.718,51.6613,2.26E-04
0.901289,0.023040896,0.279293857,70.1236,20,56.095,0.0793024,20.0266,274941,70.1236,50.9667,2.49E-04
0.998116,0.024866878,0.27056156,77.4636,20,57.2218,0.0808954,20.0232,232902,77.4636,56.4421,2.73E-04
1.04749,0.026837568,0.262499378,84.8036,20,56.918,0.0804659,20.0256,193550,84.8036,59.234,2.98E-04
1.07651,0.028964435,0.254773838,92.1436,20,57.0488,0.0806508,20.022,161593,92.1436,60.8751,3.27E-04
1.07055,0.031948491,0.246867156,99.4837,20,57.4599,0.0812321,20.022,135717,99.4837,60.538,3.58E-04
1.07264,0.036114531,0.238950281,106.889,20,56.1218,0.0793403,20.0202,109209,106.889,60.6562,3.94E-04
0.716467,0.040879452,0.23309867,114.295,20,54.1446,0.0765451,20.0258,88154.3,114.295,40.5153,4.31E-04
0.45499,0.046399262,0.225889487,121.635,20,51.6609,0.0730339,20.0207,70743.8,121.635,25.7291,4.70E-04
0.446726,0.050763037,0.220939645,128.975,20,51.2673,0.0724774,20.0303,58377.2,128.975,25.2618,5.16E-04
0.488382,0.057695916,0.214887981,136.315,20,51.5713,0.0729072,20.0204,48498.6,136.315,27.6173,5.67E-04
0.47926,0.065575641,0.209199924,143.655,20,51.6283,0.0729878,20.0174,40584.2,143.655,27.1015,6.21E-04
0.475629,0.073695221,0.205442203,151.061,20,52.0951,0.0736478,20.0272,34138.5,151.061,26.8962,6.80E-04
0.444495,0.083078381,0.201675857,158.466,20,52.5815,0.0743354,20.0302,28738.6,158.466,25.1356,7.44E-04
0.415718,0.09343784,0.197716318,165.806,20,51.8203,0.0732592,20.0231,23625.5,165.806,23.5083,8.15E-04
0.410114,0.10634369,0.192874848,173.146,20,52.7938,0.0746355,20.0137,20170.6,173.146,23.1914,8.90E-04
0.389216,0.120702908,0.186785937,180.486,20,51.9457,0.0734365,20.0282,16472.1,180.486,22.0097,9.77E-04
0.322006,0.136071268,0.181428752,187.826,20,50.9316,0.0720028,20.0159,13496.8,187.826,18.209,1.07E-03
0.330593,0.154514627,0.176459259,195.232,20,51.6963,0.0730839,20.0257,11417.5,195.232,18.6946,1.17E-03
0.358946,0.176736898,0.172595263,202.637,20,51.9028,0.0733758,20.0195,9516.77,202.637,20.2979,1.28E-03
0.38806,0.203628859,0.168608787,209.977,20,51.5586,0.0728892,20.0192,7870.11,209.977,21.9443,1.41E-03
0.373483,0.228723502,0.16531924,217.317,20,51.5992,0.0729466,20.0225,6571.43,217.317,21.12,1.54E-03
0.368915,0.255979404,0.161715794,224.657,20,50.9602,0.0720434,20.0185,5413.03,224.657,20.8616,1.69E-03
0.393073,0.28896496,0.15791222,231.997,20,51.812,0.0732475,20.027,4575.32,231.997,22.2277,1.85E-03
0.308244,0.331124589,0.153485663,239.403,20,51.0516,0.0721725,20.0239,3763.44,239.403,17.4308,2.03E-03
0.316983,0.376567113,0.149918601,246.809,20,51.2126,0.0724001,20.0283,3139.48,246.809,17.925,2.22E-03
0.275627,0.429831999,0.146503922,254.149,20,51.0785,0.0722106,20.0236,2611.7,254.149,15.5864,2.43E-03
0.274511,0.484182918,0.143573314,261.489,20,50.7796,0.071788,20.0315,2159.6,261.489,15.5232,2.67E-03
0.269868,0.554824603,0.140117623,268.829,20,50.9904,0.072086,20.025,1810.51,268.829,15.2607,2.92E-03
0.278356,0.623523025,0.137236718,276.169,20,50.7461,0.0717406,20.0235,1501.1,276.169,15.7407,3.20E-03
0.287293,0.707990606,0.134034531,283.574,20,50.3966,0.0712466,20.0248,1240.98,283.574,16.246,3.51E-03
0.309697,0.794880432,0.130997406,290.98,20,51.5877,0.0729304,20.0294,1057.61,290.98,17.5129,3.84E-03
0.295477,0.905904055,0.127592403,298.32,20,50.3434,0.0711714,20.0334,859.793,298.32,16.7088,4.21E-03
0.270697,1.025428277,0.124385404,305.66,20,50.3233,0.0711429,20.0338,716.721,305.66,15.3076,4.61E-03
0.247251,1.189528083,0.120699163,313,20,50.1532,0.0709025,20.034,595.525,313,13.9817,5.05E-03
0.246366,1.338897839,0.117854609,320.34,20,50.8559,0.0718958,20.0341,503.152,320.34,13.9317,5.53E-03
0.252194,1.528283047,0.115393856,327.746,20.01,50.6173,0.0715585,20.0119,416.805,327.746,14.2612,6.06E-03
0.246722,1.72286994,0.113616481,335.151,20,49.9346,0.0705934,20.0174,342.229,335.151,13.9518,6.65E-03
0.246701,1.933184572,0.11255109,342.491,20,49.9971,0.0706818,20.0248,285.79,342.491,13.9506,7.28E-03
0.253227,2.186545039,0.112167914,349.831,20,49.4592,0.0699213,20.0249,235.626,349.831,14.3197,7.97E-03
0.232597,2.485168845,0.112694232,357.171,20,49.0474,0.0693391,20.0357,194.735,357.171,13.153,8.73E-03
0.230554,2.875030033,0.113722976,364.511,20,48.0375,0.0679114,20.0206,159.036,364.511,13.0375,9.56E-03
0.239189,3.229340585,0.114700216,371.917,20,48.4165,0.0684472,20.0223,133.414,371.917,13.5258,0.010482
0.230498,3.642401934,0.115336281,379.322,20,49.6472,0.070187,20.0249,113.839,379.322,13.0343,0.0114908
0.229237,4.13020307,0.114938287,386.662,20,49.0825,0.0693888,20.0119,93.8521,386.662,12.9631,0.0125832
0.226785,4.719920983,0.112906434,394.002,20,48.0752,0.0679647,20.0121,76.6145,394.002,12.8244,0.0137833
0.21004,5.308471506,0.110689721,401.342,20,47.6363,0.0673443,20.007,63.2884,401.342,11.8775,0.0150958
0.210128,6.003024322,0.108825204,408.683,20,48.6083,0.0687184,20.0277,53.8513,408.683,11.8825,0.0165312
0.200606,6.820223184,0.107764419,416.088,20,46.1164,0.0651955,20.0252,42.5116,416.088,11.344,0.0181227
0.196364,7.664703699,0.107524393,423.494,20,47.248,0.0667953,20.0186,36.2515,423.494,11.1041,0.0198645
0.19181,8.570285582,0.107457417,430.834,20,46.0927,0.065162,20.0216,29.4855,430.834,10.8466,0.0217551
0.185778,9.780637306,0.106929916,438.174,20,45.8529,0.0648229,20.0317,24.4505,438.174,10.5055,0.023828
0.178814,11.14167275,0.106170279,445.514,20,45.8274,0.064787,20.0326,20.3753,445.514,10.1117,0.0260951
0.18159,12.63652958,0.105722754,452.854,20,46.0913,0.06516,20.0294,17.08,452.854,10.2686,0.0285834
0.186285,14.28493334,0.105372219,460.259,20,45.9678,0.0649855,20.0315,14.1804,460.259,10.5342,0.0313279
0.191239,16.37333417,0.10492624,467.665,20,45.5097,0.0643378,20.0266,11.685,467.665,10.8143,0.0343388
0.208402,18.60104932,0.104572482,475.005,20,45.5198,0.0643522,20.0275,9.74317,475.005,11.7849,0.0376096
0.240044,21.57778466,0.104197674,482.345,20,46.8928,0.0662931,20.0189,8.36701,482.345,13.5742,0.0411923
0.274315,24.42473948,0.104029815,489.685,20,45.6058,0.0644737,20.0264,6.78435,489.685,15.5121,0.0451133
0.31314,27.65568767,0.103686588,497.025,20,47.103,0.0665902,20.0239,5.8413,497.025,17.7076,0.0494103
0.354371,30.66226086,0.103591196,504.431,20,48.7982,0.0689869,20.0141,5.03687,504.431,20.0392,0.0541589
0.437781,34.8499089,0.103390218,511.836,20,49.1869,0.0695363,20.0414,4.22569,511.836,24.7559,0.0593642
0.521724,39.77164073,0.103155611,519.176,20,50.4334,0.0712985,20.0201,3.61225,519.176,29.5028,0.0650157
0.553013,44.02205594,0.10306444,526.516,20,49.416,0.0698602,20.0237,2.95045,526.516,31.2721,0.0712094
0.583899,49.92841065,0.102856837,533.856,20,49.2562,0.0696343,20.0256,2.45166,533.856,33.0187,0.0779918
0.53364,56.62720964,0.102649653,541.196,20,48.5235,0.0685985,20.0247,2.01334,541.196,30.1766,0.0854212
0.476395,63.45197404,0.10259334,548.602,20,46.8734,0.0662657,20.0177,1.61881,548.602,26.9395,0.0936297
0.430995,71.53092415,0.10259766,556.007,20,47.0646,0.066536,20.0211,1.35292,556.007,24.3722,0.102627
0.43485,81.30014291,0.10239861,563.347,20,47.0725,0.0665471,20.0303,1.12807,563.347,24.5902,0.112399
0.506089,90.90572448,0.102334827,570.688,20,47.0002,0.066445,20.0239,0.939031,570.688,28.6187,0.1231
0.62684,102.480192,0.102339137,578.028,20,49.3378,0.0697497,20.0202,0.821793,578.028,35.447,0.134821
0.801038,115.9486942,0.102162977,585.368,20,50.5307,0.0714361,20.0232,0.701574,585.368,45.2976,0.147669
0.802196,130.2378826,0.102076965,592.773,20,49.1555,0.069492,20.0304,0.568048,592.773,45.3631,0.161861
0.693794,146.8202722,0.102081264,600.179,20.01,47.24,0.066784,20.0227,0.454378,600.179,39.2331,0.177417
0.70203,166.1916159,0.101916815,607.519,20,44.7075,0.0632037,20.028,0.358507,607.519,39.6989,0.194308
0.878719,186.5878761,0.101819754,614.859,20,47.8564,0.0676554,20.0226,0.319941,614.859,49.6904,0.212806
1.06392,210.3449643,0.101824042,622.199,20,48.4158,0.0684462,20.0224,0.269807,622.199,60.1634,0.233086
0.945369,237.1268966,0.10182833,629.539,20,45.7613,0.0646936,20.0282,0.212609,629.539,53.4594,0.255274
1.00624,267.3188078,0.101832618,636.944,20,46.5526,0.0658122,20.0208,0.180021,636.944,56.9015,0.279807
1.2858,301.3548697,0.101836907,644.35,20,47.8664,0.0676695,20.0244,0.154054,644.35,72.7104,0.306709
1.1901,339.7245342,0.101706381,651.69,20,45.1935,0.0638908,20.0335,0.121263,651.69,67.2986,0.33591
1.36767,382.9795725,0.101576022,659.03,20,46.2943,0.0654471,20.0259,0.103559,659.03,77.3397,0.367891
1.49128,431.7420091,0.1015803,666.37,20,44.9416,0.0635347,20.0238,0.0838038,666.37,84.3301,0.40294
1.56875,486.7130672,0.101584578,673.71,20,45.3659,0.0641346,20.0313,0.0705302,673.71,88.7106,0.441292
1.72738,548.6832526,0.101588856,681.116,20,44.8979,0.0634729,20.0259,0.0580918,681.116,97.6813,0.483731
1.91356,618.5437209,0.101593134,688.521,20,45.4914,0.0643119,20.0217,0.0489922,688.521,108.209,0.530212
1.96914,697.2990937,0.101597413,695.861,20,44.9526,0.0635503,20.0257,0.0403612,695.861,111.352,0.580689
2.22217,786.0819043,0.101601692,703.201,20,44.263,0.0625753,20.0243,0.0331292,703.201,125.661,0.636009
2.42435,886.1688848,0.10160597,710.541,20,45.1628,0.0638474,20.0243,0.0281807,710.541,137.094,0.696567
2.61447,998.9993258,0.101610249,717.881,20,43.9608,0.0621482,20.0213,0.0228683,717.881,147.845,0.762895
2.83573,1126.195774,0.101614529,725.287,20,43.1667,0.0610255,20.0228,0.0186892,725.287,160.357,0.836233
3.0836,1280.004116,0.101821215,732.693,20,43.4767,0.0614637,20.0239,0.0156675,732.693,174.373,0.916594
3.34658,1431.236125,0.101892675,740.033,20,41.6798,0.0589234,20.0209,0.0125216,740.033,189.245,1.00388
3.65037,1615.421029,0.101747144,747.373,20,43.1447,0.0609944,20.0199,0.010806,747.373,206.424,1.09946
4.0267,1818.899426,0.101631647,754.713,20,43.4333,0.0614024,20.0196,9.07E-03,754.713,227.704,1.20419
4.32462,2050.488718,0.101635927,762.053,20,39.2467,0.0554837,20.0246,6.83E-03,762.053,244.551,1.31884
4.76871,2311.564851,0.101640208,769.458,20,41.6492,0.0588801,20.0143,6.03E-03,769.458,269.664,1.44564
5.19862,2605.882206,0.101644488,776.864,20,39.5103,0.0558564,20.015,4.76E-03,776.864,293.975,1.58455
5.66908,2937.673181,0.101648769,784.204,20,38.9397,0.0550497,20.0126,3.91E-03,784.204,320.579,1.73545
6.18149,3307.702429,0.101533384,791.544,20,39.5966,0.0559784,20.0239,3.32E-03,791.544,349.555,1.9007
6.76018,3535.431081,0.101386425,798.884,20,35.5215,0.0502173,20.0227,2.48E-03,798.884,382.279,2.08168