File: 09_characterizationRheology/csv/pvk_chl_00_3.csv
Filename,peo_su8_00_000_0,,,,,,,,,,
Instrument name,5333-0457,,,,,,,,,,
Operator,Osamu Katagiri,,,,,,,,,,
rundate,12/12/2019,,,,,,,,,,
Sample name,OSKT 000_PEO_SU8,,,,,,,,,,
Geometry name,60mm 0.9969° cone plate, Peltier plate Steel ,,,,,,,,,
Procedure name,Sample,,,,,,,,,,
,Flow ramp,,,,,,,,,,
proceduresegments,Flow ramp,,,,,,,,,,
[step],,,,,,,,,,,
Flow ramp - 1,,,,,,,,,,,
Stress,Shear rate,Viscosity,Step time,Temperature,Normal stress,Axial force,Gap,Normal stress coefficient,Time,Torque,Velocity
Pa,1/s,Pa.s,s,°C,Pa,N,µm,Pa.s²,s,µN.m,rad/s
-7.85E-04,4.28E-03,3167.54,3.60451,20.02,-53.9157,-0.0762215,20.016,-1202630,3.60451,-0.044409,1.17E-04
-1.04E-03,4.89E-03,900.764,10.5513,20.02,-54.7094,-0.0773436,20.024,-1013910,10.5513,-0.0590031,1.28E-04
-9.42E-04,4.95E-03,687.52,17.5637,20.02,-54.6598,-0.0772735,20.0304,-807416,17.5637,-0.0532681,1.43E-04
-1.30E-03,5.46E-03,485.065,24.576,20.02,-54.1203,-0.0765108,20.0317,-628738,24.576,-0.0737308,1.61E-04
-1.37E-03,5.71E-03,398.545,31.5228,20.01,-54.4926,-0.0770372,20.027,-513295,31.5228,-0.0776503,1.79E-04
-1.16E-03,6.20E-03,335.588,38.4697,20.01,-54.8098,-0.0774856,20.0313,-412931,38.4697,-0.0654477,2.00E-04
-8.15E-04,6.66E-03,367.332,45.482,20,-54.246,-0.0766884,20.0317,-326237,45.482,-0.0460744,2.24E-04
-5.04E-04,6.70E-03,344.067,52.4944,20.01,-54.788,-0.0774547,20.029,-261693,52.4944,-0.0284837,2.52E-04
-2.18E-04,7.09E-03,304.552,59.4412,20,-54.8828,-0.0775888,20.0286,-211033,59.4412,-0.0123423,2.81E-04
4.18E-04,7.20E-03,291.413,66.388,20,-54.8151,-0.0774931,20.0242,-168442,66.388,0.0236415,3.14E-04
8.55E-04,7.33E-03,279.612,73.4004,20,-55.1642,-0.0779866,20.0156,-134043,73.4004,0.0483663,3.53E-04
1.19E-03,7.76E-03,279.93,80.4127,20,-55.0471,-0.077821,20.0074,-107041,80.4127,0.0672592,3.95E-04
1.78E-03,7.85E-03,272.049,87.3595,20,-55.1027,-0.0778996,20.0151,-85575.6,87.3595,0.100763,4.42E-04
2.61E-03,7.95E-03,265.894,94.3063,20,-54.9395,-0.0776689,20.0292,-68141.2,94.3063,0.1474,4.94E-04
1.82E-03,8.09E-03,258.864,101.253,20,-55.1707,-0.0779958,20.028,-54362.6,101.253,0.102769,5.54E-04
1.96E-03,8.26E-03,253.739,108.266,20,-55.2342,-0.0780855,20.0336,-43612.5,108.266,0.110666,6.19E-04
2.89E-03,8.93E-03,244.799,115.278,20,-54.2864,-0.0767456,20.0281,-34193.8,115.278,0.163305,6.93E-04
4.14E-03,9.03E-03,235.371,122.225,20,-54.5236,-0.0770809,20.0287,-27418,122.225,0.234005,7.76E-04
5.28E-03,9.24E-03,231.974,129.171,20,-54.5211,-0.0770773,20.0273,-21895.9,129.171,0.298544,8.68E-04
6.41E-03,9.24E-03,233.654,136.184,20.01,-54.7793,-0.0774424,20.0293,-17519.6,136.184,0.362715,9.73E-04
7.24E-03,0.0102743,221.264,143.196,20,-54.4737,-0.0770104,20.0265,-13944.2,143.196,0.409564,1.09E-03
8.65E-03,0.0103188,224.466,150.143,20,-55.5382,-0.0785153,20.0144,-11356.2,150.143,0.488912,1.22E-03
0.0102121,0.0105185,205.919,157.09,20,-55.1101,-0.07791,20.0207,-8995.05,157.09,0.577481,1.36E-03
0.0118586,0.0105593,209.305,164.037,20,-54.7585,-0.0774129,20.019,-7143.16,164.037,0.670586,1.52E-03
0.0141783,0.0115349,199.548,171.049,20,-54.4573,-0.0769872,20.0221,-5660.14,171.049,0.801765,1.71E-03
0.0161384,0.0120613,199.155,178.061,20,-54.5882,-0.0771723,20.0289,-4521.8,178.061,0.912602,1.91E-03
0.0183456,0.0120854,178.616,185.008,20,-54.8569,-0.0775521,20.0266,-3630.7,185.008,1.03742,2.14E-03
0.0205611,0.0122469,181.134,191.955,20,-54.477,-0.0770151,20.0234,-2880.46,191.955,1.1627,2.39E-03
0.0220685,0.0129147,178.331,198.967,20,-54.8088,-0.0774841,20.0307,-2309.61,198.967,1.24794,2.68E-03
0.0236392,0.0137769,175.422,205.98,20,-54.8855,-0.0775926,20.0321,-1844.31,205.98,1.33677,3.00E-03
0.0259332,0.0139151,180.002,212.926,20,-54.8822,-0.0775879,20.024,-1473.04,212.926,1.46649,3.36E-03
0.0283556,0.0142594,175.095,219.873,20,-54.802,-0.0774745,20.0265,-1175.35,219.873,1.60347,3.76E-03
0.0306793,0.0144756,170.004,226.886,20,-54.7403,-0.0773873,20.034,-935.9,226.886,1.73487,4.21E-03
0.0330822,0.0157365,138.297,233.898,20,-55.035,-0.0778039,20.0251,-750.294,233.898,1.87075,4.71E-03
0.0350377,0.0161707,134.638,240.845,20,-54.7018,-0.0773329,20.0208,-595.814,240.845,1.98133,5.27E-03
0.0370845,0.0163784,130.332,247.792,20,-54.6478,-0.0772565,20.0185,-475.389,247.792,2.09708,5.90E-03
0.0387282,0.0166026,125.302,254.738,20,-55.2841,-0.0781561,20.0316,-384.406,254.738,2.19003,6.60E-03
0.0403007,0.0179749,147.682,261.751,20,-55.0517,-0.0778275,20.0247,-305.142,261.751,2.27895,7.39E-03
0.0420719,0.0181069,142.588,268.763,20,-54.8403,-0.0775287,20.0251,-242.457,268.763,2.37911,8.28E-03
0.0436745,0.0193308,140.014,275.71,20,-54.856,-0.0775509,20.0353,-193.724,275.71,2.46973,9.26E-03
0.0212895,0.0196419,137.428,282.657,20,-54.562,-0.0771352,20.0311,-153.808,282.657,1.20389,0.0103634
0.0152031,0.0202734,132.945,289.669,20.01,-54.6011,-0.0771905,20.0279,-122.842,289.669,0.859716,0.0116005
0.0162082,0.0205317,128.001,296.681,20,-54.8707,-0.0775716,20.0299,-98.4343,296.681,0.916554,0.0129911
0.0172318,0.0225074,146.244,303.628,20,-55.1528,-0.0779704,20.0276,-79.0471,303.628,0.974436,0.0145341
0.018487,0.0227075,121.915,310.575,20,-54.9582,-0.0776953,20.0159,-62.9378,310.575,1.04542,0.0162596
0.0198882,0.0234522,118.06,317.587,20,-54.9124,-0.0776306,20.0196,-50.1434,317.587,1.12465,0.0182086
0.0215051,0.023594,139.998,324.6,20,-55.2446,-0.0781002,20.0276,-40.2257,324.6,1.21609,0.0203911
0.0235123,0.0254097,130.738,331.547,20,-55.4057,-0.0783279,20.0297,-32.2359,331.547,1.32959,0.0228116
0.0259279,0.0262059,126.872,338.493,20,-55.3886,-0.0783038,20.0273,-25.7507,338.493,1.46619,0.025519
0.0286996,0.0267881,122.517,345.44,20,-56.0173,-0.0791926,20.0248,-20.8047,345.44,1.62292,0.0285515
0.0321077,0.0284196,118.315,352.453,20,-55.7124,-0.0787616,20.0175,-16.4999,352.453,1.81565,0.031973
0.0359881,0.028902,116.932,359.465,20,-55.6235,-0.0786358,20.0222,-13.134,359.465,2.03508,0.035808
0.0404697,0.0305121,111.276,366.412,20,-55.5021,-0.0784642,20.0154,-10.4732,366.412,2.28851,0.0400555
0.0454683,0.0305984,110.085,373.359,20,-55.5257,-0.0784976,20.0261,-8.37108,373.359,2.57117,0.0448131
0.0514439,0.031792,105.182,380.371,20,-55.8476,-0.0789526,20.0375,-6.71362,380.371,2.90908,0.0501848
0.0581242,0.0347187,83.6208,387.383,20,-55.8331,-0.0789321,20.028,-5.35227,387.383,3.28684,0.0561985
0.0650171,0.0349508,98.6699,394.33,20,-56.8202,-0.0803277,20.0154,-4.35175,394.33,3.67663,0.0628735
0.0724977,0.035526,96.1401,401.277,20,-56.921,-0.0804701,20.0186,-3.48354,401.277,4.09965,0.0703354
0.079827,0.0356005,94.9616,408.224,20,-56.29,-0.079578,20.0185,-2.75257,408.224,4.51411,0.0786855
0.087573,0.0398498,87.7464,415.236,20,-57.1466,-0.0807891,20.0332,-2.22809,415.236,4.95214,0.0881207
0.0988125,0.0399223,102.159,422.248,20,-57.1943,-0.0808565,20.0272,-1.77817,422.248,5.58771,0.0986821
0.113138,0.0413639,83.9404,429.195,20,-57.711,-0.081587,20.0261,-1.43364,429.195,6.3978,0.110397
0.125499,0.0426546,81.5249,436.142,20,-57.2141,-0.0808845,20.0333,-1.13568,436.142,7.09681,0.123502
0.139759,0.044595,78.3514,443.154,20,-57.8565,-0.0817928,20.0195,-0.91565,443.154,7.9032,0.138312
0.157252,0.0456009,75.7098,450.167,20,-58.4898,-0.082688,20.0322,-0.738109,450.167,8.89241,0.154892
0.175982,0.048161,86.1528,457.114,20,-58.5954,-0.0828373,20.0187,-0.59085,457.114,9.95154,0.173277
0.194615,0.049902,83.2453,464.06,20,-58.5297,-0.0827444,20.0325,-0.471584,464.06,11.0052,0.193846
0.220426,0.0520872,67.9615,471.073,20,-58.5028,-0.0827065,20.0252,-0.37583,471.073,12.4648,0.217091
0.24576,0.0531375,66.163,478.085,20,-59.2243,-0.0837264,20.0192,-0.303376,478.085,13.8974,0.243113
0.275476,0.055883,63.2752,485.032,20,-60.167,-0.0850591,20.0273,-0.246267,485.032,15.5778,0.271972
0.307157,0.056075,74.934,491.979,19.99,-59.0106,-0.0834243,20.0287,-0.192996,491.979,17.3693,0.304256
0.343915,0.0594962,70.0933,498.926,20.01,-59.8715,-0.0846413,20.023,-0.156461,498.926,19.4479,0.340373
0.384822,0.0624923,67.3852,505.938,20,-59.7908,-0.0845273,20.0393,-0.124581,505.938,21.7611,0.381189
0.431452,0.064315,55.5632,512.95,20,-60.3411,-0.0853052,20.0301,-0.100253,512.95,24.398,0.42688
0.482061,0.0652895,54.7318,519.897,20,-60.3949,-0.0853813,20.0326,-0.0801772,519.897,27.2599,0.477555
0.539557,0.0679591,52.8854,526.844,20,-60.8022,-0.0859571,20.0259,-0.0644973,526.844,30.5113,0.534241
0.603791,0.0699297,60.7423,533.856,20,-61.4258,-0.0868386,20.0292,-0.051952,533.856,34.1436,0.598305
0.675802,0.0760182,56.4642,540.869,20,-61.0905,-0.0863647,20.0196,-0.0411994,540.869,38.2157,0.670023
0.75634,0.0776257,55.3461,547.815,20,-62.0436,-0.0877121,20.0114,-0.0334337,547.815,42.77,0.749557
0.845483,0.0782158,54.0071,554.762,20,-60.9535,-0.086171,20.0138,-0.0262455,554.762,47.8109,0.838534
0.945607,0.0782476,45.8636,561.709,20,-61.9098,-0.0875229,20.0168,-0.0213002,561.709,53.4728,0.938072
1.0585,0.0875746,49.2681,568.721,20,-62.0033,-0.0876552,20.019,-0.0170087,568.721,59.8566,1.05056
1.18532,0.0885099,48.9343,575.734,20,-62.0983,-0.0877894,20.0281,-0.0135832,575.734,67.0284,1.17649
1.32564,0.0886673,48.2812,582.681,20,-63.0523,-0.0891381,20.0293,-0.0110203,582.681,74.9634,1.31614
1.48224,0.0957386,45.3911,589.627,20,-61.3649,-0.0867526,20.0251,-8.57E-03,589.627,83.8189,1.47237
1.65592,0.0980813,44.6956,596.509,20,-63.5595,-0.0898551,20.0309,-7.11E-03,596.509,93.6403,1.64538
,0.101279,43.163,,,,,,,,,
,0.103054,42.4957,,,,,,,,,
,0.10986,40.0018,,,,,,,,,
,0.115686,32.3614,,,,,,,,,
,0.119,31.4469,,,,,,,,,
,0.119989,31.1983,,,,,,,,,
,0.122907,36.38,,,,,,,,,
,0.132141,33.8717,,,,,,,,,
,0.137503,32.5256,,,,,,,,,
,0.139706,31.9542,,,,,,,,,
,0.147,26.0604,,,,,,,,,
,0.150937,25.6299,,,,,,,,,
,0.154081,29.474,,,,,,,,,
,0.162663,27.9709,,,,,,,,,
,0.172406,26.6637,,,,,,,,,
,0.172471,26.3265,,,,,,,,,
,0.182,21.4688,,,,,,,,,
,0.189392,24.402,,,,,,,,,
,0.192999,24.0732,,,,,,,,,
,0.19693,23.5138,,,,,,,,,
,0.215919,21.783,,,,,,,,,
,0.220514,18.1216,,,,,,,,,
,0.224941,17.978,,,,,,,,,
,0.225,21.1228,,,,,,,,,
,0.241835,19.612,,,,,,,,,
,0.25675,18.3818,,,,,,,,,
,0.256937,18.3098,,,,,,,,,
,0.270808,17.6997,,,,,,,,,
,0.273,17.7854,,,,,,,,,
,0.293485,16.4843,,,,,,,,,
,0.298941,16.2127,,,,,,,,,
,0.30298,15.9848,,,,,,,,,
,0.329,12.6889,,,,,,,,,
,0.33523,12.6318,,,,,,,,,
,0.338976,14.6328,,,,,,,,,
,0.348064,14.2745,,,,,,,,,
,0.379237,13.1385,,,,,,,,,
,0.382914,11.2892,,,,,,,,,
,0.40526,10.5587,,,,,,,,,
,0.411,10.4322,,,,,,,,,
,0.424733,11.9477,,,,,,,,,
,0.43738,11.616,,,,,,,,,
,0.471854,10.8176,,,,,,,,,
,0.475616,9.22056,,,,,,,,,
,0.499594,8.91086,,,,,,,,,
,0.508,8.66688,,,,,,,,,
,0.532122,9.75197,,,,,,,,,
,0.549392,8.15971,,,,,,,,,
,0.570657,7.87815,,,,,,,,,
,0.595331,7.6424,,,,,,,,,
,0.633,7.16479,,,,,,,,,
,0.63967,6.09593,,,,,,,,,
,0.651829,6.05171,,,,,,,,,
,0.666766,7.00825,,,,,,,,,
,0.744546,6.18181,,,,,,,,,
,0.744784,5.34019,,,,,,,,,
,0.746633,5.42539,,,,,,,,,
,0.771,5.19563,,,,,,,,,
,0.835243,5.61842,,,,,,,,,
,0.850451,4.84849,,,,,,,,,
,0.86717,4.78752,,,,,,,,,
,0.927,4.41857,,,,,,,,,
,0.934405,5.17603,,,,,,,,,
,0.971421,4.36695,,,,,,,,,
,1.00967,4.19284,,,,,,,,,
,1.04648,4.01708,,,,,,,,,
,1.09,3.34138,,,,,,,,,
,1.1096,3.3457,,,,,,,,,
,1.17189,3.177,,,,,,,,,
,1.17558,3.69752,,,,,,,,,
,1.26743,2.92439,,,,,,,,,
,1.31106,2.87114,,,,,,,,,
,1.32,2.90504,,,,,,,,,
,1.36876,2.44565,,,,,,,,,
,1.44771,2.32536,,,,,,,,,
,1.46664,2.66329,,,,,,,,,
,1.53,2.56635,,,,,,,,,
,1.59368,2.14576,,,,,,,,,
,1.64077,2.11518,,,,,,,,,
,1.65363,2.08981,,,,,,,,,
,1.75,2.28308,,,,,,,,,
,1.83748,2.19175,,,,,,,,,
,1.85556,1.9341,,,,,,,,,
,1.88885,1.88939,,,,,,,,,
,1.98,1.81421,,,,,,,,,
,2.05776,1.53243,,,,,,,,,
,2.15752,1.47812,,,,,,,,,
,2.16048,1.7049,,,,,,,,,
,2.24,1.63615,,,,,,,,,
,2.30209,1.42272,,,,,,,,,
,2.46441,1.31542,,,,,,,,,
,2.5155,1.50592,,,,,,,,,
,2.53,1.49648,,,,,,,,,
,2.5753,1.32226,,,,,,,,,
,2.81495,1.19496,,,,,,,,,
,2.85,1.17244,,,,,,,,,
,2.88417,1.35562,,,,,,,,,
,2.92885,1.33561,,,,,,,,,
,3.21536,1.08164,,,,,,,,,
,3.22,1.06841,,,,,,,,,
,3.22986,1.07205,,,,,,,,,
,3.41014,1.0165,,,,,,,,,
,3.59,1.00012,,,,,,,,,
,3.61329,0.979541,,,,,,,,,
,3.67272,0.971449,,,,,,,,,
,3.97051,0.91191,,,,,,,,,
,4.04,0.916281,,,,,,,,,
,4.04219,0.900285,,,,,,,,,
,4.19513,0.856912,,,,,,,,,
,4.52203,0.825345,,,,,,,,,
,4.62296,0.825282,,,,,,,,,
,4.64,0.811873,,,,,,,,,
,4.79185,0.772976,,,,,,,,,
,5.06428,0.665703,,,,,,,,,
,5.29,0.743169,,,,,,,,,
,5.38263,0.723395,,,,,,,,,
,5.47345,0.706107,,,,,,,,,
,5.67134,0.610202,,,,,,,,,
,6.13,0.660254,,,,,,,,,
,6.25201,0.642573,,,,,,,,,
,6.26713,0.636023,,,,,,,,,
,6.34461,0.559721,,,,,,,,,
,7.05,0.57851,,,,,,,,,
,7.09767,0.571225,,,,,,,,,
,7.1413,0.57441,,,,,,,,,
,7.29697,0.638783,,,,,,,,,
,7.94881,0.530452,,,,,,,,,
,8.07,0.516695,,,,,,,,,
,8.15709,0.518006,,,,,,,,,
,8.49605,0.565143,,,,,,,,,
,8.90165,0.48749,,,,,,,,,
,8.95,0.476303,,,,,,,,,
,9.31737,0.519064,,,,,,,,,
,9.89216,0.496907,,,,,,,,,
,9.95882,0.448748,,,,,,,,,
,10.4,0.424061,,,,,,,,,
,10.6427,0.466798,,,,,,,,,
,11.1402,0.452731,,,,,,,,,
,11.5177,0.400417,,,,,,,,,
,11.7,0.390943,,,,,,,,,
,12.0833,0.371794,,,,,,,,,
,12.4762,0.372992,,,,,,,,,
,13.4,0.355133,,,,,,,,,
,13.4103,0.351726,,,,,,,,,
,13.7188,0.387036,,,,,,,,,
,13.9716,0.344022,,,,,,,,,
,15.3,0.31443,,,,,,,,,
,15.614,0.313812,,,,,,,,,
,15.6305,0.349751,,,,,,,,,
,15.6702,0.321762,,,,,,,,,
,17.4,0.285392,,,,,,,,,
,17.4857,0.287796,,,,,,,,,
,17.8992,0.314566,,,,,,,,,
,18.1797,0.306987,,,,,,,,,
,19.5613,0.264704,,,,,,,,,
,19.7,0.257911,,,,,,,,,
,20.4452,0.253076,,,,,,,,,
,21.1671,0.273398,,,,,,,,,
,21.907,0.24425,,,,,,,,,
,22.3,0.235033,,,,,,,,,
,23.3533,0.224718,,,,,,,,,
,24.533,0.244898,,,,,,,,,
,24.6454,0.224184,,,,,,,,,
,25.1,0.214467,,,,,,,,,
,26.6751,0.203845,,,,,,,,,
,27.4447,0.204139,,,,,,,,,
,28.6953,0.199831,,,,,,,,,
,29.4,0.194272,,,,,,,,,
,30.4695,0.184994,,,,,,,,,
,30.7033,0.18861,,,,,,,,,
,33.2,0.179611,,,,,,,,,
,33.4106,0.17692,,,,,,,,,
,34.3833,0.190572,,,,,,,,,
,34.8035,0.171899,,,,,,,,,
,37.6,0.159658,,,,,,,,,
,38.5077,0.15974,,,,,,,,,
,38.9008,0.162353,,,,,,,,,
,39.754,0.15591,,,,,,,,,
,42.6,0.150168,,,,,,,,,
,43.0799,0.137912,,,,,,,,,
,45.2932,0.145092,,,,,,,,,
,45.4087,0.136127,,,,,,,,,
,48.1917,0.131075,,,,,,,,,
,48.2,0.127902,,,,,,,,,
,51.8677,0.112848,,,,,,,,,
,52.736,0.122207,,,,,,,,,
,53.9137,0.12194,,,,,,,,,
,54.4947,0.111255,,,,,,,,,
,59.2454,0.103377,,,,,,,,,
,60.3768,0.113739,,,,,,,,,
,61.4018,0.105516,,,,,,,,,
,61.5478,0.10484,,,,,,,,,
,67.6008,0.0965543,,,,,,,,,
,67.6726,0.100041,,,,,,,,,
,69.6837,0.0968447,,,,,,,,,
,71.4917,0.0957745,,,,,,,,,
,75.6548,0.0846292,,,,,,,,,
,77.2984,0.0910813,,,,,,,,,
,78.8951,0.0849862,,,,,,,,,
,83.2395,0.08192,,,,,,,,,
,84.601,0.0886706,,,,,,,,,
,88.2935,0.0793898,,,,,,,,,
,89.3241,0.0791848,,,,,,,,,
,94.5709,0.0746855,,,,,,,,,
,96.9178,0.0772063,,,,,,,,,
,99.9614,0.0717921,,,,,,,,,
,100.853,0.0698445,,,,,,,,,
,112.844,0.06292,,,,,,,,,
,114.83,0.0675745,,,,,,,,,
,115.198,0.0677584,,,,,,,,,
,130.009,0.0598431,,,,,,,,,
,131.387,0.0595548,,,,,,,,,
,131.584,0.0581395,,,,,,,,,
,147.195,0.0600449,,,,,,,,,
,150.301,0.0581549,,,,,,,,,
,152.977,0.0559594,,,,,,,,,
,166.652,0.0528871,,,,,,,,,
,171.68,0.0565548,,,,,,,,,
,178.115,0.0542152,,,,,,,,,
,188.682,0.0527078,,,,,,,,,
,196.1,0.0493035,,,,,,,,,
,207.384,0.0511975,,,,,,,,,
,213.623,0.0502364,,,,,,,,,
,223.993,0.0479931,,,,,,,,,
,241.462,0.0504064,,,,,,,,,
,241.862,0.0475994,,,,,,,,,
,255.854,0.0462798,,,,,,,,,
,273.833,0.0439886,,,,,,,,,
,281.14,0.0466455,,,,,,,,,
,292.247,0.0435172,,,,,,,,,
,310.03,0.042249,,,,,,,,,
,327.338,0.0402102,,,,,,,,,
,333.817,0.0426208,,,,,,,,,
,351.013,0.0408169,,,,,,,,,
,377.865,0.0382255,,,,,,,,,
,381.128,0.0400527,,,,,,,,,
,381.3,0.0385883,,,,,,,,,
,435.537,0.035491,,,,,,,,,
,443.757,0.0371463,,,,,,,,,
,497.488,0.035124,,,,,,,,,
,516.678,0.0368006,,,,,,,,,
,568.252,0.0337062,,,,,,,,,
,601.581,0.032283,,,,,,,,,
,649.081,0.0329647,,,,,,,,,
,700.435,0.0312186,,,,,,,,,
,741.407,0.0291821,,,,,,,,,
,815.534,0.0294156,,,,,,,,,
,846.866,0.0282835,,,,,,,,,
,949.547,0.0257424,,,,,,,,,
,967.326,0.0267719,,,,,,,,,
,1104.92,0.0247095,,,,,,,,,
,1105.58,0.0238076,,,,,,,,,
,1262.09,0.0233943,,,,,,,,,
,1287.26,0.0229979,,,,,,,,,
,1441.61,0.0210858,,,,,,,,,
,1498.78,0.0216682,,,,,,,,,
,1646.66,0.0204713,,,,,,,,,
,1745.07,0.0206805,,,,,,,,,
,1880.89,0.0193668,,,,,,,,,
,2031.83,0.0184624,,,,,,,,,
,2148.43,0.0184862,,,,,,,,,
,2365.71,0.0171047,,,,,,,,,
,2454.02,0.016707,,,,,,,,,
,2754.45,0.015806,,,,,,,,,
,2803.09,0.0159589,,,,,,,,,
,3201.8,0.0141901,,,,,,,,,
,3207.08,0.014192,,,,,,,,,
,3657.23,0.0126677,,,,,,,,,
,3657.41,0.0126703,,,,,,,,,
,4001.45,0.0117108,,,,,,,,,
,4028.64,0.0116608,,,,,,,,,
,4469.63,0.0106327,,,,,,,,,
,4490.08,0.010631,,,,,,,,,
,5055.59,9.55E-03,,,,,,,,,
,5168.23,9.44E-03,,,,,,,,,
,5693.63,8.62E-03,,,,,,,,,
,6315.97,8.00E-03,,,,,,,,,
,7353.84,6.91E-03,,,,,,,,,
,8562.26,6.24E-03,,,,,,,,,
,9969.25,5.32E-03,,,,,,,,,
,11607.4,4.49E-03,,,,,,,,,
,13514.8,4.13E-03,,,,,,,,,
,15412.6,4.70E-03,,,,,,,,,