File: Dago_s/esp_10_FR.csv
Filename,esp_10
Instrument name,5333-0457
Operator,Osamu Katagiri
rundate,31/01/2020
Sample name,ESP_10
Geometry name,60mm 0.9969° cone plate, Peltier plate Steel
Procedure name,Sample
,Flow ramp
,Temperature ramp
,Sample
proceduresegments,Flow ramp#Temperature ramp
[step]
Flow ramp - 1
Stress,Shear rate,Viscosity,Step time,Temperature,Normal stress,Modulus,Axial force,Gap,Normal stress coefficient,Time,Torque,Velocity
Pa,1/s,Pa.s,s,°C,Pa,Pa,N,µm,Pa.s²,s,µN.m,rad/s
-2.18969e-3,6.28995e-3,-0.348125,1.17604,24.93,76.7822,-0.323739,0.108548,23.0085,1940730,1.17604,-0.123824,1.09445e-4
8.56008e-4,6.95194e-3,,3.53898,24.92,76.2743,,0.107830,23.0087,1578210,3.53898,0.0484061,1.20964e-4
1.33522e-3,7.71994e-3,,5.83274,24.93,76.9372,,0.108767,23.0142,1290950,5.83274,0.0755052,1.34327e-4
1.16784e-3,8.54232e-3,,8.06096,24.92,76.0789,,0.107554,23.0136,1042590,8.06096,0.0660397,1.48636e-4
1.82917e-3,9.50924e-3,,10.3547,24.93,75.3806,,0.106567,23.0174,833618,10.3547,0.103437,1.65461e-4
1.69136e-3,0.0102902,,12.6485,24.93,75.3662,,0.106547,23.0057,711758,12.6485,0.0956444,1.79048e-4
1.59046e-4,0.0113061,0.0133420,14.8767,24.93,75.3399,1.19752e-3,0.106509,23.0136,589382,14.8767,8.99386e-3,1.96726e-4
1.49339e-4,0.0123005,0.0135327,17.1705,24.94,76.7221,1.10886e-3,0.108463,23.0082,507075,17.1705,8.44492e-3,2.14029e-4
1.91648e-4,0.0134915,0.0145514,19.4642,24.94,75.8319,1.09543e-3,0.107205,23.0041,416609,19.4642,0.0108374,2.34752e-4
2.16324e-4,0.0146716,0.0146986,21.6924,24.95,75.4054,1.02957e-3,0.106602,23.0124,350305,21.6924,0.0122329,2.55286e-4
2.94075e-4,0.0161746,0.0159345,23.9862,24.95,76.0586,1.04296e-3,0.107525,23.0165,290722,23.9862,0.0166296,2.81438e-4
2.67793e-4,0.0177038,0.0167036,26.2800,24.96,75.7561,1.03577e-3,0.107098,23.0159,241705,26.2800,0.0151433,3.08045e-4
3.44212e-4,0.0193789,0.0185958,28.5082,24.96,76.3446,1.10100e-3,0.107930,23.0129,203291,28.5082,0.0194647,3.37193e-4
3.82219e-4,0.0212263,0.0203355,30.8020,24.96,76.1295,1.15469e-3,0.107626,23.0193,168968,30.8020,0.0216140,3.69337e-4
5.86299e-4,0.0231970,0.0231005,33.0957,24.97,75.5156,1.26823e-3,0.106758,23.0175,140337,33.0957,0.0331544,4.03628e-4
7.16864e-4,0.0253986,0.0248977,35.3239,24.97,76.6295,1.32369e-3,0.108332,23.0175,118789,35.3239,0.0405377,4.41935e-4
8.21557e-4,0.0280155,0.0269453,37.6177,24.97,76.4101,1.38987e-3,0.108022,23.0193,97354.4,37.6177,0.0464580,4.87468e-4
7.84861e-4,0.0305446,0.0271524,39.9115,24.97,75.6565,1.36843e-3,0.106957,23.0186,81091.7,39.9115,0.0443829,5.31476e-4
8.82662e-4,0.0334034,0.0269506,42.1397,24.97,76.6249,1.32897e-3,0.108326,23.0179,68673.3,42.1397,0.0499134,5.81219e-4
9.61162e-4,0.0365925,0.0268035,44.4334,24.98,75.9066,1.29382e-3,0.107310,23.0219,56688.4,44.4334,0.0543524,6.36709e-4
1.08896e-3,0.0401069,0.0273363,46.7272,24.98,76.0229,1.29603e-3,0.107475,23.0214,47261.3,46.7272,0.0615790,6.97859e-4
1.25347e-3,0.0438621,0.0277022,48.9554,24.98,76.5005,1.29271e-3,0.108150,23.0170,39763.6,48.9554,0.0708822,7.63198e-4
1.36137e-3,0.0480744,0.0281846,51.2492,24.98,76.5423,1.29572e-3,0.108209,23.0174,33118.7,51.2492,0.0769835,8.36493e-4
1.49079e-3,0.0526898,0.0287756,53.5429,24.98,76.1513,1.30515e-3,0.107656,23.0149,27429.9,53.5429,0.0843019,9.16801e-4
1.64420e-3,0.0574868,0.0298429,55.7712,24.98,76.6873,1.33669e-3,0.108414,23.0138,23205.3,55.7712,0.0929773,1.00027e-3
1.89583e-3,0.0629996,0.0299576,58.0649,24.98,74.7769,1.32858e-3,0.105713,23.0137,18840.5,58.0649,0.107207,1.09619e-3
2.36721e-3,0.0687878,0.0303947,60.3587,24.98,76.1715,1.33518e-3,0.107685,23.0200,16097.9,60.3587,0.133862,1.19691e-3
9.49246e-3,0.0750843,,62.6524,24.99,78.5157,,0.110999,23.0115,13927.0,62.6524,0.536786,1.30646e-3
7.88690e-3,0.0842979,,64.9462,24.98,79.2088,,0.111979,23.0202,11146.5,64.9462,0.445994,1.46678e-3
1.41663e-3,0.0904182,,67.1744,24.99,75.3820,,0.106569,23.0156,9220.52,67.1744,0.0801083,1.57327e-3
2.91716e-3,0.0995341,0.0295171,69.4682,24.98,76.3151,1.25920e-3,0.107888,23.0180,7703.12,69.4682,0.164961,1.73189e-3
3.12830e-3,0.109098,0.0292893,71.7620,24.98,75.9267,1.24169e-3,0.107339,23.0179,6379.16,71.7620,0.176901,1.89830e-3
3.41223e-3,0.119232,0.0286703,73.9902,24.99,75.2648,1.20907e-3,0.106403,23.0129,5294.27,73.9902,0.192957,2.07463e-3
3.71848e-3,0.130679,0.0284163,76.2839,24.99,74.9230,1.19250e-3,0.105920,23.0197,4387.36,76.2839,0.210275,2.27381e-3
4.05315e-3,0.143264,0.0282214,78.5777,24.99,74.8098,1.17914e-3,0.105760,23.0200,3644.91,78.5777,0.229200,2.49278e-3
4.39160e-3,0.156588,0.0282533,80.8059,24.98,75.1615,1.17589e-3,0.106257,23.0280,3065.35,80.8059,0.248339,2.72462e-3
4.75927e-3,0.171699,0.0281971,83.0997,24.99,74.4024,1.16944e-3,0.105184,23.0339,2523.78,83.0997,0.269130,2.98755e-3
5.41128e-3,0.188105,0.0279750,85.3934,24.99,74.3191,1.15638e-3,0.105066,23.0329,2100.39,85.3934,0.306001,3.27302e-3
5.79700e-3,0.205772,0.0277446,87.6217,25.00,73.2174,1.14355e-3,0.103509,23.0267,1729.19,87.6217,0.327813,3.58042e-3
6.13131e-3,0.225410,0.0274752,89.9154,24.99,73.5131,1.12943e-3,0.103927,23.0237,1446.84,89.9154,0.346717,3.92212e-3
6.64570e-3,0.247122,0.0269762,92.2092,24.99,74.0721,1.10621e-3,0.104717,23.0317,1212.92,92.2092,0.375805,4.29991e-3
7.13511e-3,0.270245,0.0264679,94.4374,24.99,72.7425,1.08294e-3,0.102837,23.0285,996.033,94.4374,0.403481,4.70225e-3
7.78124e-3,0.296089,0.0260590,96.7312,24.98,74.4030,1.06401e-3,0.105185,23.0286,848.685,96.7312,0.440019,5.15193e-3
8.30261e-3,0.324610,0.0256196,99.0249,24.99,73.5476,1.04406e-3,0.103975,23.0299,697.983,99.0249,0.469502,5.64820e-3
8.92939e-3,0.354658,0.0251423,101.253,24.99,74.0607,1.02295e-3,0.104701,23.0241,588.801,101.253,0.504945,6.17104e-3
9.61612e-3,0.388826,0.0250157,103.547,24.99,72.6966,1.01656e-3,0.102772,23.0297,480.843,103.547,0.543779,6.76556e-3
0.0102184,0.426435,0.0251009,105.841,24.99,72.7360,1.01824e-3,0.102828,23.0276,399.986,105.841,0.577836,7.41995e-3
0.0119781,0.466674,0.0246514,108.069,24.99,73.4298,9.98769e-4,0.103809,23.0333,337.166,108.069,0.677344,8.12012e-3
0.0132592,0.510018,0.0241251,110.363,24.99,73.3171,9.76258e-4,0.103650,23.0158,281.860,110.363,0.749792,8.87430e-3
0.0128854,0.559636,0.0236270,112.656,24.99,72.5742,9.54957e-4,0.102599,23.0294,231.725,112.656,0.728651,9.73764e-3
0.0135492,0.611559,0.0227063,114.885,24.98,72.3911,9.16630e-4,0.102340,23.0303,193.557,114.885,0.766187,0.0106411
0.0145454,0.670693,0.0215890,117.178,25.00,72.0021,8.71016e-4,0.101791,23.0256,160.065,117.178,0.822525,0.0116700
0.0153785,0.735300,0.0223188,119.472,24.99,71.2630,8.99782e-4,0.100746,23.0218,131.806,119.472,0.869634,0.0127942
0.0162930,0.803699,0.0224796,121.700,24.99,71.8097,9.05706e-4,0.101519,23.0299,111.172,121.700,0.921348,0.0139843
0.0238855,0.880818,0.0230936,123.994,24.99,71.7351,9.29803e-4,0.101413,23.0352,92.4612,123.994,1.35069,0.0153262
0.0222692,0.965289,0.0227741,126.288,24.99,72.4096,9.16251e-4,0.102367,23.0292,77.7109,126.288,1.25930,0.0167960
0.0261296,1.05518,0.0224917,128.516,24.99,72.9882,9.04331e-4,0.103185,23.0292,65.5540,128.516,1.47759,0.0183601
0.0225768,1.15624,0.0206276,130.810,24.99,70.5782,8.28906e-4,0.0997776,23.0367,52.7931,130.810,1.27669,0.0201185
0.0239974,1.26745,0.0192756,133.104,25.00,71.3736,7.74215e-4,0.100902,23.0345,44.4303,133.104,1.35702,0.0220535
0.0244824,1.38550,0.0179024,135.332,24.99,70.3276,7.18771e-4,0.0994233,23.0322,36.6362,135.332,1.38444,0.0241077
0.0251116,1.51890,0.0170881,137.626,25.00,71.1248,6.85811e-4,0.100550,23.0414,30.8292,137.626,1.42003,0.0264288
0.0282728,1.66476,0.0162913,139.919,24.99,71.3622,6.53602e-4,0.100886,23.0227,25.7493,139.919,1.59879,0.0289668
0.0605056,1.82050,,142.148,25.00,73.7763,,0.104299,23.0211,22.2605,142.148,3.42151,0.0316767
0.0295760,1.99385,0.0150460,144.441,25.00,70.5830,6.03273e-4,0.0997844,23.0191,17.7548,144.441,1.67249,0.0346929
0.0314726,2.18551,0.0145324,146.735,25.00,71.2032,5.82507e-4,0.100661,23.0202,14.9071,146.735,1.77973,0.0380279
0.0332707,2.38975,0.0142021,148.963,24.99,71.2248,5.68971e-4,0.100692,23.0267,12.4717,148.963,1.88141,0.0415815
0.0352340,2.61885,0.0137795,151.257,25.00,70.9707,5.51931e-4,0.100332,23.0154,10.3481,151.257,1.99244,0.0455678
0.0413814,2.86690,0.0133832,153.551,24.99,70.9990,5.35948e-4,0.100373,23.0308,8.63831,153.551,2.34006,0.0498839
0.535235,3.11941,,155.779,24.99,108.576,,0.153496,23.0239,11.1581,155.779,30.2668,0.0542776
0.0749425,3.46132,,158.073,24.99,70.0227,,0.0989922,23.0243,5.84462,158.073,4.23790,0.0602268
0.0456633,3.76799,0.0121678,160.367,24.99,70.4494,4.87049e-4,0.0995955,23.0170,4.96200,160.367,2.58220,0.0655629
0.0472516,4.12012,0.0118791,162.595,24.99,70.7484,4.75425e-4,0.100018,23.0048,4.16770,162.595,2.67202,0.0716899
0.0517123,4.51644,0.0116643,164.889,25.00,71.1196,4.66504e-4,0.100543,23.0165,3.48655,164.889,2.92426,0.0785859
0.0554511,4.94945,0.0112022,167.182,24.99,70.3229,4.48008e-4,0.0994166,23.0352,2.87067,167.182,3.13569,0.0861202
0.0653063,5.39159,0.0108964,169.411,24.99,76.6341,4.35703e-4,0.108339,23.0294,2.63627,169.411,3.69299,0.0938134
0.341011,5.94902,,171.704,25.00,90.2838,,0.127636,23.0373,2.55105,171.704,19.2837,0.103513
0.0625995,6.49886,0.0101325,173.998,24.99,70.1200,4.05133e-4,0.0991298,23.0117,1.66023,173.998,3.53992,0.113080
0.0654988,7.10454,0.0101777,176.226,25.00,70.7418,4.06805e-4,0.100009,23.0214,1.40154,176.226,3.70387,0.123619
0.0759672,7.78712,9.54628e-3,178.520,24.99,69.9875,3.81832e-4,0.0989424,23.0219,1.15416,178.520,4.29584,0.135496
0.265431,8.44513,,180.814,24.98,92.6066,,0.130920,23.0260,1.29846,180.814,15.0098,0.146945
0.884038,9.44205,,183.108,24.99,122.305,,0.172904,23.0269,1.37186,183.108,49.9912,0.164291
0.104685,10.2503,8.90193e-3,185.401,25.00,70.0734,3.55981e-4,0.0990639,23.0278,0.666935,185.401,5.91980,0.178354
0.268748,11.2095,,187.630,25.00,91.2393,,0.128987,23.0338,0.726125,187.630,15.1974,0.195045
0.106320,12.2824,8.71498e-3,189.923,24.99,71.7992,3.48433e-4,0.101504,23.0137,0.475944,189.923,6.01223,0.213713
0.245939,13.4657,,192.217,25.00,81.3432,,0.114996,23.0227,0.448607,192.217,13.9075,0.234302
0.254980,14.7181,,194.445,24.99,81.5862,,0.115340,23.0287,0.376630,194.445,14.4188,0.256094
0.113662,16.1276,8.12758e-3,196.739,24.99,71.1179,3.24896e-4,0.100541,23.0406,0.273427,196.739,6.42745,0.280619
0.997754,17.6051,,199.033,24.99,106.188,,0.150120,23.0267,0.342609,199.033,56.4216,0.306328
1.29925,19.1394,,201.261,24.99,145.840,,0.206176,23.0055,0.398126,201.261,73.4710,0.333024
0.0935932,21.4299,,203.555,24.99,73.5859,,0.104030,23.0430,0.160233,203.555,5.29257,0.372880
0.176198,23.1966,7.08888e-3,205.849,25.00,75.0199,2.83315e-4,0.106057,23.0253,0.139421,205.849,9.96377,0.403620
0.280090,25.3909,,208.077,24.99,80.3971,,0.113659,23.0460,0.124705,208.077,15.8387,0.441800
0.386260,27.8189,,210.371,24.99,79.5664,,0.112484,23.0119,0.102813,210.371,21.8425,0.484048
0.209986,30.4825,6.97235e-3,212.664,24.99,74.5259,2.78684e-4,0.105359,23.0264,0.0802058,212.664,11.8744,0.530395
0.204518,33.3076,6.80701e-3,214.893,24.99,74.5064,2.72087e-4,0.105331,23.0186,0.0671594,214.893,11.5652,0.579551
0.275057,36.5374,6.65453e-3,217.186,25.00,81.6332,2.66014e-4,0.115406,23.0291,0.0611493,217.186,15.5541,0.635749
0.252655,40.0347,6.34405e-3,219.480,24.99,76.9789,2.53597e-4,0.108826,23.0370,0.0480283,219.480,14.2873,0.696603
0.284210,43.7595,6.36889e-3,221.708,25.00,75.5366,2.54621e-4,0.106787,23.0294,0.0394469,221.708,16.0717,0.761413
0.260766,47.9588,5.96482e-3,224.002,24.98,75.5759,2.38445e-4,0.106843,23.0263,0.0328584,224.002,14.7460,0.834481
0.562029,52.3845,,226.296,24.99,87.7217,,0.124014,23.0358,0.0319669,226.296,31.7820,0.911489
1.29254,57.6507,,228.524,25.00,167.426,,0.236693,23.0299,0.0503748,228.524,73.0917,1.00312
0.533064,62.9665,,230.818,24.99,79.1758,,0.111932,23.0219,0.0199698,230.818,30.1440,1.09562
1.16332,69.0286,,233.112,25.00,145.589,,0.205821,23.0290,0.0305541,233.112,65.7840,1.20110
0.549949,75.4750,,235.340,25.00,84.7360,,0.119793,23.0221,0.0148752,235.340,31.0989,1.31326
0.984822,82.6895,,237.634,25.00,122.046,,0.172538,23.0239,0.0178494,237.634,55.6904,1.43879
0.473273,90.6533,5.15309e-3,239.927,25.00,81.9189,2.05978e-4,0.115810,23.0225,9.96821e-3,239.927,26.7629,1.57736
0.948172,99.0976,,242.156,24.99,110.197,,0.155788,23.0230,0.0112213,242.156,53.6179,1.72429
0.717499,108.515,,244.449,25.00,93.5882,,0.132307,23.0130,7.94771e-3,244.449,40.5736,1.88816
0.970044,118.995,,246.743,25.00,118.846,,0.168015,23.0227,8.39326e-3,246.743,54.8547,2.07050
2.14950,130.244,,248.971,24.99,192.688,,0.272406,23.0163,0.0113590,248.971,121.552,2.26624
2.03452,142.623,,251.265,25.00,187.638,,0.265267,23.0276,9.22455e-3,251.265,115.049,2.48163
1.93339,156.300,,253.559,24.99,165.158,,0.233486,23.0191,6.76049e-3,253.559,109.331,2.71962
1.83495,170.839,,255.787,25.00,157.488,,0.222643,23.0216,5.39603e-3,255.787,103.764,2.97259
1.68396,187.237,,258.081,25.00,141.851,,0.200537,23.0289,4.04624e-3,258.081,95.2258,3.25791
2.04032,205.126,,260.375,24.99,159.074,,0.224886,23.0209,3.78056e-3,260.375,115.377,3.56919
1.93076,224.515,,262.603,24.99,146.309,,0.206839,23.0340,2.90255e-3,262.603,109.182,3.90655
3.77527,245.923,,264.897,24.99,174.565,,0.246785,23.0297,2.88640e-3,264.897,213.486,4.27906
1.07270,269.499,3.84734e-3,267.190,25.00,81.9213,1.53773e-4,0.115814,23.0193,1.12793e-3,267.190,60.6596,4.68927
1.19916,294.603,3.75526e-3,269.419,25.00,88.9483,1.50095e-4,0.125748,23.0209,1.02486e-3,269.419,67.8111,5.12609
1.76332,322.945,,271.712,24.99,133.941,,0.189355,23.0343,1.28427e-3,271.712,99.7132,5.61923
1.94928,353.845,,274.006,25.00,143.370,,0.202685,23.0179,1.14507e-3,274.006,110.229,6.15689
3.08434,386.703,,276.234,25.00,240.676,,0.340248,23.0257,1.60945e-3,276.234,174.415,6.72862
2.24892,424.111,,278.528,25.00,158.975,,0.224746,23.0339,8.83834e-4,278.528,127.173,7.37951
2.45354,464.859,,280.822,24.99,154.687,,0.218684,23.0156,7.15831e-4,280.822,138.745,8.08854
2.27193,508.073,,283.050,25.00,134.069,,0.189536,23.0269,5.19370e-4,283.050,128.474,8.84045
1.64213,556.802,3.02703e-3,285.344,24.99,64.5671,1.20985e-4,0.0912796,23.0213,2.08262e-4,285.344,92.8604,9.68833
1.77184,610.260,3.02553e-3,287.638,25.00,59.5917,1.20923e-4,0.0842458,23.0255,1.60013e-4,287.638,100.195,10.6185
1.91439,667.110,2.93319e-3,289.866,24.99,52.3478,1.17233e-4,0.0740049,23.0211,1.17626e-4,289.866,108.256,11.6077
2.27017,731.143,2.94644e-3,292.160,25.00,55.6075,1.17759e-4,0.0786133,23.0267,1.04023e-4,292.160,128.375,12.7219
3.03998,801.452,,294.453,25.00,81.5880,,0.115342,23.0312,1.27020e-4,294.453,171.907,13.9452
2.48535,875.985,2.97459e-3,296.681,25.01,40.6331,1.18874e-4,0.0574437,23.0218,5.29525e-5,296.681,140.543,15.2421
2.91637,954.818,2.95152e-3,298.844,24.99,66.1415,1.17946e-4,0.0935054,23.0220,7.25492e-5,298.844,164.917,16.6138