File: Dago_s/esp_10_FR.csv
Filename,esp_10
Instrument name,5333-0457
Operator,Osamu Katagiri
rundate,31/01/2020
Sample name,ESP_10
Geometry name,60mm 0.9969° cone plate, Peltier plate Steel
Procedure name,Sample
,Flow ramp
,Temperature ramp
,Sample
proceduresegments,Flow ramp#Temperature ramp
[step]
Flow ramp - 1
Stress,Shear rate,Viscosity,Step time,Temperature,Normal stress,Modulus
Pa,1/s,Pa.s,s,°C,Pa,Pa
-2.18969e-3,0.0111249,6.30212e-3,1.17604,24.93,76.7822,-0.323739
8.56008e-4,0.0120891,6.35641e-3,3.53898,24.92,76.2743,
1.33522e-3,0.0124290,6.35641e-3,5.83274,24.93,76.9372,
1.16784e-3,0.0133176,6.63414e-3,8.06096,24.92,76.0789,
1.82917e-3,0.0144721,6.67191e-3,10.3547,24.93,75.3806,
1.69136e-3,0.0159421,7.00660e-3,12.6485,24.93,75.3662,
1.59046e-4,0.0163903,7.00306e-3,14.8767,24.93,75.3399,1.19752e-3
1.49339e-4,0.0173217,7.21833e-3,17.1705,24.94,76.7221,1.10886e-3
1.91648e-4,0.0178084,7.22926e-3,19.4642,24.94,75.8319,1.09543e-3
2.16324e-4,0.0190792,7.71160e-3,21.6924,24.95,75.4054,1.02957e-3
2.94075e-4,0.0210165,8.14352e-3,23.9862,24.95,76.0586,1.04296e-3
2.67793e-4,0.0228289,8.78826e-3,26.2800,24.96,75.7561,1.03577e-3
3.44212e-4,0.0234707,8.78826e-3,28.5082,24.96,76.3446,1.10100e-3
3.82219e-4,0.0251483,9.20121e-3,30.8020,24.96,76.1295,1.15469e-3
5.86299e-4,0.0277033,9.63114e-3,33.0957,24.97,75.5156,1.26823e-3
7.16864e-4,0.0301049,9.68597e-3,35.3239,24.97,76.6295,1.32369e-3
8.21557e-4,0.0328077,9.62677e-3,37.6177,24.97,76.4101,1.38987e-3
7.84861e-4,0.0336364,9.63843e-3,39.9115,24.97,75.6566,1.36843e-3
8.82662e-4,0.0360510,9.60566e-3,42.1397,24.97,76.6249,1.32897e-3
9.61162e-4,0.0397219,9.71166e-3,44.4334,24.98,75.9066,1.29382e-3
1.08896e-3,0.0431645,9.80027e-3,46.7272,24.98,76.0229,1.29603e-3
1.25347e-3,0.0443779,9.80027e-3,48.9554,24.98,76.5005,1.29271e-3
1.36137e-3,0.0470356,9.89269e-3,51.2492,24.98,76.5423,1.29572e-3
1.49079e-3,0.0482236,9.90468e-3,53.5429,24.98,76.1513,1.30515e-3
1.64420e-3,0.0516802,0.0100405,55.7712,24.98,76.6873,1.33669e-3
1.89583e-3,0.0561550,0.0102608,58.0649,24.98,74.7769,1.32858e-3
2.36721e-3,0.0618760,0.0102867,60.3587,24.98,76.1715,1.33518e-3
9.49246e-3,0.0636154,0.0102867,62.6524,24.99,78.5157,
7.88690e-3,0.0681774,0.0103753,64.9462,24.98,79.2088,
1.41663e-3,0.0977697,0.0101976,67.1744,24.99,75.3820,
2.91716e-3,0.107735,0.0101398,69.4682,24.98,76.3151,1.25920e-3
3.12830e-3,0.117087,0.0100152,71.7620,24.98,75.9267,1.24169e-3
3.41223e-3,0.120379,0.0100102,73.9902,24.99,75.2648,1.20907e-3
3.71848e-3,0.127247,9.94976e-3,76.2839,24.99,74.9230,1.19250e-3
4.05315e-3,0.130823,9.96483e-3,78.5777,24.99,74.8097,1.17914e-3
4.39160e-3,0.142172,9.92344e-3,80.8059,24.98,75.1615,1.17589e-3
4.75927e-3,0.154502,9.92719e-3,83.0997,24.99,74.4024,1.16944e-3
5.41128e-3,0.168370,9.89269e-3,85.3934,24.99,74.3191,1.15638e-3
5.79700e-3,0.172623,9.90468e-3,87.6217,25.00,73.2174,1.14355e-3
6.13131e-3,0.185015,9.87100e-3,89.9154,24.99,73.5131,1.12943e-3
6.64570e-3,0.203872,9.82999e-3,92.2092,24.99,74.0721,1.10621e-3
7.13511e-3,0.221561,9.77065e-3,94.4374,24.99,72.7425,1.08294e-3
7.78124e-3,0.241466,9.62677e-3,96.7312,24.98,74.4030,1.06401e-3
8.30261e-3,0.247564,9.63843e-3,99.0249,24.99,73.5476,1.04406e-3
8.92939e-3,0.269052,9.53203e-3,101.253,24.99,74.0607,1.02295e-3
9.61612e-3,0.292401,9.45061e-3,103.547,24.99,72.6966,1.01656e-3
0.0102184,0.317780,9.34746e-3,105.841,24.99,72.7360,1.01824e-3
0.0119781,0.345360,9.25243e-3,108.069,24.99,73.4298,9.98769e-4
0.0132592,0.355069,9.25243e-3,110.363,24.99,73.3171,9.76258e-4
0.0128854,0.385868,9.22912e-3,112.656,24.99,72.5742,9.54957e-4
0.0135492,0.419334,9.22446e-3,114.885,24.98,72.3911,9.16630e-4
0.0145454,0.456998,9.11618e-3,117.178,25.00,72.0021,8.71016e-4
0.0153785,0.468541,9.12723e-3,119.472,24.99,71.2630,8.99782e-4
0.0162930,0.502199,9.02647e-3,121.700,24.99,71.8097,9.05706e-4
0.0238855,0.553415,8.90207e-3,123.994,24.99,71.7351,9.29803e-4
0.0222692,0.601498,8.68576e-3,126.288,24.99,72.4096,9.16251e-4
0.0261296,0.655595,8.42610e-3,128.516,24.99,72.9882,9.04331e-4
0.0225768,0.672153,8.43631e-3,130.810,24.99,70.5782,8.28906e-4
0.0239974,0.730364,8.59963e-3,133.104,25.00,71.3736,7.74215e-4
0.0244824,0.793685,8.63659e-3,135.332,24.99,70.3276,7.18771e-4
0.0251116,0.862430,8.78826e-3,137.626,25.00,71.1248,6.85811e-4
0.0282728,0.886673,8.78826e-3,139.919,24.99,71.3622,6.53602e-4
0.0605056,0.950354,8.71320e-3,142.148,25.00,73.7763,
0.0295760,0.977064,8.72200e-3,144.441,25.00,70.5830,6.03273e-4
0.0314726,1.04724,8.63986e-3,146.735,25.00,71.2032,5.82507e-4
0.0332707,1.13841,8.20332e-3,148.963,24.99,71.2248,5.68971e-4
0.0352340,1.23744,7.88075e-3,151.257,25.00,70.9707,5.51931e-4
0.0413814,1.27222,7.88075e-3,153.551,24.99,70.9990,5.35948e-4
0.535235,1.36389,7.53086e-3,155.779,24.99,108.576,
0.0749425,1.40224,7.51947e-3,158.073,24.99,70.0227,
0.0456633,1.50312,7.31458e-3,160.367,24.99,70.4494,4.87049e-4
0.0472516,1.63376,7.10629e-3,162.595,24.99,70.7484,4.75425e-4
0.0517123,1.97872,6.77573e-3,164.889,25.00,71.1196,4.66504e-4
0.0554511,2.15656,6.63665e-3,167.182,24.99,70.3229,4.48008e-4
0.0653063,2.34378,6.54850e-3,169.411,24.99,76.6341,4.35703e-4
0.341011,2.59007,6.41635e-3,171.704,25.00,90.2838,
0.0625995,2.65549,6.42413e-3,173.998,24.99,70.1200,4.05133e-4
0.0654988,2.84634,6.32123e-3,176.226,25.00,70.7418,4.06805e-4
0.0759672,3.70529,5.94682e-3,178.520,24.99,69.9875,3.81832e-4
0.265431,3.80942,5.95583e-3,180.814,24.98,92.6066,
0.884038,4.08313,5.87524e-3,183.108,24.99,122.305,
0.104685,4.43755,5.80745e-3,185.401,25.00,70.0734,3.55981e-4
0.268748,4.89041,5.66848e-3,187.630,25.00,91.2393,
0.106320,5.02789,5.66562e-3,189.923,24.99,71.7992,3.48433e-4
0.245939,5.31504,5.57768e-3,192.217,25.00,81.3432,
0.254980,6.36620,5.33475e-3,194.445,24.99,81.5862,
0.113662,7.01474,5.35160e-3,196.739,24.99,71.1179,3.24896e-4
0.997754,7.21189,5.35701e-3,199.033,24.99,106.188,
1.29925,7.73135,5.13987e-3,201.261,24.99,145.840,
0.0935932,10.0633,4.92905e-3,203.555,24.99,73.5859,
0.176198,10.3461,4.93652e-3,205.849,25.00,75.0199,2.83315e-4
0.280090,12.0513,4.86726e-3,208.077,24.99,80.3971,
0.386260,15.9052,4.67116e-3,210.371,24.99,79.5664,
0.209986,22.8179,4.29149e-3,212.664,24.99,74.5259,2.78684e-4
0.204518,30.1089,4.26020e-3,214.893,24.99,74.5064,2.72087e-4
0.275057,32.7234,4.18721e-3,217.186,25.00,81.6332,2.66014e-4
0.252655,36.0605,4.13316e-3,219.480,24.99,76.9789,2.53597e-4
0.284210,37.0741,4.13524e-3,221.708,25.00,75.5366,2.54621e-4
0.260766,39.1941,4.02409e-3,224.002,24.98,75.5759,2.38445e-4
0.562029,40.2962,4.01800e-3,226.296,24.99,87.7217,
1.29254,43.1877,4.02409e-3,228.524,25.00,167.426,
0.533064,47.5992,3.87073e-3,230.818,24.99,79.1758,
1.16332,90.1055,3.53555e-3,233.112,25.00,145.589,
0.549949,265.927,2.96391e-3,235.340,25.00,84.7360,
0.984822,273.402,2.96391e-3,237.634,25.00,122.046,
0.473272,290.016,2.92381e-3,239.927,25.00,81.9189,2.05978e-4
0.948172,297.137,2.92381e-3,242.156,24.99,110.197,
0.717499,548.753,2.56380e-3,244.449,25.00,93.5882,
0.970044,562.613,2.56690e-3,246.743,25.00,118.846,
2.14950,611.410,2.56399e-3,248.971,24.99,192.688,
2.03452,664.507,2.51688e-3,251.265,25.00,187.638,
1.93339,722.124,2.52451e-3,253.559,24.99,165.158,
1.83495,742.424,2.52451e-3,255.787,25.00,157.488,
1.68396,876.754,2.53856e-3,258.081,25.00,141.851,
2.04032,952.822,2.52451e-3,260.375,24.99,159.074,