File: Dago_s/esp_0_FR.csv
Filename,esp_0
Instrument name,5333-0457
Operator,Osamu Katagiri
rundate,31/01/2020
Sample name,ESP_0
Geometry name,60mm 0.9969° cone plate, Peltier plate Steel
Procedure name,Sample
,Flow ramp
,Temperature ramp
proceduresegments,Flow ramp#Temperature ramp
[step]
Flow ramp - 1
Stress,Shear rate,Viscosity,Step time,Temperature,Normal stress,Modulus,Axial force,Gap,Normal stress coefficient,Time,Torque,Velocity
Pa,1/s,Pa.s,s,°C,Pa,Pa,N,µm,Pa.s²,s,µN.m,rad/s
-0.0109345,0.0702815,-0.155581,1.20281,24.89,22.0388,,0.0311567,20.0211,4461.76,1.20281,-0.618330,1.22290e-3
6.86753e-4,6.95648e-3,0.0987214,3.53898,24.89,22.2898,-0.0278015,0.0315115,20.0263,460605,3.53898,0.0388350,1.21042e-4
1.21759e-3,7.70709e-3,0.160457,5.83274,24.88,22.4642,-0.154145,0.0317580,20.0310,378190,5.83274,0.0688529,1.34103e-4
1.76554e-3,8.45838e-3,0.200103,8.06096,24.89,21.7696,0.160344,0.0307761,20.0335,304282,8.06096,0.0998387,1.47176e-4
2.33984e-3,9.29055e-3,0.238134,10.3547,24.89,22.1323,0.0950557,0.0312888,20.0271,256415,10.3547,0.132315,1.61655e-4
2.94799e-3,0.0102113,0.279127,12.6485,24.90,21.9020,0.0670776,0.0309632,20.0260,210051,12.6485,0.166705,1.77676e-4
3.54935e-3,0.0111643,0.311371,14.8767,24.91,21.7311,0.0498028,0.0307216,20.0303,174348,14.8767,0.200711,1.94258e-4
4.23417e-3,0.0122486,0.333227,17.1705,24.91,22.0335,0.0415832,0.0311491,20.0358,146863,17.1705,0.239437,2.13125e-4
4.95573e-3,0.0134489,0.348931,19.4642,24.92,21.5666,0.0364080,0.0304891,20.0319,119237,19.4642,0.280240,2.34010e-4
5.16891e-3,0.0146980,0.350481,21.6924,24.92,22.2433,0.0321410,0.0314457,20.0237,102964,21.6924,0.292295,2.55744e-4
5.82734e-3,0.0160988,0.342331,23.9862,24.93,20.9209,0.0281844,0.0295762,20.0336,80722.3,23.9862,0.329528,2.80118e-4
5.77770e-3,0.0177364,0.326669,26.2800,24.94,21.8918,0.0245229,0.0309489,20.0306,69590.5,26.2800,0.326721,3.08613e-4
5.92174e-3,0.0193308,0.310796,28.5082,24.95,21.5242,0.0217543,0.0304292,20.0356,57600.7,28.5082,0.334867,3.36355e-4
6.29128e-3,0.0212934,0.290131,30.8020,24.93,22.2432,0.0190089,0.0314456,20.0269,49057.7,30.8020,0.355764,3.70504e-4
6.25963e-3,0.0232525,0.278344,33.0957,24.95,20.7055,0.0172846,0.0292717,20.0248,38295.5,33.0957,0.353974,4.04592e-4
6.64583e-3,0.0254440,0.268099,35.3239,24.94,22.1991,0.0159142,0.0313833,20.0303,34289.8,35.3239,0.375813,4.42725e-4
7.31541e-3,0.0278234,0.255420,37.6177,24.95,22.1194,0.0145350,0.0312706,20.0280,28572.8,37.6177,0.413676,4.84127e-4
7.75473e-3,0.0306732,0.245194,39.9115,24.95,21.0252,0.0134245,0.0297237,20.0365,22347.2,39.9115,0.438520,5.33712e-4
7.72623e-3,0.0333291,0.235350,42.1397,24.96,22.5194,0.0125193,0.0318361,20.0283,20272.7,42.1397,0.436908,5.79925e-4
8.15600e-3,0.0365956,0.220825,44.4334,24.96,21.4148,0.0114167,0.0302745,20.0334,15990.3,44.4334,0.461211,6.36761e-4
8.35607e-3,0.0401841,0.204731,46.7272,24.97,21.5526,0.0103030,0.0304693,20.0230,13347.3,46.7272,0.472525,6.99202e-4
8.45303e-3,0.0438910,0.186679,48.9554,24.97,21.3114,9.20702e-3,0.0301283,20.0267,11062.7,48.9554,0.478007,7.63703e-4
8.44014e-3,0.0480484,0.167101,51.2492,24.96,21.1125,8.07579e-3,0.0298470,20.0349,9144.95,51.2492,0.477279,8.36040e-4
7.58590e-3,0.0529285,0.149524,53.5429,24.97,20.9442,7.08536e-3,0.0296092,20.0358,7476.28,53.5429,0.428973,9.20954e-4
7.35617e-3,0.0575081,0.137480,55.7712,24.97,21.9747,6.41550e-3,0.0310660,20.0250,6644.54,55.7712,0.415982,1.00064e-3
7.86132e-3,0.0630696,0.125873,58.0649,24.96,21.3782,5.78862e-3,0.0302228,20.0211,5374.43,58.0649,0.444547,1.09741e-3
8.34467e-3,0.0690350,0.117401,60.3587,24.98,20.7962,5.32274e-3,0.0293999,20.0184,4363.59,60.3587,0.471880,1.20121e-3
8.64036e-3,0.0758379,0.109659,62.6524,24.97,21.7533,4.91284e-3,0.0307530,20.0217,3782.27,62.6524,0.488601,1.31958e-3
8.40529e-3,0.0830310,0.101275,64.9462,24.97,21.8466,4.49036e-3,0.0308849,20.0103,3168.86,64.9462,0.475308,1.44474e-3
8.34080e-3,0.0908033,0.0922499,67.1744,24.98,21.6279,4.05270e-3,0.0305757,20.0119,2623.08,67.1744,0.471661,1.57997e-3
8.31944e-3,0.0995698,0.0834485,69.4682,24.98,21.8230,3.63342e-3,0.0308516,20.0180,2201.20,69.4682,0.470453,1.73251e-3
8.17785e-3,0.109018,0.0760600,71.7620,24.98,21.8755,3.28684e-3,0.0309258,20.0223,1840.61,71.7620,0.462446,1.89691e-3
8.30420e-3,0.119240,0.0692447,73.9902,24.97,21.6793,2.97127e-3,0.0306484,20.0099,1524.76,73.9902,0.469592,2.07477e-3
8.31831e-3,0.130811,0.0628875,76.2839,24.97,20.4319,2.68073e-3,0.0288849,20.0145,1194.05,76.2839,0.470389,2.27610e-3
8.16434e-3,0.143214,0.0575215,78.5777,24.97,21.8209,2.43834e-3,0.0308486,20.0159,1063.90,78.5777,0.461682,2.49192e-3
8.16923e-3,0.156631,0.0523685,80.8059,24.98,21.2917,2.20867e-3,0.0301004,20.0214,867.870,80.8059,0.461959,2.72537e-3
8.23554e-3,0.171727,0.0476516,83.0997,24.98,20.3619,1.99978e-3,0.0287859,20.0332,690.465,83.0997,0.465709,2.98804e-3
8.12450e-3,0.188247,0.0433177,85.3934,24.98,21.4885,1.81020e-3,0.0303787,20.0218,606.387,85.3934,0.459430,3.27549e-3
8.22206e-3,0.205729,0.0392226,87.6217,24.97,21.4857,1.63265e-3,0.0303746,20.0264,507.643,87.6217,0.464947,3.57968e-3
8.02467e-3,0.225533,0.0354392,89.9154,24.97,21.3387,1.46995e-3,0.0301668,20.0306,419.514,89.9154,0.453784,3.92427e-3
7.74291e-3,0.247053,0.0322165,92.2092,24.97,21.1139,1.33185e-3,0.0298491,20.0331,345.931,92.2092,0.437851,4.29871e-3
7.85923e-3,0.270342,0.0293179,94.4374,24.97,20.7443,1.20839e-3,0.0293265,20.0276,283.838,94.4374,0.444429,4.70395e-3
7.95721e-3,0.296174,0.0269432,96.7312,24.97,22.1174,1.10741e-3,0.0312678,20.0252,252.139,96.7312,0.449970,5.15342e-3
8.05014e-3,0.324498,0.0250410,99.0249,24.97,21.6987,1.02668e-3,0.0306758,20.0310,206.068,99.0249,0.455225,5.64625e-3
8.29974e-3,0.354738,0.0232635,101.253,24.97,20.6376,9.51677e-4,0.0291757,20.0379,164.000,101.253,0.469339,6.17242e-3
8.47080e-3,0.388753,0.0215392,103.547,24.97,21.3238,8.79373e-4,0.0301459,20.0263,141.097,103.547,0.479012,6.76428e-3
8.50934e-3,0.426426,0.0199424,105.841,24.98,20.7900,8.12602e-4,0.0293911,20.0223,114.332,105.841,0.481192,7.41980e-3
8.54967e-3,0.466140,0.0182059,108.069,24.99,19.9136,7.40703e-4,0.0281522,20.0250,91.6469,108.069,0.483472,8.11082e-3
8.68774e-3,0.510486,0.0165093,110.363,24.99,20.3649,6.70639e-4,0.0287902,20.0295,78.1472,110.363,0.491280,8.88244e-3
8.22042e-3,0.559981,0.0150642,112.656,24.98,20.1266,6.11038e-4,0.0284534,20.0354,64.1836,112.656,0.464854,9.74366e-3
8.18030e-3,0.611667,0.0138718,114.885,24.98,19.6865,5.61924e-4,0.0278311,20.0232,52.6186,114.885,0.462585,0.0106430
8.55600e-3,0.670875,0.0125947,117.178,25.00,19.9280,5.09651e-4,0.0281726,20.0226,44.2773,117.178,0.483830,0.0116732
8.80270e-3,0.735087,0.0116182,119.472,24.99,20.2249,4.69564e-4,0.0285923,20.0299,37.4290,119.472,0.497781,0.0127905
8.50212e-3,0.803705,0.0107597,121.700,24.99,20.1266,4.34508e-4,0.0284534,20.0303,31.1586,121.700,0.480783,0.0139844
8.66788e-3,0.880489,9.89075e-3,123.994,24.98,21.3268,3.99041e-4,0.0301501,20.0161,27.5092,123.994,0.490157,0.0153205
8.71373e-3,0.965549,9.07053e-3,126.288,25.00,20.3671,3.65643e-4,0.0287933,20.0099,21.8464,126.288,0.492750,0.0168005
8.86205e-3,1.05525,8.44742e-3,128.516,24.99,19.8195,3.40267e-4,0.0280192,20.0131,17.7984,128.516,0.501137,0.0183614
9.04509e-3,1.15655,7.85734e-3,130.810,24.99,20.4939,3.16306e-4,0.0289726,20.0143,15.3215,130.810,0.511488,0.0201238
9.30630e-3,1.26764,7.34455e-3,133.104,24.99,20.3701,2.95461e-4,0.0287976,20.0119,12.6765,133.104,0.526259,0.0220570
9.53468e-3,1.38578,6.91974e-3,135.332,24.99,20.5509,2.78210e-4,0.0290532,20.0090,10.7015,135.332,0.539173,0.0241125
9.82047e-3,1.51877,6.52385e-3,137.626,25.00,20.5585,2.62168e-4,0.0290640,20.0232,8.91272,137.626,0.555334,0.0264265
0.0103045,1.66438,6.12132e-3,139.919,24.99,19.8484,2.45876e-4,0.0280600,20.0101,7.16509,139.919,0.582707,0.0289601
0.0106353,1.81996,5.79742e-3,142.148,24.99,20.4224,2.32771e-4,0.0288714,20.0163,6.16571,142.148,0.601409,0.0316672
0.0106812,1.99452,5.47797e-3,144.441,24.99,20.3418,2.19860e-4,0.0287575,20.0291,5.11341,144.441,0.604010,0.0347046
0.0113944,2.18614,5.18044e-3,146.735,24.99,19.7273,2.07845e-4,0.0278888,20.0319,4.12772,146.735,0.644338,0.0380388
0.0116732,2.38955,4.92414e-3,148.963,24.99,20.2552,1.97494e-4,0.0286351,20.0290,3.54734,148.963,0.660104,0.0415782
0.0123019,2.61878,4.69479e-3,151.257,24.99,19.9705,1.88238e-4,0.0282326,20.0317,2.91200,151.257,0.695657,0.0455666
0.0129400,2.87055,4.44948e-3,153.551,25.00,19.6513,1.78350e-4,0.0277813,20.0365,2.38485,153.551,0.731738,0.0499474
0.0132700,3.13777,4.22579e-3,155.779,24.99,20.3116,1.69341e-4,0.0287148,20.0317,2.06300,155.779,0.750403,0.0545972
0.0137518,3.43932,4.01324e-3,158.073,24.99,20.2094,1.60790e-4,0.0285704,20.0247,1.70847,158.073,0.777643,0.0598441
0.0141374,3.76925,3.80166e-3,160.367,24.99,19.9698,1.52279e-4,0.0282317,20.0255,1.40561,160.367,0.799451,0.0655847
0.0150059,4.12040,3.63629e-3,162.595,25.00,19.2429,1.45629e-4,0.0272040,20.0214,1.13342,162.595,0.848563,0.0716948
0.0155698,4.51607,3.47421e-3,164.889,24.99,19.9914,1.39114e-4,0.0282622,20.0284,0.980218,164.889,0.880452,0.0785795
0.0166705,4.94984,3.34217e-3,167.182,25.00,19.5208,1.33805e-4,0.0275969,20.0246,0.796739,167.182,0.942693,0.0861270
0.0172674,5.41096,3.20697e-3,169.411,25.00,19.1602,1.28374e-4,0.0270870,20.0099,0.654412,169.411,0.976451,0.0941504
0.0183688,5.93024,3.07750e-3,171.704,24.99,20.4959,1.23175e-4,0.0289754,20.0124,0.582804,171.704,1.03873,0.103186
0.0191672,6.49981,2.93850e-3,173.998,25.00,20.1944,1.17597e-4,0.0285492,20.0301,0.478002,173.998,1.08388,0.113097
0.0199777,7.10468,2.82642e-3,176.226,25.00,20.0852,1.13098e-4,0.0283948,20.0388,0.397912,176.226,1.12971,0.123621
0.0208714,7.78796,2.71508e-3,178.520,24.99,19.2986,1.08633e-4,0.0272827,20.0139,0.318184,178.520,1.18025,0.135510
0.0223060,8.53474,2.61136e-3,180.814,25.00,20.5804,1.04473e-4,0.0290949,20.0172,0.282536,180.814,1.26137,0.148504
0.0237431,9.35511,2.52239e-3,183.108,25.00,19.0034,1.00906e-4,0.0268654,20.0256,0.217137,183.108,1.34264,0.162779
0.0249046,10.2524,2.43277e-3,185.401,25.00,19.9711,9.73125e-5,0.0282335,20.0230,0.189999,185.401,1.40832,0.178391
0.0265287,11.2078,2.33431e-3,187.630,24.99,19.6986,9.33680e-5,0.0278482,20.0345,0.156817,187.630,1.50016,0.195015
0.0275042,12.2844,2.22689e-3,189.923,25.00,19.5044,8.90654e-5,0.0275737,20.0358,0.129249,189.923,1.55533,0.213747
0.0284857,13.4632,2.12883e-3,192.217,24.99,18.6441,8.51385e-5,0.0263575,20.0142,0.102859,192.217,1.61083,0.234260
0.0295935,14.7173,2.05063e-3,194.445,25.00,20.6252,8.20065e-5,0.0291582,20.0117,0.0952224,194.445,1.67347,0.256081
0.0313691,16.1309,1.99153e-3,196.739,25.00,19.5841,7.96390e-5,0.0276864,20.0343,0.0752640,196.739,1.77388,0.280677
0.0345345,17.6789,1.95295e-3,199.033,24.99,18.7727,7.80922e-5,0.0265393,20.0308,0.0600640,199.033,1.95288,0.307613
0.0374629,19.3260,1.92677e-3,201.261,24.99,19.9641,7.70427e-5,0.0282236,20.0119,0.0534523,201.261,2.11848,0.336271
0.0406614,21.1818,1.90134e-3,203.555,24.99,19.2933,7.60234e-5,0.0272753,20.0271,0.0430012,203.555,2.29935,0.368563
0.0435904,23.2157,1.85883e-3,205.849,25.00,19.5979,7.43210e-5,0.0277059,20.0198,0.0363619,205.849,2.46498,0.403952
0.0462038,25.3778,1.81574e-3,208.077,24.99,18.9311,7.25959e-5,0.0267632,20.0110,0.0293945,208.077,2.61276,0.441574
0.0485989,27.8154,1.77731e-3,210.371,24.99,19.0097,7.10579e-5,0.0268743,20.0250,0.0245700,210.371,2.74820,0.483986
0.0523866,30.4850,1.74543e-3,212.664,24.99,19.5941,6.97811e-5,0.0277005,20.0246,0.0210840,212.664,2.96239,0.530438
0.0575827,33.3247,1.71764e-3,214.893,25.00,19.7228,6.86682e-5,0.0278825,20.0294,0.0177597,214.893,3.25622,0.579849
0.0626912,36.5256,1.69792e-3,217.186,25.00,20.2103,6.78786e-5,0.0285717,20.0215,0.0151488,217.186,3.54510,0.635543
0.0671795,40.0311,1.68459e-3,219.480,24.99,19.0833,6.73441e-5,0.0269784,20.0253,0.0119086,219.480,3.79891,0.696540
0.0722047,43.7600,1.66796e-3,221.708,25.00,19.1876,6.66784e-5,0.0271259,20.0292,0.0100200,221.708,4.08308,0.761422
0.0792918,47.9631,1.64654e-3,224.002,25.00,18.8517,6.58209e-5,0.0266510,20.0219,8.19475e-3,224.002,4.48384,0.834556
0.0863230,52.5671,1.63365e-3,226.296,25.00,19.5411,6.53045e-5,0.0276256,20.0292,7.07166e-3,226.296,4.88145,0.914665
0.0925112,57.4634,1.62299e-3,228.524,24.99,20.4370,6.48778e-5,0.0288921,20.0269,6.18919e-3,228.524,5.23138,0.999861
0.101663,62.9828,1.60958e-3,230.818,25.01,20.5136,6.43409e-5,0.0290004,20.0256,5.17127e-3,230.818,5.74890,1.09590
0.110130,69.0277,1.59649e-3,233.112,25.00,19.6767,6.38169e-5,0.0278172,20.0329,4.12957e-3,233.112,6.22771,1.20108
0.119737,75.4573,1.58847e-3,235.340,24.99,19.3525,6.34957e-5,0.0273590,20.0335,3.39888e-3,235.340,6.77099,1.31295
0.130425,82.7060,1.57693e-3,237.634,25.00,18.4744,6.30336e-5,0.0261175,20.0362,2.70082e-3,237.634,7.37534,1.43908
0.142195,90.6432,1.56872e-3,239.927,24.99,19.9292,6.27051e-5,0.0281742,20.0216,2.42560e-3,239.927,8.04095,1.57719
0.154275,99.0864,1.56090e-3,242.156,25.00,19.8319,6.23918e-5,0.0280367,20.0287,2.01993e-3,242.156,8.72405,1.72410
0.168861,108.605,1.55320e-3,244.449,24.99,20.1787,6.20836e-5,0.0285269,20.0310,1.71078e-3,244.449,9.54887,1.88972
0.184104,119.027,1.54666e-3,246.743,24.99,19.4787,6.18218e-5,0.0275374,20.0294,1.37489e-3,246.743,10.4109,2.07107
0.200233,130.115,1.54204e-3,248.971,25.00,18.9349,6.16369e-5,0.0267686,20.0250,1.11843e-3,248.971,11.3229,2.26400
0.219097,142.614,1.53725e-3,251.265,25.00,18.7824,6.14451e-5,0.0265530,20.0239,9.23487e-4,251.265,12.3897,2.48147
0.239646,156.301,1.53311e-3,253.559,24.99,19.7175,6.12792e-5,0.0278749,20.0308,8.07101e-4,253.559,13.5517,2.71963
0.261612,170.859,1.53061e-3,255.787,24.99,19.6889,6.11788e-5,0.0278345,20.0342,6.74442e-4,255.787,14.7938,2.97294
0.285810,187.273,1.52804e-3,258.081,25.00,18.6857,6.10758e-5,0.0264164,20.0347,5.32797e-4,258.081,16.1622,3.25854
0.313210,205.245,1.52631e-3,260.375,24.99,18.0859,6.10065e-5,0.0255683,20.0179,4.29335e-4,260.375,17.7116,3.57125
0.341841,224.363,1.52492e-3,262.603,24.99,16.9883,6.09508e-5,0.0240167,20.0267,3.37480e-4,262.603,19.3307,3.90391
0.374940,245.915,1.52467e-3,264.897,24.99,18.5682,6.09407e-5,0.0262502,20.0349,3.07043e-4,264.897,21.2024,4.27892
0.410765,269.516,1.52477e-3,267.190,25.00,17.9677,6.09446e-5,0.0254012,20.0402,2.47356e-4,267.190,23.2282,4.68957
0.449289,294.622,1.52569e-3,269.419,25.00,17.1516,6.09811e-5,0.0242476,20.0225,1.97595e-4,269.419,25.4067,5.12640
0.492943,322.922,1.52702e-3,271.712,25.00,14.8829,6.10340e-5,0.0210402,20.0280,1.42722e-4,271.712,27.8753,5.61883
0.540882,353.914,1.52912e-3,274.006,25.00,14.2574,6.11179e-5,0.0201560,20.0303,1.13827e-4,274.006,30.5861,6.15808
0.592408,386.880,1.53176e-3,276.234,25.00,14.9833,6.12233e-5,0.0211821,20.0262,1.00105e-4,276.234,33.4999,6.73170
0.650684,424.043,1.53508e-3,278.528,24.99,14.1518,6.13558e-5,0.0200066,20.0349,7.87031e-5,278.528,36.7953,7.37833
0.715001,464.739,1.53919e-3,280.822,25.00,11.9186,6.15199e-5,0.0168495,20.0188,5.51831e-5,280.822,40.4324,8.08645
0.783852,508.029,1.54369e-3,283.050,25.00,7.98266,6.16996e-5,0.0112852,20.0152,3.09294e-5,283.050,44.3258,8.83968
0.862312,556.829,1.54905e-3,285.344,25.00,4.80680,6.19139e-5,6.79546e-3,20.0148,1.55029e-5,285.344,48.7626,9.68881
0.948535,610.270,1.55505e-3,287.638,24.99,3.17945,6.21538e-5,4.49484e-3,20.0179,8.53705e-6,287.638,53.6384,10.6187
1.04138,667.114,1.56157e-3,289.866,25.00,0.526654,6.24143e-5,7.44539e-4,20.0078,1.18338e-6,289.866,58.8887,11.6078
1.14665,731.197,1.56908e-3,292.160,24.99,-3.17026,6.27143e-5,-4.48185e-3,20.0158,-5.92960e-6,292.160,64.8418,12.7228
1.26322,801.375,1.57757e-3,294.453,24.99,-10.4891,6.30535e-5,-0.0148286,20.0170,-1.63330e-5,294.453,71.4334,13.9439
1.38916,876.018,1.58622e-3,296.681,25.00,-17.9548,6.33994e-5,-0.0253830,20.0182,-2.33967e-5,296.681,78.5554,15.2427
1.52407,955.075,1.59563e-3,298.844,24.99,-24.8511,6.37752e-5,-0.0351324,20.0190,-2.72440e-5,298.844,86.1844,16.6183