File: Dago_s/esp_4_FR.csv
Filename,esp_4
Instrument name,5333-0457
Operator,Osamu Katagiri
rundate,31/01/2020
Sample name,ESP_4
Geometry name,60mm 0.9969° cone plate, Peltier plate Steel
Procedure name,Sample
,Flow ramp
,Temperature ramp
,Sample
proceduresegments,Flow ramp#Temperature ramp
[step]
Flow ramp - 1
Stress,Shear rate,Viscosity,Step time,Temperature,Normal stress,Modulus
Pa,1/s,Pa.s,s,°C,Pa,Pa
7.40954e-4,7.07284e-3,0.0290372,3.48115,25.05,43.5978,0.0395538
7.82484e-4,7.81037e-3,0.0279829,5.83274,25.03,43.1967,0.0242054
8.24458e-4,8.54360e-3,0.0268476,8.06096,25.03,41.1945,0.0170481
8.57390e-4,9.37318e-3,0.0256063,10.3547,25.01,41.9641,0.0121192
8.83266e-4,0.0102803,0.0244586,12.6485,24.99,41.3464,9.39830e-3
8.99618e-4,0.0112287,0.0232245,14.8767,25.00,41.8340,7.67373e-3
9.26223e-4,0.0123057,0.0221507,17.1705,24.99,41.3763,6.38378e-3
9.51513e-4,0.0134887,0.0210954,19.4642,24.98,42.0621,5.42992e-3
9.68650e-4,0.0147499,0.0200606,21.6924,24.97,41.4633,4.70482e-3
1.00221e-3,0.0161628,0.0189360,23.9862,24.98,40.9480,4.10487e-3
1.01377e-3,0.0177249,0.0179806,26.2800,24.97,41.8677,3.60167e-3
1.03353e-3,0.0193693,0.0170733,28.5082,24.97,40.5917,3.20455e-3
1.04524e-3,0.0212390,0.0161879,30.8020,24.96,40.7052,2.83956e-3
1.07362e-3,0.0232656,0.0153030,33.0957,24.97,40.6288,2.54102e-3
1.07733e-3,0.0254396,0.0145094,35.3239,24.97,40.4723,2.29268e-3
1.10675e-3,0.0278997,0.0139207,37.6177,24.96,39.2723,2.07081e-3
1.13867e-3,0.0305679,0.0131988,39.9115,24.97,39.2268,1.87964e-3
1.15583e-3,0.0333896,0.0124773,42.1397,24.98,39.1700,1.72085e-3
1.18889e-3,0.0366019,0.0119004,44.4334,24.97,39.0332,1.57080e-3
1.21074e-3,0.0401143,0.0112388,46.7272,24.97,39.0062,1.42674e-3
1.23184e-3,0.0438614,0.0106665,48.9554,24.98,38.7506,1.30773e-3
1.22139e-3,0.0480733,0.0101734,51.2492,24.98,38.5457,1.19944e-3
1.26848e-3,0.0527266,9.70300e-3,53.5429,24.98,38.8409,1.10058e-3
1.31581e-3,0.0575495,9.29555e-3,55.7712,24.98,38.1795,1.01528e-3
1.33739e-3,0.0629925,8.91840e-3,58.0649,24.98,38.0972,9.44312e-4
1.35881e-3,0.0691370,8.46840e-3,60.3587,24.98,37.8768,8.78581e-4
1.41306e-3,0.0757530,8.17303e-3,62.6524,24.98,37.2971,8.21602e-4
1.47979e-3,0.0830130,7.87629e-3,64.9462,24.98,37.6526,7.65706e-4
1.55313e-3,0.0907857,7.59033e-3,67.1744,24.98,37.3734,7.22436e-4
1.54456e-3,0.0995604,7.19670e-3,69.4682,24.99,36.8814,6.79390e-4
1.65216e-3,0.109133,7.01797e-3,71.7620,24.98,37.5089,6.43499e-4
1.69851e-3,0.119291,6.76317e-3,73.9902,24.98,36.4805,6.01019e-4
1.83589e-3,0.130501,6.52728e-3,76.2839,24.99,36.9122,5.70974e-4
1.77613e-3,0.143447,6.32762e-3,78.5777,24.99,36.7980,5.44067e-4
1.92173e-3,0.156662,6.17048e-3,80.8059,24.99,36.2731,5.15257e-4
2.11373e-3,0.171534,5.97290e-3,83.0997,24.99,36.0525,4.91539e-4
2.06718e-3,0.188114,5.75605e-3,85.3934,24.98,36.5393,4.72839e-4
2.32501e-3,0.205690,5.55528e-3,87.6217,24.99,36.9170,4.49915e-4
2.35045e-3,0.225446,5.37475e-3,89.9154,24.99,35.5754,4.25261e-4
2.38690e-3,0.247517,5.24386e-3,92.2092,24.98,35.8278,4.06728e-4
2.55315e-3,0.269824,5.07595e-3,94.4374,25.00,36.9078,3.87987e-4
2.65911e-3,0.296072,4.95722e-3,96.7312,24.99,36.2214,3.73447e-4
2.89080e-3,0.324719,4.79849e-3,99.0249,24.99,35.9323,3.55989e-4
3.10287e-3,0.354855,4.67932e-3,101.253,24.99,36.4908,3.42721e-4
2.99706e-3,0.389306,4.52279e-3,103.547,24.99,36.1772,3.29595e-4
3.33962e-3,0.425926,4.48283e-3,105.841,24.98,36.2410,3.16048e-4
3.48670e-3,0.465823,4.39094e-3,108.069,25.00,35.8728,3.02358e-4
3.70681e-3,0.510952,4.27557e-3,110.363,24.99,35.9331,2.96551e-4
3.93889e-3,0.559700,4.18793e-3,112.656,24.99,35.8886,2.87993e-4
4.31847e-3,0.612040,4.10210e-3,114.885,25.00,34.5368,2.78120e-4
4.56551e-3,0.670436,4.01802e-3,117.178,24.99,34.8216,2.71556e-4
4.63003e-3,0.735267,3.93566e-3,119.472,25.00,35.4834,2.64640e-4
5.20493e-3,0.803565,3.88936e-3,121.700,24.99,35.5399,2.56189e-4
5.48528e-3,0.880770,3.81528e-3,123.994,24.99,35.3885,2.48955e-4
5.79272e-3,0.965269,3.73708e-3,126.288,24.99,35.7101,2.43957e-4
6.25632e-3,1.05475,3.67676e-3,128.516,24.99,34.8157,2.37116e-4
6.61441e-3,1.15679,3.61563e-3,130.810,25.00,34.6294,2.30843e-4
7.11549e-3,1.26757,3.54327e-3,133.104,24.99,35.0328,2.25733e-4
7.58553e-3,1.38568,3.49124e-3,135.332,24.99,34.4830,2.20362e-4
8.17727e-3,1.51903,3.41463e-3,137.626,25.00,34.7279,2.14630e-4
8.74503e-3,1.66468,3.34464e-3,139.919,24.99,34.5942,2.08875e-4
9.15420e-3,1.81965,3.26318e-3,142.148,24.99,34.8810,2.03086e-4
9.80572e-3,1.99395,3.17431e-3,144.441,24.99,35.1367,1.96692e-4
0.0103765,2.18630,3.11078e-3,146.735,25.00,34.5390,1.89860e-4
0.0109972,2.38948,3.05153e-3,148.963,24.99,33.5290,1.84290e-4
0.0115761,2.61928,2.99784e-3,151.257,24.99,34.2937,1.78829e-4
0.0124073,2.87020,2.97135e-3,153.551,24.99,34.4087,1.74253e-4
0.0133151,3.13817,2.91907e-3,155.779,25.00,34.0998,1.70745e-4
0.0143730,3.43921,2.88900e-3,158.073,24.99,32.8686,1.67622e-4
0.0156529,3.76901,2.86347e-3,160.367,25.00,33.7685,1.64584e-4
0.0166356,4.12041,2.84237e-3,162.595,25.00,33.6139,1.62064e-4
0.0178460,4.51610,2.82142e-3,164.889,24.99,32.7312,1.59849e-4
0.0194209,4.94959,2.80063e-3,167.182,25.00,32.2252,1.57619e-4
0.0211443,5.41066,2.75951e-3,169.411,24.99,32.2149,1.56218e-4
0.0229830,5.93050,2.73243e-3,171.704,24.99,32.5068,1.54387e-4
0.0250883,6.49954,2.68700e-3,173.998,24.99,31.6551,1.51740e-4
0.0264922,7.10504,2.64754e-3,176.226,24.99,32.4040,1.48894e-4
0.0280685,7.78741,2.61640e-3,178.520,25.00,31.8660,1.45887e-4
0.0302762,8.53489,2.59328e-3,180.814,24.99,31.6722,1.42933e-4
0.0327758,9.35478,2.57798e-3,183.108,25.00,31.6769,1.41065e-4
0.0357635,10.2525,2.57798e-3,185.401,24.99,32.0568,1.40042e-4
0.0391524,11.2076,2.56277e-3,187.630,25.00,31.2389,1.38967e-4
0.0427070,12.2839,2.52514e-3,189.923,24.99,31.3981,1.37829e-4
0.0459382,13.4630,2.48438e-3,192.217,24.99,31.3461,1.36287e-4
0.0495168,14.7171,2.44790e-3,194.445,24.99,32.0559,1.33973e-4
0.0532470,16.1310,2.40839e-3,196.739,25.00,32.5235,1.31146e-4
0.0565907,17.6793,2.38711e-3,199.033,25.00,31.9884,1.28652e-4
0.0604758,19.3256,2.35903e-3,201.261,25.00,31.3297,1.26163e-4
0.0657518,21.1823,2.34858e-3,203.555,24.99,30.0698,1.24005e-4
0.0706826,23.2149,2.31067e-3,205.849,24.99,30.3980,1.22409e-4
0.0769477,25.3774,2.29704e-3,208.077,24.99,31.2432,1.21019e-4
0.0835093,27.8154,2.27674e-3,210.371,25.00,31.8514,1.19189e-4
0.0899993,30.4849,2.24996e-3,212.664,24.99,31.1946,1.17484e-4
0.0959316,33.3240,2.22678e-3,214.893,24.99,30.2480,1.15903e-4
0.103588,36.5255,2.20384e-3,217.186,24.99,29.9896,1.14289e-4
0.113220,40.0307,2.18114e-3,219.480,24.99,30.0245,1.12501e-4
0.122609,43.7598,2.15867e-3,221.708,24.99,31.7638,1.11058e-4
0.130960,47.9632,2.14594e-3,224.002,24.99,31.4861,1.09855e-4
0.141669,52.5660,2.12383e-3,226.296,24.99,29.5517,1.08394e-4
0.154467,57.4629,2.11442e-3,228.524,24.99,29.9888,1.06862e-4
0.166733,62.9829,2.08955e-3,230.818,24.99,29.9119,1.05616e-4
0.179880,69.0272,2.06803e-3,233.112,24.99,31.3338,1.04626e-4
0.194432,75.4572,2.04975e-3,235.340,24.98,31.0035,1.03179e-4
0.212790,82.7053,2.03665e-3,237.634,25.00,31.4100,1.01952e-4
0.226961,90.6426,2.00774e-3,239.927,24.99,29.0926,1.00650e-4
0.247274,99.0858,1.98705e-3,242.156,24.99,28.9764,9.94267e-5
0.265599,108.604,1.97533e-3,244.449,25.00,29.6127,9.80245e-5
0.288057,119.027,1.96658e-3,246.743,24.99,29.9359,9.69221e-5
0.312100,130.114,1.94345e-3,248.971,25.00,29.3642,9.57414e-5
0.337696,142.613,1.93771e-3,251.265,24.99,27.9929,9.47102e-5
0.366388,156.300,1.91775e-3,253.559,25.00,27.3512,9.37265e-5
0.396087,170.859,1.89518e-3,255.787,24.99,28.9925,9.27429e-5
0.430424,187.271,1.88679e-3,258.081,25.00,29.1096,9.18141e-5
0.466463,205.244,1.87844e-3,260.375,25.00,28.0160,9.09034e-5
0.505516,224.363,1.86460e-3,262.603,24.99,26.7287,9.00674e-5
0.548725,245.914,1.85634e-3,264.897,25.00,26.1692,8.92176e-5
0.595938,269.514,1.83722e-3,267.190,25.00,26.5817,8.84573e-5
0.646187,294.620,1.82638e-3,269.419,25.00,25.2770,8.77175e-5
0.703499,322.919,1.82368e-3,271.712,24.99,24.6395,8.70282e-5
0.763898,353.912,1.81829e-3,274.006,24.99,21.8393,8.64082e-5
0.830286,386.878,1.81829e-3,276.234,24.99,21.4950,8.58935e-5
0.905049,424.042,1.81829e-3,278.528,25.00,19.7933,8.57192e-5
0.988585,464.738,1.80756e-3,280.822,24.99,20.5787,8.54411e-5
1.09596,508.026,1.80756e-3,283.050,25.00,19.6698,8.52194e-5
1.18259,556.829,1.80222e-3,285.344,25.00,15.6017,8.49802e-5
1.29260,610.267,1.79956e-3,287.638,24.99,12.4362,8.46981e-5
1.40414,667.114,1.79690e-3,289.866,25.00,7.46394,8.41468e-5
1.53034,731.194,1.79690e-3,292.160,25.00,5.05730,8.40755e-5
1.67213,801.370,1.78894e-3,294.453,24.99,-0.855376,8.39810e-5
1.85313,876.015,,296.681,25.00,-7.84060,8.43091e-5
1.99834,955.073,,298.844,25.00,-17.3799,8.36281e-5