File: Dago_s/esp_2_FR.csv
Filename,esp_2
Instrument name,5333-0457
Operator,Osamu Katagiri
rundate,31/01/2020
Sample name,ESP_2
Geometry name,60mm 0.9969° cone plate, Peltier plate Steel
Procedure name,Sample
,Flow ramp
,Temperature ramp
,Sample
proceduresegments,Flow ramp#Temperature ramp
[step]
Flow ramp - 1
Stress,Shear rate,Viscosity,Step time,Temperature,Normal stress,Modulus,Axial force,Gap,Normal stress coefficient,Time,Torque,Velocity
Pa,1/s,Pa.s,s,°C,Pa,Pa,N,µm,Pa.s²,s,µN.m,rad/s
7.26090e-3,6.45388e-3,,1.11759,25.07,11.8686,,0.0167788,23.0405,284943,1.11759,0.410594,1.12297e-4
6.80827e-4,6.99954e-3,0.0975065,3.53898,25.06,11.0049,0.0286018,0.0155578,23.0282,224620,3.53898,0.0384999,1.21792e-4
7.41439e-4,7.75509e-3,0.0949322,5.83274,25.04,10.1115,0.0195122,0.0142948,23.0195,168129,5.83274,0.0419274,1.34938e-4
7.91016e-4,8.53240e-3,0.0922050,8.06096,25.04,9.87103,0.0145498,0.0139548,23.0234,135588,8.06096,0.0447309,1.48463e-4
8.36382e-4,9.37052e-3,0.0889740,10.3547,25.02,9.87760,0.0110628,0.0139641,23.0221,112493,10.3547,0.0472963,1.63047e-4
8.93844e-4,0.0102772,0.0853774,12.6485,25.01,9.25041,8.92734e-3,0.0130775,23.0234,87580.8,12.6485,0.0505457,1.78823e-4
9.13399e-4,0.0112243,0.0818416,14.8767,25.01,8.58011,7.50880e-3,0.0121298,23.0260,68104.4,14.8767,0.0516515,1.95302e-4
9.57776e-4,0.0123033,0.0783823,17.1705,24.99,7.94228,6.44352e-3,0.0112281,23.0273,52468.8,17.1705,0.0541610,2.14077e-4
1.00328e-3,0.0134833,0.0752286,19.4642,24.99,7.38537,5.65354e-3,0.0104408,23.0248,40623.8,19.4642,0.0567341,2.34609e-4
1.06344e-3,0.0147404,0.0724153,21.6924,24.99,6.98840,5.05806e-3,9.87962e-3,23.0241,32163.2,21.6924,0.0601362,2.56482e-4
1.14727e-3,0.0161657,0.0698312,23.9862,24.98,6.87464,4.57348e-3,9.71879e-3,23.0313,26306.2,23.9862,0.0648768,2.81283e-4
1.18642e-3,0.0177102,0.0672473,26.2800,24.97,5.91382,4.17075e-3,8.36047e-3,23.0253,18854.7,26.2800,0.0670905,3.08157e-4
1.26068e-3,0.0193608,0.0643426,28.5082,24.98,5.67478,3.81108e-3,8.02253e-3,23.0313,15139.2,28.5082,0.0712897,3.36877e-4
1.30944e-3,0.0212207,0.0609139,30.8020,24.98,4.94757,3.46094e-3,6.99446e-3,23.0295,10986.9,30.8020,0.0740473,3.69239e-4
1.33889e-3,0.0232738,0.0573814,33.0957,24.97,4.23212,3.14337e-3,5.98302e-3,23.0269,7813.11,33.0957,0.0757124,4.04963e-4
1.37678e-3,0.0254349,0.0539106,35.3239,24.97,4.24577,2.86346e-3,6.00231e-3,23.0313,6562.92,35.3239,0.0778552,4.42566e-4
1.39332e-3,0.0278804,0.0503015,37.6177,24.97,2.89623,2.59748e-3,4.09444e-3,23.0334,3725.92,37.6177,0.0787902,4.85119e-4
1.44356e-3,0.0305745,0.0467044,39.9115,24.97,2.88199,2.35131e-3,4.07432e-3,23.0290,3083.01,39.9115,0.0816314,5.31994e-4
1.46376e-3,0.0334343,0.0431031,42.1397,24.98,3.00945,2.12297e-3,4.25451e-3,23.0326,2692.18,42.1397,0.0827734,5.81755e-4
1.46306e-3,0.0366294,0.0395898,44.4334,24.97,2.11850,1.91144e-3,2.99496e-3,23.0330,1578.95,44.4334,0.0827339,6.37350e-4
1.44347e-3,0.0401397,0.0362505,46.7272,24.98,1.88710,1.71889e-3,2.66782e-3,23.0260,1171.24,46.7272,0.0816264,6.98429e-4
1.43710e-3,0.0438940,0.0332502,48.9554,24.98,0.774743,1.55154e-3,1.09527e-3,23.0329,402.113,48.9554,0.0812663,7.63754e-4
1.46837e-3,0.0480992,0.0305730,51.2492,24.97,-0.189184,1.40530e-3,-2.67453e-4,23.0317,-81.7727,51.2492,0.0830344,8.36925e-4
1.48625e-3,0.0526911,0.0283491,53.5429,24.99,-0.742998,1.28576e-3,-1.05039e-3,23.0303,-267.616,53.5429,0.0840456,9.16824e-4
1.51841e-3,0.0575055,0.0264644,55.7712,24.98,-0.222693,1.18620e-3,-3.14825e-4,23.0326,-67.3423,55.7712,0.0858638,1.00059e-3
1.55933e-3,0.0630621,0.0245085,58.0649,24.99,-1.42967,1.08647e-3,-2.02115e-3,23.0313,-359.501,58.0649,0.0881780,1.09728e-3
1.58311e-3,0.0690790,0.0227481,60.3587,24.98,-2.15931,9.98599e-4,-3.05266e-3,23.0290,-452.506,60.3587,0.0895228,1.20197e-3
1.58392e-3,0.0757791,0.0210325,62.6524,24.98,-1.89964,9.15490e-4,-2.68555e-3,23.0302,-330.805,62.6524,0.0895688,1.31855e-3
1.61443e-3,0.0830403,0.0195330,64.9462,24.99,-2.89802,8.43514e-4,-4.09698e-3,23.0292,-420.266,64.9462,0.0912941,1.44490e-3
1.62865e-3,0.0908517,0.0181306,67.1744,24.98,-2.84945,7.77541e-4,-4.02832e-3,23.0340,-345.219,67.1744,0.0920978,1.58082e-3
1.70124e-3,0.0994632,0.0168850,69.4682,24.99,-2.70839,7.19607e-4,-3.82890e-3,23.0334,-273.771,69.4682,0.0962027,1.73066e-3
1.71210e-3,0.109010,0.0158090,71.7620,24.99,-3.67340,6.69966e-4,-5.19315e-3,23.0301,-309.125,71.7620,0.0968168,1.89677e-3
1.74555e-3,0.119311,0.0148916,73.9902,24.98,-4.45243,6.27588e-4,-6.29447e-3,23.0322,-312.776,73.9902,0.0987088,2.07601e-3
1.83504e-3,0.130811,0.0139143,76.2839,24.99,-5.44122,5.83646e-4,-7.69234e-3,23.0321,-317.987,76.2839,0.103769,2.27610e-3
1.89878e-3,0.143118,0.0130242,78.5777,24.98,-5.56447,5.44219e-4,-7.86658e-3,23.0313,-271.665,78.5777,0.107374,2.49025e-3
1.91552e-3,0.156603,0.0123152,80.8059,24.99,-6.21763,5.12486e-4,-8.78996e-3,23.0313,-253.527,80.8059,0.108320,2.72489e-3
1.93227e-3,0.171922,0.0115253,83.0997,24.99,-7.29903,4.77905e-4,-0.0103188,23.0291,-246.946,83.0997,0.109267,2.99144e-3
2.07267e-3,0.188064,0.0108021,85.3934,24.99,-7.19903,4.46587e-4,-0.0101774,23.0313,-203.545,85.3934,0.117207,3.27231e-3
2.09279e-3,0.205937,0.0101098,87.6217,24.99,-7.73203,4.16732e-4,-0.0109309,23.0340,-182.316,87.6217,0.118345,3.58330e-3
2.15471e-3,0.225486,9.53619e-3,89.9154,24.99,-8.21407,3.91916e-4,-0.0116124,23.0286,-161.555,89.9154,0.121846,3.92345e-3
2.16703e-3,0.247090,8.94285e-3,92.2092,24.99,-8.20900,3.66672e-4,-0.0116052,23.0276,-134.456,92.2092,0.122543,4.29936e-3
2.26967e-3,0.270137,8.45206e-3,94.4374,25.00,-8.58820,3.45706e-4,-0.0121413,23.0306,-117.689,94.4374,0.128347,4.70037e-3
2.37255e-3,0.296134,8.01437e-3,96.7312,24.99,-9.44646,3.27184e-4,-0.0133546,23.0273,-107.719,96.7312,0.134164,5.15272e-3
2.47316e-3,0.324520,7.67673e-3,99.0249,24.99,-9.17422,3.12773e-4,-0.0129697,23.0296,-87.1135,99.0249,0.139854,5.64664e-3
2.60931e-3,0.355088,7.38819e-3,101.253,25.00,-9.17470,3.00513e-4,-0.0129704,23.0285,-72.7643,101.253,0.147553,6.17853e-3
2.75435e-3,0.388559,7.04017e-3,103.547,24.99,-9.88854,2.85951e-4,-0.0139796,23.0256,-65.4966,103.547,0.155755,6.76091e-3
2.94859e-3,0.426173,6.71241e-3,105.841,25.00,-10.4940,2.72251e-4,-0.0148356,23.0234,-57.7791,105.841,0.166739,7.41539e-3
2.92927e-3,0.466200,6.42069e-3,108.069,24.99,-11.2058,2.60057e-4,-0.0158418,23.0209,-51.5581,108.069,0.165646,8.11186e-3
3.08038e-3,0.510661,6.10785e-3,110.363,24.99,-11.3608,2.47148e-4,-0.0160609,23.0280,-43.5655,110.363,0.174191,8.88549e-3
3.28235e-3,0.559841,5.76222e-3,112.656,24.99,-11.2159,2.32930e-4,-0.0158561,23.0414,-35.7853,112.656,0.185612,9.74122e-3
3.38165e-3,0.611984,5.52851e-3,114.885,25.00,-11.5315,2.23232e-4,-0.0163022,23.0335,-30.7896,114.885,0.191228,0.0106485
3.47970e-3,0.670844,5.24918e-3,117.178,25.00,-12.8927,2.11768e-4,-0.0182266,23.0269,-28.6484,117.178,0.196772,0.0116727
3.73496e-3,0.734838,4.97349e-3,119.472,24.99,-11.5408,2.00473e-4,-0.0163155,23.0255,-21.3724,119.472,0.211207,0.0127861
3.75171e-3,0.803537,4.73403e-3,121.700,25.00,-13.5163,1.90680e-4,-0.0191083,23.0221,-20.9338,121.700,0.212154,0.0139815
3.94825e-3,0.880666,4.54692e-3,123.994,24.99,-13.7965,1.82999e-4,-0.0195043,23.0330,-17.7888,123.994,0.223268,0.0153235
4.14715e-3,0.965362,4.33518e-3,126.288,24.99,-14.0360,1.74396e-4,-0.0198429,23.0352,-15.0613,126.288,0.234516,0.0167973
4.48630e-3,1.05486,4.19436e-3,128.516,25.00,-14.3379,1.68641e-4,-0.0202697,23.0329,-12.8854,128.516,0.253694,0.0183545
4.64272e-3,1.15713,4.07167e-3,130.810,24.99,-14.8459,1.63614e-4,-0.0209878,23.0315,-11.0877,130.810,0.262540,0.0201340
4.99433e-3,1.26766,3.94045e-3,133.104,24.99,-15.1984,1.58273e-4,-0.0214862,23.0292,-9.45778,133.104,0.282423,0.0220573
5.37154e-3,1.38516,3.81744e-3,135.332,24.99,-15.6328,1.53275e-4,-0.0221003,23.0246,-8.14778,135.332,0.303754,0.0241017
5.54690e-3,1.51919,3.73535e-3,137.626,24.99,-16.4472,1.49909e-4,-0.0232516,23.0197,-7.12632,137.626,0.313670,0.0264339
6.01437e-3,1.66440,3.63753e-3,139.919,25.00,-16.5013,1.45930e-4,-0.0233282,23.0156,-5.95665,139.919,0.340105,0.0289605
6.56786e-3,1.81983,3.53172e-3,142.148,24.99,-17.0148,1.41654e-4,-0.0240541,23.0113,-5.13764,142.148,0.371404,0.0316650
6.88733e-3,1.99447,3.45457e-3,144.441,24.99,-17.8930,1.38507e-4,-0.0252957,23.0221,-4.49809,144.441,0.389469,0.0347037
7.29574e-3,2.18617,3.36946e-3,146.735,24.99,-18.3554,1.35059e-4,-0.0259494,23.0278,-3.84058,146.735,0.412564,0.0380393
7.82172e-3,2.38912,3.26948e-3,148.963,24.99,-17.9340,1.31022e-4,-0.0253536,23.0352,-3.14198,148.963,0.442308,0.0415705
8.36899e-3,2.61887,3.17665e-3,151.257,25.00,-18.3188,1.27269e-4,-0.0258976,23.0289,-2.67097,151.257,0.473255,0.0455683
8.87976e-3,2.87092,3.09562e-3,153.551,25.00,-18.3386,1.23994e-4,-0.0259256,23.0294,-2.22496,153.551,0.502139,0.0499540
9.39747e-3,3.13740,3.01515e-3,155.779,24.99,-19.2932,1.20755e-4,-0.0272751,23.0370,-1.96003,155.779,0.531414,0.0545907
0.0101063,3.43925,2.93137e-3,158.073,24.99,-18.9782,1.17381e-4,-0.0268298,23.0449,-1.60445,158.073,0.571497,0.0598429
0.0107784,3.76969,2.85875e-3,160.367,24.99,-20.6044,1.14449e-4,-0.0291288,23.0225,-1.44994,160.367,0.609505,0.0655924
0.0114579,4.12043,2.79679e-3,162.595,24.99,-20.3905,1.11958e-4,-0.0288263,23.0177,-1.20099,162.595,0.647928,0.0716954
0.0123396,4.51592,2.72985e-3,164.889,24.99,-21.3459,1.09262e-4,-0.0301770,23.0148,-1.04670,164.889,0.697791,0.0785768
0.0132504,4.95026,2.66196e-3,167.182,24.99,-20.4044,1.06530e-4,-0.0288461,23.0177,-0.832661,167.182,0.749293,0.0861343
0.0141030,5.41020,2.59561e-3,169.411,24.99,-21.2785,1.03864e-4,-0.0300818,23.0234,-0.726968,169.411,0.797507,0.0941372
0.0149746,5.93069,2.52609e-3,171.704,25.00,-22.3489,1.01073e-4,-0.0315950,23.0265,-0.635399,171.704,0.846792,0.103194
0.0158781,6.49967,2.46033e-3,173.998,24.99,-22.8582,9.84300e-5,-0.0323150,23.0370,-0.541076,173.998,0.897885,0.113094
0.0169823,7.10506,2.40154e-3,176.226,25.00,-23.2055,9.60718e-5,-0.0328059,23.0395,-0.459679,176.226,0.960326,0.123628
0.0182953,7.78753,2.35035e-3,178.520,24.99,-22.5523,9.40160e-5,-0.0318826,23.0282,-0.371871,178.520,1.03458,0.135503
0.0196586,8.53488,2.31587e-3,180.814,24.99,-22.4247,9.26299e-5,-0.0317022,23.0331,-0.307845,180.814,1.11167,0.148507
0.0212249,9.35481,2.29603e-3,183.108,25.00,-22.4183,9.18305e-5,-0.0316931,23.0217,-0.256173,183.108,1.20024,0.162773
0.0232735,10.2525,2.29100e-3,185.401,24.99,-23.3369,9.16234e-5,-0.0329917,23.0092,-0.222014,185.401,1.31608,0.178394
0.0256657,11.2077,2.30324e-3,187.630,25.00,-23.6251,9.21085e-5,-0.0333992,23.0202,-0.188080,187.630,1.45136,0.195013
0.0285340,12.2839,2.32426e-3,189.923,24.99,-22.5295,9.29443e-5,-0.0318504,23.0260,-0.149306,189.923,1.61356,0.213740
0.0318722,13.4631,2.33979e-3,192.217,24.99,-22.2895,9.35612e-5,-0.0315110,23.0347,-0.122973,192.217,1.80233,0.234257
0.0349208,14.7173,2.34110e-3,194.445,24.99,-23.2147,9.36097e-5,-0.0328190,23.0313,-0.107178,194.445,1.97473,0.256081
0.0378427,16.1308,2.32614e-3,196.739,24.99,-23.4296,9.30089e-5,-0.0331228,23.0210,-0.0900440,196.739,2.13995,0.280675
0.0406071,17.6791,2.28812e-3,199.033,24.99,-24.3315,9.14853e-5,-0.0343978,23.0186,-0.0778477,199.033,2.29628,0.307616
0.0434851,19.3262,2.24271e-3,201.261,24.99,-23.9194,8.96668e-5,-0.0338153,23.0409,-0.0640412,201.261,2.45903,0.336275
0.0462334,21.1821,2.20107e-3,203.555,24.99,-24.1905,8.79998e-5,-0.0341985,23.0258,-0.0539146,203.555,2.61444,0.368568
0.0497047,23.2151,2.17517e-3,205.849,25.00,-25.2241,8.69618e-5,-0.0356598,23.0414,-0.0468030,205.849,2.81074,0.403943
0.0542851,25.3775,2.15961e-3,208.077,25.00,-25.2549,8.63373e-5,-0.0357033,23.0205,-0.0392147,208.077,3.06975,0.441568
0.0602483,27.8152,2.14969e-3,210.371,24.99,-24.7278,8.59393e-5,-0.0349581,23.0286,-0.0319610,210.371,3.40696,0.483984
0.0661377,30.4848,2.13629e-3,212.664,25.00,-24.6896,8.54020e-5,-0.0349040,23.0211,-0.0265672,212.664,3.74000,0.530435
0.0710824,33.3246,2.12148e-3,214.893,24.99,-25.0173,8.48084e-5,-0.0353674,23.0283,-0.0225274,214.893,4.01961,0.579846
0.0758283,36.5257,2.10541e-3,217.186,24.99,-25.4466,8.41645e-5,-0.0359743,23.0371,-0.0190736,217.186,4.28799,0.635546
0.0825994,40.0308,2.08321e-3,219.480,24.99,-25.0040,8.32758e-5,-0.0353486,23.0340,-0.0156034,219.480,4.67089,0.696535
0.0913253,43.7597,2.06092e-3,221.708,24.99,-24.3189,8.23834e-5,-0.0343801,23.0241,-0.0126998,221.708,5.16432,0.761417
0.0987213,47.9636,2.05170e-3,224.002,24.99,-25.4733,8.20139e-5,-0.0360120,23.0367,-0.0110729,224.002,5.58256,0.834565
0.106177,52.5666,2.04124e-3,226.296,25.00,-25.9370,8.15949e-5,-0.0366675,23.0347,-9.38642e-3,226.296,6.00419,0.914656
0.116692,57.4628,2.02129e-3,228.524,24.99,-25.2243,8.07968e-5,-0.0356600,23.0234,-7.63916e-3,228.524,6.59878,0.999850
0.126740,62.9831,2.00713e-3,230.818,24.99,-26.4183,8.02298e-5,-0.0373480,23.0313,-6.65974e-3,230.818,7.16696,1.09590
0.137027,69.0270,1.99472e-3,233.112,24.99,-27.1996,7.97331e-5,-0.0384526,23.0358,-5.70855e-3,233.112,7.74869,1.20107
0.150013,75.4577,1.98057e-3,235.340,24.99,-26.4208,7.91670e-5,-0.0373515,23.0165,-4.64021e-3,235.340,8.48304,1.31296
0.162029,82.7052,1.96535e-3,237.634,24.98,-25.9888,7.85579e-5,-0.0367408,23.0232,-3.79945e-3,237.634,9.16254,1.43907
0.177482,90.6434,1.95266e-3,239.927,24.99,-26.7336,7.80501e-5,-0.0377938,23.0246,-3.25376e-3,239.927,10.0364,1.57719
0.191921,99.0855,1.93895e-3,242.156,24.99,-26.6019,7.75017e-5,-0.0376075,23.0253,-2.70952e-3,242.156,10.8529,1.72408
0.208811,108.605,1.92785e-3,244.449,24.99,-28.6149,7.70577e-5,-0.0404534,23.0330,-2.42602e-3,244.449,11.8080,1.88972
0.228258,119.027,1.91440e-3,246.743,24.99,-28.0176,7.65197e-5,-0.0396089,23.0234,-1.97759e-3,246.743,12.9077,2.07107
0.247790,130.114,1.90293e-3,248.971,25.00,-27.4542,7.60608e-5,-0.0388125,23.0338,-1.62166e-3,248.971,14.0122,2.26399
0.269720,142.614,1.89143e-3,251.265,24.99,-26.7498,7.56010e-5,-0.0378166,23.0315,-1.31522e-3,251.265,15.2523,2.48147
0.293576,156.300,1.87916e-3,253.559,25.00,-28.8079,7.51103e-5,-0.0407262,23.0400,-1.17921e-3,253.559,16.6013,2.71962
0.318821,170.859,1.86738e-3,255.787,25.00,-29.5134,7.46389e-5,-0.0417236,23.0365,-1.01098e-3,255.787,18.0289,2.97294
0.347756,187.272,1.85604e-3,258.081,24.99,-31.1644,7.41856e-5,-0.0440576,23.0334,-8.88613e-4,258.081,19.6651,3.25853
0.378487,205.245,1.84488e-3,260.375,24.99,-30.4050,7.37392e-5,-0.0429840,23.0269,-7.21771e-4,260.375,21.4029,3.57125
0.411761,224.362,1.83515e-3,262.603,25.00,-30.1264,7.33502e-5,-0.0425902,23.0398,-5.98476e-4,262.603,23.2846,3.90390
0.448318,245.915,1.82515e-3,264.897,24.99,-31.5146,7.29502e-5,-0.0445527,23.0328,-5.21124e-4,264.897,25.3518,4.27892
0.489468,269.516,1.81616e-3,267.190,24.99,-33.4544,7.25907e-5,-0.0472951,23.0287,-4.60558e-4,267.190,27.6787,4.68957
0.532530,294.621,1.80837e-3,269.419,25.00,-34.3309,7.22790e-5,-0.0485342,23.0221,-3.95511e-4,269.419,30.1139,5.12639
0.581124,322.921,1.80131e-3,271.712,25.00,-34.1381,7.19967e-5,-0.0482616,23.0228,-3.27377e-4,271.712,32.8618,5.61881
0.635379,353.912,1.79535e-3,274.006,25.00,-34.6511,7.17587e-5,-0.0489868,23.0234,-2.76647e-4,274.006,35.9298,6.15806
0.691807,386.879,1.79048e-3,276.234,25.00,-35.9799,7.15637e-5,-0.0508654,23.0241,-2.40386e-4,276.234,39.1208,6.73169
0.757588,424.043,1.78678e-3,278.528,25.00,-39.2020,7.14159e-5,-0.0554206,23.0273,-2.18016e-4,278.528,42.8406,7.37833
0.828421,464.738,1.78370e-3,280.822,24.99,-41.6336,7.12925e-5,-0.0588581,23.0255,-1.92764e-4,280.822,46.8461,8.08643
0.904973,508.029,1.78258e-3,283.050,25.00,-43.1099,7.12477e-5,-0.0609452,23.0267,-1.67032e-4,283.050,51.1750,8.83968
0.991141,556.829,1.78137e-3,285.344,24.99,-45.0484,7.11994e-5,-0.0636857,23.0234,-1.45290e-4,285.344,56.0477,9.68880
1.08774,610.268,1.78114e-3,287.638,25.00,-48.2931,7.11902e-5,-0.0682728,23.0326,-1.29671e-4,287.638,61.5100,10.6186
1.18787,667.114,1.78155e-3,289.866,24.99,-53.9149,7.12062e-5,-0.0762203,23.0331,-1.21146e-4,289.866,67.1726,11.6078
1.30255,731.197,1.78278e-3,292.160,25.00,-59.6314,7.12553e-5,-0.0843018,23.0280,-1.11534e-4,292.160,73.6576,12.7228
1.42916,801.371,1.78420e-3,294.453,25.00,-64.9344,7.13121e-5,-0.0917989,23.0310,-1.01113e-4,294.453,80.8172,13.9438
1.56464,876.017,1.78638e-3,296.681,25.00,-69.7378,7.13993e-5,-0.0985895,23.0299,-9.08748e-5,296.681,88.4784,15.2427
1.70888,955.076,1.78916e-3,298.844,25.00,-75.3107,7.15103e-5,-0.106468,23.0352,-8.25620e-5,298.844,96.6346,16.6183