File: 9_characterizationRheology/csv/peo_su8_all_075.csv
Filename,peo_su8_all_075
Instrument name,5333-0457
Operator,Osamu Katagiri
rundate,29/01/2020
Sample name,PEO_SU8_01_075_0
Geometry name,60mm 0.9969° cone plate, Peltier plate Steel
Procedure name,Sample
,Flow ramp
proceduresegments,Flow ramp
[step]
Flow ramp - 1
Stress,Shear rate,Viscosity,Step time,Temperature,Normal stress,Axial force,Gap,Normal stress coefficient,Time,Torque,Velocity
Pa,1/s,Pa.s,s,°C,Pa,N,µm,Pa.s²,s,µN.m,rad/s
,4.28000e-3,4816.47,,,,,,,,,
17683.9,4.89000e-3,3942.80,1.00000,1.00,707.355,1.00000,1000000,2.95815e7,1.00000,1000000,1.00000
17683.9,4.95000e-3,4957.39,1.00000,1.00,707.355,1.00000,1000000,2.88687e7,1.00000,1000000,1.00000
17683.9,5.46000e-3,4052.92,1.00000,1.00,707.355,1.00000,1000000,2.37275e7,1.00000,1000000,1.00000
17683.9,5.71000e-3,4957.39,1.00000,1.00,707.355,1.00000,1000000,2.16953e7,1.00000,1000000,1.00000
17683.9,6.20000e-3,3986.30,1.00000,1.00,707.355,1.00000,1000000,1.84015e7,1.00000,1000000,1.00000
17683.9,6.66000e-3,4788.27,1.00000,1.00,707.355,1.00000,1000000,1.59474e7,1.00000,1000000,1.00000
17683.9,7.09000e-3,3737.97,1.00000,1.00,707.355,1.00000,1000000,1.40717e7,1.00000,1000000,1.00000
17683.9,7.33000e-3,4277.49,1.00000,1.00,707.355,1.00000,1000000,1.31653e7,1.00000,1000000,1.00000
17683.9,7.76000e-3,4260.29,1.00000,1.00,707.355,1.00000,1000000,1.17467e7,1.00000,1000000,1.00000
17683.9,7.85000e-3,4277.49,1.00000,1.00,707.355,1.00000,1000000,1.14788e7,1.00000,1000000,1.00000
17683.9,8.09000e-3,3505.11,1.00000,1.00,707.355,1.00000,1000000,1.08079e7,1.00000,1000000,1.00000
17683.9,8.26000e-3,4009.95,1.00000,1.00,707.355,1.00000,1000000,1.03676e7,1.00000,1000000,1.00000
17683.9,9.03000e-3,3782.41,1.00000,1.00,707.355,1.00000,1000000,8674850,1.00000,1000000,1.00000
17683.9,9.24000e-3,3535.86,1.00000,1.00,707.355,1.00000,1000000,8285020,1.00000,1000000,1.00000
17683.9,9.24000e-3,3256.70,1.00000,1.00,707.355,1.00000,1000000,8285020,1.00000,1000000,1.00000
17683.9,0.0103188,3149.99,1.00000,1.00,707.355,1.00000,1000000,6643230,1.00000,1000000,1.00000
17683.9,0.0105185,3347.36,1.00000,1.00,707.355,1.00000,1000000,6393370,1.00000,1000000,1.00000
17683.9,0.0105593,2964.73,1.00000,1.00,707.355,1.00000,1000000,6344060,1.00000,1000000,1.00000
17683.9,0.0115349,2811.11,1.00000,1.00,707.355,1.00000,1000000,5316310,1.00000,1000000,1.00000
17683.9,0.0120613,2633.61,1.00000,1.00,707.355,1.00000,1000000,4862390,1.00000,1000000,1.00000
17683.9,0.0122469,2959.17,1.00000,1.00,707.355,1.00000,1000000,4716120,1.00000,1000000,1.00000
17683.9,0.0129147,2521.87,1.00000,1.00,707.355,1.00000,1000000,4241010,1.00000,1000000,1.00000
17683.9,0.0137769,2346.65,1.00000,1.00,707.355,1.00000,1000000,3726790,1.00000,1000000,1.00000
17683.9,0.0142594,2596.45,1.00000,1.00,707.355,1.00000,1000000,3478850,1.00000,1000000,1.00000
17683.9,0.0144756,2269.01,1.00000,1.00,707.355,1.00000,1000000,3375700,1.00000,1000000,1.00000
17683.9,0.0157365,2050.79,1.00000,1.00,707.355,1.00000,1000000,2856420,1.00000,1000000,1.00000
17683.9,0.0161707,2052.53,1.00000,1.00,707.355,1.00000,1000000,2705080,1.00000,1000000,1.00000
17683.9,0.0166026,2268.44,1.00000,1.00,707.355,1.00000,1000000,2566170,1.00000,1000000,1.00000
17683.9,0.0179749,1759.59,1.00000,1.00,707.355,1.00000,1000000,2189300,1.00000,1000000,1.00000
17683.9,0.0181069,1855.56,1.00000,1.00,707.355,1.00000,1000000,2157490,1.00000,1000000,1.00000
17683.9,0.0193308,1952.35,1.00000,1.00,707.355,1.00000,1000000,1892940,1.00000,1000000,1.00000
17683.9,0.0202734,1679.16,1.00000,1.00,707.355,1.00000,1000000,1721010,1.00000,1000000,1.00000
17683.9,0.0205317,1498.99,1.00000,1.00,707.355,1.00000,1000000,1677980,1.00000,1000000,1.00000
17683.9,0.0225074,1662.39,1.00000,1.00,707.355,1.00000,1000000,1396330,1.00000,1000000,1.00000
17683.9,0.0227075,1520.51,1.00000,1.00,707.355,1.00000,1000000,1371830,1.00000,1000000,1.00000
17683.9,0.0234522,1260.15,1.00000,1.00,707.355,1.00000,1000000,1286090,1.00000,1000000,1.00000
17683.9,0.0254097,1378.94,1.00000,1.00,707.355,1.00000,1000000,1095570,1.00000,1000000,1.00000
17683.9,0.0262059,1455.50,1.00000,1.00,707.355,1.00000,1000000,1030010,1.00000,1000000,1.00000
17683.9,0.0267881,1070.24,1.00000,1.00,707.355,1.00000,1000000,985720,1.00000,1000000,1.00000
17683.9,0.0284196,1251.24,1.00000,1.00,707.355,1.00000,1000000,875793,1.00000,1000000,1.00000
17683.9,0.0305121,1255.37,1.00000,1.00,707.355,1.00000,1000000,759790,1.00000,1000000,1.00000
17683.9,0.0305984,908.016,1.00000,1.00,707.355,1.00000,1000000,755510,1.00000,1000000,1.00000
17683.9,0.0317920,1134.99,1.00000,1.00,707.355,1.00000,1000000,699845,1.00000,1000000,1.00000
17683.9,0.0349508,771.958,1.00000,1.00,707.355,1.00000,1000000,579060,1.00000,1000000,1.00000
17683.9,0.0355260,1067.78,1.00000,1.00,707.355,1.00000,1000000,560460,1.00000,1000000,1.00000
17683.9,0.0356005,1028.89,1.00000,1.00,707.355,1.00000,1000000,558117,1.00000,1000000,1.00000
17683.9,0.0398498,932.700,1.00000,1.00,707.355,1.00000,1000000,445436,1.00000,1000000,1.00000
17683.9,0.0399223,663.022,1.00000,1.00,707.355,1.00000,1000000,443820,1.00000,1000000,1.00000
17683.9,0.0413639,918.012,1.00000,1.00,707.355,1.00000,1000000,413423,1.00000,1000000,1.00000
17683.9,0.0445950,844.972,1.00000,1.00,707.355,1.00000,1000000,355685,1.00000,1000000,1.00000
17683.9,0.0456009,561.378,1.00000,1.00,707.355,1.00000,1000000,340166,1.00000,1000000,1.00000
17683.9,0.0481610,776.660,1.00000,1.00,707.355,1.00000,1000000,304963,1.00000,1000000,1.00000
17683.9,0.0499020,765.099,1.00000,1.00,707.355,1.00000,1000000,284055,1.00000,1000000,1.00000
17683.9,0.0520872,476.774,1.00000,1.00,707.355,1.00000,1000000,260721,1.00000,1000000,1.00000
17683.9,0.0558830,692.245,1.00000,1.00,707.355,1.00000,1000000,226505,1.00000,1000000,1.00000
17683.9,0.0560750,662.021,1.00000,1.00,707.355,1.00000,1000000,224957,1.00000,1000000,1.00000
17683.9,0.0594962,409.493,1.00000,1.00,707.355,1.00000,1000000,199829,1.00000,1000000,1.00000
17683.9,0.0624923,626.528,1.00000,1.00,707.355,1.00000,1000000,181128,1.00000,1000000,1.00000
17683.9,0.0652895,576.531,1.00000,1.00,707.355,1.00000,1000000,165940,1.00000,1000000,1.00000
17683.9,0.0679591,348.135,1.00000,1.00,707.355,1.00000,1000000,153159,1.00000,1000000,1.00000
17683.9,0.0699297,566.307,1.00000,1.00,707.355,1.00000,1000000,144649,1.00000,1000000,1.00000
17683.9,0.0760182,491.433,1.00000,1.00,707.355,1.00000,1000000,122406,1.00000,1000000,1.00000
17683.9,0.0776257,302.693,1.00000,1.00,707.355,1.00000,1000000,117389,1.00000,1000000,1.00000
17683.9,0.0782476,511.990,1.00000,1.00,707.355,1.00000,1000000,115530,1.00000,1000000,1.00000
17683.9,0.0875746,462.453,1.00000,1.00,707.355,1.00000,1000000,92231.9,1.00000,1000000,1.00000
17683.9,0.0885099,429.810,1.00000,1.00,707.355,1.00000,1000000,90293.0,1.00000,1000000,1.00000
17683.9,0.0886673,260.776,1.00000,1.00,707.355,1.00000,1000000,89972.7,1.00000,1000000,1.00000
17683.9,0.0980813,417.346,1.00000,1.00,707.355,1.00000,1000000,73530.1,1.00000,1000000,1.00000
17683.9,0.101279,223.063,1.00000,1.00,707.355,1.00000,1000000,68960.2,1.00000,1000000,1.00000
17683.9,0.103054,370.316,1.00000,1.00,707.355,1.00000,1000000,66605.2,1.00000,1000000,1.00000
17683.9,0.109860,376.525,1.00000,1.00,707.355,1.00000,1000000,58608.2,1.00000,1000000,1.00000
17683.9,0.115686,192.566,1.00000,1.00,707.355,1.00000,1000000,52853.8,1.00000,1000000,1.00000
17683.9,0.119989,319.400,1.00000,1.00,707.355,1.00000,1000000,49130.9,1.00000,1000000,1.00000
17683.9,0.122907,339.682,1.00000,1.00,707.355,1.00000,1000000,46825.7,1.00000,1000000,1.00000
17683.9,0.132141,167.431,1.00000,1.00,707.355,1.00000,1000000,40510.0,1.00000,1000000,1.00000
17683.9,0.137503,306.055,1.00000,1.00,707.355,1.00000,1000000,37412.2,1.00000,1000000,1.00000
17683.9,0.139706,276.371,1.00000,1.00,707.355,1.00000,1000000,36241.6,1.00000,1000000,1.00000
17683.9,0.150937,147.521,1.00000,1.00,707.355,1.00000,1000000,31048.9,1.00000,1000000,1.00000
17683.9,0.154081,275.570,1.00000,1.00,707.355,1.00000,1000000,29794.7,1.00000,1000000,1.00000
17683.9,0.162663,240.682,1.00000,1.00,707.355,1.00000,1000000,26733.8,1.00000,1000000,1.00000
17683.9,0.172406,127.222,1.00000,1.00,707.355,1.00000,1000000,23797.6,1.00000,1000000,1.00000
17683.9,0.172471,248.292,1.00000,1.00,707.355,1.00000,1000000,23779.6,1.00000,1000000,1.00000
17683.9,0.189392,213.227,1.00000,1.00,707.355,1.00000,1000000,19720.3,1.00000,1000000,1.00000
17683.9,0.192999,223.850,1.00000,1.00,707.355,1.00000,1000000,18990.1,1.00000,1000000,1.00000
17683.9,0.196930,110.616,1.00000,1.00,707.355,1.00000,1000000,18239.5,1.00000,1000000,1.00000
17683.9,0.215919,202.161,1.00000,1.00,707.355,1.00000,1000000,15172.5,1.00000,1000000,1.00000
17683.9,0.220514,185.692,1.00000,1.00,707.355,1.00000,1000000,14546.7,1.00000,1000000,1.00000
17683.9,0.224941,97.0650,1.00000,1.00,707.355,1.00000,1000000,13979.8,1.00000,1000000,1.00000
17683.9,0.241835,182.725,1.00000,1.00,707.355,1.00000,1000000,12094.8,1.00000,1000000,1.00000
17683.9,0.256750,162.931,1.00000,1.00,707.355,1.00000,1000000,10730.4,1.00000,1000000,1.00000
17683.9,0.256937,85.1743,1.00000,1.00,707.355,1.00000,1000000,10714.8,1.00000,1000000,1.00000
17683.9,0.270808,165.200,1.00000,1.00,707.355,1.00000,1000000,9645.27,1.00000,1000000,1.00000
17683.9,0.293485,74.5877,1.00000,1.00,707.355,1.00000,1000000,8212.32,1.00000,1000000,1.00000
17683.9,0.298941,142.806,1.00000,1.00,707.355,1.00000,1000000,7915.29,1.00000,1000000,1.00000
17683.9,0.302980,149.382,1.00000,1.00,707.355,1.00000,1000000,7705.66,1.00000,1000000,1.00000
17683.9,0.335230,65.3170,1.00000,1.00,707.355,1.00000,1000000,6294.36,1.00000,1000000,1.00000
17683.9,0.338976,135.046,1.00000,1.00,707.355,1.00000,1000000,6156.02,1.00000,1000000,1.00000
17683.9,0.348064,125.167,1.00000,1.00,707.355,1.00000,1000000,5838.74,1.00000,1000000,1.00000
17683.9,0.379237,121.999,1.00000,1.00,707.355,1.00000,1000000,4918.31,1.00000,1000000,1.00000
17683.9,0.382914,57.3155,1.00000,1.00,707.355,1.00000,1000000,4824.31,1.00000,1000000,1.00000
17683.9,0.405260,110.297,1.00000,1.00,707.355,1.00000,1000000,4306.95,1.00000,1000000,1.00000
17683.9,0.424733,109.968,1.00000,1.00,707.355,1.00000,1000000,3921.08,1.00000,1000000,1.00000
17683.9,0.437380,50.6549,1.00000,1.00,707.355,1.00000,1000000,3697.60,1.00000,1000000,1.00000
17683.9,0.471854,97.2969,1.00000,1.00,707.355,1.00000,1000000,3177.04,1.00000,1000000,1.00000
,0.475616,98.9499,,,,,,,,,
17683.9,0.499594,45.0434,1.00000,1.00,707.355,1.00000,1000000,2834.02,1.00000,1000000,1.00000
17683.9,0.532122,88.8700,1.00000,1.00,707.355,1.00000,1000000,2498.13,1.00000,1000000,1.00000
17683.9,0.549392,84.7325,1.00000,1.00,707.355,1.00000,1000000,2343.54,1.00000,1000000,1.00000
17683.9,0.570657,39.8496,1.00000,1.00,707.355,1.00000,1000000,2172.14,1.00000,1000000,1.00000
17683.9,0.595331,79.6178,1.00000,1.00,707.355,1.00000,1000000,1995.82,1.00000,1000000,1.00000
17683.9,0.639670,73.6325,1.00000,1.00,707.355,1.00000,1000000,1728.72,1.00000,1000000,1.00000
17683.9,0.651829,35.5076,1.00000,1.00,707.355,1.00000,1000000,1664.83,1.00000,1000000,1.00000
17683.9,0.666766,71.1137,1.00000,1.00,707.355,1.00000,1000000,1591.08,1.00000,1000000,1.00000
17683.9,0.744546,31.7357,1.00000,1.00,707.355,1.00000,1000000,1276.01,1.00000,1000000,1.00000
17683.9,0.744784,65.1633,1.00000,1.00,707.355,1.00000,1000000,1275.20,1.00000,1000000,1.00000
17683.9,0.746633,63.3283,1.00000,1.00,707.355,1.00000,1000000,1268.89,1.00000,1000000,1.00000
17683.9,0.835243,56.3219,1.00000,1.00,707.355,1.00000,1000000,1013.94,1.00000,1000000,1.00000
17683.9,0.850451,27.7628,1.00000,1.00,707.355,1.00000,1000000,978.000,1.00000,1000000,1.00000
17683.9,0.867170,56.7485,1.00000,1.00,707.355,1.00000,1000000,940.652,1.00000,1000000,1.00000
17683.9,0.934405,49.9467,1.00000,1.00,707.355,1.00000,1000000,810.153,1.00000,1000000,1.00000
17683.9,0.971421,24.2130,1.00000,1.00,707.355,1.00000,1000000,749.588,1.00000,1000000,1.00000
17683.9,1.00967,49.3144,1.00000,1.00,707.355,1.00000,1000000,693.871,1.00000,1000000,1.00000
17683.9,1.04648,44.1286,1.00000,1.00,707.355,1.00000,1000000,645.916,1.00000,1000000,1.00000
17683.9,1.10960,22.2457,1.00000,1.00,707.355,1.00000,1000000,574.519,1.00000,1000000,1.00000
17683.9,1.17189,38.8377,1.00000,1.00,707.355,1.00000,1000000,515.067,1.00000,1000000,1.00000
17683.9,1.17558,43.6423,1.00000,1.00,707.355,1.00000,1000000,511.839,1.00000,1000000,1.00000
17683.9,1.26743,19.8218,1.00000,1.00,707.355,1.00000,1000000,440.342,1.00000,1000000,1.00000
17683.9,1.31106,34.1676,1.00000,1.00,707.355,1.00000,1000000,411.521,1.00000,1000000,1.00000
17683.9,1.36876,38.0065,1.00000,1.00,707.355,1.00000,1000000,377.557,1.00000,1000000,1.00000
17683.9,1.44771,17.8432,1.00000,1.00,707.355,1.00000,1000000,337.501,1.00000,1000000,1.00000
17683.9,1.46664,30.0289,1.00000,1.00,707.355,1.00000,1000000,328.844,1.00000,1000000,1.00000
17683.9,1.59368,32.9923,1.00000,1.00,707.355,1.00000,1000000,278.507,1.00000,1000000,1.00000
17683.9,1.64077,26.4766,1.00000,1.00,707.355,1.00000,1000000,262.750,1.00000,1000000,1.00000
17683.9,1.65363,15.8828,1.00000,1.00,707.355,1.00000,1000000,258.679,1.00000,1000000,1.00000
17683.9,1.83748,23.3587,1.00000,1.00,707.355,1.00000,1000000,209.504,1.00000,1000000,1.00000
17683.9,1.85556,28.6396,1.00000,1.00,707.355,1.00000,1000000,205.441,1.00000,1000000,1.00000
17683.9,1.88885,14.0658,1.00000,1.00,707.355,1.00000,1000000,198.263,1.00000,1000000,1.00000
17683.9,2.05776,20.6787,1.00000,1.00,707.355,1.00000,1000000,167.051,1.00000,1000000,1.00000
17683.9,2.15752,12.1551,1.00000,1.00,707.355,1.00000,1000000,151.960,1.00000,1000000,1.00000
17683.9,2.16048,25.4544,1.00000,1.00,707.355,1.00000,1000000,151.543,1.00000,1000000,1.00000
17683.9,2.30209,18.2939,1.00000,1.00,707.355,1.00000,1000000,133.473,1.00000,1000000,1.00000
17683.9,2.46441,10.6009,1.00000,1.00,707.355,1.00000,1000000,116.469,1.00000,1000000,1.00000
17683.9,2.51550,22.1673,1.00000,1.00,707.355,1.00000,1000000,111.786,1.00000,1000000,1.00000
17683.9,2.57530,16.1819,1.00000,1.00,707.355,1.00000,1000000,106.655,1.00000,1000000,1.00000
17683.9,2.81495,9.12357,1.00000,1.00,707.355,1.00000,1000000,89.2681,1.00000,1000000,1.00000
17683.9,2.88417,14.2555,1.00000,1.00,707.355,1.00000,1000000,85.0346,1.00000,1000000,1.00000
17683.9,2.92885,20.0427,1.00000,1.00,707.355,1.00000,1000000,82.4600,1.00000,1000000,1.00000
17683.9,3.21536,7.74858,1.00000,1.00,707.355,1.00000,1000000,68.4193,1.00000,1000000,1.00000
17683.9,3.22986,12.5064,1.00000,1.00,707.355,1.00000,1000000,67.8063,1.00000,1000000,1.00000
17683.9,3.41014,18.0249,1.00000,1.00,707.355,1.00000,1000000,60.8265,1.00000,1000000,1.00000
17683.9,3.61329,10.9319,1.00000,1.00,707.355,1.00000,1000000,54.1791,1.00000,1000000,1.00000
17683.9,3.67272,6.48079,1.00000,1.00,707.355,1.00000,1000000,52.4399,1.00000,1000000,1.00000
17683.9,3.97051,16.4729,1.00000,1.00,707.355,1.00000,1000000,44.8689,1.00000,1000000,1.00000
17683.9,4.04219,9.58241,1.00000,1.00,707.355,1.00000,1000000,43.2917,1.00000,1000000,1.00000
17683.9,4.19513,5.62337,1.00000,1.00,707.355,1.00000,1000000,40.1927,1.00000,1000000,1.00000
17683.9,4.52203,8.36251,1.00000,1.00,707.355,1.00000,1000000,34.5916,1.00000,1000000,1.00000
17683.9,4.62296,14.6566,1.00000,1.00,707.355,1.00000,1000000,33.0977,1.00000,1000000,1.00000
17683.9,4.79185,5.23551,1.00000,1.00,707.355,1.00000,1000000,30.8057,1.00000,1000000,1.00000
17683.9,5.06428,7.26495,1.00000,1.00,707.355,1.00000,1000000,27.5805,1.00000,1000000,1.00000
17683.9,5.38263,12.4798,1.00000,1.00,707.355,1.00000,1000000,24.4145,1.00000,1000000,1.00000
17683.9,5.47345,4.79053,1.00000,1.00,707.355,1.00000,1000000,23.6110,1.00000,1000000,1.00000
17683.9,5.67134,6.36518,1.00000,1.00,707.355,1.00000,1000000,21.9921,1.00000,1000000,1.00000
17683.9,6.25201,4.48294,1.00000,1.00,707.355,1.00000,1000000,18.0967,1.00000,1000000,1.00000
17683.9,6.26713,10.4010,1.00000,1.00,707.355,1.00000,1000000,18.0094,1.00000,1000000,1.00000
17683.9,6.34461,5.52349,1.00000,1.00,707.355,1.00000,1000000,17.5723,1.00000,1000000,1.00000
17683.9,7.09767,4.74610,1.00000,1.00,707.355,1.00000,1000000,14.0413,1.00000,1000000,1.00000
17683.9,7.14130,3.80344,1.00000,1.00,707.355,1.00000,1000000,13.8702,1.00000,1000000,1.00000
17683.9,7.29697,9.09675,1.00000,1.00,707.355,1.00000,1000000,13.2847,1.00000,1000000,1.00000
17683.9,7.94881,4.04848,1.00000,1.00,707.355,1.00000,1000000,11.1952,1.00000,1000000,1.00000
17683.9,8.15709,3.09149,1.00000,1.00,707.355,1.00000,1000000,10.6308,1.00000,1000000,1.00000
17683.9,8.49605,8.48455,1.00000,1.00,707.355,1.00000,1000000,9.79949,1.00000,1000000,1.00000
17683.9,8.90165,3.39166,1.00000,1.00,707.355,1.00000,1000000,8.92681,1.00000,1000000,1.00000
17683.9,9.31737,2.74622,1.00000,1.00,707.355,1.00000,1000000,8.14800,1.00000,1000000,1.00000
17683.9,9.89216,7.35729,1.00000,1.00,707.355,1.00000,1000000,7.22862,1.00000,1000000,1.00000
17683.9,9.95882,2.81718,1.00000,1.00,707.355,1.00000,1000000,7.13217,1.00000,1000000,1.00000
17683.9,10.6427,2.61488,1.00000,1.00,707.355,1.00000,1000000,6.24502,1.00000,1000000,1.00000
17683.9,11.1402,2.37824,1.00000,1.00,707.355,1.00000,1000000,5.69970,1.00000,1000000,1.00000
17683.9,11.5177,6.16469,1.00000,1.00,707.355,1.00000,1000000,5.33220,1.00000,1000000,1.00000
17683.9,12.0833,2.22715,1.00000,1.00,707.355,1.00000,1000000,4.84470,1.00000,1000000,1.00000
17683.9,12.4762,2.01976,1.00000,1.00,707.355,1.00000,1000000,4.54436,1.00000,1000000,1.00000
17683.9,13.4103,5.74365,1.00000,1.00,707.355,1.00000,1000000,3.93333,1.00000,1000000,1.00000
17683.9,13.7188,1.89963,1.00000,1.00,707.355,1.00000,1000000,3.75842,1.00000,1000000,1.00000
17683.9,13.9716,1.73626,1.00000,1.00,707.355,1.00000,1000000,3.62364,1.00000,1000000,1.00000
17683.9,15.6140,4.83330,1.00000,1.00,707.355,1.00000,1000000,2.90141,1.00000,1000000,1.00000
17683.9,15.6305,1.54199,1.00000,1.00,707.355,1.00000,1000000,2.89529,1.00000,1000000,1.00000
17683.9,15.6702,1.77042,1.00000,1.00,707.355,1.00000,1000000,2.88064,1.00000,1000000,1.00000
17683.9,17.4857,1.35623,1.00000,1.00,707.355,1.00000,1000000,2.31351,1.00000,1000000,1.00000
17683.9,17.8992,1.46421,1.00000,1.00,707.355,1.00000,1000000,2.20785,1.00000,1000000,1.00000
17683.9,18.1797,4.37943,1.00000,1.00,707.355,1.00000,1000000,2.14025,1.00000,1000000,1.00000
17683.9,19.5613,1.21040,1.00000,1.00,707.355,1.00000,1000000,1.84860,1.00000,1000000,1.00000
17683.9,20.4452,1.31537,1.00000,1.00,707.355,1.00000,1000000,1.69221,1.00000,1000000,1.00000
17683.9,21.1671,3.74102,1.00000,1.00,707.355,1.00000,1000000,1.57876,1.00000,1000000,1.00000
17683.9,21.9070,1.08250,1.00000,1.00,707.355,1.00000,1000000,1.47391,1.00000,1000000,1.00000
17683.9,23.3533,1.14485,1.00000,1.00,707.355,1.00000,1000000,1.29700,1.00000,1000000,1.00000
17683.9,24.5330,1.00140,1.00000,1.00,707.355,1.00000,1000000,1.17527,1.00000,1000000,1.00000
17683.9,24.6454,3.28598,1.00000,1.00,707.355,1.00000,1000000,1.16457,1.00000,1000000,1.00000
17683.9,26.6751,1.01387,1.00000,1.00,707.355,1.00000,1000000,0.994089,1.00000,1000000,1.00000
17683.9,27.4447,0.890786,1.00000,1.00,707.355,1.00000,1000000,0.939119,1.00000,1000000,1.00000
17683.9,28.6953,2.92679,1.00000,1.00,707.355,1.00000,1000000,0.859045,1.00000,1000000,1.00000
17683.9,30.4695,0.871688,1.00000,1.00,707.355,1.00000,1000000,0.761916,1.00000,1000000,1.00000
17683.9,30.7033,0.824112,1.00000,1.00,707.355,1.00000,1000000,0.750356,1.00000,1000000,1.00000
17683.9,33.4106,2.51357,1.00000,1.00,707.355,1.00000,1000000,0.633679,1.00000,1000000,1.00000
17683.9,34.3833,0.764968,1.00000,1.00,707.355,1.00000,1000000,0.598332,1.00000,1000000,1.00000
17683.9,34.8035,0.795162,1.00000,1.00,707.355,1.00000,1000000,0.583972,1.00000,1000000,1.00000
17683.9,38.5077,0.710081,1.00000,1.00,707.355,1.00000,1000000,0.477026,1.00000,1000000,1.00000
17683.9,38.9008,2.22684,1.00000,1.00,707.355,1.00000,1000000,0.467434,1.00000,1000000,1.00000
17683.9,39.7540,0.677397,1.00000,1.00,707.355,1.00000,1000000,0.447585,1.00000,1000000,1.00000
153.329,43.0799,0.617407,22.2167,20.01,9106.99,12.8747,20.0039,4.90711,22.2167,8670.54,1.00032e-4
167.396,45.2932,1.93720,25.9523,20.02,8918.16,12.6077,20.0082,4.34719,25.9523,9466.03,1.15797e-4
186.608,45.4087,0.596846,33.2923,20.01,8489.44,12.0017,20.0094,4.11719,33.2923,10552.4,1.46466e-4
195.919,48.1917,0.544447,40.6324,20.00,8080.49,11.4235,20.0096,3.47931,40.6324,11079.0,1.70295e-4
200.817,51.8677,0.536722,47.9724,20.01,7681.02,10.8588,20.0083,2.85513,47.9724,11355.9,1.90473e-4
202.550,52.7360,1.68343,55.3124,20.00,7279.53,10.2912,20.0056,2.61751,55.3124,11454.0,2.11189e-4
203.450,53.9137,0.475283,62.7180,20.00,6995.60,9.88979,20.0138,2.40672,62.7180,11504.8,2.35047e-4
201.831,59.2454,0.470491,70.1236,20.00,6705.47,9.47963,20.0049,1.91038,70.1236,11413.3,2.59888e-4
198.718,60.3768,0.409869,77.4636,20.00,6509.58,9.20270,20.0143,1.78572,77.4636,11237.2,2.85812e-4
194.484,61.4018,1.48184,84.8036,20.00,6310.68,8.92152,20.0098,1.67384,84.8036,10997.8,3.12845e-4
189.709,67.6008,0.342750,92.1436,20.00,6142.44,8.68367,20.0061,1.34412,92.1436,10727.8,3.45185e-4
184.362,67.6726,0.406166,99.4837,20.00,6039.49,8.53813,20.0160,1.31879,99.4837,10425.4,3.77294e-4
178.559,71.4917,1.30299,106.889,20.00,5911.71,8.35748,20.0156,1.15665,106.889,10097.3,4.11298e-4
172.892,75.6548,0.299599,114.295,20.00,5807.80,8.21059,20.0101,1.01470,114.295,9776.83,4.51160e-4
167.662,77.2984,0.363390,121.635,20.00,5723.64,8.09161,20.0146,0.957924,121.635,9481.07,4.91410e-4
162.578,83.2395,1.12625,128.975,20.00,5636.13,7.96790,20.0164,0.813434,128.975,9193.58,5.39003e-4
158.190,84.6010,0.256011,136.315,20.00,5598.37,7.91451,20.0186,0.782187,136.315,8945.42,5.86912e-4
154.007,88.2935,0.318223,143.655,20.00,5523.72,7.80898,20.0167,0.708556,143.655,8708.88,6.42928e-4
149.440,94.5709,0.228250,151.061,20.00,5451.10,7.70632,20.0160,0.609494,151.061,8450.66,7.03125e-4
146.020,96.9178,0.998845,158.466,20.00,5422.67,7.66612,20.0241,0.577306,158.466,8257.24,7.70149e-4
142.267,100.853,0.283549,165.806,20.00,5360.31,7.57797,20.0204,0.527002,165.806,8045.02,8.42431e-4
139.228,112.844,0.868928,173.146,20.00,5343.84,7.55467,20.0174,0.419659,173.146,7873.13,9.21552e-4
136.656,115.198,0.245283,180.486,20.00,5335.71,7.54318,20.0276,0.402070,180.486,7727.69,1.00663e-3
133.025,131.387,0.755908,187.826,20.00,5271.04,7.45176,20.0172,0.305346,187.826,7522.37,1.10380e-3
130.503,131.584,0.219675,195.232,20.00,5250.02,7.42203,20.0156,0.303218,195.232,7379.76,1.20826e-3
128.073,150.301,0.194742,202.637,20.00,5205.93,7.35970,20.0266,0.230449,202.637,7242.35,1.32298e-3
125.767,152.977,0.657589,209.977,20.00,5185.15,7.33033,20.0195,0.221569,209.977,7111.95,1.45003e-3
123.078,171.680,0.171060,217.317,20.00,5148.77,7.27890,20.0296,0.174688,217.317,6959.90,1.58630e-3
121.105,178.115,0.567782,224.657,20.00,5100.57,7.21076,20.0314,0.160775,224.657,6848.35,1.73645e-3
119.475,196.100,0.147975,231.997,20.00,5094.50,7.20218,20.0278,0.132479,231.997,6756.14,1.90085e-3
118.262,207.384,0.501400,239.403,20.00,5094.19,7.20175,20.0278,0.118447,239.403,6687.56,2.08375e-3
116.480,223.993,0.129450,246.809,20.01,5067.72,7.16432,20.0151,0.101005,246.809,6586.81,2.28367e-3
114.847,241.462,0.430148,254.149,20.00,5031.37,7.11294,20.0220,0.0862957,254.149,6494.46,2.50085e-3
113.774,255.854,0.113361,261.489,20.00,5002.00,7.07141,20.0266,0.0764115,261.489,6433.78,2.73624e-3
112.847,281.140,0.376614,268.829,20.00,4994.10,7.06024,20.0207,0.0631847,268.829,6381.35,2.99759e-3
111.972,292.247,0.101009,276.169,20.00,4944.70,6.99041,20.0191,0.0578949,276.169,6331.89,3.28157e-3
110.901,327.338,0.327980,283.574,20.00,4923.67,6.96067,20.0210,0.0459511,283.574,6271.29,3.59767e-3
109.514,333.817,0.0899108,290.980,20.00,4894.41,6.91931,20.0292,0.0439221,290.980,6192.88,3.94176e-3
108.995,381.128,0.280770,298.320,20.00,4883.37,6.90370,20.0202,0.0336185,298.320,6163.54,4.31495e-3
108.684,381.300,0.0775389,305.660,20.00,4884.11,6.90475,20.0190,0.0335933,305.660,6145.95,4.72567e-3
108.879,435.537,0.0656518,313.000,20.00,4915.60,6.94926,20.0234,0.0259135,313.000,6156.97,5.17419e-3
108.872,443.757,0.241906,320.340,20.00,4905.48,6.93497,20.0299,0.0249110,320.340,6156.55,5.66488e-3
108.477,497.488,0.0586179,327.746,20.00,4922.62,6.95919,20.0302,0.0198898,327.746,6134.23,6.21078e-3
107.968,516.678,0.211573,335.151,20.00,4911.92,6.94407,20.0241,0.0183997,335.151,6105.42,6.80468e-3
107.817,568.252,0.0521775,342.491,20.00,4899.15,6.92602,20.0278,0.0151719,342.491,6096.90,7.45170e-3
107.959,601.581,0.184054,349.831,20.00,4883.04,6.90324,20.0273,0.0134928,349.831,6104.95,8.16088e-3
106.976,649.081,0.0471134,357.171,20.00,4850.12,6.85670,20.0222,0.0115121,357.171,6049.37,8.93513e-3
107.127,700.435,0.161666,364.511,20.00,4916.24,6.95017,20.0180,0.0100207,364.511,6057.88,9.78273e-3
108.668,741.407,0.0424973,371.917,20.00,4995.46,7.06216,20.0203,9.08787e-3,371.917,6145.02,0.0107202
110.298,815.534,0.141698,379.322,20.00,5075.18,7.17487,20.0286,7.63076e-3,379.322,6237.22,0.0117481
111.356,846.866,0.0365002,386.662,20.00,5111.58,7.22633,20.0262,7.12731e-3,386.662,6297.03,0.0128677
110.932,949.547,0.123268,394.002,20.00,5016.98,7.09260,20.0217,5.56429e-3,394.002,6273.05,0.0140908
109.205,967.326,0.0320616,401.342,20.00,4872.37,6.88815,20.0109,5.20708e-3,401.342,6175.38,0.0154306
107.993,1104.92,0.0305907,408.683,20.00,4865.04,6.87779,20.0291,3.98497e-3,408.683,6106.87,0.0168938
110.858,1105.58,0.107235,416.088,20.00,5010.41,7.08330,20.0260,4.09914e-3,416.088,6268.86,0.0185108
113.062,1262.09,0.0291277,423.494,20.00,5146.07,7.27509,20.0278,3.23069e-3,423.494,6393.49,0.0202898
112.480,1287.26,0.0937881,430.834,20.01,5118.26,7.23577,20.0265,3.08880e-3,430.834,6360.57,0.0222176
114.636,1441.61,0.0257428,438.174,20.00,5153.77,7.28597,20.0262,2.47987e-3,438.174,6482.49,0.0243256
116.527,1498.78,0.0825569,445.514,20.00,5186.36,7.33205,20.0289,2.30880e-3,445.514,6589.44,0.0266372
118.105,1646.66,0.0227048,452.854,20.00,5189.27,7.33616,20.0253,1.91381e-3,452.854,6678.66,0.0291701
118.348,1745.07,0.0725151,460.259,20.00,5221.41,7.38160,20.0252,1.71460e-3,460.259,6692.42,0.0319722
116.424,1880.89,0.0202515,467.665,20.00,5108.43,7.22188,20.0250,1.44398e-3,467.665,6583.60,0.0350360
115.641,2031.83,0.0626788,475.005,20.00,4991.85,7.05706,20.0214,1.20917e-3,475.005,6539.32,0.0383655
114.294,2148.43,0.0177707,482.345,20.00,4918.41,6.95324,20.0241,1.06557e-3,482.345,6463.16,0.0420080
112.062,2365.71,0.0546434,489.685,20.00,4818.22,6.81160,20.0289,8.60922e-4,489.685,6336.96,0.0460043
109.998,2454.02,0.0158667,497.025,20.00,4782.74,6.76144,20.0289,7.94183e-4,497.025,6220.22,0.0503700
108.438,2754.45,0.0465777,504.431,20.00,4734.83,6.69371,20.0191,6.24072e-4,504.431,6132.04,0.0552043
103.106,2803.09,0.0139515,511.836,20.00,4580.86,6.47604,20.0210,5.83006e-4,511.836,5830.49,0.0604981
100.477,3201.80,0.0123933,519.176,20.00,4509.58,6.37527,20.0162,4.39894e-4,519.176,5681.84,0.0662451
97.3253,3207.08,0.0391533,526.516,20.00,4411.12,6.23607,20.0292,4.28873e-4,526.516,5503.62,0.0725348
102.327,3657.23,0.0117046,533.856,20.00,4675.13,6.60930,20.0276,3.49533e-4,533.856,5786.48,0.0794160
104.272,3657.41,0.0321582,541.196,20.00,4779.39,6.75670,20.0213,3.57293e-4,541.196,5896.45,0.0869668
107.343,4001.45,0.0238008,548.602,20.00,4836.85,6.83793,20.0204,3.02084e-4,548.602,6070.08,0.0953058
113.920,4028.64,0.0114633,556.007,20.00,5037.02,7.12092,20.0331,3.10354e-4,556.007,6442.00,0.104439
116.176,4469.63,0.0183314,563.347,20.00,5013.07,7.08706,20.0237,2.50935e-4,563.347,6569.62,0.114371
111.427,4490.08,0.0117122,570.688,20.00,4743.19,6.70552,20.0324,2.35268e-4,570.688,6301.03,0.125238
104.263,5055.59,0.0117122,578.028,20.00,4577.36,6.47109,20.0292,1.79090e-4,578.028,5895.92,0.137137
96.6225,5168.23,0.0145569,585.368,20.00,4373.17,6.18243,20.0233,1.63724e-4,585.368,5463.87,0.150158
101.927,5693.63,0.0111124,592.773,20.00,4672.96,6.60625,20.0275,1.44150e-4,592.773,5763.85,0.164563
109.735,6315.97,8.93000e-3,600.179,20.00,4899.12,6.92597,20.0379,1.22811e-4,600.179,6205.34,0.180334
112.513,7353.84,9.20000e-3,607.519,20.00,4817.75,6.81093,20.0116,8.90873e-5,607.519,6362.48,0.197481
101.423,8562.26,9.80000e-3,614.859,20.00,4473.69,6.32453,20.0211,6.10224e-5,614.859,5735.35,0.216244
96.8011,9969.25,9.39000e-3,622.199,20.00,4462.25,6.30836,20.0264,4.48982e-5,622.199,5473.98,0.236768
108.311,11607.4,8.94000e-3,629.539,20.00,4843.05,6.84670,20.0250,3.59459e-5,629.539,6124.83,0.259271
106.362,13514.8,8.12000e-3,636.944,20.00,4617.20,6.52741,20.0163,2.52790e-5,636.944,6014.62,0.284157
95.5523,15412.6,7.15000e-3,644.350,20.00,4429.02,6.26138,20.0200,1.86447e-5,644.350,5403.35,0.311379