File: 9_characterizationRheology/csv/psb_nmp_00_10.csv
Filename,psb_nmp_00_10
Instrument name,5333-0457
Operator,Osamu Katagiri
rundate,12/12/2019
Sample name,OSKT 10_PSB_NMP
Geometry name,60mm 0.9969° cone plate, Peltier plate Steel
Procedure name,Sample
,Flow ramp
proceduresegments,Flow ramp
[step]
Flow ramp - 1
Stress,Shear rate,Viscosity,Step time,Temperature,Normal stress,Axial force,Gap,Normal stress coefficient,Time,Torque,Velocity
Pa,1/s,Pa.s,s,°C,Pa,N,µm,Pa.s²,s,µN.m,rad/s
0.0128417,6.38265e-3,2.01198,3.26241,19.97,-26.0238,-0.0367902,20.0182,-638805,3.26241,0.726183,1.11058e-4
4.29826e-4,7.33974e-3,0.0624149,10.5791,19.97,-26.6851,-0.0377252,20.0188,-495344,10.5791,0.0243061,1.27711e-4
4.76341e-4,8.22922e-3,0.0575591,17.5637,19.98,-27.6649,-0.0391103,20.0125,-408518,17.5637,0.0269365,1.43188e-4
4.72749e-4,9.22163e-3,0.0525974,24.5760,19.98,-27.7670,-0.0392546,20.0185,-326522,24.5760,0.0267333,1.60456e-4
5.46738e-4,0.0103108,0.0490858,31.5228,19.99,-28.4708,-0.0402497,20.0136,-267801,31.5228,0.0309173,1.79408e-4
5.86932e-4,0.0115446,0.0465357,38.4697,19.99,-29.4250,-0.0415986,20.0075,-220779,38.4697,0.0331902,2.00876e-4
5.94441e-4,0.0129247,0.0446654,45.4820,19.99,-28.8522,-0.0407889,20.0065,-172720,45.4820,0.0336148,2.24888e-4
5.54301e-4,0.0144824,0.0431104,52.4944,20.00,-29.6784,-0.0419568,20.0102,-141501,52.4944,0.0313450,2.51993e-4
5.29563e-4,0.0161879,0.0417124,59.4412,20.00,-31.3932,-0.0443811,20.0162,-119799,59.4412,0.0299461,2.81669e-4
5.82319e-4,0.0181127,0.0403784,66.3880,20.00,-31.8957,-0.0450915,20.0116,-97222.2,66.3880,0.0329294,3.15161e-4
6.69960e-4,0.0202822,0.0390818,73.4004,20.00,-31.9400,-0.0451541,20.0152,-77643.3,73.4004,0.0378854,3.52910e-4
6.86967e-4,0.0226999,0.0376895,80.4127,20.00,-32.7229,-0.0462610,20.0131,-63504.5,80.4127,0.0388471,3.94977e-4
9.32254e-4,0.0254067,0.0363030,87.3595,20.00,-32.4478,-0.0458720,20.0218,-50267.8,87.3595,0.0527177,4.42075e-4
1.07452e-3,0.0284159,0.0350480,94.3063,20.00,-34.1139,-0.0482273,20.0279,-42248.3,94.3063,0.0607629,4.94435e-4
1.25508e-3,0.0318042,0.0336502,101.253,20.00,-34.3750,-0.0485965,20.0213,-33983.9,101.253,0.0709731,5.53392e-4
1.29958e-3,0.0356194,0.0323064,108.266,20.00,-34.8354,-0.0492475,20.0190,-27456.7,108.266,0.0734898,6.19776e-4
1.38764e-3,0.0398939,0.0312626,115.278,20.00,-35.1013,-0.0496232,20.0265,-22055.1,115.278,0.0784692,6.94152e-4
1.43793e-3,0.0446259,0.0305925,122.225,20.00,-36.1895,-0.0511616,20.0330,-18172.2,122.225,0.0813131,7.76489e-4
1.54052e-3,0.0499135,0.0302212,129.171,20.00,-36.6979,-0.0518805,20.0295,-14730.1,129.171,0.0871142,8.68493e-4
1.65235e-3,0.0559075,0.0299410,136.184,20.00,-35.7893,-0.0505959,20.0143,-11450.2,136.184,0.0934379,9.72788e-4
1.83657e-3,0.0625318,0.0297690,143.196,20.00,-36.1720,-0.0511370,20.0250,-9250.62,143.196,0.103856,1.08805e-3
1.98652e-3,0.0699551,0.0300994,150.143,20.00,-36.3239,-0.0513517,20.0273,-7422.56,150.143,0.112335,1.21722e-3
2.05124e-3,0.0783035,0.0305825,157.090,20.00,-37.2449,-0.0526538,20.0278,-6074.42,157.090,0.115995,1.36248e-3
2.14396e-3,0.0875810,0.0312541,164.037,20.00,-37.4187,-0.0528994,20.0341,-4878.30,164.037,0.121238,1.52391e-3
2.30569e-3,0.0980919,0.0319932,171.049,20.00,-37.3684,-0.0528283,20.0365,-3883.63,171.049,0.130384,1.70680e-3
2.71426e-3,0.109874,0.0327191,178.061,20.00,-38.5941,-0.0545612,20.0219,-3196.90,178.061,0.153488,1.91181e-3
3.11212e-3,0.122946,0.0332439,185.008,20.00,-38.3010,-0.0541467,20.0157,-2533.86,185.008,0.175986,2.13925e-3
3.55884e-3,0.137518,0.0335198,191.955,20.00,-38.4803,-0.0544002,20.0256,-2034.78,191.955,0.201247,2.39281e-3
4.16117e-3,0.154036,0.0336490,198.967,20.00,-38.4158,-0.0543090,20.0283,-1619.06,198.967,0.235309,2.68023e-3
5.09324e-3,0.172490,0.0340165,205.980,20.00,-38.9784,-0.0551045,20.0335,-1310.07,205.980,0.288016,3.00133e-3
7.19238e-3,0.192966,0.0343999,212.926,20.00,-39.1134,-0.0552953,20.0342,-1050.42,212.926,0.406720,3.35760e-3
0.0107353,0.215909,0.0348606,219.873,20.00,-39.5448,-0.0559052,20.0301,-848.296,219.873,0.607067,3.75681e-3
0.0138401,0.241782,0.0348015,226.886,20.00,-39.7005,-0.0561252,20.0292,-679.121,226.886,0.782638,4.20700e-3
0.0166769,0.270846,0.0345795,233.898,20.00,-38.3635,-0.0542351,20.0281,-522.965,233.898,0.943056,4.71271e-3
0.0168791,0.302997,0.0340853,240.845,20.00,-38.1733,-0.0539662,20.0324,-415.798,240.845,0.954491,5.27214e-3
0.0159826,0.339143,0.0334552,247.792,20.00,-38.5873,-0.0545515,20.0263,-335.490,247.792,0.903793,5.90107e-3
0.0143602,0.379274,0.0325369,254.738,20.00,-39.1805,-0.0553901,20.0258,-272.374,254.738,0.812049,6.59935e-3
0.0140310,0.424709,0.0314945,261.751,20.00,-39.9284,-0.0564475,20.0360,-221.360,261.751,0.793434,7.38993e-3
0.0172207,0.475503,0.0304171,268.763,20.00,-39.8164,-0.0562891,20.0261,-176.098,268.763,0.973807,8.27374e-3
0.0193990,0.532053,0.0289437,275.710,20.00,-39.0262,-0.0551720,20.0220,-137.863,275.710,1.09699,9.25770e-3
0.0218171,0.595417,0.0266979,282.657,20.00,-39.5320,-0.0558870,20.0237,-111.508,282.657,1.23373,0.0103602
0.0168757,0.666890,0.0231105,289.669,20.00,-39.6042,-0.0559892,20.0299,-89.0499,289.669,0.954301,0.0116039
0.0161669,0.746556,0.0188194,296.681,20.00,-39.8136,-0.0562852,20.0213,-71.4344,296.681,0.914214,0.0129900
0.0149614,0.835236,0.0159487,303.628,20.00,-39.6030,-0.0559874,20.0181,-56.7688,303.628,0.846046,0.0145331
0.0162106,0.934613,0.0139703,310.575,20.00,-39.7892,-0.0562507,20.0186,-45.5514,310.575,0.916689,0.0162622
0.0155318,1.04647,0.0127094,317.587,20.00,-39.5456,-0.0559062,20.0203,-36.1113,317.587,0.878305,0.0182086
0.0163692,1.17190,0.0116357,324.600,20.00,-39.1018,-0.0552788,20.0206,-28.4720,324.600,0.925655,0.0203909
0.0183313,1.31099,0.0106581,331.547,20.00,-39.4050,-0.0557075,20.0297,-22.9272,331.547,1.03661,0.0228112
0.0167917,1.46669,9.58474e-3,338.493,20.00,-40.2343,-0.0568799,20.0248,-18.7033,338.493,0.949546,0.0255204
0.0131440,1.64117,8.65265e-3,345.440,20.00,-40.1986,-0.0568295,20.0276,-14.9246,345.440,0.743277,0.0285563
5.96633e-3,1.83777,7.78727e-3,352.453,20.00,-40.3967,-0.0571095,20.0200,-11.9609,352.453,0.337388,0.0319772
2.39111e-3,2.05777,7.10227e-3,359.465,20.00,-42.3029,-0.0598043,20.0148,-9.99024,359.465,0.135214,0.0358051
6.04372e-3,2.30199,6.54234e-3,366.412,20.00,-40.8057,-0.0576877,20.0187,-7.70044,366.412,0.341764,0.0400545
0.0115142,2.57523,6.08785e-3,373.359,20.00,-41.2615,-0.0583321,20.0328,-6.22176,373.359,0.651113,0.0448089
0.0227655,2.88418,5.57155e-3,380.371,20.00,-41.1812,-0.0582185,20.0282,-4.95055,380.371,1.28736,0.0501846
0.0231127,3.23023,5.22150e-3,387.383,20.00,-41.0031,-0.0579668,20.0302,-3.92962,387.383,1.30699,0.0562059
0.0222395,3.61321,4.91096e-3,394.330,20.00,-40.4427,-0.0571745,20.0222,-3.09781,394.330,1.25761,0.0628697
0.0193023,4.04245,4.61396e-3,401.277,20.00,-39.5449,-0.0559053,20.0295,-2.41992,401.277,1.09152,0.0703384
0.0235106,4.52223,4.38207e-3,408.224,20.00,-40.0759,-0.0566560,20.0180,-1.95965,408.224,1.32950,0.0786866
0.0252914,5.06447,4.20958e-3,415.236,20.00,-39.7334,-0.0561718,20.0069,-1.54913,415.236,1.43020,0.0881216
0.0251009,5.67144,4.25531e-3,422.248,20.00,-40.4715,-0.0572152,20.0213,-1.25824,422.248,1.41942,0.0986828
0.0286696,6.34490,4.54338e-3,429.195,20.00,-39.8538,-0.0563420,20.0234,-0.989966,429.195,1.62123,0.110401
0.0322242,7.09796,4.64036e-3,436.142,20.00,-39.6103,-0.0559978,20.0199,-0.786214,436.142,1.82224,0.123504
0.0257640,7.94891,4.61394e-3,443.154,20.00,-39.8630,-0.0563550,20.0305,-0.630892,443.154,1.45692,0.138311
0.0386645,8.90203,4.45852e-3,450.167,20.00,-39.9596,-0.0564916,20.0182,-0.504246,450.167,2.18642,0.154895
0.0432022,9.95839,4.32752e-3,457.114,19.99,-39.4999,-0.0558416,20.0265,-0.398306,457.114,2.44303,0.173276
0.0475662,11.1407,4.23758e-3,464.060,20.00,-39.3782,-0.0556696,20.0252,-0.317273,464.060,2.68981,0.193847
0.0536766,12.4768,4.21492e-3,471.073,20.00,-39.3702,-0.0556583,20.0198,-0.252906,471.073,3.03534,0.217096
0.0521646,13.9721,4.24805e-3,478.085,20.00,-39.2787,-0.0555290,20.0233,-0.201204,478.085,2.94984,0.243113
0.0622562,15.6308,4.22376e-3,485.032,20.00,-39.1144,-0.0552966,20.0278,-0.160093,485.032,3.52051,0.271976
0.0705487,17.4861,4.22771e-3,491.979,20.00,-39.0290,-0.0551760,20.0272,-0.127644,491.979,3.98944,0.304258
0.0765387,19.5620,4.22864e-3,498.926,20.00,-38.9298,-0.0550356,20.0248,-0.101731,498.926,4.32816,0.340378
0.0881071,21.9077,4.23797e-3,505.938,20.00,-38.8528,-0.0549269,20.0334,-0.0809522,505.938,4.98234,0.381193
0.101211,24.5338,4.31952e-3,512.950,20.00,-38.7797,-0.0548235,20.0257,-0.0644280,512.950,5.72336,0.426887
0.111216,27.4458,4.32989e-3,519.897,20.00,-38.2196,-0.0540317,20.0222,-0.0507382,519.897,6.28910,0.477556
0.126692,30.7039,4.33734e-3,526.844,20.00,-38.4232,-0.0543196,20.0237,-0.0407575,526.844,7.16426,0.534246
0.148427,34.3854,4.35578e-3,533.856,20.00,-37.9897,-0.0537066,20.0308,-0.0321306,533.856,8.39336,0.598304
0.232201,38.5087,4.38646e-3,540.869,19.99,-38.9661,-0.0550870,20.0317,-0.0262766,540.869,13.1307,0.670050
0.192912,43.0773,4.44938e-3,547.815,20.00,-38.6428,-0.0546300,20.0293,-0.0208243,547.815,10.9089,0.749544
0.217201,48.1923,4.50129e-3,554.762,20.00,-38.7132,-0.0547295,20.0194,-0.0166687,554.762,12.2824,0.838545
0.244815,53.9123,4.55239e-3,561.709,20.00,-39.2028,-0.0554217,20.0324,-0.0134878,561.709,13.8439,0.938073
0.285591,60.3779,4.60046e-3,568.721,20.00,-38.8117,-0.0548688,20.0311,-0.0106465,568.721,16.1498,1.05057
0.314530,67.6150,4.63453e-3,575.734,20.00,-41.0977,-0.0581005,20.0234,-8.98942e-3,575.734,17.7863,1.17650
0.344087,75.6414,4.65078e-3,582.681,20.00,-40.7268,-0.0575762,20.0237,-7.11805e-3,582.681,19.4577,1.31616
0.379573,84.6207,4.61965e-3,589.627,20.00,-41.1875,-0.0582275,20.0263,-5.75191e-3,589.627,21.4643,1.47240
0.437120,94.5636,4.51682e-3,596.509,20.00,-41.5762,-0.0587769,20.0208,-4.64939e-3,596.509,24.7186,1.64540