File: 9_characterizationRheology/csv/psms_dmf_00_8.csv
Filename,psms_dmf_00_8
Instrument name,5333-0457
Operator,Osamu Katagiri
rundate,13/12/2019
Sample name,_8_PSMS_DMF
Geometry name,60.0mm 0.996944° cone plate, Peltier plate Steel
Procedure name,Sample
,Flow ramp
proceduresegments,Flow ramp
[step]
Flow ramp - 1
Stress,Shear rate,Viscosity,Step time,Temperature,Normal stress,Axial force,Gap,Normal stress coefficient,Time,Torque,Velocity
Pa,1/s,Pa.s,s,°C,Pa,N,µm,Pa.s²,s,µN.m,rad/s
9.65032e-3,6.04487e-3,1.59645,5.13973,19.99,-79.2901,-0.112094,20.0351,-2169930,5.13973,0.545712,1.05180e-4
9.43345e-3,6.88066e-3,1.36542,12.7140,19.99,-80.2883,-0.113505,20.0332,-1695870,12.7140,0.533449,1.19723e-4
9.39412e-3,7.54056e-3,1.23510,21.1682,20.00,-81.2917,-0.114923,20.0296,-1429680,21.1682,0.531225,1.31205e-4
9.10366e-3,8.25588e-3,1.11786,29.6223,20.00,-82.1069,-0.116076,20.0386,-1204630,29.6223,0.514800,1.43652e-4
9.04441e-3,9.04310e-3,1.01294,38.0109,20.00,-82.8283,-0.117096,20.0237,-1012850,38.0109,0.511449,1.57350e-4
9.14437e-3,9.90578e-3,0.922057,46.3995,20.00,-83.8678,-0.118565,20.0258,-854708,46.3995,0.517102,1.72360e-4
9.02197e-3,0.0108494,0.845030,54.7881,20.00,-83.8636,-0.118559,20.0380,-712460,54.7881,0.510180,1.88780e-4
8.88514e-3,0.0118714,0.775131,63.1767,20.00,-84.1728,-0.118996,20.0294,-597264,63.1767,0.502443,2.06562e-4
8.86911e-3,0.0130068,0.712123,71.6309,20.00,-84.7587,-0.119825,20.0192,-501008,71.6309,0.501536,2.26318e-4
8.99768e-3,0.0142479,0.654138,80.0850,20.00,-84.7927,-0.119873,20.0303,-417690,80.0850,0.508807,2.47914e-4
9.28621e-3,0.0155902,0.598467,88.4736,20.00,-68.6094,-0.0969943,20.0329,-282280,88.4736,0.525123,2.71269e-4
9.70458e-3,0.0170764,0.546686,96.8622,20.00,-70.8747,-0.100197,20.0351,-243053,96.8622,0.548781,2.97128e-4
9.82528e-3,0.0186991,0.500016,105.251,20.00,-72.8479,-0.102986,20.0219,-208341,105.251,0.555606,3.25364e-4
0.0100926,0.0204742,0.457654,113.639,20.00,-74.1433,-0.104818,20.0227,-176872,113.639,0.570722,3.56249e-4
9.74465e-3,0.0224603,0.416431,122.094,20.00,-74.3685,-0.105136,20.0289,-147421,122.094,0.551047,3.90808e-4
9.16254e-3,0.0245829,0.381458,130.548,20.00,-75.7062,-0.107027,20.0303,-125275,130.548,0.518129,4.27742e-4
9.19766e-3,0.0269117,0.349835,138.936,20.00,-76.4229,-0.108040,20.0334,-105522,138.936,0.520116,4.68262e-4
9.17609e-3,0.0294626,0.318942,147.325,20.00,-77.0992,-0.108996,20.0338,-88819.2,147.325,0.518896,5.12649e-4
9.09704e-3,0.0322676,0.290203,155.714,20.00,-77.6456,-0.109769,20.0226,-74573.4,155.714,0.514425,5.61455e-4
8.70138e-3,0.0353194,0.263498,164.102,20.00,-78.1337,-0.110459,20.0096,-62634.1,164.102,0.492052,6.14557e-4
9.25551e-3,0.0386871,0.239807,172.556,20.00,-78.6672,-0.111213,20.0100,-52560.6,172.556,0.523387,6.73155e-4
9.69575e-3,0.0424083,0.219235,181.010,20.00,-79.0003,-0.111684,20.0069,-43926.6,181.010,0.548282,7.37902e-4
9.50258e-3,0.0464104,0.200824,189.399,20.00,-79.4650,-0.112341,20.0029,-36893.2,189.399,0.537358,8.07539e-4
9.45601e-3,0.0508186,0.183653,197.788,20.00,-80.0983,-0.113236,20.0145,-31015.4,197.788,0.534725,8.84242e-4
9.43233e-3,0.0556444,0.167952,206.176,20.00,-80.6388,-0.114000,20.0140,-26043.6,206.176,0.533385,9.68211e-4
9.41371e-3,0.0608343,0.154726,214.565,20.00,-81.2268,-0.114832,20.0160,-21948.4,214.565,0.532333,1.05851e-3
9.37522e-3,0.0666625,0.141506,223.019,20.00,-82.0617,-0.116012,20.0178,-18466.2,223.019,0.530156,1.15993e-3
9.45362e-3,0.0730383,0.128847,231.473,20.00,-82.2042,-0.116213,20.0170,-15409.6,231.473,0.534590,1.27086e-3
9.31462e-3,0.0799803,0.117233,239.862,20.00,-83.0835,-0.117457,20.0134,-12988.2,239.862,0.526730,1.39165e-3
9.23387e-3,0.0875703,0.106292,248.250,20.00,-83.7439,-0.118390,20.0227,-10920.4,248.250,0.522163,1.52372e-3
9.41184e-3,0.0959005,0.0963259,256.639,20.00,-83.9369,-0.118663,20.0208,-9126.64,256.639,0.532227,1.66867e-3
9.48035e-3,0.105069,0.0867691,265.093,20.00,-84.7088,-0.119754,20.0203,-7673.24,265.093,0.536101,1.82820e-3
9.44707e-3,0.115136,0.0776064,273.547,20.00,-85.5027,-0.120877,20.0213,-6449.93,273.547,0.534219,2.00337e-3
9.12695e-3,0.126062,0.0686810,281.936,20.00,-85.3119,-0.120607,20.0132,-5368.33,281.936,0.516117,2.19348e-3
8.72475e-3,0.138017,0.0602003,290.325,20.00,-85.7297,-0.121198,20.0112,-4500.54,290.325,0.493373,2.40149e-3
8.67672e-3,0.151082,0.0519763,298.713,20.00,-86.3479,-0.122071,20.0122,-3782.93,298.713,0.490657,2.62881e-3
8.14570e-3,0.165511,0.0439351,307.102,20.00,-87.0589,-0.123077,20.0278,-3178.03,307.102,0.460629,2.87989e-3
7.52527e-3,0.181289,0.0360484,315.556,20.00,-87.3212,-0.123447,20.0294,-2656.91,315.556,0.425544,3.15442e-3
6.68248e-3,0.198611,0.0288267,324.010,20.00,-87.6888,-0.123967,20.0237,-2223.00,324.010,0.377886,3.45582e-3
5.91347e-3,0.217509,0.0226669,332.399,20.00,-88.0982,-0.124546,20.0306,-1862.14,332.399,0.334399,3.78465e-3
4.94349e-3,0.238214,0.0175806,340.787,20.00,-88.5087,-0.125126,20.0243,-1559.73,340.787,0.279548,4.14492e-3
4.04915e-3,0.260620,0.0135630,349.176,20.00,-88.3854,-0.124952,20.0259,-1301.27,349.176,0.228974,4.53477e-3
2.93268e-3,0.285541,0.0106789,357.564,20.00,-88.6357,-0.125306,20.0289,-1087.10,357.564,0.165839,4.96841e-3
2.21749e-3,0.312865,8.45752e-3,366.019,20.00,-87.9509,-0.124338,20.0365,-898.516,366.019,0.125396,5.44384e-3
1.76517e-3,0.342537,6.77215e-3,374.473,20.00,-88.1748,-0.124654,20.0248,-751.502,374.473,0.0998178,5.96013e-3
1.45154e-3,0.375197,5.48508e-3,382.861,20.00,-88.7587,-0.125480,20.0294,-630.509,382.861,0.0820825,6.52842e-3
1.31164e-3,0.410669,4.64306e-3,391.250,20.00,-89.3799,-0.126358,20.0294,-529.976,391.250,0.0741718,7.14563e-3
1.62094e-3,0.449837,3.86188e-3,399.639,20.00,-89.4108,-0.126402,20.0239,-441.854,399.639,0.0916621,7.82716e-3
1.60055e-3,0.492330,2.99774e-3,408.027,20.00,-89.7245,-0.126845,20.0205,-370.167,408.027,0.0905089,8.56653e-3
1.56277e-3,0.539429,2.59078e-3,416.481,20.00,-89.3219,-0.126276,20.0299,-306.965,416.481,0.0883723,9.38605e-3
1.58849e-3,0.590904,2.62743e-3,424.935,20.00,-90.0031,-0.127239,20.0309,-257.765,424.935,0.0898273,0.0102817
2.12234e-3,0.647213,2.77371e-3,433.324,20.00,-89.4789,-0.126498,20.0239,-213.612,433.324,0.120015,0.0112615
1.45580e-3,0.708495,2.92494e-3,441.713,20.00,-89.5466,-0.126594,20.0159,-178.392,441.713,0.0823238,0.0123278
4.85785e-4,0.775774,2.97588e-3,450.101,20.00,-89.6849,-0.126789,20.0122,-149.022,450.101,0.0274705,0.0134984
-3.30288e-6,0.849288,-3.88900e-6,458.490,20.00,-89.6408,-0.126727,20.0182,-124.278,458.490,-1.86773e-4,0.0147776
1.16534e-3,0.930131,3.49741e-3,466.944,20.00,-89.3318,-0.126290,20.0227,-103.257,466.944,0.0658986,0.0161842
6.30605e-3,1.01925,3.83696e-3,475.398,20.00,-89.7177,-0.126835,20.0261,-86.3612,475.398,0.356599,0.0177349
9.08996e-3,1.11610,4.02809e-3,483.787,20.00,-90.4342,-0.127848,20.0290,-72.5986,483.787,0.514025,0.0194201
8.39071e-3,1.22195,3.71403e-3,492.175,20.00,-90.5400,-0.127998,20.0269,-60.6364,492.175,0.474484,0.0212619
7.17770e-3,1.33773,3.68929e-3,500.564,20.00,-89.9736,-0.127197,20.0229,-50.2777,500.564,0.405889,0.0232765
0.0102072,1.46573,3.99456e-3,509.018,20.00,-90.5533,-0.128017,20.0290,-42.1499,509.018,0.577204,0.0255036
0.0128152,1.60605,3.70426e-3,517.472,20.00,-90.6222,-0.128114,20.0310,-35.1329,517.472,0.724683,0.0279453
9.25259e-3,1.75823,2.54219e-3,525.861,20.00,-90.7800,-0.128337,20.0353,-29.3656,525.861,0.523222,0.0305931
3.23326e-3,1.92508,1.90721e-3,534.250,20.00,-91.2571,-0.129012,20.0283,-24.6245,534.250,0.182837,0.0334964
4.73901e-3,2.10754,1.64058e-3,542.638,20.00,-90.8422,-0.128425,20.0225,-20.4520,542.638,0.267985,0.0366711
3.71428e-3,2.30747,1.43714e-3,551.027,20.00,-90.7593,-0.128308,20.0178,-17.0459,551.027,0.210038,0.0401498
1.40292e-3,2.52837,1.34271e-3,559.481,20.00,-91.1476,-0.128857,20.0291,-14.2582,559.481,0.0793333,0.0439935
2.71105e-4,2.76973,1.16281e-3,567.935,20.00,-91.2068,-0.128941,20.0343,-11.8892,567.935,0.0153306,0.0481932
1.03761e-3,3.03222,1.02677e-3,576.324,20.00,-91.4226,-0.129246,20.0327,-9.94332,576.324,0.0586752,0.0527606
4.29359e-3,3.32004,1.05480e-3,584.712,20.00,-91.2356,-0.128981,20.0255,-8.27711,584.712,0.242797,0.0577685
4.51561e-3,3.63478,1.03495e-3,593.101,20.00,-92.1382,-0.130257,20.0156,-6.97404,593.101,0.255352,0.0632450
0.0133823,3.97956,1.00567e-3,601.489,20.00,-93.0964,-0.131612,20.0255,-5.87845,601.489,0.756752,0.0692442
7.15580e-3,4.36046,1.06665e-3,609.944,20.00,-94.6335,-0.133785,20.0260,-4.97715,609.944,0.404651,0.0758718
6.37142e-3,4.77673,1.37318e-3,618.398,20.00,-95.0728,-0.134406,20.0192,-4.16673,618.398,0.360295,0.0831149
0.0118239,5.23024,1.59293e-3,626.786,20.00,-96.3696,-0.136239,20.0229,-3.52288,626.786,0.668626,0.0910059
0.0105101,5.72622,1.63722e-3,635.175,20.00,-96.6534,-0.136640,20.0334,-2.94769,635.175,0.594333,0.0996360
7.41030e-3,6.26950,1.65820e-3,643.564,20.00,-96.3946,-0.136275,20.0164,-2.45237,643.564,0.419042,0.109089
7.17345e-3,6.86349,1.50863e-3,651.952,20.00,-96.0433,-0.135778,20.0262,-2.03881,651.952,0.405649,0.119425
0.0118331,7.51988,1.51067e-3,660.406,20.00,-96.6269,-0.136603,20.0127,-1.70874,660.406,0.669148,0.130846
0.0144796,8.23950,1.53853e-3,668.860,20.00,-97.7404,-0.138177,20.0277,-1.43970,668.860,0.818804,0.143367
0.0157660,9.02015,1.45811e-3,677.249,20.00,-98.4549,-0.139187,20.0223,-1.21007,677.249,0.891548,0.156950
0.0140995,9.87635,1.43635e-3,685.638,20.00,-98.4621,-0.139198,20.0303,-1.00943,685.638,0.797310,0.171848
0.0128515,10.8125,1.47092e-3,694.026,20.00,-97.3655,-0.137647,20.0264,-0.832823,694.026,0.726736,0.188137
0.0197411,11.8379,1.50450e-3,702.415,20.00,-97.6096,-0.137992,20.0162,-0.696533,702.415,1.11633,0.205979
0.0211691,12.9704,1.50567e-3,710.869,20.00,-98.9198,-0.139845,20.0254,-0.588003,710.869,1.19708,0.225684
0.0177838,14.2100,1.47080e-3,719.323,20.00,-98.9651,-0.139909,20.0208,-0.490111,719.323,1.00565,0.247253
0.0242009,15.5576,1.45366e-3,727.712,20.00,-98.8936,-0.139808,20.0184,-0.408583,727.712,1.36853,0.270702
0.0261615,17.0333,1.45418e-3,736.100,20.00,-99.8940,-0.141222,20.0294,-0.344304,736.100,1.47940,0.296379
0.0249521,18.6484,1.48026e-3,744.489,20.00,-99.7279,-0.140987,20.0192,-0.286771,744.489,1.41101,0.324481
0.0324591,20.4324,1.46656e-3,752.943,20.00,-99.9939,-0.141363,20.0146,-0.239516,752.943,1.83552,0.355523
0.0304103,22.3849,1.45461e-3,761.397,20.00,-100.378,-0.141906,20.0212,-0.200321,761.397,1.71966,0.389497
0.0376408,24.5088,1.47964e-3,769.786,20.00,-100.744,-0.142423,20.0142,-0.167716,769.786,2.12854,0.426452
0.0384627,26.8327,1.47590e-3,778.174,20.00,-100.673,-0.142323,20.0143,-0.139825,778.174,2.17501,0.466889
0.0424407,29.3774,1.47524e-3,786.563,20.00,-100.852,-0.142576,20.0220,-0.116858,786.563,2.39997,0.511166
0.0484403,32.1637,1.49512e-3,794.952,20.00,-100.838,-0.142556,20.0181,-0.0974742,794.952,2.73924,0.559648
0.0525428,35.2392,1.49799e-3,803.406,20.00,-101.530,-0.143535,20.0115,-0.0817605,803.406,2.97123,0.613160
0.0583181,38.6085,1.51977e-3,811.860,20.00,-101.636,-0.143684,20.0190,-0.0681839,811.860,3.29781,0.671786
0.0639466,42.2700,1.52068e-3,820.249,20.00,-101.706,-0.143783,20.0162,-0.0569222,820.249,3.61609,0.735496
0.0707453,46.2787,1.55392e-3,828.637,20.00,-102.190,-0.144468,20.0161,-0.0477143,828.637,4.00055,0.805248
0.0785552,50.6682,1.59543e-3,837.026,20.00,-102.127,-0.144379,20.0156,-0.0397804,837.026,4.44219,0.881625
0.0899807,55.4733,1.60328e-3,845.414,20.00,-101.916,-0.144080,20.0170,-0.0331187,845.414,5.08829,0.965233
0.0967213,60.7775,1.61894e-3,853.869,20.00,-102.160,-0.144425,20.0226,-0.0276563,853.869,5.46946,1.05753
0.102969,66.5890,1.64282e-3,862.323,20.00,-102.914,-0.145491,20.0196,-0.0232098,862.323,5.82275,1.15865
0.132604,72.9012,1.66826e-3,870.711,20.00,-102.031,-0.144244,20.0189,-0.0191984,870.711,7.49860,1.26848
0.154199,79.8202,1.69213e-3,879.100,20.00,-102.405,-0.144772,20.0202,-0.0160729,879.100,8.71973,1.38887
0.138970,87.3877,1.70947e-3,887.489,20.00,-102.947,-0.145538,20.0204,-0.0134808,887.489,7.85857,1.52054
0.158451,95.6073,1.72613e-3,895.812,20.00,-103.114,-0.145774,20.0276,-0.0112807,895.812,8.96018,1.66356