File: Viscosity/csv/oskt 6_psb_thfdmf.csv
Stress,Shear rate,Viscosity,Step time,Temperature,Normal stress
MPa,1/s,Pa.s,s,Â°C,MPa
8.02E-11,6.30E-03,0.0127156,3.59091,20,-2.73E-05
-5.17E-10,7.36E-03,-0.0702085,10.5094,20,-2.92E-05
-2.97E-10,8.21E-03,-0.0361736,17.5637,20,-3.02E-05
-3.41E-10,9.19E-03,-0.0370542,24.576,20,-3.12E-05
-4.97E-11,0.0103519,-4.80E-03,31.5228,20,-3.23E-05
-3.25E-10,0.0115151,-0.0281992,38.4697,20,-3.36E-05
2.39E-10,0.0128831,0.0185283,45.482,20,-3.43E-05
4.83E-10,0.0144595,0.0333983,52.4944,20,-3.53E-05
5.56E-10,0.0161833,0.0343738,59.4412,20,-3.58E-05
5.84E-10,0.0181078,0.0322476,66.388,20,-3.67E-05
7.09E-10,0.0202737,0.0349959,73.4004,20,-3.71E-05
7.85E-10,0.0227202,0.0345599,80.4127,20,-3.82E-05
7.26E-10,0.0254207,0.028551,87.3595,20,-3.85E-05
6.49E-10,0.0284181,0.0228429,94.3063,20,-3.94E-05
9.46E-10,0.0318151,0.0297481,101.253,20,-3.94E-05
1.02E-09,0.0356217,0.0286222,108.266,20,-4.04E-05
1.31E-09,0.0398862,0.0328129,115.278,20,-4.18E-05
1.44E-09,0.0446291,0.0323482,122.225,20,-4.34E-05
1.77E-09,0.0499221,0.0354329,129.171,20,-4.37E-05
1.90E-09,0.0559127,0.0339936,136.184,20,-4.47E-05
2.17E-09,0.0625255,0.0347392,143.196,20,-4.64E-05
2.38E-09,0.0699789,0.0340133,150.143,20,-4.70E-05
2.52E-09,0.0782793,0.0322157,157.09,20,-4.76E-05
2.71E-09,0.087591,0.0309293,164.037,20,-4.85E-05
2.88E-09,0.0981125,0.0293599,171.049,20,-4.98E-05
2.90E-09,0.10986,0.0264352,178.061,20,-5.04E-05
3.07E-09,0.12294,0.0249915,185.008,20,-5.08E-05
3.11E-09,0.137577,0.022604,191.955,20,-5.27E-05
3.01E-09,0.154035,0.0195633,198.967,20,-5.38E-05
2.53E-09,0.172602,0.0146422,205.98,20,-5.49E-05
1.90E-09,0.193069,9.82E-03,212.926,20,-5.58E-05
1.26E-09,0.215968,5.84E-03,219.873,20,-5.68E-05
6.76E-10,0.241889,2.80E-03,226.886,20,-5.76E-05
1.06E-10,0.270953,3.92E-04,233.898,19.99,-5.82E-05
3.61E-10,0.302925,1.19E-03,240.845,20,-5.93E-05
9.35E-10,0.338976,2.76E-03,247.792,20,-5.97E-05
1.76E-09,0.379207,4.65E-03,254.738,20,-6.07E-05
2.66E-09,0.424734,6.27E-03,261.751,20.01,-6.18E-05
3.21E-09,0.475669,6.76E-03,268.763,20,-6.32E-05
2.95E-09,0.532161,5.54E-03,275.71,20,-6.46E-05
2.12E-09,0.595347,3.56E-03,282.657,19.99,-6.49E-05
2.43E-09,0.666699,3.64E-03,289.669,20,-6.62E-05
3.94E-09,0.746508,5.27E-03,296.681,20,-6.71E-05
5.02E-09,0.83521,6.01E-03,303.628,20,-6.77E-05
8.25E-09,0.934497,8.82E-03,310.575,20,-6.98E-05
1.23E-08,1.04636,0.0117512,317.587,20,-7.13E-05
1.66E-08,1.17181,0.0141712,324.6,20,-7.25E-05
1.76E-08,1.31119,0.0133964,331.547,20,-7.25E-05
1.54E-08,1.46674,0.0104955,338.493,20,-7.43E-05
1.51E-08,1.64069,9.18E-03,345.44,20,-7.57E-05
1.15E-08,1.83791,6.24E-03,352.453,20,-7.81E-05
5.11E-09,2.05811,2.48E-03,359.465,20,-8.08E-05
3.42E-09,2.30196,1.49E-03,366.412,20,-8.22E-05
1.01E-08,2.57526,3.94E-03,373.359,20,-8.38E-05
9.83E-09,2.88454,3.41E-03,380.371,20,-8.69E-05
1.04E-08,3.22963,3.22E-03,387.383,20,-9.00E-05
8.67E-09,3.61379,2.40E-03,394.33,20,-9.36E-05
8.73E-09,4.04225,2.16E-03,401.277,20,-9.63E-05
1.18E-08,4.52204,2.61E-03,408.224,19.99,-9.89E-05
1.61E-08,5.06459,3.18E-03,415.236,20,-1.01E-04
1.77E-08,5.67142,3.13E-03,422.248,20,-1.03E-04
2.11E-08,6.34476,3.32E-03,429.195,20,-1.06E-04
3.29E-08,7.0978,4.64E-03,436.142,20,-1.07E-04
2.58E-08,7.94909,3.24E-03,443.154,20,-1.12E-04
2.90E-08,8.90205,3.26E-03,450.167,20,-1.15E-04
2.76E-08,9.95855,2.77E-03,457.114,20,-1.20E-04
3.50E-08,11.1406,3.14E-03,464.06,20,-1.23E-04
4.47E-08,12.4766,3.58E-03,471.073,20,-1.24E-04
4.56E-08,13.9726,3.27E-03,478.085,20,-1.27E-04
4.71E-08,15.6305,3.01E-03,485.032,20,-1.32E-04
5.54E-08,17.4862,3.17E-03,491.979,20,-1.35E-04
6.54E-08,19.5622,3.34E-03,498.926,20,-1.37E-04
6.73E-08,21.9076,3.07E-03,505.938,20,-1.45E-04
8.07E-08,24.5336,3.29E-03,512.95,20,-1.48E-04
8.51E-08,27.4462,3.10E-03,519.897,20,-1.53E-04
9.90E-08,30.7039,3.22E-03,526.844,20,-1.55E-04
1.08E-07,34.3855,3.14E-03,533.856,20,-1.60E-04
1.20E-07,38.5079,3.11E-03,540.869,20,-1.64E-04
1.35E-07,43.0786,3.14E-03,547.815,20,-1.66E-04
1.50E-07,48.1924,3.12E-03,554.762,20,-1.68E-04
1.67E-07,53.913,3.10E-03,561.709,20,-1.74E-04
1.87E-07,60.3777,3.10E-03,568.721,20,-1.78E-04
2.10E-07,67.6148,3.11E-03,575.734,20,-1.82E-04
2.34E-07,75.6419,3.09E-03,582.681,20,-1.87E-04
2.61E-07,84.6204,3.09E-03,589.627,20,-1.91E-04
2.90E-07,94.5634,3.07E-03,596.509,20,-1.98E-04