File: Viscosity/csv/peo_su8_00_100_0.csv
Filename,peo_su8_00_100_0
Instrument name,5333-0457
Operator,Osamu Katagiri
rundate,12/12/2019
Sample name,OSKT 100_PEO_SU8
Geometry name,60mm 0.9969° cone plate, Peltier plate Steel
Procedure name,Sample
,Flow ramp
proceduresegments,Flow ramp
[step]
Flow ramp - 1
Stress,Shear rate,Viscosity,Step time,Temperature,Normal stress,Axial force,Gap,Normal stress coefficient,Time,Torque,Velocity
Pa,1/s,Pa.s,s,°C,Pa,N,µm,Pa.s²,s,µN.m,rad/s
84.1471,6.62671e-3,12265.7,17.5637,19.99,2612.19,3.69290,20.0237,5.94852e7,17.5637,4758.41,1.15305e-4
102.628,7.98072e-3,12496.3,24.5760,20.00,2641.36,3.73413,20.0258,4.14709e7,24.5760,5803.45,1.38864e-4
116.015,9.46532e-3,12316.3,31.5228,19.99,2631.68,3.72045,20.0196,2.93739e7,31.5228,6560.52,1.64696e-4
124.831,0.0109913,12011.0,38.4697,20.00,2647.63,3.74300,20.0165,2.19159e7,38.4697,7059.02,1.91248e-4
130.616,0.0125626,11459.5,45.4820,20.00,2634.78,3.72483,20.0207,1.66949e7,45.4820,7386.17,2.18589e-4
134.446,0.0142420,10791.6,52.4944,20.00,2625.17,3.71125,20.0151,1.29425e7,52.4944,7602.73,2.47809e-4
137.245,0.0160229,10103.6,59.4412,20.00,2616.04,3.69835,20.0135,1.01898e7,59.4412,7761.04,2.78797e-4
139.130,0.0179582,9425.39,66.3880,20.00,2607.08,3.68567,20.0117,8084000,66.3880,7867.64,3.12473e-4
140.900,0.0201669,8750.45,73.4004,20.00,2610.62,3.69067,20.0187,6418970,73.4004,7967.72,3.50903e-4
142.435,0.0226246,8111.21,80.4127,20.00,2592.00,3.66436,20.0185,5063770,80.4127,8054.49,3.93667e-4
143.714,0.0253330,7520.07,87.3595,20.00,2576.78,3.64284,20.0138,4015190,87.3595,8126.86,4.40793e-4
145.030,0.0283447,6968.17,94.3063,20.00,2575.31,3.64077,20.0186,3205440,94.3063,8201.25,4.93196e-4
146.201,0.0317252,6451.17,101.253,20.00,2548.10,3.60230,20.0136,2531680,101.253,8267.46,5.52017e-4
147.252,0.0355634,5964.09,108.266,20.00,2548.88,3.60339,20.0123,2015320,108.266,8326.92,6.18802e-4
148.349,0.0397983,5517.68,115.278,20.00,2546.30,3.59974,20.0220,1607610,115.278,8388.93,6.92489e-4
149.418,0.0445692,5099.03,122.225,20.00,2532.69,3.58050,20.0123,1275000,122.225,8449.38,7.75502e-4
150.433,0.0498516,4715.16,129.171,20.01,2526.01,3.57106,20.0198,1016430,129.171,8506.79,8.67415e-4
151.193,0.0558649,4353.43,136.184,20.00,2496.75,3.52969,20.0191,800013,136.184,8549.75,9.72047e-4
152.100,0.0624710,4025.77,143.196,20.00,2511.81,3.55099,20.0192,643621,143.196,8601.04,1.08699e-3
153.049,0.0698791,3721.14,150.143,20.00,2488.21,3.51762,20.0203,509555,150.143,8654.72,1.21589e-3
154.212,0.0782145,3438.67,157.090,20.00,2503.37,3.53905,20.0206,409214,157.090,8720.51,1.36093e-3
155.088,0.0875269,3178.81,164.037,20.00,2471.11,3.49344,20.0139,322559,164.037,8770.02,1.52296e-3
156.003,0.0980224,2937.15,171.049,20.00,2467.54,3.48840,20.0206,256811,171.049,8821.75,1.70559e-3
157.136,0.109817,2712.29,178.061,20.00,2468.37,3.48957,20.0091,204680,178.061,8885.83,1.91080e-3
158.149,0.122855,2507.74,185.008,20.00,2442.76,3.45338,20.0199,161843,185.008,8943.12,2.13768e-3
159.095,0.137492,2318.52,191.955,20.00,2446.44,3.45858,20.0177,129414,191.955,8996.63,2.39235e-3
160.197,0.153965,2142.18,198.967,20.00,2431.75,3.43781,20.0163,102583,198.967,9058.92,2.67899e-3
161.314,0.172444,1978.14,205.980,20.00,2427.43,3.43170,20.0268,81630.1,205.980,9122.11,3.00052e-3
162.288,0.192965,1827.47,212.926,20.00,2408.62,3.40511,20.0170,64686.1,212.926,9177.16,3.35759e-3
162.981,0.215912,1686.85,219.873,20.00,2386.70,3.37411,20.0149,51196.7,219.873,9216.35,3.75687e-3
163.805,0.241787,1554.64,226.886,20.00,2386.61,3.37399,20.0280,40824.2,226.886,9262.97,4.20708e-3
164.195,0.270848,1431.15,233.898,20.00,2342.09,3.31105,20.0185,31926.5,233.898,9285.02,4.71275e-3
164.539,0.302979,1318.58,240.845,20.00,2346.38,3.31711,20.0182,25560.8,240.845,9304.45,5.27182e-3
164.788,0.339021,1215.30,247.792,20.00,2318.15,3.27720,20.0254,20169.2,247.792,9318.53,5.89895e-3
165.338,0.379171,1121.84,254.738,20.00,2314.04,3.27139,20.0232,16095.3,254.738,9349.62,6.59757e-3
166.652,0.424663,1036.42,261.751,20.00,2322.56,3.28344,20.0281,12878.9,261.751,9423.96,7.38911e-3
168.062,0.475522,959.455,268.763,20.00,2311.74,3.26814,20.0223,10223.4,268.763,9503.70,8.27407e-3
169.937,0.532015,890.165,275.710,20.00,2339.37,3.30721,20.0244,8265.15,275.710,9609.74,9.25705e-3
171.805,0.595183,825.364,282.657,20.00,2333.60,3.29905,20.0277,6587.57,282.657,9715.36,0.0103562
173.804,0.666556,763.644,289.669,20.00,2345.52,3.31590,20.0248,5279.16,289.669,9828.41,0.0115981
174.609,0.746683,705.232,296.681,20.00,2333.05,3.29827,20.0262,4184.57,296.681,9873.91,0.0129923
174.812,0.835246,651.309,303.628,20.00,2327.36,3.29023,20.0211,3336.07,303.628,9885.37,0.0145333
175.321,0.934449,600.108,310.575,20.00,2335.99,3.30242,20.0251,2675.22,310.575,9914.15,0.0162594
176.380,1.04640,551.547,317.587,20.00,2321.01,3.28125,20.0228,2119.74,317.587,9974.06,0.0182073
176.448,1.17203,507.315,324.600,20.00,2294.17,3.24330,20.0153,1670.12,324.600,9977.88,0.0203933
175.640,1.31107,467.767,331.547,20.00,2249.50,3.18016,20.0209,1308.68,331.547,9932.23,0.0228126
176.697,1.46661,430.060,338.493,20.00,2242.67,3.17050,20.0291,1042.64,338.493,9991.98,0.0255190
178.525,1.64076,394.811,345.440,20.00,2239.56,3.16611,20.0199,831.903,345.440,10095.4,0.0285492
177.043,1.83791,363.666,352.453,20.00,2143.13,3.02978,20.0207,634.453,352.453,10011.6,0.0319796
175.864,2.05778,335.722,359.465,20.00,2100.97,2.97017,20.0357,496.160,359.465,9944.86,0.0358053
178.866,2.30184,309.675,366.412,19.99,2139.97,3.02531,20.0334,403.883,366.412,10114.6,0.0400520
181.608,2.57527,286.998,373.359,20.00,2184.53,3.08830,20.0282,329.392,373.359,10269.7,0.0448095
182.168,2.88436,262.873,380.371,20.00,2181.82,3.08447,20.0164,262.252,380.371,10301.3,0.0501878
185.096,3.23019,237.922,387.383,20.00,2197.19,3.10621,20.0159,210.578,387.383,10467.0,0.0562052
173.984,3.61412,212.700,394.330,20.00,2105.05,2.97595,20.0239,161.161,394.330,9838.55,0.0628855
166.792,4.04322,187.922,401.277,20.00,1981.02,2.80060,20.0304,121.181,401.277,9431.87,0.0703519
158.559,4.52283,162.155,408.224,20.00,1880.25,2.65814,20.0254,91.9166,408.224,8966.28,0.0786971
149.764,5.06539,139.401,415.236,20.00,1697.25,2.39943,20.0245,66.1487,415.236,8468.96,0.0881375
135.079,5.67285,120.638,422.248,20.00,1449.97,2.04984,20.0251,45.0563,422.248,7638.56,0.0987074
125.635,6.34492,103.458,429.195,20.00,1500.40,2.12114,20.0409,37.2696,429.195,7104.51,0.110401
124.495,7.09803,86.4177,436.142,20.00,1550.56,2.19206,20.0185,30.7761,436.142,7040.04,0.123506
112.055,7.94880,71.8166,443.154,20.00,1391.72,1.96750,20.0339,22.0267,443.154,6336.57,0.138309
92.8408,8.90242,59.7317,450.167,20.00,1146.93,1.62143,20.0296,14.4717,450.167,5250.02,0.154902
82.3574,9.95811,50.0733,457.114,20.00,1022.07,1.44492,20.0341,10.3069,457.114,4657.20,0.173271
77.0598,11.1404,41.4925,464.060,20.00,874.423,1.23619,20.0285,7.04566,464.060,4357.63,0.193842
78.4140,12.4772,35.7847,471.073,20.00,1058.14,1.49591,20.0352,6.79683,471.073,4434.21,0.217104
66.7867,13.9708,31.1120,478.085,20.00,974.856,1.37817,20.0307,4.99455,478.085,3776.70,0.243092
68.1525,15.6305,27.9924,485.032,20.00,930.237,1.31509,20.0293,3.80759,485.032,3853.93,0.271969
62.8107,17.4854,24.3269,491.979,20.00,914.656,1.29306,20.0301,2.99162,491.979,3551.86,0.304246
69.3843,19.5608,21.1069,498.926,20.00,1283.43,1.81441,20.0287,3.35429,498.926,3923.59,0.340357
59.3704,21.9089,18.4090,505.938,20.00,957.824,1.35409,20.0315,1.99547,505.938,3357.32,0.381214
50.0954,24.5317,16.2113,512.950,20.00,817.094,1.15514,20.0281,1.35774,512.950,2832.83,0.426850
52.9249,27.4470,14.0275,519.897,20.00,778.399,1.10044,20.0302,1.03326,519.897,2992.83,0.477577
51.0946,30.6997,12.7719,526.844,20.00,883.597,1.24916,20.0270,0.937533,526.844,2889.33,0.534173
51.3684,34.3848,11.6380,533.856,20.00,741.989,1.04896,20.0327,0.627573,533.856,2904.81,0.598295
56.7736,38.5112,10.4470,540.869,20.00,919.229,1.29953,20.0324,0.619798,540.869,3210.47,0.670093
48.2798,43.0759,9.54448,547.815,20.00,747.286,1.05645,20.0321,0.402734,547.815,2730.16,0.749519
47.3872,48.1893,8.58870,554.762,20.00,668.345,0.944851,20.0275,0.287806,554.762,2679.68,0.838492
49.6467,53.9127,7.49232,561.709,20.00,721.340,1.01977,20.0313,0.248175,561.709,2807.45,0.938078
46.2913,60.3816,6.91888,568.721,20.00,601.261,0.850013,20.0331,0.164913,568.721,2617.71,1.05064
43.8390,67.6005,6.27747,575.734,20.00,504.706,0.713511,20.0343,0.110443,575.734,2479.03,1.17625
49.7973,75.6452,5.68689,582.681,20.00,696.549,0.984724,20.0252,0.121728,582.681,2815.97,1.31622
44.6666,84.6097,5.26158,589.627,20.00,507.162,0.716983,20.0362,0.0708445,589.627,2525.83,1.47221
46.7138,94.5740,4.86280,596.509,20.00,592.887,0.838174,20.0287,0.0662869,596.509,2641.61,1.64558