File: Viscosity/csv/peo_su8_01_000_1.csv
Filename,peo_su8_01_000_1
Instrument name,5333-0457
Operator,Osamu Katagiri
rundate,28/01/2020
Sample name,PEO_SU8_01_000
Geometry name,60mm 0.9969° cone plate, Peltier plate Steel
Procedure name,Sample
,Flow ramp
proceduresegments,Flow ramp
[step]
Flow ramp - 1
Stress,Shear rate,Viscosity,Step time,Temperature,Normal stress,Axial force,Gap,Normal stress coefficient,Time,Torque,Velocity
Pa,1/s,Pa.s,s,°C,Pa,N,µm,Pa.s²,s,µN.m,rad/s
-0.302570,7.20541e-3,0.0805622,3.81348,20.00,-180.608,-0.255328,20.0282,-3478720,3.81348,-17.1099,5.78100e-3
7.83212e-3,7.51981e-3,0.0852273,11.1412,20.01,-182.055,-0.257375,20.0282,-3219510,11.1412,0.442896,1.22175e-4
0.0122514,7.89558e-3,0.0902384,18.5467,20.01,-184.896,-0.261390,20.0228,-2965910,18.5467,0.692799,1.35005e-4
0.0155387,8.59615e-3,0.0948391,25.9523,20.02,-187.061,-0.264452,20.0182,-2531490,25.9523,0.878694,1.48196e-4
0.0180893,9.70358e-3,0.0977076,33.2923,20.01,-189.573,-0.268002,20.0211,-2013320,33.2923,1.02293,1.62428e-4
0.0200414,0.0110859,0.0990655,40.6324,20.01,-191.690,-0.270996,20.0119,-1559770,40.6324,1.13331,1.78061e-4
0.0224998,0.0126649,0.100233,47.9724,20.00,-193.639,-0.273750,20.0141,-1207230,47.9724,1.27234,1.94858e-4
0.0251129,0.0144675,0.0999848,55.3124,20.00,-194.935,-0.275583,20.0076,-931334,55.3124,1.42010,2.13435e-4
0.0275425,0.0165258,0.0989282,62.7180,20.00,-196.202,-0.277374,20.0201,-718423,62.7180,1.55749,2.34141e-4
0.0298106,0.0188760,0.0971809,70.1236,20.00,-197.516,-0.279232,20.0266,-554347,70.1236,1.68575,2.56442e-4
0.0323100,0.0215597,0.0948698,77.4636,20.00,-198.048,-0.279984,20.0280,-426077,77.4636,1.82709,2.80953e-4
0.0344427,0.0246247,0.0925260,84.8036,20.00,-200.080,-0.282857,20.0258,-329961,84.8036,1.94769,3.07680e-4
0.0362406,0.0281231,0.0890687,92.1436,20.00,-201.152,-0.284372,20.0347,-254331,92.1436,2.04935,3.37019e-4
0.0379960,0.0319239,0.0853836,99.4837,20.00,-202.074,-0.285676,20.0251,-198280,99.4837,2.14862,3.69080e-4
0.0398631,0.0362385,0.0818664,106.889,20.00,-203.283,-0.287384,20.0317,-154796,106.889,2.25421,4.04229e-4
0.0418159,0.0413891,0.0794668,114.295,20.00,-203.740,-0.288030,20.0294,-118934,114.295,2.36463,4.43409e-4
0.0425538,0.0472706,0.0768750,121.635,20.00,-205.565,-0.290611,20.0306,-91995.4,121.635,2.40636,4.85518e-4
0.0431527,0.0539873,0.0742131,128.975,20.00,-205.956,-0.291163,20.0243,-70662.7,128.975,2.44023,5.31507e-4
0.0438004,0.0616622,0.0723385,136.315,20.00,-206.649,-0.292143,20.0384,-54349.4,136.315,2.47685,5.82186e-4
0.0445820,0.0704301,0.0708191,143.655,20.00,-207.959,-0.293995,20.0223,-41923.8,143.655,2.52105,6.37284e-4
0.0466336,0.0804389,0.0685613,151.061,20.00,-209.190,-0.295735,20.0289,-32330.2,151.061,2.63707,6.98380e-4
0.0489296,0.0918708,0.0664509,158.466,20.00,-209.605,-0.296322,20.0304,-24834.0,158.466,2.76690,7.65480e-4
0.0501261,0.104945,0.0661482,165.806,20.00,-210.549,-0.297656,20.0151,-19117.3,165.806,2.83456,8.38312e-4
0.0514636,0.119880,0.0657846,173.146,20.00,-211.131,-0.298479,20.0133,-14691.2,173.146,2.91020,9.17881e-4
0.0539285,0.136927,0.0644760,180.486,20.00,-211.780,-0.299397,20.0107,-11295.5,180.486,3.04958,1.00346e-3
0.0571343,0.156404,0.0635776,187.826,20.00,-212.261,-0.300077,20.0127,-8677.05,187.826,3.23087,1.09895e-3
0.0603638,0.178640,0.0620303,195.232,19.99,-212.226,-0.300027,20.0202,-6650.29,195.232,3.41349,1.20468e-3
0.0626589,0.201565,0.0596614,202.637,20.00,-213.496,-0.301823,20.0218,-5254.86,202.637,3.54328,1.32033e-3
0.0646515,0.219315,0.0570217,209.977,20.00,-213.655,-0.302048,20.0302,-4441.97,209.977,3.65595,1.44611e-3
0.0665322,0.232924,0.0544946,217.317,20.00,-213.337,-0.301598,20.0195,-3932.23,217.317,3.76231,1.58356e-3
0.0719500,0.248877,0.0520365,224.657,20.00,-214.910,-0.303821,20.0268,-3469.66,224.657,4.06867,1.73378e-3
0.0808204,0.265922,0.0496893,231.997,20.00,-215.635,-0.304847,20.0319,-3049.37,231.997,4.57028,1.89901e-3
0.0861929,0.279019,0.0472890,239.403,20.00,-216.001,-0.305365,20.0213,-2774.53,239.403,4.87410,2.08152e-3
0.0911600,0.289230,0.0447671,246.809,20.00,-216.369,-0.305885,20.0331,-2586.47,246.809,5.15498,2.28126e-3
0.0964681,0.299818,0.0424386,254.149,20.00,-217.463,-0.307431,20.0351,-2419.19,254.149,5.45514,2.49801e-3
0.103803,0.310806,0.0404834,261.489,20.00,-217.960,-0.308134,20.0220,-2256.31,261.489,5.86992,2.73552e-3
0.110545,0.338143,0.0381025,268.829,20.00,-217.951,-0.308121,20.0301,-1906.15,268.829,6.25118,2.99596e-3
0.111219,0.370179,0.0368055,276.169,20.00,-218.468,-0.308852,20.0355,-1594.28,276.169,6.28927,3.28044e-3
0.114060,0.395517,0.0349253,283.574,20.00,-219.479,-0.310282,20.0350,-1403.02,283.574,6.44993,3.59581e-3
0.106972,0.440912,0.0336630,290.980,20.00,-219.559,-0.310395,20.0243,-1129.40,290.980,6.04913,3.94047e-3
0.0983684,0.503592,0.0328127,298.320,20.00,-220.636,-0.311917,20.0207,-870.000,298.320,5.56260,4.31495e-3
0.0947191,0.575074,0.0310529,305.660,20.00,-220.731,-0.312051,20.0259,-667.446,305.660,5.35624,4.72737e-3
0.0718876,0.652872,0.0303205,313.000,20.00,-221.938,-0.313758,20.0259,-520.686,313.000,4.06515,5.17338e-3
0.0605908,0.710297,0.0285403,320.340,20.00,-222.187,-0.314110,20.0292,-440.391,320.340,3.42633,5.66550e-3
0.0655090,0.745275,0.0271362,327.746,20.00,-222.722,-0.314866,20.0289,-400.987,327.746,3.70445,6.20976e-3
0.0589600,0.782012,0.0259900,335.151,20.00,-222.818,-0.315002,20.0317,-364.354,335.151,3.33411,6.80449e-3
0.0589073,0.815598,0.0248272,342.491,20.00,-223.836,-0.316441,20.0352,-336.494,342.491,3.33113,7.45073e-3
0.0632347,0.845435,0.0234543,349.831,20.00,-224.363,-0.317186,20.0294,-313.900,349.831,3.57584,8.15940e-3
0.0654943,0.876356,0.0221265,357.171,20.00,-224.208,-0.316967,20.0178,-291.937,357.171,3.70362,8.93604e-3
0.0629333,0.908457,0.0210486,364.511,20.00,-224.987,-0.318068,20.0292,-272.615,364.511,3.55880,9.78448e-3
0.0678218,0.941754,0.0200928,371.917,20.00,-225.290,-0.318497,20.0242,-254.020,371.917,3.83523,0.0107218
0.0709511,0.982176,0.0191207,379.322,20.00,-226.852,-0.320705,20.0249,-235.160,379.322,4.01219,0.0117495
0.0601329,1.03057,0.0182464,386.662,20.00,-227.391,-0.321467,20.0296,-214.102,386.662,3.40044,0.0128692
0.0550633,1.09448,0.0173580,394.002,20.00,-228.044,-0.322390,20.0269,-190.371,394.002,3.11375,0.0140873
0.0412288,1.21264,0.0165232,401.342,20.00,-228.394,-0.322885,20.0318,-155.317,401.342,2.33143,0.0154317
0.0342708,1.38518,0.0163609,408.683,20.00,-229.307,-0.324175,20.0319,-119.511,408.683,1.93797,0.0168951
0.0296584,1.58226,0.0162126,416.088,20.00,-228.367,-0.322846,20.0260,-91.2173,416.088,1.67714,0.0185155
0.0277926,1.72178,0.0157483,423.494,20.00,-227.555,-0.321699,20.0287,-76.7595,423.494,1.57164,0.0202878
0.0292149,1.78491,0.0150646,430.834,20.00,-226.788,-0.320614,20.0261,-71.1846,430.834,1.65207,0.0222147
0.0323299,1.85034,0.0143905,438.174,20.00,-227.116,-0.321078,20.0139,-66.3352,438.174,1.82821,0.0243315
0.0345088,1.91816,0.0137370,445.514,20.00,-229.024,-0.323775,20.0167,-62.2459,445.514,1.95143,0.0266369
0.0375924,2.08699,0.0130422,452.854,20.00,-230.931,-0.326471,20.0255,-53.0200,452.854,2.12580,0.0291739
0.0320257,2.28592,0.0136663,460.259,20.00,-232.952,-0.329328,20.0319,-44.5805,460.259,1.81101,0.0319698
0.0257068,2.50404,0.0145348,467.665,20.00,-233.833,-0.330574,20.0318,-37.2927,467.665,1.45369,0.0350349
0.0291770,2.86032,0.0144084,475.005,20.00,-234.270,-0.331191,20.0264,-28.6342,475.005,1.64992,0.0383597
0.0416078,3.26660,0.0138150,482.345,20.00,-234.988,-0.332206,20.0300,-22.0218,482.345,2.35286,0.0420074
0.0465696,3.73156,0.0137938,489.685,20.00,-234.718,-0.331825,20.0285,-16.8564,489.685,2.63345,0.0459992
0.0488833,4.26324,0.0140466,497.025,20.00,-234.347,-0.331301,20.0174,-12.8938,497.025,2.76428,0.0503698
0.0481240,4.85933,0.0144964,504.431,19.99,-234.592,-0.331647,20.0126,-9.93486,504.431,2.72135,0.0552002
0.0519239,4.99117,0.0148452,511.836,20.00,-235.100,-0.332364,20.0183,-9.43729,511.836,2.93623,0.0604888
0.0573643,5.46255,0.0137457,519.176,20.00,-234.639,-0.331713,20.0296,-7.86339,519.176,3.24387,0.0662390
0.0652472,6.08982,0.0133553,526.516,20.00,-233.157,-0.329617,20.0182,-6.28693,526.516,3.68964,0.0725332
0.0733127,6.91436,0.0132388,533.856,20.00,-231.652,-0.327491,20.0241,-4.84544,533.856,4.14573,0.0794228
0.0910032,7.89892,0.0133215,541.196,20.00,-232.866,-0.329207,20.0112,-3.73225,541.196,5.14611,0.0869680
0.0798853,9.02426,0.0135374,548.602,20.00,-235.135,-0.332414,20.0269,-2.88732,548.602,4.51741,0.0953108
0.0863008,10.3077,0.0133134,556.007,20.00,-233.766,-0.330479,20.0229,-2.20016,556.007,4.88020,0.104451
0.0845973,11.7744,0.0132002,563.347,20.00,-237.931,-0.336367,20.0092,-1.71622,563.347,4.78386,0.114369
0.102256,13.4515,0.0133608,570.688,20.00,-238.987,-0.337859,20.0254,-1.32078,570.688,5.78244,0.125241
0.107773,15.3649,0.0131747,578.028,20.00,-238.475,-0.337137,20.0214,-1.01014,578.028,6.09440,0.137135
0.122457,17.5528,0.0132545,585.368,20.00,-236.628,-0.334525,20.0259,-0.768024,585.368,6.92476,0.150168
0.138793,20.0506,0.0131741,592.773,20.00,-234.335,-0.331283,20.0179,-0.582883,592.773,7.84858,0.164568
0.141085,22.9052,0.0132088,600.179,20.00,-237.647,-0.335966,20.0271,-0.452965,600.179,7.97816,0.180345
0.152967,26.1657,0.0132110,607.519,20.00,-240.986,-0.340685,20.0247,-0.351986,607.519,8.65009,0.197480
0.168227,29.8903,0.0132058,614.859,20.00,-239.246,-0.338226,20.0292,-0.267783,614.859,9.51302,0.216239
0.193138,34.1446,0.0131730,622.199,20.00,-236.927,-0.334948,20.0271,-0.203221,622.199,10.9217,0.236794
0.199628,39.0052,0.0131777,629.539,20.00,-239.388,-0.338426,20.0228,-0.157346,629.539,11.2887,0.259280
0.219874,44.5572,0.0131650,636.944,20.00,-242.195,-0.342395,20.0295,-0.121991,636.944,12.4336,0.284151
0.246922,50.9000,0.0131672,644.350,20.00,-238.266,-0.336841,20.0230,-0.0919660,644.350,13.9631,0.311395
0.261882,58.1456,0.0131694,651.690,20.00,-240.956,-0.340644,20.0296,-0.0712697,651.690,14.8091,0.340980
0.288210,66.4226,0.0131717,659.030,20.00,-242.020,-0.342148,20.0276,-0.0548554,659.030,16.2979,0.373377
0.317117,75.8779,0.0131739,666.370,20.00,-239.992,-0.339281,20.0275,-0.0416838,666.370,17.9326,0.408850
0.345286,86.6791,0.0131761,673.710,20.00,-243.413,-0.344117,20.0269,-0.0323977,673.710,19.5255,0.447692
0.379419,99.0179,0.0131783,681.116,20.00,-241.372,-0.341232,20.0154,-0.0246184,681.116,21.4557,0.490629
0.415845,113.113,0.0131806,688.521,20.00,-240.983,-0.340681,20.0151,-0.0188348,688.521,23.5155,0.537676
0.452199,129.215,0.0131828,695.861,20.00,-243.348,-0.344025,20.0220,-0.0145748,695.861,25.5713,0.588751
0.497829,147.608,0.0131850,703.201,20.00,-241.508,-0.341423,20.0168,-0.0110843,703.201,28.1516,0.644694
0.543023,168.620,0.0131872,710.541,20.00,-241.858,-0.341918,20.0218,-8.50627e-3,710.541,30.7072,0.705940
0.594763,192.624,0.0131894,717.881,20.00,-242.561,-0.342913,20.0176,-6.53737e-3,717.881,33.6331,0.773011
0.650555,220.044,0.0131917,725.287,20.00,-242.287,-0.342525,20.0206,-5.00395e-3,725.287,36.7880,0.847147
0.711406,251.365,0.0131764,732.693,20.00,-243.827,-0.344703,20.0266,-3.85899e-3,732.693,40.2291,0.928374
0.779744,287.141,0.0131413,740.033,20.00,-243.541,-0.344298,20.0249,-2.95380e-3,740.033,44.0935,1.01657
0.852200,328.016,0.0131435,747.373,20.00,-243.132,-0.343720,20.0335,-2.25971e-3,747.373,48.1908,1.11315
0.934444,374.709,0.0131457,754.713,20.00,-243.781,-0.344638,20.0236,-1.73625e-3,754.713,52.8415,1.21892
1.02098,428.049,0.0131479,762.053,20.00,-243.414,-0.344118,20.0260,-1.32849e-3,762.053,57.7352,1.33472
1.12007,488.981,0.0131501,769.458,20.00,-244.832,-0.346123,20.0274,-1.02396e-3,769.458,63.3386,1.46273
1.22665,558.588,0.0131523,776.864,20.00,-244.288,-0.345354,20.0278,-7.82923e-4,776.864,69.3652,1.60298
1.34208,638.103,0.0131546,784.204,20.00,-244.013,-0.344966,20.0305,-5.99283e-4,784.204,75.8928,1.75527
1.46869,728.937,0.0131568,791.544,20.00,-245.542,-0.347126,20.0252,-4.62110e-4,791.544,83.0524,1.92204
1.60855,832.701,0.0131590,798.884,20.00,-244.273,-0.345333,20.0333,-3.52288e-4,798.884,90.9612,2.10465
1.75979,951.236,0.0131612,806.224,20.00,-244.260,-0.345315,20.0256,-2.69946e-4,806.224,99.5139,2.30460
1.92837,1086.64,0.0131634,813.629,20.00,-245.637,-0.347261,20.0185,-2.08026e-4,813.629,109.047,2.52563
2.11263,1241.33,0.0131657,821.035,20.00,-244.261,-0.345315,20.0239,-1.58518e-4,821.035,119.466,2.76779
2.31277,1418.03,0.0131679,828.375,20.00,-246.275,-0.348164,20.0364,-1.22475e-4,828.375,130.784,3.03075
2.53174,1619.89,0.0131701,835.715,20.00,-245.398,-0.346924,20.0193,-9.35193e-5,835.715,143.166,3.31869
2.77162,1850.48,0.0131723,843.055,20.00,-244.673,-0.345899,20.0250,-7.14526e-5,843.055,156.732,3.63399
3.03498,2113.90,0.0131745,850.395,20.00,-246.998,-0.349185,20.0261,-5.52746e-5,850.395,171.624,3.97924
3.32505,2414.81,0.0131768,857.801,20.00,-245.425,-0.346961,20.0291,-4.20875e-5,857.801,188.027,4.36088
3.64356,2758.56,0.0131790,865.206,20.00,-246.286,-0.348179,20.0165,-3.23651e-5,865.206,206.039,4.77901
3.98829,3151.24,0.0131812,872.546,20.00,-246.360,-0.348284,20.0089,-2.48090e-5,872.546,225.532,5.23305
4.36718,3599.82,0.0131834,879.886,20.00,-244.938,-0.346273,20.0190,-1.89015e-5,879.886,246.958,5.73022
4.78286,4112.24,0.0131782,887.226,20.00,-248.240,-0.350942,20.0241,-1.46797e-5,887.226,270.465,6.27464
5.23655,4475.60,0.0131414,894.566,20.00,-246.261,-0.348143,20.0199,-1.22940e-5,894.566,296.120,6.87077