File: Viscosity/csv/ps_thf_00_0.csv
Filename,ps_thf_00_0
Instrument name,5333-0457
Operator,Osamu Katagiri
rundate,11/12/2019
Sample name,OSKT 0_PS_THF
Geometry name,60mm 0.9969° cone plate, Peltier plate Steel
Procedure name,Sample
,Flow ramp
proceduresegments,Flow ramp
[step]
Flow ramp - 1
Stress,Shear rate,Viscosity,Step time,Temperature,Normal stress,Axial force,Gap,Normal stress coefficient,Time,Torque,Velocity
Pa,1/s,Pa.s,s,°C,Pa,N,µm,Pa.s²,s,µN.m,rad/s
-0.0411900,6.33322e-3,-6.50380,3.47463,19.95,-85.6626,-0.121103,20.0072,-2135710,3.47463,-2.32924,1.10198e-4
-9.97968e-3,7.35022e-3,-1.35774,10.5513,19.96,-84.9926,-0.120155,20.0142,-1573190,10.5513,-0.564337,1.27894e-4
-0.0100061,8.22584e-3,-1.21643,17.5637,19.97,-85.3621,-0.120678,20.0247,-1261550,17.5637,-0.565834,1.43129e-4
-9.64836e-3,9.22057e-3,-1.04639,24.5760,19.98,-85.5642,-0.120964,20.0206,-1006410,24.5760,-0.545602,1.60438e-4
-9.72462e-3,0.0103169,-0.942591,31.5228,19.99,-85.4215,-0.120762,20.0226,-802542,31.5228,-0.549914,1.79514e-4
-9.79364e-3,0.0115444,-0.848344,38.4697,19.99,-85.0538,-0.120242,20.0307,-638188,38.4697,-0.553818,2.00873e-4
-9.88632e-3,0.0129243,-0.764942,45.4820,19.99,-85.7936,-0.121288,20.0246,-513621,45.4820,-0.559058,2.24882e-4
-0.0100904,0.0144767,-0.697011,52.4944,19.99,-85.1188,-0.120334,20.0278,-406150,52.4944,-0.570599,2.51894e-4
-0.0100723,0.0161893,-0.622161,59.4412,20.00,-84.7960,-0.119878,20.0285,-323534,59.4412,-0.569578,2.81693e-4
-9.77315e-3,0.0181165,-0.539461,66.3880,19.99,-84.8835,-0.120001,20.0272,-258627,66.3880,-0.552659,3.15227e-4
-9.70665e-3,0.0202847,-0.478522,73.4004,20.00,-84.8766,-0.119992,20.0206,-206278,73.4004,-0.548898,3.52952e-4
-9.75018e-3,0.0227229,-0.429091,80.4127,20.00,-84.9486,-0.120093,20.0290,-164524,80.4127,-0.551359,3.95377e-4
-9.80432e-3,0.0254159,-0.385755,87.3595,20.00,-84.8345,-0.119932,20.0357,-131329,87.3595,-0.554421,4.42236e-4
-9.76412e-3,0.0284358,-0.343374,94.3063,20.00,-85.2273,-0.120487,20.0251,-105402,94.3063,-0.552148,4.94783e-4
-9.73593e-3,0.0318108,-0.306057,101.253,20.00,-84.1729,-0.118997,20.0276,-83180.8,101.253,-0.550554,5.53507e-4
-9.81463e-3,0.0356225,-0.275518,108.266,20.00,-84.8102,-0.119898,20.0261,-66834.5,108.266,-0.555004,6.19829e-4
-9.80961e-3,0.0398956,-0.245882,115.278,20.00,-84.8544,-0.119960,20.0238,-53311.9,115.278,-0.554720,6.94182e-4
-9.85359e-3,0.0446324,-0.220772,122.225,20.00,-85.1076,-0.120318,20.0284,-42723.5,122.225,-0.557207,7.76603e-4
-9.87982e-3,0.0499275,-0.197883,129.171,20.00,-84.9755,-0.120131,20.0296,-34089.0,129.171,-0.558691,8.68737e-4
-9.85220e-3,0.0559077,-0.176222,136.184,20.00,-84.6387,-0.119655,20.0212,-27078.5,136.184,-0.557129,9.72793e-4
-9.83254e-3,0.0625353,-0.157232,143.196,20.00,-85.6903,-0.121142,20.0194,-21911.9,143.196,-0.556017,1.08811e-3
-9.79916e-3,0.0699642,-0.140060,150.143,20.00,-86.4047,-0.122152,20.0223,-17651.6,150.143,-0.554129,1.21737e-3
-9.86687e-3,0.0782884,-0.126032,157.090,20.00,-85.8199,-0.121325,20.0100,-14002.1,157.090,-0.557958,1.36222e-3
-9.87846e-3,0.0876018,-0.112765,164.037,20.00,-85.8700,-0.121396,20.0251,-11189.6,164.037,-0.558614,1.52427e-3
-0.0100339,0.0981090,-0.102273,171.049,20.00,-86.4229,-0.122178,20.0223,-8978.66,171.049,-0.567406,1.70709e-3
-0.0100886,0.109915,-0.0917850,178.061,20.00,-86.5121,-0.122304,20.0335,-7160.79,178.061,-0.570495,1.91252e-3
-9.85436e-3,0.122916,-0.0801717,185.008,20.00,-85.9821,-0.121554,20.0246,-5691.06,185.008,-0.557251,2.13873e-3
-9.53397e-3,0.137539,-0.0693183,191.955,20.00,-86.2204,-0.121891,20.0289,-4557.84,191.955,-0.539133,2.39317e-3
-9.00331e-3,0.154076,-0.0584342,198.967,20.00,-86.3029,-0.122008,20.0319,-3635.42,198.967,-0.509125,2.68092e-3
-8.31828e-3,0.172483,-0.0482267,205.980,20.00,-86.3063,-0.122013,20.0302,-2901.03,205.980,-0.470387,3.00119e-3
-7.54597e-3,0.193009,-0.0390965,212.926,20.00,-86.7769,-0.122678,20.0312,-2329.42,212.926,-0.426715,3.35835e-3
-6.89195e-3,0.215922,-0.0319187,219.873,20.00,-86.8648,-0.122802,20.0279,-1863.16,219.873,-0.389731,3.75704e-3
-5.84584e-3,0.241946,-0.0241618,226.886,20.00,-86.3848,-0.122124,20.0177,-1475.71,226.886,-0.330574,4.20985e-3
-4.47753e-3,0.270721,-0.0165393,233.898,20.00,-87.0304,-0.123036,20.0149,-1187.48,233.898,-0.253199,4.71054e-3
-3.34988e-3,0.303059,-0.0110536,240.845,20.00,-86.9990,-0.122992,20.0148,-947.242,240.845,-0.189431,5.27321e-3
-2.68619e-3,0.338987,-7.92419e-3,247.792,20.00,-87.7322,-0.124028,20.0236,-763.473,247.792,-0.151901,5.89835e-3
-1.99367e-3,0.379144,-5.25834e-3,254.738,20.00,-88.1878,-0.124673,20.0307,-613.479,254.738,-0.112739,6.59709e-3
-1.64572e-3,0.424772,-3.87436e-3,261.751,20.00,-88.1813,-0.124663,20.0300,-488.725,261.751,-0.0930633,7.39101e-3
-2.19888e-3,0.475710,-4.62232e-3,268.763,20.00,-88.0880,-0.124532,20.0251,-389.254,268.763,-0.124344,8.27733e-3
-3.68169e-3,0.532263,-6.91705e-3,275.710,20.00,-87.2397,-0.123332,20.0238,-307.937,275.710,-0.208195,9.26136e-3
-4.80276e-3,0.595493,-8.06519e-3,282.657,20.00,-87.0663,-0.123087,20.0291,-245.526,282.657,-0.271590,0.0103616
-5.15240e-3,0.666465,-7.73093e-3,289.669,20.00,-86.9218,-0.122883,20.0281,-195.692,289.669,-0.291361,0.0115965
-5.47986e-3,0.746888,-7.33692e-3,296.681,20.00,-86.7232,-0.122602,20.0198,-155.462,296.681,-0.309879,0.0129958
-6.40792e-3,0.835255,-7.67181e-3,303.628,20.00,-86.1333,-0.121768,20.0122,-123.462,303.628,-0.362359,0.0145334
-6.35072e-3,0.934437,-6.79631e-3,310.575,20.00,-85.9010,-0.121440,20.0079,-98.3781,310.575,-0.359125,0.0162592
-5.24517e-3,1.04643,-5.01246e-3,317.587,20.00,-86.1790,-0.121833,20.0145,-78.7019,317.587,-0.296607,0.0182078
-1.80532e-3,1.17168,-1.54079e-3,324.600,20.00,-85.9997,-0.121579,20.0180,-62.6434,324.600,-0.102089,0.0203873
2.21108e-3,1.31077,1.68685e-3,331.547,20.00,-85.7225,-0.121187,20.0105,-49.8930,331.547,0.125033,0.0228074
2.54413e-3,1.46681,1.73446e-3,338.493,20.00,-85.6989,-0.121154,20.0046,-39.8315,338.493,0.143867,0.0255225
3.60519e-3,1.64082,2.19719e-3,345.440,20.00,-85.2770,-0.120557,20.0159,-31.6746,345.440,0.203868,0.0285501
3.62729e-3,1.83763,1.97390e-3,352.453,20.00,-85.2680,-0.120545,20.0152,-25.2506,352.453,0.205119,0.0319746
1.64602e-3,2.05818,7.99749e-4,359.465,20.00,-84.3672,-0.119271,20.0307,-19.9163,359.465,0.0930805,0.0358122
1.63360e-4,2.30198,7.09647e-5,366.412,20.00,-84.1411,-0.118952,20.0315,-15.8783,366.412,9.23778e-3,0.0400545
1.87618e-3,2.57531,7.28526e-4,373.359,20.00,-84.4309,-0.119361,20.0289,-12.7304,373.359,0.106096,0.0448104
5.78621e-3,2.88420,2.00618e-3,380.371,20.00,-84.2845,-0.119154,20.0245,-10.1321,380.371,0.327202,0.0501849
3.58044e-3,3.23046,1.10834e-3,387.383,20.00,-84.4288,-0.119358,20.0253,-8.09025,387.383,0.202469,0.0562099
4.02454e-3,3.61299,1.11391e-3,394.330,20.00,-83.9131,-0.118629,20.0283,-6.42830,394.330,0.227582,0.0628659
4.59536e-3,4.04275,1.13669e-3,401.277,20.00,-83.8299,-0.118512,20.0303,-5.12916,401.277,0.259861,0.0703436
3.70411e-3,4.52207,8.19117e-4,408.224,20.00,-83.7540,-0.118404,20.0271,-4.09573,408.224,0.209462,0.0786839
6.69174e-3,5.06440,1.32133e-3,415.236,20.00,-83.7687,-0.118425,20.0177,-3.26608,415.236,0.378409,0.0881203
-1.50951e-3,5.67257,-2.66107e-4,422.248,20.00,-83.7753,-0.118434,20.0124,-2.60349,422.248,-0.0853609,0.0987026
-2.19703e-3,6.34476,-3.46275e-4,429.195,20.00,-83.8346,-0.118518,20.0371,-2.08254,429.195,-0.124239,0.110399
1.67958e-3,7.09720,2.36655e-4,436.142,20.00,-84.1608,-0.118980,20.0228,-1.67084,436.142,0.0949782,0.123491
3.70722e-3,7.94923,4.66363e-4,443.154,20.00,-82.9720,-0.117299,20.0319,-1.31305,443.154,0.209639,0.138316
5.15484e-3,8.90203,5.79064e-4,450.167,20.00,-82.6790,-0.116885,20.0138,-1.04332,450.167,0.291499,0.154895
5.55593e-3,9.95863,5.57901e-4,457.114,20.00,-82.8310,-0.117100,20.0290,-0.835206,457.114,0.314180,0.173280
4.38769e-3,11.1419,3.93803e-4,464.060,20.00,-82.6715,-0.116874,20.0110,-0.665949,464.060,0.248118,0.193868
9.24194e-4,12.4757,7.40796e-5,471.073,20.00,-83.2959,-0.117757,20.0266,-0.535173,471.073,0.0522620,0.217077
6.68286e-3,13.9723,4.78295e-4,478.085,20.00,-82.7430,-0.116975,20.0279,-0.423836,478.085,0.377907,0.243117
6.85173e-3,15.6310,4.38342e-4,485.032,20.00,-82.3114,-0.116365,20.0187,-0.336888,485.032,0.387456,0.271979
3.87961e-3,17.4872,2.21855e-4,491.979,20.00,-82.5655,-0.116724,20.0291,-0.269998,491.979,0.219387,0.304276
7.92242e-3,19.5615,4.05002e-4,498.926,20.00,-81.9525,-0.115858,20.0200,-0.214171,498.926,0.448002,0.340369
9.30892e-3,21.9086,4.24898e-4,505.938,20.00,-81.5748,-0.115324,20.0217,-0.169952,505.938,0.526407,0.381209
6.02281e-3,24.5335,2.45493e-4,512.950,20.00,-82.1527,-0.116141,20.0175,-0.136490,512.950,0.340582,0.426883
0.0111382,27.4467,4.05811e-4,519.897,20.00,-81.4607,-0.115162,20.0270,-0.108136,519.897,0.629848,0.477571
8.95602e-3,30.7037,2.91691e-4,526.844,20.00,-81.4214,-0.115107,20.0220,-0.0863687,526.844,0.506451,0.534244
0.0107611,34.3859,3.12950e-4,533.856,20.00,-81.2282,-0.114834,20.0282,-0.0686983,533.856,0.608523,0.598313
0.0143565,38.5088,3.72811e-4,540.869,20.00,-80.6656,-0.114038,20.0318,-0.0543962,540.869,0.811840,0.670052
0.0134841,43.0785,3.13013e-4,547.815,20.00,-80.4488,-0.113732,20.0265,-0.0433510,547.815,0.762509,0.749564
0.0157688,48.1928,3.27201e-4,554.762,20.00,-80.2918,-0.113510,20.0289,-0.0345706,554.762,0.891702,0.838554
0.0177847,53.9135,3.29875e-4,561.709,20.00,-79.6195,-0.112559,20.0259,-0.0273921,561.709,1.00570,0.938093
0.0204467,60.3782,3.38645e-4,568.721,20.00,-79.6043,-0.112538,20.0286,-0.0218362,568.721,1.15624,1.05058
0.0211485,67.6158,3.12775e-4,575.734,20.00,-79.6287,-0.112572,20.0296,-0.0174170,575.734,1.19592,1.17651
0.0252074,75.6424,3.33245e-4,582.681,20.00,-79.4596,-0.112333,20.0281,-0.0138873,582.681,1.42545,1.31617
0.0271607,84.6212,3.20968e-4,589.627,20.00,-79.6751,-0.112638,20.0268,-0.0111266,589.627,1.53590,1.47241
0.0307032,94.5650,3.24678e-4,596.509,20.00,-78.6718,-0.111220,20.0291,-8.79749e-3,596.509,1.73622,1.64543