File: Viscosity/csv/ps_thf_01_3.csv
Filename,ps_thf_01_3
Instrument name,5333-0457
Operator,Osamu Katagiri
rundate,18/12/2019
Sample name,PS_THF_01_3
Geometry name,60.0mm 0.996944° cone plate, Peltier plate Steel
Procedure name,Sample
,Flow ramp
proceduresegments,Flow ramp
[step]
Flow ramp - 1
Stress,Shear rate,Viscosity,Step time,Temperature,Normal stress,Axial force,Gap,Normal stress coefficient,Time,Torque,Velocity
Pa,1/s,Pa.s,s,°C,Pa,N,µm,Pa.s²,s,µN.m,rad/s
-0.996480,-0.0526338,18.9323,5.12444,20.00,9.23447,0.0130549,20.0285,3333.37,5.12444,-56.3496,-9.15826e-4
0.0283476,6.86995e-3,4.12632,11.1412,20.00,2.63547,3.72580e-3,20.0322,55840.6,11.1412,1.60302,1.19537e-4
0.0308267,7.53676e-3,4.11226,18.5467,20.00,1.09032,1.54141e-3,20.0262,19194.9,18.5467,1.74321,1.31139e-4
0.0342322,8.26578e-3,4.09357,25.9523,20.00,-1.44270,-2.03957e-3,20.0195,-21115.8,25.9523,1.93579,1.43824e-4
0.0367232,9.04745e-3,4.06366,33.2923,20.00,1.08382,1.53221e-3,20.0249,13240.5,33.2923,2.07665,1.57425e-4
0.0399660,9.89965e-3,4.03388,40.6324,20.00,-0.995883,-1.40790e-3,20.0325,-10161.7,40.6324,2.26002,1.72254e-4
0.0433615,0.0108614,3.99115,47.9724,20.00,-3.19041,-4.51033e-3,20.0296,-27044.3,47.9724,2.45204,1.88988e-4
0.0468368,0.0118885,3.95597,55.3124,20.00,-1.26919,-1.79427e-3,20.0280,-8979.93,55.3124,2.64856,2.06859e-4
0.0512815,0.0130486,3.90824,62.7180,20.00,-1.39987,-1.97902e-3,20.0334,-8221.64,62.7180,2.89990,2.27046e-4
0.0554655,0.0142913,3.86552,70.1236,20.00,-4.13440,-5.84487e-3,20.0224,-20242.8,70.1236,3.13650,2.48668e-4
0.0595292,0.0156554,3.82316,77.4636,20.00,-4.67667,-6.61148e-3,20.0104,-19081.2,77.4636,3.36630,2.72404e-4
0.0648116,0.0171561,3.76921,84.8036,20.00,-5.84149,-8.25821e-3,20.0179,-19846.6,84.8036,3.66501,2.98516e-4
0.0700237,0.0187848,3.71889,92.1436,20.00,-4.97445,-7.03246e-3,20.0253,-14097.1,92.1436,3.95975,3.26855e-4
0.0752861,0.0205579,3.67638,99.4837,20.00,-3.77889,-5.34228e-3,20.0274,-8941.39,99.4837,4.25733,3.57707e-4
0.0817734,0.0225420,3.63401,106.889,20.00,-6.01480,-8.50323e-3,20.0300,-11836.9,106.889,4.62418,3.92230e-4
0.0886388,0.0247090,3.59344,114.295,20.00,-5.93790,-8.39451e-3,20.0342,-9725.74,114.295,5.01240,4.29936e-4
0.0965648,0.0270685,3.56216,121.635,20.00,-5.03656,-7.12027e-3,20.0289,-6873.96,121.635,5.46061,4.70990e-4
0.104516,0.0296487,3.53780,128.975,20.00,-7.46738,-0.0105568,20.0255,-8494.87,128.975,5.91023,5.15886e-4
0.113870,0.0324890,3.51650,136.315,20.00,-5.38045,-7.60644e-3,20.0155,-5097.36,136.315,6.43922,5.65308e-4
0.124715,0.0355831,3.49805,143.655,20.00,-6.17425,-8.72864e-3,20.0193,-4876.38,143.655,7.05246,6.19144e-4
0.135748,0.0389984,3.48567,151.061,20.00,-6.61554,-9.35250e-3,20.0255,-4349.82,151.061,7.67636,6.78571e-4
0.148539,0.0427515,3.47517,158.466,20.00,-7.35772,-0.0104017,20.0305,-4025.69,158.466,8.39967,7.43875e-4
0.162171,0.0468245,3.46380,165.806,20.00,-6.39113,-9.03525e-3,20.0273,-2914.95,165.806,9.17058,8.14745e-4
0.177069,0.0512827,3.45425,173.146,20.00,-4.74533,-6.70855e-3,20.0267,-1804.36,173.146,10.0130,8.92318e-4
0.193635,0.0561632,3.44545,180.486,20.00,-4.99796,-7.06571e-3,20.0257,-1584.49,180.486,10.9498,9.77237e-4
0.210944,0.0614429,3.43666,187.826,20.00,-8.29481,-0.0117265,20.0345,-2197.17,187.826,11.9286,1.06910e-3
0.231003,0.0673394,3.42910,195.232,20.00,-3.55808,-5.03011e-3,20.0277,-784.651,195.232,13.0629,1.17170e-3
0.252447,0.0738401,3.42050,202.637,20.00,-4.59066,-6.48989e-3,20.0300,-841.957,202.637,14.2756,1.28482e-3
0.276155,0.0808581,3.41338,209.977,20.00,-3.63149,-5.13390e-3,20.0200,-555.442,209.977,15.6162,1.40693e-3
0.301691,0.0885999,3.40618,217.317,20.00,-3.51036,-4.96265e-3,20.0198,-447.182,217.317,17.0602,1.54164e-3
0.329680,0.0970403,3.39980,224.657,20.00,-3.71837,-5.25672e-3,20.0327,-394.865,224.657,18.6430,1.68850e-3
0.360752,0.106277,3.39371,231.997,20.00,-2.28555,-3.23112e-3,20.0262,-202.354,231.997,20.4000,1.84921e-3
0.394554,0.116495,3.38899,239.403,20.00,-2.22666,-3.14786e-3,20.0312,-164.075,239.403,22.3115,2.02700e-3
0.432426,0.127760,3.38430,246.809,20.00,-2.68596,-3.79719e-3,20.0317,-164.554,246.809,24.4531,2.22302e-3
0.473077,0.139899,3.38016,254.149,20.00,0.107307,1.51702e-4,20.0268,5.48280,254.149,26.7519,2.43423e-3
0.516993,0.153221,3.37673,261.489,20.00,-3.24601,-4.58894e-3,20.0326,-138.266,261.489,29.2353,2.66604e-3
0.566167,0.167825,3.37240,268.829,20.00,-0.744214,-1.05211e-3,20.0257,-26.4232,268.829,32.0160,2.92015e-3
0.619479,0.183839,3.36776,276.169,20.00,2.06501,2.91933e-3,20.0324,61.1009,276.169,35.0307,3.19879e-3
0.677679,0.201510,3.36342,283.574,20.00,-1.93022,-2.72878e-3,20.0282,-47.5351,283.574,38.3219,3.50626e-3
0.741673,0.220846,3.35783,290.980,20.00,0.628474,8.88484e-4,20.0303,12.8857,290.980,41.9406,3.84271e-3
0.811066,0.241923,3.35191,298.320,20.00,-0.184692,-2.61102e-4,20.0264,-3.15568,298.320,45.8647,4.20946e-3
0.886565,0.264986,3.34617,305.660,20.00,2.24324,3.17131e-3,20.0223,31.9470,305.660,50.1340,4.61075e-3
0.969399,0.290235,3.34109,313.000,20.00,-0.332908,-4.70638e-4,20.0110,-3.95208,313.000,54.8182,5.05007e-3
1.05986,0.317869,3.33633,320.340,20.00,1.81777,2.56981e-3,20.0223,17.9905,320.340,59.9336,5.53090e-3
1.16124,0.348423,3.33230,327.746,20.00,3.30476,4.67200e-3,20.0194,27.2225,327.746,65.6665,6.06254e-3
1.27121,0.381894,3.32963,335.151,20.00,0.965574,1.36505e-3,20.0150,6.62064,335.151,71.8851,6.64494e-3
1.39121,0.418322,3.32817,342.491,20.00,2.13352,3.01620e-3,20.0139,12.1920,342.491,78.6709,7.27879e-3
1.52410,0.458141,3.32785,349.831,20.00,-0.166623,-2.35558e-4,20.0220,-0.793845,349.831,86.1860,7.97164e-3
1.66939,0.501780,3.32933,357.171,20.00,2.95512,4.17771e-3,20.0287,11.7368,357.171,94.4016,8.73096e-3
1.83084,0.549595,3.33214,364.511,20.00,4.66438,6.59411e-3,20.0271,15.4422,364.511,103.531,9.56293e-3
2.00963,0.602383,3.33494,371.917,20.00,1.51496,2.14172e-3,20.0262,4.17497,371.917,113.642,0.0104815
2.20535,0.660327,3.33778,379.322,20.00,2.50975,3.54808e-3,20.0215,5.75590,379.322,124.710,0.0114897
2.41583,0.723167,3.34010,386.662,20.00,-0.0373914,-5.28608e-5,20.0159,-0.0714980,386.662,136.612,0.0125831
2.64639,0.792083,3.34147,394.002,20.00,2.15742,3.04999e-3,20.0103,3.43870,394.002,149.650,0.0137822
2.89989,0.867484,3.34246,401.342,20.00,8.64974,0.0122283,20.0232,11.4942,401.342,163.985,0.0150942
3.17616,0.950090,3.34373,408.683,19.99,10.0026,0.0141408,20.0305,11.0811,408.683,179.607,0.0165315
3.48356,1.04150,3.34534,416.088,20.00,8.28643,0.0117147,20.0256,7.63923,416.088,196.991,0.0181221
3.82079,1.14155,3.34617,423.494,20.00,9.05941,0.0128074,20.0328,6.95196,423.494,216.060,0.0198630
4.18719,1.25026,3.34601,430.834,20.00,6.02444,8.51686e-3,20.0261,3.85406,430.834,236.780,0.0217544
4.58320,1.36934,3.34456,438.174,20.00,1.66671,2.35626e-3,20.0206,0.888864,438.174,259.174,0.0238265
5.01244,1.49973,3.34307,445.514,20.00,-0.267811,-3.78609e-4,20.0253,-0.119070,445.514,283.447,0.0260952
5.48193,1.64253,3.34185,452.854,20.00,0.582602,8.23634e-4,20.0192,0.215946,452.854,309.996,0.0285799
6.01263,1.80044,3.34012,460.259,20.00,9.14186,0.0129240,20.0267,2.82019,460.259,340.006,0.0313276
6.59725,1.97347,3.33864,467.665,20.00,-1.93409,-2.73425e-3,20.0223,-0.496607,467.665,373.066,0.0343384
7.21567,2.16143,3.33797,475.005,20.00,4.66226,6.59112e-3,20.0296,0.997964,475.005,408.037,0.0376088
7.89461,2.36730,3.33591,482.345,20.00,3.71408,5.25066e-3,20.0275,0.662742,482.345,446.430,0.0411910
8.64432,2.59269,3.33250,489.685,20.00,6.33119,8.95051e-3,20.0303,0.941858,489.685,488.825,0.0451126
9.45369,2.83959,3.32892,497.025,20.00,8.32820,0.0117737,20.0285,1.03286,497.025,534.594,0.0494087
10.3520,3.11256,3.32514,504.431,20.00,0.779159,1.10151e-3,20.0186,0.0804249,504.431,585.394,0.0541585
11.3282,3.41168,3.32034,511.836,20.00,1.85396,2.62097e-3,20.0233,0.159281,511.836,640.593,0.0593631
12.3907,3.73653,3.31593,519.176,20.00,5.28900,7.47715e-3,20.0236,0.378824,519.176,700.675,0.0650154
13.5468,4.09242,3.31068,526.516,20.00,4.47569,6.32736e-3,20.0318,0.267239,526.516,766.051,0.0712080
14.8227,4.48205,3.30530,533.856,20.00,1.41495,2.00033e-3,20.0271,0.0704347,533.856,838.204,0.0779875
16.1974,4.90890,3.30046,541.196,20.00,-8.70756,-0.0123100,20.0213,-0.361351,541.196,915.940,0.0854146
17.7216,5.38079,3.29629,548.602,20.00,-11.0472,-0.0156176,20.0233,-0.381558,548.602,1002.13,0.0936256
19.4144,5.89786,3.29252,556.007,20.00,-7.58423,-0.0107220,20.0301,-0.218034,556.007,1097.86,0.102622
21.2487,6.45959,3.29035,563.347,20.00,-19.1441,-0.0270644,20.0268,-0.458802,563.347,1201.58,0.112397
23.2641,7.07472,3.28930,570.688,20.00,-0.914691,-1.29311e-3,20.0301,-0.0182749,570.688,1315.55,0.123100
25.4822,7.74838,3.28818,578.028,20.00,2.42345,3.42607e-3,20.0283,0.0403657,578.028,1440.98,0.134822
27.9042,8.48620,3.28657,585.368,20.00,17.2342,0.0243643,20.0283,0.239312,585.368,1577.95,0.147660
30.5684,9.30208,3.28449,592.773,20.00,15.9999,0.0226193,20.0258,0.184908,592.773,1728.60,0.161856
33.4568,10.1959,3.28220,600.179,20.00,12.6234,0.0178460,20.0306,0.121430,600.179,1891.94,0.177409
36.6050,11.1668,3.28036,607.519,20.00,-2.45207,-3.46654e-3,20.0176,-0.0196640,607.519,2069.96,0.194303
40.0826,12.2303,3.27847,614.859,20.00,12.9713,0.0183377,20.0223,0.0867183,614.859,2266.62,0.212806
43.9208,13.3950,3.27677,622.199,20.00,20.3633,0.0287880,20.0200,0.113492,622.199,2483.66,0.233072
48.0709,14.6704,3.27561,629.539,20.00,1.33298,1.88446e-3,20.0228,6.19360e-3,629.539,2718.35,0.255264
52.6301,16.0808,3.27372,636.944,20.00,9.27237,0.0131085,20.0262,0.0358570,636.944,2976.16,0.279806
57.6761,17.6261,3.27026,644.350,20.00,32.0253,0.0452747,20.0246,0.103081,644.350,3261.51,0.306694
63.0857,19.3045,3.26653,651.690,20.00,13.3483,0.0188707,20.0229,0.0358184,651.690,3567.41,0.335898
68.9629,21.1430,3.26238,659.030,20.00,22.1397,0.0312993,20.0204,0.0495267,659.030,3899.76,0.367887
75.4435,23.1562,3.25827,666.370,20.00,29.4270,0.0416015,20.0315,0.0548796,666.370,4266.23,0.402917
82.4771,25.3615,3.25411,673.710,20.00,27.6861,0.0391403,20.0259,0.0430438,673.710,4663.97,0.441290
90.3929,27.7994,3.24995,681.116,20.00,27.3514,0.0386671,20.0168,0.0353922,681.116,5111.60,0.483709
98.9409,30.4710,3.24532,688.521,20.00,56.3836,0.0797105,20.0253,0.0607269,688.521,5594.98,0.530194
108.161,33.3727,3.24041,695.861,20.00,30.6827,0.0433767,20.0210,0.0275494,695.861,6116.38,0.580683
118.242,36.5507,3.23394,703.201,20.00,52.0120,0.0735303,20.0204,0.0389326,703.201,6686.42,0.635980
129.199,40.0312,3.22622,710.541,20.00,76.9263,0.108752,20.0184,0.0480039,710.541,7306.00,0.696542
141.143,43.8434,3.21742,717.881,20.00,70.7940,0.100083,20.0157,0.0368289,717.881,7981.45,0.762873
154.189,48.0579,3.20717,725.287,20.00,86.5160,0.122309,20.0150,0.0374599,725.287,8719.16,0.836206
168.400,52.6763,3.19510,732.693,20.00,94.4151,0.133476,20.0200,0.0340259,732.693,9522.78,0.916567
183.698,57.6928,3.17860,740.033,20.00,101.084,0.142905,20.0146,0.0303697,740.033,10387.9,1.00385
200.144,63.1865,3.16139,747.373,20.00,134.333,0.189909,20.0163,0.0336460,747.373,11317.9,1.09944
217.077,69.2038,3.13915,754.713,20.00,160.621,0.227072,20.0174,0.0335383,754.713,12275.4,1.20414
232.445,75.7939,3.06681,762.053,20.00,161.210,0.227905,20.0168,0.0280622,762.053,13144.5,1.31881
251.719,83.0800,3.02983,769.458,20.00,209.846,0.296662,20.0122,0.0304023,769.458,14234.4,1.44559
271.670,91.0637,2.98330,776.864,20.00,223.009,0.315272,20.0166,0.0268926,776.864,15362.6,1.58450
294.222,99.7361,2.95001,784.204,20.00,267.086,0.377584,20.0047,0.0268502,784.204,16637.9,1.73540
314.184,109.233,2.87628,791.544,20.00,276.022,0.390217,20.0094,0.0231333,791.544,17766.7,1.90065
342.276,119.636,2.86099,798.884,20.00,332.123,0.469528,20.0156,0.0232049,798.884,19355.2,2.08165
366.644,131.028,2.79820,806.224,20.00,379.711,0.536804,20.0066,0.0221168,806.224,20733.2,2.27989
392.477,143.624,2.73268,813.629,20.00,394.980,0.558390,20.0025,0.0191480,813.629,22194.1,2.49905
422.704,157.426,2.68510,821.035,20.00,458.024,0.647516,20.0119,0.0184814,821.035,23903.3,2.73920
445.540,172.420,2.58404,828.375,20.00,465.303,0.657806,19.9978,0.0156516,828.375,25194.7,3.00011
450.042,188.835,2.38325,835.715,20.00,444.999,0.629103,20.0064,0.0124794,835.715,25449.3,3.28573
454.852,206.820,2.19926,843.055,20.00,551.012,0.778975,20.0066,0.0128817,843.055,25721.3,3.59867
508.180,226.515,2.24347,850.395,20.00,675.756,0.955328,20.0033,0.0131704,850.395,28736.9,3.94135
571.257,248.284,2.30082,857.801,20.00,873.226,1.23449,20.0048,0.0141654,857.801,32303.8,4.32013
640.365,272.149,2.35300,865.206,20.00,962.891,1.36126,19.9950,0.0130007,865.206,36211.8,4.73537
701.264,298.063,2.35274,872.546,20.00,1068.33,1.51032,19.9906,0.0120252,872.546,39655.5,5.18628
775.878,326.449,2.37672,879.886,20.00,1227.60,1.73548,19.9936,0.0115193,879.886,43874.9,5.68020
832.814,357.537,2.32931,887.226,20.00,1313.75,1.85727,19.9807,0.0102771,887.226,47094.5,6.22114
866.846,391.581,2.21371,894.566,20.01,1489.57,2.10584,19.9935,9.71445e-3,894.566,49019.0,6.81350
941.127,429.225,2.19262,901.972,20.00,1635.29,2.31183,19.9786,8.87613e-3,901.972,53219.5,7.46850
1019.73,470.477,2.16744,909.378,20.00,1773.00,2.50653,19.9798,8.01001e-3,909.378,57664.4,8.18628
1092.50,515.276,2.12022,916.718,20.00,2006.55,2.83669,19.9791,7.55735e-3,916.718,61779.4,8.96579
1176.28,564.346,2.08433,924.058,20.00,2172.87,3.07182,19.9618,6.82249e-3,924.058,66517.3,9.81960
1260.91,618.085,2.04002,931.398,20.01,2399.81,3.39266,19.9706,6.28175e-3,931.398,71302.5,10.7547
1358.07,676.946,2.00617,938.738,20.01,2640.64,3.73312,19.9699,5.76237e-3,938.738,76796.8,11.7788
1450.71,742.022,1.95508,946.143,20.01,2851.67,4.03146,19.9624,5.17924e-3,946.143,82035.9,12.9112
1536.18,813.334,1.88875,953.549,20.01,3139.61,4.43852,19.9600,4.74611e-3,953.549,86869.0,14.1520
1628.08,890.779,1.82770,960.889,20.01,3398.66,4.80474,19.9519,4.28319e-3,960.889,92065.8,15.4995
1744.62,975.607,1.78824,968.229,20.01,3672.84,5.19235,19.9420,3.85880e-3,968.229,98656.0,16.9755
1892.02,1068.51,1.77071,975.569,20.01,4040.44,5.71203,19.9508,3.53895e-3,975.569,106991,18.5919
1809.48,1170.27,1.54620,982.909,20.01,4226.95,5.97571,19.9389,3.08640e-3,982.909,102324,20.3627
1837.36,1282.78,1.43233,990.315,20.01,4590.03,6.48900,19.9424,2.78940e-3,990.315,103900,22.3203
1929.97,1406.04,1.37263,997.720,20.01,5030.84,7.11218,19.9515,2.54474e-3,997.720,109137,24.4651
1957.75,1539.95,1.27131,1005.06,20.01,5368.28,7.58922,19.9415,2.26373e-3,1005.06,110708,26.7950
1854.88,1686.61,1.09977,1012.40,20.01,5636.16,7.96793,19.9602,1.98131e-3,1012.40,104891,29.3470
1836.15,1847.19,0.994025,1019.74,20.01,5898.77,8.33919,19.9507,1.72877e-3,1019.74,103832,32.1410
1840.16,2023.10,0.909576,1027.08,20.01,6214.23,8.78516,19.9644,1.51829e-3,1027.08,104059,35.2018
1808.21,2217.59,0.815391,1034.49,20.01,6569.83,9.28788,19.9765,1.33595e-3,1034.49,102252,38.5861
1729.69,2430.73,0.711594,1041.89,20.01,6834.08,9.66146,19.9705,1.15667e-3,1041.89,97811.7,42.2946
1543.94,2662.29,0.579930,1049.23,20.01,7049.33,9.96576,19.9878,9.94574e-4,1049.23,87307.8,46.3238
814.370,2915.89,0.279287,1056.57,19.99,5705.02,8.06528,19.9997,6.70987e-4,1056.57,46051.5,50.7364
89.9733,3193.96,0.0281698,1063.91,19.93,1681.58,2.37728,20.0382,1.64839e-4,1063.91,5087.87,55.5748
14.4784,3497.48,4.13966e-3,1071.25,19.97,517.082,0.731008,20.0903,4.22718e-5,1071.25,818.732,60.8559
18.3435,3833.65,4.78487e-3,1078.66,19.99,435.913,0.616257,20.1006,2.96602e-5,1078.66,1037.30,66.7054
22.4016,4202.11,5.33103e-3,1086.06,20.00,202.233,0.285901,20.1194,1.14529e-5,1086.06,1266.78,73.1166
26.6318,4602.27,5.78666e-3,1093.40,19.99,26.4459,0.0373870,20.1170,1.24857e-6,1093.40,1505.99,80.0793
31.5437,5040.52,6.25802e-3,1100.74,19.99,-14.2810,-0.0201894,20.1184,-5.62094e-7,1100.74,1783.75,87.7049
36.4370,5520.47,6.60034e-3,1108.08,19.99,-91.4449,-0.129277,20.1161,-3.00059e-6,1108.08,2060.46,96.0560
46.4481,6046.20,7.68221e-3,1115.42,19.99,-473.730,-0.669720,20.1094,-1.29588e-5,1115.42,2626.58,105.204
57.6855,6627.41,8.70408e-3,1122.83,19.99,-941.801,-1.33144,20.0992,-2.14423e-5,1122.83,3262.04,115.317
68.6860,7264.24,9.45536e-3,1130.23,19.99,-1393.20,-1.96959,20.0932,-2.64018e-5,1130.23,3884.10,126.397
84.1045,7956.14,0.0105710,1137.57,19.99,-1983.03,-2.80344,20.0894,-3.13274e-5,1137.57,4756.00,138.436
94.8590,8713.78,0.0108861,1144.91,20.00,-2979.13,-4.21165,20.0776,-3.92353e-5,1144.91,5364.15,151.619
107.339,9543.46,0.0112474,1152.25,20.00,-3434.15,-4.85492,20.0802,-3.77058e-5,1152.25,6069.90,166.056
125.799,10452.3,0.0120356,1159.59,20.00,-4526.56,-6.39927,20.0735,-4.14332e-5,1159.59,7113.77,181.869
146.213,11457.1,0.0127617,1167.00,20.01,-5473.21,-7.73757,20.0754,-4.16956e-5,1167.00,8268.14,199.354
170.424,12557.9,0.0135711,1174.41,20.01,-6017.68,-8.50730,20.0770,-3.81589e-5,1174.41,9637.27,218.507
206.831,13754.1,0.0150378,1181.75,20.01,-2749.65,-3.88723,20.0678,-1.45350e-5,1181.75,11696.0,239.321
224.741,15063.8,0.0149193,1189.09,20.02,-723.361,-1.02263,20.0668,-3.18777e-6,1189.09,12708.8,262.109
254.506,16484.7,0.0154390,1196.36,20.03,1223.48,1.72965,20.0624,4.50233e-6,1196.36,14392.0,286.832