File: Viscosity/csv/ps_thf_00_4.csv
Filename,ps_thf_00_4
Instrument name,5333-0457
Operator,Osamu Katagiri
rundate,11/12/2019
Sample name,OSKT 42_PS_THF
Geometry name,60mm 0.9969° cone plate, Peltier plate Steel
Procedure name,Sample
,Flow ramp
proceduresegments,Flow ramp
[step]
Flow ramp - 1
Stress,Shear rate,Viscosity,Step time,Temperature,Normal stress,Axial force,Gap,Normal stress coefficient,Time,Torque,Velocity
Pa,1/s,Pa.s,s,°C,Pa,N,µm,Pa.s²,s,µN.m,rad/s
-0.0122951,5.90815e-3,-2.08104,3.59586,19.98,3.28455,4.64342e-3,20.0355,94096.4,3.59586,-0.695272,1.02802e-4
6.58009e-4,7.36818e-3,0.0893041,10.5513,19.98,-0.358880,-5.07355e-4,20.0248,-6610.42,10.5513,0.0372095,1.28206e-4
7.44280e-4,8.21969e-3,0.0905484,17.5637,19.99,-2.79903,-3.95704e-3,20.0333,-41428.4,17.5637,0.0420880,1.43022e-4
6.25300e-4,9.22203e-3,0.0678051,24.5760,19.99,-4.94770,-6.99464e-3,20.0342,-58176.9,24.5760,0.0353599,1.60463e-4
7.18870e-4,0.0103079,0.0697396,31.5228,19.99,-6.49248,-9.17852e-3,20.0231,-61104.0,31.5228,0.0406511,1.79357e-4
9.60677e-4,0.0115209,0.0833858,38.4697,19.99,-8.72416,-0.0123335,20.0251,-65728.4,38.4697,0.0543250,2.00463e-4
1.26861e-3,0.0129035,0.0983156,45.4820,19.99,-10.1938,-0.0144111,20.0307,-61224.0,45.4820,0.0717383,2.24520e-4
1.56843e-3,0.0144521,0.108526,52.4944,19.99,-11.1526,-0.0157666,20.0331,-53396.6,52.4944,0.0886927,2.51466e-4
2.07257e-3,0.0161558,0.128287,59.4412,19.99,-13.2536,-0.0187369,20.0300,-50778.4,59.4412,0.117201,2.81110e-4
2.68578e-3,0.0180825,0.148529,66.3880,19.99,-14.6117,-0.0206568,20.0258,-44687.2,66.3880,0.151877,3.14635e-4
3.42849e-3,0.0202598,0.169226,73.4004,19.99,-15.7661,-0.0222888,20.0333,-38410.9,73.4004,0.193877,3.52520e-4
4.06658e-3,0.0226978,0.179161,80.4127,19.99,-17.8080,-0.0251755,20.0079,-34565.8,80.4127,0.229960,3.94942e-4
4.98936e-3,0.0254018,0.196418,87.3595,20.00,-18.4301,-0.0260550,20.0134,-28562.7,87.3595,0.282142,4.41991e-4
6.09752e-3,0.0284007,0.214696,94.3063,20.00,-20.1278,-0.0284550,20.0198,-24953.9,94.3063,0.344807,4.94170e-4
7.29950e-3,0.0317762,0.229716,101.253,20.00,-20.4004,-0.0288403,20.0108,-20203.8,101.253,0.412777,5.52905e-4
8.86678e-3,0.0355981,0.249080,108.266,20.00,-21.8744,-0.0309243,20.0158,-17261.7,108.266,0.501404,6.19406e-4
0.0104208,0.0398716,0.261358,115.278,20.00,-22.7576,-0.0321728,20.0149,-14315.3,115.278,0.589280,6.93764e-4
0.0123299,0.0446010,0.276448,122.225,20.00,-24.5900,-0.0347633,20.0057,-12361.5,122.225,0.697238,7.76056e-4
0.0147560,0.0499017,0.295700,129.171,20.00,-25.3150,-0.0357883,20.0099,-10165.9,129.171,0.834430,8.68288e-4
0.0173407,0.0558897,0.310267,136.184,20.00,-25.1215,-0.0355147,20.0147,-8042.34,136.184,0.980594,9.72478e-4
0.0206632,0.0625019,0.330600,143.196,20.00,-26.7466,-0.0378121,20.0217,-6846.71,143.196,1.16847,1.08753e-3
0.0247829,0.0699183,0.354455,150.143,20.00,-26.5789,-0.0375751,20.0223,-5436.95,150.143,1.40144,1.21658e-3
0.0298350,0.0782487,0.381285,157.090,20.00,-27.4284,-0.0387760,20.0314,-4479.67,157.090,1.68713,1.36152e-3
0.0363179,0.0875645,0.414756,164.037,20.00,-27.3413,-0.0386529,20.0231,-3565.85,164.037,2.05373,1.52362e-3
0.0446358,0.0980785,0.455103,171.049,20.00,-28.5027,-0.0402948,20.0269,-2963.05,171.049,2.52409,1.70656e-3
0.0552835,0.109854,0.503244,178.061,20.00,-27.8944,-0.0394348,20.0266,-2311.44,178.061,3.12621,1.91146e-3
0.0687855,0.122884,0.559760,185.008,20.00,-29.1649,-0.0412310,20.0310,-1931.40,185.008,3.88973,2.13818e-3
0.0858240,0.137490,0.624221,191.955,20.00,-29.5847,-0.0418244,20.0267,-1565.04,191.955,4.85323,2.39232e-3
0.107910,0.154032,0.700566,198.967,20.00,-29.3654,-0.0415143,20.0337,-1237.69,198.967,6.10216,2.68016e-3
0.136403,0.172466,0.790898,205.980,20.00,-30.0105,-0.0424263,20.0279,-1008.94,205.980,7.71340,3.00090e-3
0.173213,0.192994,0.897502,212.926,20.00,-30.4962,-0.0431130,20.0335,-818.761,212.926,9.79495,3.35809e-3
0.220367,0.215893,1.02072,219.873,20.00,-30.7262,-0.0434382,20.0301,-659.223,219.873,12.4615,3.75653e-3
0.280868,0.241820,1.16148,226.886,20.00,-31.5280,-0.0445716,20.0312,-539.153,226.886,15.8827,4.20766e-3
0.358093,0.270805,1.32232,233.898,20.00,-31.2916,-0.0442374,20.0277,-426.690,233.898,20.2497,4.71200e-3
0.454235,0.302975,1.49925,240.845,20.00,-32.7981,-0.0463673,20.0250,-357.302,240.845,25.6864,5.27176e-3
0.573521,0.338954,1.69203,247.792,20.00,-31.8433,-0.0450175,20.0301,-277.164,247.792,32.4319,5.89779e-3
0.717397,0.379212,1.89181,254.738,20.00,-32.5154,-0.0459675,20.0209,-226.113,254.738,40.5678,6.59827e-3
0.888815,0.424684,2.09289,261.751,20.00,-32.2839,-0.0456402,20.0257,-179.000,261.751,50.2613,7.38948e-3
1.09123,0.475610,2.29438,268.763,20.00,-32.2215,-0.0455520,20.0298,-142.444,268.763,61.7077,8.27559e-3
1.32573,0.532073,2.49164,275.710,20.00,-33.6384,-0.0475552,20.0276,-118.821,275.710,74.9684,9.25805e-3
1.59376,0.595257,2.67744,282.657,20.00,-32.1711,-0.0454808,20.0231,-90.7939,282.657,90.1251,0.0103574
1.89382,0.666674,2.84070,289.669,20.00,-32.9416,-0.0465701,20.0145,-74.1171,289.669,107.093,0.0116001
2.19391,0.746575,2.93862,296.681,20.00,-33.0610,-0.0467389,20.0144,-59.3156,296.681,124.062,0.0129904
2.50132,0.835206,2.99485,303.628,20.00,-32.6668,-0.0461817,20.0240,-46.8296,303.628,141.446,0.0145325
2.82503,0.934385,3.02341,310.575,20.00,-33.7044,-0.0476485,20.0138,-38.6042,310.575,159.752,0.0162583
3.14797,1.04643,3.00828,317.587,20.00,-30.9310,-0.0437277,20.0079,-28.2468,317.587,178.014,0.0182079
3.46989,1.17186,2.96100,324.600,20.00,-32.6493,-0.0461569,20.0048,-23.7750,324.600,196.218,0.0203904
3.82283,1.31103,2.91589,331.547,20.00,-31.0323,-0.0438708,20.0145,-18.0545,331.547,216.176,0.0228119
4.20240,1.46660,2.86540,338.493,20.00,-31.6109,-0.0446889,20.0150,-14.6965,338.493,237.640,0.0255188
4.57968,1.64076,2.79119,345.440,20.00,-31.4805,-0.0445045,20.0150,-11.6936,345.440,258.975,0.0285492
4.85157,1.83750,2.64031,352.453,20.00,-30.2824,-0.0428107,20.0222,-8.96886,352.453,274.350,0.0319724
5.11959,2.05777,2.48794,359.465,20.00,-32.0374,-0.0452918,20.0274,-7.56599,359.465,289.506,0.0358050
5.45233,2.30205,2.36847,366.412,20.00,-30.3449,-0.0428992,20.0304,-5.72608,366.412,308.322,0.0400556
5.85929,2.57530,2.27519,373.359,19.99,-34.8605,-0.0492829,20.0237,-5.25628,373.359,331.335,0.0448101
6.17423,2.88416,2.14074,380.371,20.00,-34.9547,-0.0494160,20.0194,-4.20210,380.371,349.144,0.0501843
6.59277,3.22982,2.04122,387.383,20.00,-37.7001,-0.0532973,20.0143,-3.61399,387.383,372.812,0.0561987
6.95991,3.61332,1.92618,394.330,20.00,-38.7514,-0.0547835,20.0125,-2.96807,394.330,393.574,0.0628717
7.38899,4.04211,1.82800,401.277,20.00,-36.4901,-0.0515867,20.0128,-2.23336,401.277,417.837,0.0703326
7.80602,4.52199,1.72623,408.224,20.00,-41.9021,-0.0592377,20.0276,-2.04916,408.224,441.420,0.0786825
8.40575,5.06423,1.65983,415.236,20.00,-43.0231,-0.0608225,20.0145,-1.67755,415.236,475.334,0.0881175
9.21123,5.67130,1.62418,422.248,20.00,-48.3282,-0.0683224,20.0310,-1.50258,422.248,520.883,0.0986804
9.41415,6.34455,1.48382,429.195,20.00,-48.9852,-0.0692512,20.0226,-1.21692,429.195,532.358,0.110395
9.55763,7.09774,1.34657,436.142,20.00,-54.6772,-0.0772980,20.0209,-1.08534,436.142,540.471,0.123500
9.45314,7.94883,1.18925,443.154,20.00,-58.8138,-0.0831460,20.0295,-0.930834,443.154,534.563,0.138309
9.07695,8.90162,1.01970,450.167,20.00,-59.9483,-0.0847500,20.0141,-0.756553,450.167,513.289,0.154888
9.09676,9.95833,0.913482,457.114,20.00,-62.7701,-0.0887391,20.0199,-0.632965,457.114,514.410,0.173275
9.00208,11.1405,0.808047,464.060,20.00,-67.0849,-0.0948390,20.0157,-0.540520,464.060,509.056,0.193845
8.29259,12.4766,0.664654,471.073,20.00,-80.9234,-0.114403,20.0270,-0.519857,471.073,468.935,0.217092
6.53438,13.9723,0.467667,478.085,20.00,-98.9928,-0.139948,20.0268,-0.507071,478.085,369.510,0.243117
4.90807,15.6308,0.313999,485.032,20.00,-106.540,-0.150617,20.0192,-0.436061,485.032,277.545,0.271976
4.20085,17.4849,0.240255,491.979,20.00,-123.529,-0.174634,20.0252,-0.404054,491.979,237.552,0.304237
4.92496,19.5617,0.251765,498.926,20.00,-123.341,-0.174370,20.0251,-0.322326,498.926,278.500,0.340373
4.80885,21.9071,0.219511,505.938,20.00,-117.896,-0.166672,20.0156,-0.245658,505.938,271.934,0.381182
5.27391,24.5334,0.214969,512.950,20.00,-135.267,-0.191229,20.0297,-0.224738,512.950,298.233,0.426880
5.85428,27.4452,0.213308,519.897,20.00,-123.088,-0.174012,20.0196,-0.163412,519.897,331.052,0.477545
6.75048,30.7028,0.219865,526.844,20.00,-139.503,-0.197218,20.0259,-0.147988,526.844,381.731,0.534228
7.30944,34.3846,0.212579,533.856,20.00,-129.788,-0.183483,20.0184,-0.109776,533.856,413.339,0.598291
8.23681,38.5070,0.213904,540.869,20.00,-134.442,-0.190063,20.0164,-0.0906683,540.869,465.780,0.670020
9.28024,43.0763,0.215437,547.815,20.00,-139.693,-0.197486,20.0231,-0.0752830,547.815,524.785,0.749527
10.2515,48.1917,0.212724,554.762,20.00,-141.868,-0.200561,20.0221,-0.0610859,554.762,579.709,0.838533
11.5960,53.9114,0.215093,561.709,20.00,-141.366,-0.199852,20.0177,-0.0486390,561.709,655.737,0.938056
12.7794,60.3753,0.211666,568.721,20.00,-140.072,-0.198022,20.0192,-0.0384265,568.721,722.657,1.05053
14.6207,67.6135,0.216240,575.734,20.00,-149.384,-0.211187,20.0164,-0.0326768,575.734,826.782,1.17647
16.2836,75.6392,0.215280,582.681,20.00,-150.316,-0.212504,20.0181,-0.0262731,582.681,920.815,1.31612
15.5659,84.6191,0.183953,589.627,20.00,-168.704,-0.238500,20.0231,-0.0235608,589.627,880.233,1.47237
16.4708,94.5613,0.174181,596.509,20.00,-162.002,-0.229025,20.0226,-0.0181173,596.509,931.400,1.64536