File: Viscosity/csv/ps_thf_01_2.csv
Filename,ps_thf_01_2
Instrument name,5333-0457
Operator,Osamu Katagiri
rundate,18/12/2019
Sample name,PS_THF_01_2
Geometry name,60.0mm 0.996944° cone plate, Peltier plate Steel
Procedure name,Sample
,Flow ramp
proceduresegments,Flow ramp
[step]
Flow ramp - 1
Stress,Shear rate,Viscosity,Step time,Temperature,Normal stress,Axial force,Gap,Normal stress coefficient,Time,Torque,Velocity
Pa,1/s,Pa.s,s,°C,Pa,N,µm,Pa.s²,s,µN.m,rad/s
-1.33084,-0.0624410,21.3135,5.01354,20.01,56.1008,0.0793106,20.0273,14388.9,5.01354,-75.2571,-1.08647e-3
0.0138892,6.87058e-3,2.02155,11.1412,20.00,54.9424,0.0776730,20.0270,1163910,11.1412,0.785418,1.19548e-4
0.0149566,7.54630e-3,1.98198,18.5467,20.00,54.0607,0.0764265,20.0228,949321,18.5467,0.845777,1.31305e-4
0.0157260,8.26213e-3,1.90338,25.9523,20.00,54.3463,0.0768303,20.0236,796133,25.9523,0.889284,1.43761e-4
0.0167101,9.05000e-3,1.84642,33.2923,20.00,53.7889,0.0760423,20.0223,656743,33.2923,0.944936,1.57470e-4
0.0177712,9.92203e-3,1.79109,40.6324,20.00,53.3930,0.0754826,20.0237,542354,40.6324,1.00494,1.72643e-4
0.0187871,0.0108611,1.72975,47.9724,20.00,53.4202,0.0755210,20.0234,452850,47.9724,1.06239,1.88984e-4
0.0201885,0.0119105,1.69502,55.3124,20.00,53.3112,0.0753669,20.0260,375802,55.3124,1.14163,2.07242e-4
0.0213983,0.0130457,1.64026,62.7180,20.00,53.9912,0.0763282,20.0275,317242,62.7180,1.21004,2.26994e-4
0.0229120,0.0143024,1.60197,70.1236,20.00,53.1013,0.0750702,20.0288,259591,70.1236,1.29564,2.48861e-4
0.0245043,0.0156467,1.56610,77.4636,20.00,53.0716,0.0750282,20.0335,216778,77.4636,1.38569,2.72252e-4
0.0261109,0.0171546,1.52209,84.8036,20.00,53.1590,0.0751517,20.0295,180641,84.8036,1.47653,2.98489e-4
0.0280662,0.0187916,1.49355,92.1436,20.00,53.2463,0.0752751,20.0348,150786,92.1436,1.58711,3.26973e-4
0.0300979,0.0205726,1.46301,99.4837,20.00,54.4111,0.0769219,20.0228,128561,99.4837,1.70199,3.57963e-4
0.0324083,0.0225597,1.43655,106.889,20.00,53.2649,0.0753015,20.0208,104658,106.889,1.83264,3.92538e-4
0.0348641,0.0247204,1.41034,114.295,20.00,53.1702,0.0751676,20.0248,87007.7,114.295,1.97152,4.30134e-4
0.0375788,0.0270832,1.38753,121.635,20.00,54.1753,0.0765885,20.0231,73858.9,121.635,2.12503,4.71246e-4
0.0405236,0.0296549,1.36651,128.975,20.00,53.6966,0.0759117,20.0215,61059.7,128.975,2.29156,5.15993e-4
0.0438687,0.0324804,1.35062,136.315,20.00,53.3599,0.0754358,20.0250,50579.2,136.315,2.48072,5.65158e-4
0.0472793,0.0355735,1.32906,143.655,20.00,53.4520,0.0755659,20.0273,42238.7,143.655,2.67358,6.18977e-4
0.0513069,0.0390014,1.31551,151.061,20.00,54.1275,0.0765210,20.0284,35584.2,151.061,2.90134,6.78624e-4
0.0555732,0.0427491,1.29998,158.466,20.00,53.6744,0.0758804,20.0304,29370.6,158.466,3.14259,7.43834e-4
0.0601627,0.0468166,1.28507,165.806,20.00,54.3360,0.0768157,20.0396,24790.6,165.806,3.40212,8.14608e-4
0.0652243,0.0512762,1.27202,173.146,20.00,53.6487,0.0758441,20.0356,20404.6,173.146,3.68835,8.92204e-4
0.0706571,0.0561641,1.25805,180.486,20.00,54.6010,0.0771904,20.0101,17309.4,180.486,3.99556,9.77254e-4
0.0768666,0.0614171,1.25155,187.826,20.00,54.0367,0.0763926,20.0035,14325.5,187.826,4.34670,1.06865e-3
0.0836534,0.0673673,1.24175,195.232,20.00,53.7226,0.0759485,20.0317,11837.5,195.232,4.73049,1.17219e-3
0.0909078,0.0738165,1.23154,202.637,20.00,54.4672,0.0770012,20.0154,9996.05,202.637,5.14071,1.28440e-3
0.0989800,0.0808957,1.22355,209.977,20.00,54.3277,0.0768040,20.0176,8301.77,209.977,5.59719,1.40758e-3
0.107736,0.0885736,1.21635,217.317,20.00,54.5289,0.0770884,20.0183,6950.53,217.317,6.09234,1.54118e-3
0.117409,0.0970384,1.20993,224.657,20.00,53.4741,0.0755972,20.0239,5678.79,224.657,6.63935,1.68846e-3
0.127937,0.106295,1.20361,231.997,20.00,53.9061,0.0762080,20.0223,4771.07,231.997,7.23466,1.84952e-3
0.139590,0.116514,1.19806,239.403,20.00,53.7775,0.0760262,20.0204,3961.38,239.403,7.89362,2.02733e-3
0.152182,0.127737,1.19137,246.809,20.00,53.2194,0.0752372,20.0211,3261.65,246.809,8.60570,2.22262e-3
0.166214,0.139897,1.18811,254.149,20.00,54.2155,0.0766453,20.0169,2770.16,254.149,9.39917,2.43421e-3
0.181165,0.153207,1.18248,261.489,20.00,52.9990,0.0749256,20.0238,2257.92,261.489,10.2446,2.66580e-3
0.197955,0.167842,1.17942,268.829,20.00,53.8551,0.0761358,20.0319,1911.74,268.829,11.1941,2.92044e-3
0.216421,0.183835,1.17726,276.169,20.00,54.1840,0.0766009,20.0168,1603.31,276.169,12.2383,3.19871e-3
0.236977,0.201506,1.17603,283.574,20.00,53.5844,0.0757532,20.0176,1319.67,283.574,13.4007,3.50619e-3
0.259569,0.220889,1.17511,290.980,20.00,53.1196,0.0750960,20.0229,1088.69,290.980,14.6783,3.84346e-3
0.285194,0.241929,1.17884,298.320,20.00,54.4823,0.0770225,20.0255,930.852,298.320,16.1274,4.20955e-3
0.312455,0.264979,1.17917,305.660,20.00,53.3511,0.0754234,20.0311,759.840,305.660,17.6689,4.61062e-3
0.341582,0.290225,1.17696,313.000,20.00,53.0210,0.0749566,20.0331,629.474,313.000,19.3160,5.04990e-3
0.375048,0.317858,1.17992,320.340,20.00,54.0995,0.0764813,20.0209,535.459,320.340,21.2085,5.53072e-3
0.412221,0.348438,1.18305,327.746,20.01,53.2117,0.0752263,20.0196,438.284,327.746,23.3106,6.06281e-3
0.453083,0.381921,1.18632,335.151,20.00,53.6253,0.0758110,20.0221,367.639,335.151,25.6212,6.64542e-3
0.496077,0.418301,1.18593,342.491,20.00,52.4691,0.0741764,20.0324,299.865,342.491,28.0525,7.27842e-3
0.542390,0.458140,1.18390,349.831,20.00,53.6132,0.0757939,20.0278,255.433,349.831,30.6714,7.97161e-3
0.592930,0.501791,1.18163,357.171,20.00,52.6070,0.0743713,20.0232,208.928,357.171,33.5294,8.73115e-3
0.647461,0.549589,1.17808,364.511,20.00,52.6705,0.0744612,20.0142,174.378,364.511,36.6131,9.56282e-3
0.707880,0.602396,1.17511,371.917,20.00,53.8590,0.0761414,20.0050,148.420,371.917,40.0297,0.0104817
0.773849,0.660316,1.17194,379.322,20.00,52.3955,0.0740724,20.0156,120.168,379.322,43.7601,0.0114895
0.845317,0.723206,1.16885,386.662,20.00,52.3554,0.0740158,20.0278,100.101,386.662,47.8015,0.0125838
0.924240,0.792080,1.16685,394.002,20.00,52.9925,0.0749164,20.0339,84.4649,394.002,52.2645,0.0137822
1.01070,0.867509,1.16506,401.342,20.00,52.4475,0.0741459,20.0356,69.6910,401.342,57.1538,0.0150946
1.10818,0.950140,1.16634,408.683,20.00,53.2714,0.0753107,20.0290,59.0091,408.683,62.6664,0.0165324
1.21572,1.04148,1.16730,416.088,20.01,52.4911,0.0742076,20.0406,48.3930,416.088,68.7473,0.0181217
1.32985,1.14154,1.16496,423.494,20.00,53.8011,0.0760595,20.0313,41.2867,423.494,75.2013,0.0198627
1.45291,1.25027,1.16208,430.834,20.00,52.9095,0.0747991,20.0219,33.8472,430.834,82.1604,0.0217547
1.58498,1.36934,1.15748,438.174,20.00,51.1463,0.0723064,20.0154,27.2766,438.174,89.6286,0.0238265
1.73270,1.49978,1.15530,445.514,20.00,53.5750,0.0757399,20.0167,23.8181,445.514,97.9820,0.0260961
1.90160,1.64253,1.15773,452.854,20.00,52.0389,0.0735683,20.0041,19.2886,452.854,107.533,0.0285800
2.08234,1.80053,1.15651,460.259,20.00,51.3732,0.0726271,20.0183,15.8465,460.259,117.753,0.0313292
2.28064,1.97349,1.15563,467.665,20.00,52.6627,0.0744501,20.0186,13.5217,467.665,128.967,0.0343387
2.48557,2.16146,1.14995,475.005,20.00,50.3252,0.0711456,20.0165,10.7719,475.005,140.556,0.0376093
2.71453,2.36720,1.14673,482.345,20.00,52.5804,0.0743337,20.0164,9.38324,482.345,153.503,0.0411892
2.97265,2.59276,1.14652,489.685,20.00,50.6046,0.0715406,20.0203,7.52774,489.685,168.099,0.0451140
3.25447,2.83961,1.14610,497.025,20.00,51.5816,0.0729218,20.0373,6.39702,497.025,184.036,0.0494091
3.56571,3.11254,1.14559,504.431,20.00,53.4333,0.0755395,20.0284,5.51546,504.431,201.636,0.0541581
3.89957,3.41170,1.14300,511.836,20.00,49.0731,0.0693754,20.0183,4.21602,511.836,220.515,0.0593634
4.27772,3.73669,1.14479,519.176,20.00,49.1172,0.0694378,20.0226,3.51770,519.176,241.899,0.0650183
4.67513,4.09241,1.14239,526.516,20.00,52.3854,0.0740581,20.0294,3.12789,526.516,264.372,0.0712078
5.11940,4.48220,1.14216,533.856,20.00,50.1825,0.0709438,20.0218,2.49787,533.856,289.495,0.0779901
5.60386,4.90894,1.14156,541.196,20.00,52.6064,0.0743706,20.0289,2.18305,541.196,316.891,0.0854154
6.14028,5.38086,1.14113,548.602,20.00,50.3373,0.0711627,20.0269,1.73855,548.602,347.224,0.0936268
6.72844,5.89803,1.14079,556.007,20.00,50.7532,0.0717507,20.0298,1.45898,556.007,380.485,0.102626
7.36925,6.45968,1.14081,563.347,20.00,51.5495,0.0728764,20.0170,1.23539,563.347,416.721,0.112398
8.05738,7.07473,1.13890,570.688,20.00,47.5466,0.0672174,20.0167,0.949949,570.688,455.634,0.123100
8.82531,7.74846,1.13898,578.028,20.00,51.0432,0.0721607,20.0265,0.850172,578.028,499.060,0.134823
9.67121,8.48631,1.13962,585.368,20.00,49.0977,0.0694103,20.0268,0.681747,585.368,546.894,0.147662
10.6063,9.30212,1.14021,592.773,20.00,49.7227,0.0702938,20.0249,0.574634,592.773,599.775,0.161856
11.6393,10.1960,1.14156,600.179,20.00,54.5312,0.0770917,20.0227,0.524552,600.179,658.185,0.177409
12.7599,11.1670,1.14265,607.519,20.00,49.3692,0.0697940,20.0223,0.395899,607.519,721.556,0.194305
13.9793,12.2305,1.14298,614.859,19.99,50.5488,0.0714617,20.0310,0.337927,614.859,790.508,0.212810
15.3158,13.3951,1.14338,622.199,20.00,54.6656,0.0772816,20.0334,0.304664,622.199,866.087,0.233075
16.7838,14.6706,1.14404,629.539,20.00,51.8563,0.0733101,20.0270,0.240938,629.539,949.100,0.255268
18.3889,16.0809,1.14353,636.944,20.00,52.3867,0.0740599,20.0249,0.202582,636.944,1039.87,0.279807
20.1496,17.6265,1.14315,644.350,20.00,50.3479,0.0711776,20.0240,0.162051,644.350,1139.43,0.306700
22.0736,19.3048,1.14342,651.690,20.00,54.0126,0.0763585,20.0164,0.144932,651.690,1248.23,0.335903
24.1657,21.1432,1.14295,659.030,20.00,52.6376,0.0744146,20.0200,0.117748,659.030,1366.54,0.367891
26.4717,23.1566,1.14316,666.370,20.00,53.3415,0.0754098,20.0224,0.0994755,666.370,1496.94,0.402924
28.9840,25.3617,1.14283,673.710,20.00,50.5067,0.0714021,20.0235,0.0785224,673.710,1639.00,0.441292
31.7633,27.7997,1.14258,681.116,20.00,60.1161,0.0849871,20.0271,0.0777876,681.116,1796.17,0.483714
34.7962,30.4715,1.14193,688.521,20.00,47.6467,0.0673589,20.0322,0.0513152,688.521,1967.68,0.530202
38.1206,33.3729,1.14226,695.861,20.00,57.5006,0.0812896,20.0244,0.0516278,695.861,2155.67,0.580688
41.7357,36.5512,1.14184,703.201,20.00,56.3288,0.0796330,20.0180,0.0421627,703.201,2360.10,0.635989
45.7102,40.0316,1.14185,710.541,20.00,53.6229,0.0758076,20.0151,0.0334614,710.541,2584.85,0.696548
50.1349,43.8438,1.14349,717.881,20.00,59.2437,0.0837538,20.0249,0.0308195,717.881,2835.06,0.762880
54.9629,48.0585,1.14367,725.287,20.00,54.3354,0.0768148,20.0299,0.0235257,725.287,3108.08,0.836216
60.2047,52.6771,1.14290,732.693,20.00,61.5406,0.0870009,20.0162,0.0221778,732.693,3404.49,0.916579
65.8975,57.6933,1.14220,740.033,20.00,61.8653,0.0874600,20.0116,0.0185864,740.033,3726.41,1.00386
72.0666,63.1873,1.14052,747.373,20.00,55.0998,0.0778954,20.0238,0.0138004,747.373,4075.27,1.09946
78.8702,69.2042,1.13967,754.713,20.00,66.1284,0.0934868,20.0218,0.0138077,754.713,4460.00,1.20415
86.2873,75.7945,1.13844,762.053,20.00,63.2019,0.0893495,20.0172,0.0110016,762.053,4879.43,1.31882
94.4350,83.0805,1.13667,769.458,20.00,66.5537,0.0940881,20.0260,9.64215e-3,769.458,5340.17,1.44560
103.360,91.0649,1.13501,776.864,20.00,72.3538,0.102288,20.0114,8.72488e-3,776.864,5844.85,1.58453
112.897,99.7366,1.13195,784.204,20.00,68.3374,0.0966098,20.0239,6.86988e-3,784.204,6384.18,1.73541
123.111,109.234,1.12704,791.544,20.00,82.8579,0.117138,20.0070,6.94410e-3,791.544,6961.76,1.90067
134.206,119.636,1.12178,798.884,20.00,76.7269,0.108470,20.0163,5.36070e-3,798.884,7589.17,2.08167
146.067,131.029,1.11477,806.224,20.00,85.0278,0.120205,20.0206,4.95253e-3,806.224,8259.90,2.27990
158.376,143.625,1.10271,813.629,20.00,96.8350,0.136897,20.0130,4.69432e-3,813.629,8955.96,2.49907
168.656,157.429,1.07131,821.035,20.00,94.2109,0.133188,20.0181,3.80130e-3,821.035,9537.26,2.73926
174.124,172.418,1.00989,828.375,20.00,120.420,0.170240,20.0131,4.05073e-3,828.375,9846.48,3.00007
196.305,188.837,1.03955,835.715,20.00,126.309,0.178565,20.0154,3.54209e-3,835.715,11100.8,3.28575
212.461,206.820,1.02727,843.055,20.00,131.510,0.185918,20.0175,3.07449e-3,843.055,12014.4,3.59866
231.025,226.517,1.01990,850.395,20.00,133.339,0.188504,20.0130,2.59871e-3,850.395,13064.2,3.94138
235.433,248.295,0.948197,857.801,20.00,159.108,0.224933,20.0101,2.58080e-3,857.801,13313.4,4.32033
225.608,272.145,0.828996,865.206,20.00,243.901,0.344807,20.0145,3.29315e-3,865.206,12757.8,4.73532
253.605,298.065,0.850837,872.546,20.00,265.650,0.375553,20.0124,2.99011e-3,872.546,14341.0,5.18632
297.858,326.455,0.912402,879.886,20.00,223.774,0.316353,20.0107,2.09973e-3,879.886,16843.5,5.68030
331.850,357.536,0.928158,887.226,20.00,265.105,0.374784,20.0086,2.07386e-3,887.226,18765.7,6.22111
370.020,391.585,0.944930,894.566,20.00,279.936,0.395750,20.0054,1.82560e-3,894.566,20924.2,6.81357
404.363,429.229,0.942070,901.972,20.00,302.842,0.428132,20.0119,1.64376e-3,901.972,22866.2,7.46856
435.773,470.478,0.926236,909.378,20.00,348.330,0.492440,19.9985,1.57367e-3,909.378,24642.4,8.18629
480.117,515.280,0.931758,916.718,20.00,375.230,0.530470,20.0016,1.41322e-3,916.718,27149.9,8.96586
526.250,564.349,0.932491,924.058,20.00,421.389,0.595724,19.9992,1.32309e-3,924.058,29758.8,9.81965
573.239,618.091,0.927434,931.398,20.01,482.082,0.681528,19.9957,1.26188e-3,931.398,32415.9,10.7548
616.453,676.948,0.910636,938.738,20.00,523.601,0.740223,19.9986,1.14259e-3,938.738,34859.6,11.7789
672.612,742.023,0.906457,946.143,20.00,627.114,0.886561,19.9864,1.13897e-3,946.143,38035.3,12.9112
732.072,813.334,0.900088,953.549,20.00,673.678,0.952389,19.9927,1.01839e-3,953.549,41397.7,14.1520
793.954,890.786,0.891296,960.889,20.01,760.074,1.07453,19.9918,9.57875e-4,960.889,44897.1,15.4997
859.116,975.612,0.880592,968.229,20.01,869.945,1.22986,19.9741,9.13982e-4,968.229,48581.9,16.9756
927.532,1068.52,0.868056,975.569,20.01,934.753,1.32148,19.9925,8.18718e-4,975.569,52450.7,18.5922
999.373,1170.27,0.853969,982.909,20.02,1061.78,1.50105,19.9728,7.75286e-4,982.909,56513.2,20.3626
1075.69,1282.77,0.838568,990.315,20.01,1168.64,1.65212,19.9733,7.10205e-4,990.315,60828.7,22.3201
1156.35,1406.04,0.822412,997.720,20.02,1283.25,1.81415,19.9722,6.49100e-4,997.720,65390.0,24.4651
1240.62,1539.94,0.805629,1005.06,20.01,1446.23,2.04456,19.9646,6.09859e-4,1005.06,70155.3,26.7949
1329.81,1686.58,0.788465,1012.40,20.01,1560.28,2.20579,19.9713,5.48515e-4,1012.40,75199.0,29.3464
1423.22,1847.19,0.770477,1019.74,20.01,1743.27,2.46449,19.9559,5.10905e-4,1019.74,80481.1,32.1411
1519.67,2023.09,0.751163,1027.08,20.01,1913.26,2.70481,19.9494,4.67460e-4,1027.08,85935.4,35.2017
1621.69,2217.57,0.731292,1034.49,20.02,2067.23,2.92248,19.9576,4.20372e-4,1034.49,91704.6,38.5857
1727.05,2430.69,0.710519,1041.89,20.02,2302.02,3.25441,19.9391,3.89628e-4,1041.89,97662.4,42.2939
1833.21,2662.16,0.688618,1049.23,20.02,2480.72,3.50703,19.9488,3.50034e-4,1049.23,103666,46.3214
1933.01,2915.67,0.662974,1056.57,20.02,2708.19,3.82862,19.9451,3.18569e-4,1056.57,109309,50.7325
1004.76,3193.61,0.314614,1063.91,20.01,2220.16,3.13867,19.9331,2.17680e-4,1063.91,56817.7,55.5688
446.586,3497.67,0.127681,1071.25,19.99,1205.45,1.70417,19.9727,9.85356e-5,1071.25,25253.8,60.8593
177.496,3834.01,0.0462951,1078.66,20.00,-164.236,-0.232184,20.0393,-1.11728e-5,1078.66,10037.2,66.7116
81.9068,4202.02,0.0194923,1086.06,19.99,-1239.49,-1.75228,20.0640,-7.01982e-5,1086.06,4631.72,73.1149
74.0989,4602.24,0.0161006,1093.40,19.97,-1234.19,-1.74479,20.0843,-5.82697e-5,1093.40,4190.19,80.0788
74.9527,5040.57,0.0148699,1100.74,19.98,-1115.41,-1.57688,20.0846,-4.39011e-5,1100.74,4238.48,87.7058
76.7016,5520.60,0.0138937,1108.08,19.97,-946.481,-1.33806,20.0914,-3.10556e-5,1108.08,4337.37,96.0582
73.7824,6046.27,0.0122029,1115.42,19.98,-791.922,-1.11955,20.0898,-2.16624e-5,1115.42,4172.29,105.205
62.3563,6627.45,9.40879e-3,1122.83,19.98,-647.677,-0.915632,20.0853,-1.47457e-5,1122.83,3526.17,115.317
67.3766,7264.50,9.27478e-3,1130.23,19.98,-597.606,-0.844846,20.0848,-1.13241e-5,1130.23,3810.06,126.402
57.2193,7956.15,7.19183e-3,1137.57,19.98,-372.266,-0.526279,20.0751,-5.88095e-6,1137.57,3235.67,138.437
56.1985,8713.82,6.44935e-3,1144.91,19.99,-156.918,-0.221837,20.0776,-2.06659e-6,1144.91,3177.95,151.620
65.2585,9543.71,6.83785e-3,1152.25,19.99,-60.4248,-0.0854236,20.0791,-6.63408e-7,1152.25,3690.28,166.060
56.8437,10452.4,5.43836e-3,1159.59,19.99,-55.4902,-0.0784475,20.0673,-5.07910e-7,1159.59,3214.44,181.871
54.3398,11457.2,4.74287e-3,1167.00,19.99,-77.6900,-0.109832,20.0720,-5.91850e-7,1167.00,3072.84,199.354
55.2812,12558.3,4.40197e-3,1174.41,19.99,-74.1978,-0.104895,20.0617,-4.70468e-7,1174.41,3126.08,218.514
55.1578,13754.3,4.01023e-3,1181.75,19.99,-166.018,-0.234702,20.0562,-8.77563e-7,1181.75,3119.10,239.324
58.1375,15063.9,3.85940e-3,1189.09,20.00,-232.935,-0.329304,20.0542,-1.02651e-6,1189.09,3287.60,262.111
63.4079,16484.7,3.84647e-3,1196.36,19.99,-374.884,-0.529980,20.0665,-1.37954e-6,1196.36,3585.63,286.833