File: Viscosity/csv/psb_thfdmf_01_6.csv
Filename,psb_thfdmf_01_6,,,,,,,,,,,,
Instrument name,5333-0457,,,,,,,,,,,,
Operator,Osamu Katagiri,,,,,,,,,,,,
rundate,19/12/2019,,,,,,,,,,,,
Sample name,PSB_THFDMF_01_6,,,,,,,,,,,,
Geometry name,60.0mm 0.996944° cone plate, Peltier plate Steel ,,,,,,,,,,,
Procedure name,Sample,,,,,,,,,,,,
,Flow ramp,,,,,,,,,,,,
proceduresegments,Flow ramp,,,,,,,,,,,,
[step],,,,,,,,,,,,,
Flow ramp - 1,,,,,,,,,,,,,
Stress,Shear rate,Viscosity,Step time,Temperature,Normal stress,Axial force,Gap,Normal stress coefficient,Time,Torque,Velocity,,
Pa,1/s,Pa.s,s,°C,Pa,N,µm,Pa.s²,s,µN.m,rad/s,,
-1.87656,2.06561,-0.908475,1.14691,19.98,61.1354,0.0864281,20.0348,14.3283,1.14691,-106.117,0.0359416,,
1.35767,7.67E-03,177.029,11.4939,19.98,62.6721,0.0886006,20.03,1065560,11.4939,76.7743,1.33E-04,,
1.49671,7.38E-03,198.259,18.5467,19.99,63.9196,0.0903642,20.0328,1121570,18.5467,84.6368,1.31E-04,,
1.49671,7.55E-03,198.259,18.5467,19.99,63.9196,0.0903642,20.0328,1121570,18.5467,84.6368,1.31E-04,,
1.35721,8.27E-03,164.159,25.9523,19.99,62.202,0.0879361,20.0205,909997,25.9523,76.7485,1.44E-04,,
1.31071,8.96E-03,146.248,33.2923,20,61.8606,0.0874534,20.0239,770159,33.2923,74.1188,1.56E-04,,
1.37322,0.0100139,137.131,40.6324,19.99,62.5321,0.0884027,20.0298,623586,40.6324,77.6535,1.74E-04,,
1.22142,0.0108743,112.322,47.9724,20,59.6036,0.0842626,20.0322,504045,47.9724,69.0699,1.89E-04,,
1.16978,0.0119762,97.6757,55.3124,20,59.9146,0.0847023,20.0302,417732,55.3124,66.1495,2.08E-04,,
0.913573,0.013015,70.194,62.718,20,57.4848,0.0812672,20.0277,339364,62.718,51.6613,2.26E-04,,
0.901289,0.0142837,63.099,70.1236,20,56.095,0.0793024,20.0266,274941,70.1236,50.9667,2.49E-04,,
0.998116,0.0156745,63.6776,77.4636,20,57.2218,0.0808954,20.0232,232902,77.4636,56.4421,2.73E-04,,
1.04749,0.0171486,61.0829,84.8036,20,56.918,0.0804659,20.0256,193550,84.8036,59.234,2.98E-04,,
1.07651,0.0187893,57.2936,92.1436,20,57.0488,0.0806508,20.022,161593,92.1436,60.8751,3.27E-04,,
1.07055,0.0205762,52.0284,99.4837,20,57.4599,0.0812321,20.022,135717,99.4837,60.538,3.58E-04,,
1.07264,0.0226692,47.3169,106.889,20,56.1218,0.0793403,20.0202,109209,106.889,60.6562,3.94E-04,,
0.716467,0.0247831,28.9095,114.295,20,54.1446,0.0765451,20.0258,88154.3,114.295,40.5153,4.31E-04,,
0.45499,0.0270232,16.837,121.635,20,51.6609,0.0730339,20.0207,70743.8,121.635,25.7291,4.70E-04,,
0.446726,0.0296346,15.0745,128.975,20,51.2673,0.0724774,20.0303,58377.2,128.975,25.2618,5.16E-04,,
0.488382,0.0326092,14.9768,136.315,20,51.5713,0.0729072,20.0204,48498.6,136.315,27.6173,5.67E-04,,
0.47926,0.0356669,13.4371,143.655,20,51.6283,0.0729878,20.0174,40584.2,143.655,27.1015,6.21E-04,,
0.475629,0.039064,12.1757,151.061,20,52.0951,0.0736478,20.0272,34138.5,151.061,26.8962,6.80E-04,,
0.444495,0.0427744,10.3916,158.466,20,52.5815,0.0743354,20.0302,28738.6,158.466,25.1356,7.44E-04,,
0.415718,0.0468338,8.87645,165.806,20,51.8203,0.0732592,20.0231,23625.5,165.806,23.5083,8.15E-04,,
0.410114,0.0511602,8.01627,173.146,20,52.7938,0.0746355,20.0137,20170.6,173.146,23.1914,8.90E-04,,
0.389216,0.0561566,6.93091,180.486,20,51.9457,0.0734365,20.0282,16472.1,180.486,22.0097,9.77E-04,,
0.322006,0.0614297,5.24187,187.826,20,50.9316,0.0720028,20.0159,13496.8,187.826,18.209,1.07E-03,,
0.330593,0.0672891,4.91303,195.232,20,51.6963,0.0730839,20.0257,11417.5,195.232,18.6946,1.17E-03,,
0.358946,0.07385,4.86047,202.637,20,51.9028,0.0733758,20.0195,9516.77,202.637,20.2979,1.28E-03,,
0.38806,0.0809394,4.79445,209.977,20,51.5586,0.0728892,20.0192,7870.11,209.977,21.9443,1.41E-03,,
0.373483,0.0886118,4.21482,217.317,20,51.5992,0.0729466,20.0225,6571.43,217.317,21.12,1.54E-03,,
0.368915,0.0970277,3.80216,224.657,20,50.9602,0.0720434,20.0185,5413.03,224.657,20.8616,1.69E-03,,
0.393073,0.106415,3.69376,231.997,20,51.812,0.0732475,20.027,4575.32,231.997,22.2277,1.85E-03,,
0.308244,0.11647,2.64656,239.403,20,51.0516,0.0721725,20.0239,3763.44,239.403,17.4308,2.03E-03,,
0.316983,0.12772,2.48185,246.809,20,51.2126,0.0724001,20.0283,3139.48,246.809,17.925,2.22E-03,,
0.275627,0.139848,1.9709,254.149,20,51.0785,0.0722106,20.0236,2611.7,254.149,15.5864,2.43E-03,,
0.274511,0.153341,1.7902,261.489,20,50.7796,0.071788,20.0315,2159.6,261.489,15.5232,2.67E-03,,
0.269868,0.16782,1.60808,268.829,20,50.9904,0.072086,20.025,1810.51,268.829,15.2607,2.92E-03,,
0.278356,0.183864,1.51393,276.169,20,50.7461,0.0717406,20.0235,1501.1,276.169,15.7407,3.20E-03,,
0.287293,0.20152,1.42563,283.574,20,50.3966,0.0712466,20.0248,1240.98,283.574,16.246,3.51E-03,,
0.309697,0.220856,1.40225,290.98,20,51.5877,0.0729304,20.0294,1057.61,290.98,17.5129,3.84E-03,,
0.295477,0.241977,1.22109,298.32,20,50.3434,0.0711714,20.0334,859.793,298.32,16.7088,4.21E-03,,
0.270697,0.264978,1.02159,305.66,20,50.3233,0.0711429,20.0338,716.721,305.66,15.3076,4.61E-03,,
0.247251,0.290201,0.851997,313,20,50.1532,0.0709025,20.034,595.525,313,13.9817,5.05E-03,,
0.246366,0.317922,0.774925,320.34,20,50.8559,0.0718958,20.0341,503.152,320.34,13.9317,5.53E-03,,
0.252194,0.348484,0.723688,327.746,20.01,50.6173,0.0715585,20.0119,416.805,327.746,14.2612,6.06E-03,,
0.246722,0.381982,0.645899,335.151,20,49.9346,0.0705934,20.0174,342.229,335.151,13.9518,6.65E-03,,
0.246701,0.418263,0.589824,342.491,20,49.9971,0.0706818,20.0248,285.79,342.491,13.9506,7.28E-03,,
0.253227,0.458154,0.552712,349.831,20,49.4592,0.0699213,20.0249,235.626,349.831,14.3197,7.97E-03,,
0.232597,0.501864,0.463465,357.171,20,49.0474,0.0693391,20.0357,194.735,357.171,13.153,8.73E-03,,
0.230554,0.549594,0.419499,364.511,20,48.0375,0.0679114,20.0206,159.036,364.511,13.0375,9.56E-03,,
0.239189,0.602416,0.39705,371.917,20,48.4165,0.0684472,20.0223,133.414,371.917,13.5258,0.010482,,
0.230498,0.660391,0.349032,379.322,20,49.6472,0.070187,20.0249,113.839,379.322,13.0343,0.0114908,,
0.229237,0.723172,0.316989,386.662,20,49.0825,0.0693888,20.0119,93.8521,386.662,12.9631,0.0125832,,
0.226785,0.792146,0.286292,394.002,20,48.0752,0.0679647,20.0121,76.6145,394.002,12.8244,0.0137833,,
0.21004,0.867575,0.2421,401.342,20,47.6363,0.0673443,20.007,63.2884,401.342,11.8775,0.0150958,,
0.210128,0.950074,0.22117,408.683,20,48.6083,0.0687184,20.0277,53.8513,408.683,11.8825,0.0165312,,
0.200606,1.04153,0.192606,416.088,20,46.1164,0.0651955,20.0252,42.5116,416.088,11.344,0.0181227,,
0.196364,1.14164,0.172002,423.494,20,47.248,0.0667953,20.0186,36.2515,423.494,11.1041,0.0198645,,
0.19181,1.25029,0.153412,430.834,20,46.0927,0.065162,20.0216,29.4855,430.834,10.8466,0.0217551,,
0.185778,1.36943,0.135661,438.174,20,45.8529,0.0648229,20.0317,24.4505,438.174,10.5055,0.023828,,
0.178814,1.49972,0.119232,445.514,20,45.8274,0.064787,20.0326,20.3753,445.514,10.1117,0.0260951,,
0.18159,1.64273,0.110541,452.854,20,46.0913,0.06516,20.0294,17.08,452.854,10.2686,0.0285834,,
0.186285,1.80046,0.103465,460.259,20,45.9678,0.0649855,20.0315,14.1804,460.259,10.5342,0.0313279,,
0.191239,1.9735,0.0969036,467.665,20,45.5097,0.0643378,20.0266,11.685,467.665,10.8143,0.0343388,,
0.208402,2.16147,0.0964167,475.005,20,45.5198,0.0643522,20.0275,9.74317,475.005,11.7849,0.0376096,,
0.240044,2.36738,0.101397,482.345,20,46.8928,0.0662931,20.0189,8.36701,482.345,13.5742,0.0411923,,
0.274315,2.59272,0.105802,489.685,20,45.6058,0.0644737,20.0264,6.78435,489.685,15.5121,0.0451133,,
0.31314,2.83968,0.110273,497.025,20,47.103,0.0665902,20.0239,5.8413,497.025,17.7076,0.0494103,,
0.354371,3.11259,0.113851,504.431,20,48.7982,0.0689869,20.0141,5.03687,504.431,20.0392,0.0541589,,
0.437781,3.41174,0.128316,511.836,20,49.1869,0.0695363,20.0414,4.22569,511.836,24.7559,0.0593642,,
0.521724,3.73654,0.139628,519.176,20,50.4334,0.0712985,20.0201,3.61225,519.176,29.5028,0.0650157,,
0.553013,4.09251,0.135128,526.516,20,49.416,0.0698602,20.0237,2.95045,526.516,31.2721,0.0712094,,
0.583899,4.48229,0.130268,533.856,20,49.2562,0.0696343,20.0256,2.45166,533.856,33.0187,0.0779918,,
0.53364,4.90927,0.1087,541.196,20,48.5235,0.0685985,20.0247,2.01334,541.196,30.1766,0.0854212,,
0.476395,5.38103,0.0885323,548.602,20,46.8734,0.0662657,20.0177,1.61881,548.602,26.9395,0.0936297,,
0.430995,5.89809,0.0730736,556.007,20,47.0646,0.066536,20.0211,1.35292,556.007,24.3722,0.102627,,
0.43485,6.45974,0.067317,563.347,20,47.0725,0.0665471,20.0303,1.12807,563.347,24.5902,0.112399,,
0.506089,7.07473,0.0715348,570.688,20,47.0002,0.066445,20.0239,0.939031,570.688,28.6187,0.1231,,
0.62684,7.74834,0.0808999,578.028,20,49.3378,0.0697497,20.0202,0.821793,578.028,35.447,0.134821,,
0.801038,8.48674,0.094387,585.368,20,50.5307,0.0714361,20.0232,0.701574,585.368,45.2976,0.147669,,
0.802196,9.30237,0.0862356,592.773,20,49.1555,0.069492,20.0304,0.568048,592.773,45.3631,0.161861,,
0.693794,10.1964,0.0680431,600.179,20.01,47.24,0.066784,20.0227,0.454377,600.179,39.2331,0.177417,,
0.70203,11.1671,0.0628658,607.519,20,44.7075,0.0632037,20.028,0.358507,607.519,39.6989,0.194308,,
0.878719,12.2302,0.071848,614.859,20,47.8564,0.0676554,20.0226,0.319941,614.859,49.6904,0.212806,,
1.06392,13.3958,0.0794224,622.199,20,48.4158,0.0684462,20.0224,0.269807,622.199,60.1634,0.233086,,
0.945369,14.6709,0.0644382,629.539,20,45.7614,0.0646936,20.0282,0.212609,629.539,53.4594,0.255274,,
1.00624,16.0809,0.0625736,636.944,20,46.5526,0.0658122,20.0208,0.180021,636.944,56.9015,0.279807,,
1.2858,17.627,0.072945,644.35,20,47.8664,0.0676695,20.0244,0.154054,644.35,72.7104,0.306709,,
1.1901,19.3052,0.0616467,651.69,20,45.1935,0.0638908,20.0335,0.121263,651.69,67.2986,0.33591,,
1.36767,21.1432,0.0646859,659.03,20,46.2943,0.0654471,20.0259,0.103559,659.03,77.3397,0.367891,,
1.49128,23.1575,0.0643974,666.37,20,44.9416,0.0635347,20.0238,0.0838038,666.37,84.3301,0.40294,,
1.56875,25.3616,0.0618551,673.71,20,45.3659,0.0641346,20.0313,0.0705302,673.71,88.7106,0.441292,,
1.72738,27.8007,0.0621346,681.116,20,44.8979,0.0634729,20.0259,0.0580918,681.116,97.6813,0.483731,,
1.91356,30.472,0.0627973,688.521,20,45.4914,0.0643119,20.0217,0.0489922,688.521,108.209,0.530212,,
1.96914,33.373,0.0590039,695.861,20,44.9526,0.0635503,20.0257,0.0403612,695.861,111.352,0.580689,,
2.22217,36.5523,0.0607942,703.201,20,44.263,0.0625753,20.0243,0.0331292,703.201,125.661,0.636009,,
2.42435,40.0327,0.0605592,710.541,20,45.1628,0.0638474,20.0243,0.0281807,710.541,137.094,0.696567,,
2.61447,43.8446,0.0596303,717.881,20,43.9608,0.0621482,20.0213,0.0228683,717.881,147.845,0.762895,,
2.83573,48.0595,0.0590047,725.287,20,43.1667,0.0610255,20.0228,0.0186892,725.287,160.357,0.836233,,
3.0836,52.6779,0.0585368,732.693,20,43.4767,0.0614637,20.0239,0.0156675,732.693,174.373,0.916594,,
3.34658,57.6943,0.0580054,740.033,20,41.6798,0.0589234,20.0209,0.0125216,740.033,189.245,1.00388,,
3.65037,63.1876,0.0577704,747.373,20,43.1447,0.0609944,20.0199,0.010806,747.373,206.424,1.09946,,
4.0267,69.2063,0.058184,754.713,20,43.4333,0.0614024,20.0196,9.07E-03,754.713,227.704,1.20419,,
4.32462,75.7954,0.0570565,762.053,20,39.2467,0.0554837,20.0246,6.83E-03,762.053,244.551,1.31884,,
4.76871,83.0828,0.0573971,769.458,20,41.6492,0.0588801,20.0143,6.03E-03,769.458,269.664,1.44564,,
5.19862,91.0664,0.057086,776.864,20,39.5103,0.0558564,20.015,4.76E-03,776.864,293.975,1.58455,,
5.66908,99.7385,0.0568394,784.204,20,38.9397,0.0550497,20.0126,3.91E-03,784.204,320.579,1.73545,,
6.18149,109.236,0.0565883,791.544,20,39.5966,0.0559784,20.0239,3.32E-03,791.544,349.555,1.9007,,
6.76018,119.637,0.0565057,798.884,20,35.5215,0.0502173,20.0227,2.48E-03,798.884,382.279,2.08168,,
7.30056,131.032,0.0557159,806.224,20,32.5401,0.0460025,20.0137,1.90E-03,806.224,412.837,2.27995,,
7.9795,143.627,0.055557,813.629,20,28.279,0.0399786,20.0127,1.37E-03,813.629,451.23,2.49911,,
8.72454,157.43,0.0554187,821.035,20,24.3361,0.0344044,20.0197,9.82E-04,821.035,493.361,2.73927,,
9.54663,172.423,0.0553676,828.375,20,24.2179,0.0342372,20.0259,8.15E-04,828.375,539.849,3.00015,,
10.4252,188.84,0.0552065,835.715,20,22.546,0.0318737,20.0175,6.32E-04,835.715,589.532,3.28581,,
11.3911,206.824,0.0550765,843.055,20,22.9593,0.032458,20.0314,5.37E-04,843.055,644.154,3.59873,,
12.4528,226.518,0.054975,850.395,20,24.4214,0.0345249,20.0196,4.76E-04,850.395,704.189,3.9414,,
13.6294,248.294,0.0548921,857.801,20,20.6827,0.0292395,20.0291,3.35E-04,857.801,770.723,4.32031,,
14.9053,272.157,0.0547672,865.206,20,24.6862,0.0348993,20.0219,3.33E-04,865.206,842.873,4.73552,,
16.2944,298.072,0.054666,872.546,20,27.2265,0.0384905,20.0342,3.06E-04,872.546,921.427,5.18644,,
17.8157,326.457,0.0545728,879.886,20,33.3107,0.047092,20.0246,3.13E-04,879.886,1007.45,5.68034,,
19.4641,357.543,0.0544384,887.226,20,41.8806,0.0592073,20.0273,3.28E-04,887.226,1100.67,6.22124,,
21.2851,391.592,0.0543553,894.566,20,39.7377,0.0561778,20.0239,2.59E-04,894.566,1203.64,6.81368,,
23.2928,429.235,0.0542659,901.972,19.99,44.5266,0.062948,20.0217,2.42E-04,901.972,1317.18,7.46868,,
25.4968,470.485,0.0541927,909.378,20,43.5896,0.0616234,20.0236,1.97E-04,909.378,1441.81,8.18641,,
27.8973,515.29,0.054139,916.718,20,39.2922,0.055548,20.0196,1.48E-04,916.718,1577.55,8.96603,,
30.5331,564.357,0.0541025,924.058,20,44.7169,0.0632171,20.0273,1.40E-04,924.058,1726.61,9.81978,,
33.4274,618.101,0.0540809,931.398,20,34.7479,0.0491237,20.0178,9.10E-05,931.398,1890.28,10.7549,,
36.6082,676.959,0.0540774,938.738,20,34.2205,0.0483781,20.0289,7.47E-05,938.738,2070.14,11.7791,,
40.1421,742.036,0.0540973,946.143,20,32.8609,0.0464561,20.0207,5.97E-05,946.143,2269.98,12.9114,,
44.0534,813.347,0.0541631,953.549,20,22.03,0.0311442,20.0278,3.33E-05,953.549,2491.16,14.1522,,
48.3741,890.798,0.0543043,960.889,20,24.5385,0.0346905,20.022,3.09E-05,960.889,2735.49,15.4999,,
53.0874,975.627,0.0544136,968.229,20,14.8434,0.0209844,20.0206,1.56E-05,968.229,3002.02,16.9759,,
58.2554,1068.53,0.0545191,975.569,20,2.03788,2.88E-03,20.0245,1.78E-06,975.569,3294.27,18.5924,,
63.9101,1170.29,0.0546107,982.909,20,-0.550896,-7.79E-04,20.0229,-4.02E-07,982.909,3614.03,20.3629,,
70.1147,1282.78,0.0546583,990.315,20,-17.2933,-0.0244478,20.0204,-1.05E-05,990.315,3964.89,22.3204,,
76.8436,1406.06,0.0546515,997.72,20,-33.7843,-0.0477614,20.0224,-1.71E-05,997.72,4345.4,24.4655,,
84.1028,1539.96,0.0546136,1005.06,20,-39.8835,-0.0563839,20.0197,-1.68E-05,1005.06,4755.9,26.7952,,
92.0108,1686.6,0.0545539,1012.4,20,-66.4408,-0.0939284,20.0183,-2.34E-05,1012.4,5203.09,29.3468,,
100.63,1847.22,0.0544767,1019.74,20,-83.9418,-0.11867,20.0224,-2.46E-05,1019.74,5690.51,32.1415,,
110.011,2023.12,0.0543769,1027.08,20,-125.373,-0.177242,20.0087,-3.06E-05,1027.08,6220.97,35.2022,,
120.367,2217.6,0.0542782,1034.49,20,-158.541,-0.224131,20.0151,-3.22E-05,1034.49,6806.62,38.5862,,
131.635,2430.71,0.054155,1041.89,20,-190.617,-0.269478,20.0197,-3.23E-05,1041.89,7443.8,42.2943,,
143.798,2662.19,0.0540149,1049.23,20,-244.102,-0.34509,20.0195,-3.44E-05,1049.23,8131.58,46.322,,
157.079,2915.7,0.0538735,1056.57,20,-304.596,-0.430613,20.019,-3.58E-05,1056.57,8882.61,50.7331,,
171.503,3193.35,0.0537063,1063.91,20,-394.158,-0.557227,20.0179,-3.87E-05,1063.91,9698.26,55.5641,,
187.269,3497.44,0.0535446,1071.25,20.01,-488.516,-0.690623,20.0169,-3.99E-05,1071.25,10589.8,60.8554,,
99.6584,3834.21,0.0259919,1078.66,20.04,-620.008,-0.876515,20.0133,-4.22E-05,1078.66,5635.55,66.7152,,
24.237,4202.17,5.77E-03,1086.06,20.07,-763.638,-1.07957,20.0174,-4.32E-05,1086.06,1370.57,73.1175,,
22.9333,4602.25,4.98E-03,1093.4,20,-887.035,-1.25402,20.025,-4.19E-05,1093.4,1296.85,80.0789,,
24.8718,5040.62,4.93E-03,1100.74,19.98,-1028.77,-1.45439,20.0324,-4.05E-05,1100.74,1406.47,87.7067,,
25.0673,5520.52,4.54E-03,1108.08,19.97,-1184.37,-1.67436,20.0333,-3.89E-05,1108.08,1417.52,96.0568,,
25.8231,6046.29,4.27E-03,1115.42,19.98,-1297.27,-1.83397,20.0294,-3.55E-05,1115.42,1460.26,105.205,,
26.0727,6627.49,3.93E-03,1122.83,19.98,-1378.29,-1.94852,20.0245,-3.14E-05,1122.83,1474.37,115.318,,
22.8767,7264.55,3.15E-03,1130.23,19.98,-531.994,-0.752088,20.0269,-1.01E-05,1130.23,1293.65,126.403,,
21.0857,7956.17,2.65E-03,1137.57,19.99,-39.8122,-0.0562831,20.0389,-6.29E-07,1137.57,1192.37,138.437,,
23.2306,8713.86,2.67E-03,1144.91,19.99,-68.6082,-0.0969926,20.0204,-9.04E-07,1144.91,1313.66,151.621,,
23.9469,9543.64,2.51E-03,1152.25,19.99,-84.6273,-0.119639,20.0266,-9.29E-07,1152.25,1354.17,166.059,,
24.4702,10452.4,2.34E-03,1159.59,19.99,-82.1004,-0.116067,20.0327,-7.51E-07,1159.59,1383.75,181.871,,
24.545,11457.1,2.14E-03,1167,19.99,-115.607,-0.163436,20.0311,-8.81E-07,1167,1387.99,199.354,,
27.4096,12558.6,2.18E-03,1174.41,19.99,-149.758,-0.211716,20.0213,-9.50E-07,1174.41,1549.98,218.518,,
23.5132,13754.2,1.71E-03,1181.75,19.99,-164.69,-0.232824,20.0284,-8.71E-07,1181.75,1329.64,239.323,,
28.0015,15063.7,1.86E-03,1189.09,19.99,-167.392,-0.236645,20.0159,-7.38E-07,1189.09,1583.45,262.108,,
30.7144,16484.9,1.86E-03,1196.36,19.99,-119.254,-0.168591,20.0285,-4.39E-07,1196.36,1736.86,286.836,,