File: Viscosity/csv/pvk_dcm_00_4.csv
Filename,pvk_dcm_00_4
Instrument name,5333-0457
Operator,Osamu Katagiri
rundate,13/12/2019
Sample name,4_PVK_CHL
Geometry name,60.0mm 0.996944° cone plate, Peltier plate Steel
Procedure name,Sample
,Flow ramp
proceduresegments,Flow ramp
[step]
Flow ramp - 1
Stress,Shear rate,Viscosity,Step time,Temperature,Normal stress,Axial force,Gap,Normal stress coefficient,Time,Torque,Velocity
Pa,1/s,Pa.s,s,°C,Pa,N,µm,Pa.s²,s,µN.m,rad/s
1.36190,8.01728e-3,169.871,5.96381,20.00,6.95405,9.83106e-3,20.0264,108189,5.96381,77.0136,1.39500e-4
1.74302,6.81285e-3,258.132,12.7140,20.00,-16.9611,-0.0239782,20.0305,-365423,12.7140,98.5655,1.18543e-4
2.26860,7.50373e-3,293.936,21.1682,20.00,0.928978,1.31331e-3,20.0325,16498.8,21.1682,128.286,1.30565e-4
2.77733,8.24118e-3,319.554,29.6223,20.00,-1.12610,-1.59198e-3,20.0318,-16580.4,29.6223,157.054,1.43396e-4
3.18231,9.02204e-3,340.356,38.0109,20.00,-10.2612,-0.0145064,20.0316,-126063,38.0109,179.955,1.56983e-4
3.54128,9.87952e-3,349.412,46.3995,20.00,-10.2693,-0.0145178,20.0349,-105213,46.3995,200.254,1.71903e-4
3.83314,0.0108209,348.062,54.7881,20.00,4.53284,6.40815e-3,20.0330,38711.9,54.7881,216.759,1.88283e-4
4.09227,0.0118585,340.494,63.1767,20.00,-11.5069,-0.0162675,20.0309,-81827.2,63.1767,231.412,2.06338e-4
4.29375,0.0129953,328.697,71.6309,20.00,12.6802,0.0179262,20.0317,75084.6,71.6309,242.806,2.26118e-4
4.50181,0.0142445,314.596,80.0850,20.00,13.2840,0.0187798,20.0289,65468.7,80.0850,254.571,2.47854e-4
4.68789,0.0155899,299.770,88.4736,20.00,31.5581,0.0446143,20.0305,129845,88.4736,265.094,2.71264e-4
4.86401,0.0170670,285.128,96.8622,20.00,33.0277,0.0466918,20.0314,113387,96.8622,275.053,2.96966e-4
5.05659,0.0186870,270.846,105.251,20.00,29.3435,0.0414835,20.0333,84029.9,105.251,285.943,3.25153e-4
5.25950,0.0204650,257.084,113.639,20.00,10.4439,0.0147648,20.0326,24936.9,113.639,297.418,3.56090e-4
5.47982,0.0224222,243.978,122.094,20.00,26.4081,0.0373336,20.0329,52526.8,122.094,309.877,3.90146e-4
5.69044,0.0245651,231.381,130.548,20.00,10.9638,0.0154997,20.0316,18168.6,130.548,321.787,4.27433e-4
5.90712,0.0268973,219.247,138.936,20.00,9.43304,0.0133356,20.0311,13038.7,138.936,334.040,4.68013e-4
6.11927,0.0294537,207.310,147.325,20.00,-0.676104,-9.55820e-4,20.0272,-779.351,147.325,346.037,5.12494e-4
6.32638,0.0322493,195.602,155.714,20.00,10.0288,0.0141779,20.0281,9642.96,155.714,357.748,5.61136e-4
6.52203,0.0353099,184.116,164.102,20.00,-1.14009,-1.61177e-3,20.0339,-914.425,164.102,368.812,6.14391e-4
6.69775,0.0386870,172.809,172.556,20.00,1.62432,2.29633e-3,20.0360,1085.28,172.556,378.749,6.73152e-4
6.87143,0.0423872,161.782,181.010,20.00,16.4437,0.0232467,20.0281,9152.29,181.010,388.570,7.37535e-4
7.03305,0.0464088,151.187,189.399,20.00,-4.70516,-6.65176e-3,20.0213,-2184.61,189.399,397.710,8.07512e-4
7.17933,0.0508116,141.091,197.788,20.00,2.11424,2.98893e-3,20.0245,818.894,197.788,405.981,8.84121e-4
7.31638,0.0556312,131.502,206.176,20.00,-8.95138,-0.0126547,20.0219,-2892.36,206.176,413.731,9.67982e-4
7.45743,0.0608147,122.569,214.565,20.00,-21.6772,-0.0306455,20.0223,-5861.21,214.565,421.708,1.05817e-3
7.60257,0.0666532,113.887,223.019,20.00,-20.7896,-0.0293907,20.0254,-4679.55,223.019,429.915,1.15976e-3
7.73652,0.0730311,105.802,231.473,20.00,-41.2255,-0.0582811,20.0255,-7729.46,231.473,437.490,1.27074e-3
7.85566,0.0799760,98.3276,239.862,20.00,-44.3907,-0.0627558,20.0276,-6940.20,239.862,444.227,1.39158e-3
7.99019,0.0875605,91.3336,248.250,20.00,-41.3769,-0.0584953,20.0303,-5396.87,248.250,451.835,1.52355e-3
8.14412,0.0958840,84.6984,256.639,20.00,-45.0061,-0.0636259,20.0320,-4895.30,256.639,460.539,1.66838e-3
8.27259,0.105059,78.4478,265.093,20.00,-27.2645,-0.0385443,20.0139,-2470.20,265.093,467.804,1.82802e-3
8.35658,0.115112,72.6686,273.547,20.00,-38.8591,-0.0549358,20.0253,-2932.59,273.547,472.553,2.00295e-3
8.45268,0.126044,67.4217,281.936,20.00,-48.8785,-0.0691004,20.0267,-3076.63,281.936,477.988,2.19316e-3
8.60401,0.138004,62.6494,290.325,20.00,-64.3974,-0.0910397,20.0299,-3381.29,290.325,486.545,2.40127e-3
8.81420,0.151117,58.4067,298.713,20.00,-69.0802,-0.0976599,20.0327,-3025.02,298.713,498.431,2.62942e-3
9.01878,0.165438,54.6156,307.102,20.00,-66.9225,-0.0946095,20.0373,-2445.14,307.102,510.000,2.87861e-3
9.26580,0.181275,51.0951,315.556,20.00,-61.4396,-0.0868582,20.0303,-1869.71,315.556,523.969,3.15417e-3
9.50872,0.198620,47.7883,324.010,20.00,-71.0717,-0.100475,20.0376,-1801.57,324.010,537.706,3.45598e-3
9.73297,0.217455,44.7338,332.399,20.00,-95.8506,-0.135506,20.0347,-2027.01,332.399,550.387,3.78371e-3
9.95534,0.238098,41.8896,340.787,20.00,-82.9224,-0.117229,20.0233,-1462.71,340.787,562.961,4.14290e-3
10.2012,0.260682,39.2871,349.176,20.00,-88.8436,-0.125600,20.0277,-1307.39,349.176,576.866,4.53586e-3
10.5008,0.285412,36.9649,357.564,20.00,-88.2692,-0.124788,20.0314,-1083.59,357.564,593.809,4.96615e-3
10.8571,0.312711,34.7922,366.019,20.00,-78.3102,-0.110708,20.0214,-800.815,366.019,613.953,5.44116e-3
11.2976,0.342630,32.8952,374.473,20.00,-82.5196,-0.116659,20.0210,-702.922,374.473,638.864,5.96174e-3
11.6025,0.375120,31.1304,382.861,20.00,-100.416,-0.141959,20.0328,-713.610,382.861,656.106,6.52707e-3
12.1597,0.410709,29.4856,391.250,20.00,-75.6311,-0.106921,20.0216,-448.365,391.250,687.617,7.14633e-3
12.5454,0.449674,27.9262,399.639,20.00,-73.7832,-0.104309,20.0119,-364.890,399.639,709.426,7.82431e-3
13.0250,0.492315,26.5150,408.027,20.00,-68.7753,-0.0972288,20.0168,-283.757,408.027,736.544,8.56626e-3
13.5494,0.539405,25.1577,416.481,20.00,-75.6823,-0.106993,20.0120,-260.114,416.481,766.203,9.38563e-3
14.0914,0.590991,23.9671,424.935,20.00,-51.6005,-0.0729485,20.0134,-147.738,424.935,796.849,0.0102832
14.7499,0.647033,22.9436,433.324,20.00,-63.0760,-0.0891715,20.0117,-150.664,433.324,834.089,0.0112584
15.5269,0.708409,22.0645,441.713,20.00,-62.8693,-0.0888793,20.0132,-125.277,441.713,878.025,0.0123263
16.4827,0.775590,21.3011,450.101,20.00,-54.0623,-0.0764288,20.0084,-89.8733,450.101,932.077,0.0134952
17.5398,0.849157,20.5620,458.490,20.00,-80.5692,-0.113902,20.0098,-111.736,458.490,991.853,0.0147753
18.5975,0.930379,19.8079,466.944,20.00,-74.7538,-0.105681,20.0118,-86.3602,466.944,1051.66,0.0161886
19.4658,1.01934,18.9992,475.398,20.00,-83.4510,-0.117976,20.0273,-80.3146,475.398,1100.76,0.0177365
20.3093,1.11602,18.1609,483.787,20.00,-89.6856,-0.126790,20.0206,-72.0073,483.787,1148.46,0.0194188
21.1033,1.22186,17.3044,492.175,20.00,-69.4689,-0.0982093,20.0331,-46.5313,492.175,1193.37,0.0212604
22.0360,1.33775,16.4992,500.564,20.00,-43.0356,-0.0608402,20.0270,-24.0478,500.564,1246.11,0.0232769
22.9927,1.46567,15.7161,509.018,20.00,-40.0701,-0.0566477,20.0186,-18.6529,509.018,1300.20,0.0255027
24.1471,1.60582,14.9428,517.472,20.00,-23.2724,-0.0329006,20.0241,-9.02503,517.472,1365.49,0.0279412
25.1172,1.75813,14.1748,525.861,20.00,-9.54485,-0.0134937,20.0224,-3.08793,525.861,1420.35,0.0305914
25.8622,1.92488,13.4236,534.250,20.00,2.84713,4.02504e-3,20.0262,0.768425,534.250,1462.47,0.0334928
26.6457,2.10743,12.6874,542.638,20.00,-41.7620,-0.0590396,20.0286,-9.40314,542.638,1506.78,0.0366693
27.5570,2.30729,11.9964,551.027,20.00,-85.5058,-0.120881,20.0251,-16.0617,551.027,1558.31,0.0401467
28.6581,2.52796,11.3834,559.481,20.00,-99.0022,-0.139961,20.0230,-15.4920,559.481,1620.58,0.0439863
29.8793,2.76962,10.8461,567.935,20.00,-101.383,-0.143327,20.0215,-13.2168,567.935,1689.63,0.0481912
31.3841,3.03231,10.3537,576.324,20.00,55.4901,0.0784472,20.0364,6.03489,576.324,1774.73,0.0527620
32.9950,3.31986,9.88817,584.712,20.00,-3.04900,-4.31043e-3,20.0229,-0.276642,584.712,1865.82,0.0577655
34.3878,3.63472,9.43232,593.101,20.00,-26.0455,-0.0368210,20.0177,-1.97147,593.101,1944.58,0.0632441
35.8306,3.97950,8.97352,601.489,20.00,-38.2363,-0.0540553,20.0226,-2.41446,601.489,2026.17,0.0692431
37.1349,4.36002,8.51971,609.944,20.00,-23.2294,-0.0328398,20.0236,-1.22197,609.944,2099.93,0.0758642
38.4990,4.77683,8.08626,618.398,20.00,9.77286,0.0138161,20.0199,0.428295,618.398,2177.07,0.0831166
40.1483,5.22989,7.68326,626.786,20.00,61.1213,0.0864083,20.0263,2.23464,626.786,2270.33,0.0910000
41.7734,5.72588,7.31342,635.175,20.00,150.604,0.212912,20.0250,4.59360,635.175,2362.23,0.0996301
43.6774,6.26899,6.99066,643.564,20.00,73.1370,0.103395,20.0309,1.86098,643.564,2469.90,0.109080
45.6610,6.86349,6.70304,651.952,20.00,27.7767,0.0392683,20.0298,0.589645,651.952,2582.07,0.119424
48.3456,7.51967,6.44662,660.406,20.00,-15.1792,-0.0214590,20.0180,-0.268442,660.406,2733.88,0.130842
51.2319,8.23877,6.20531,668.860,20.00,-3.90851,-5.52553e-3,20.0212,-0.0575820,668.860,2897.10,0.143354
54.1957,9.02002,5.96261,677.249,20.00,72.4986,0.102493,20.0184,0.891075,677.249,3064.70,0.156948
56.9048,9.87554,5.70920,685.638,20.00,173.797,0.245699,20.0203,1.78205,685.638,3217.89,0.171834
58.8907,10.8121,5.44648,694.026,20.00,174.712,0.246993,20.0244,1.49451,694.026,3330.19,0.188131
61.2323,11.8376,5.18272,702.415,20.00,126.471,0.178795,20.0237,0.902536,702.415,3462.61,0.205974
63.6994,12.9696,4.92676,710.869,20.00,205.336,0.290287,20.0218,1.22070,710.869,3602.12,0.225671
66.5571,14.2095,4.69666,719.323,20.00,374.330,0.529197,20.0192,1.85394,719.323,3763.71,0.247245
69.6752,15.5572,4.48394,727.712,20.00,303.593,0.429194,20.0267,1.25438,727.712,3940.04,0.270694
73.1154,17.0326,4.27714,736.100,20.00,271.681,0.384080,20.0190,0.936482,736.100,4134.58,0.296366
76.4504,18.6480,4.07567,744.489,20.00,223.991,0.316660,20.0305,0.644119,744.489,4323.17,0.324474
79.1879,20.4313,3.88461,752.943,20.00,309.137,0.437032,20.0163,0.740558,752.943,4477.97,0.355504
82.3089,22.3845,3.69697,761.397,20.00,584.237,0.825946,20.0197,1.16599,761.397,4654.46,0.389489
86.4390,24.5075,3.51851,769.786,20.00,412.019,0.582478,20.0267,0.685993,769.786,4888.01,0.426429
90.0228,26.8318,3.35336,778.174,20.00,269.824,0.381454,20.0215,0.374785,778.174,5090.67,0.466872
93.9671,29.3764,3.19867,786.563,20.00,658.636,0.931125,20.0167,0.763215,786.563,5313.72,0.511149
97.9846,32.1625,3.04651,794.952,20.00,534.055,0.755002,20.0230,0.516282,794.952,5540.90,0.559626
102.281,35.2383,2.90352,803.406,20.00,475.567,0.672317,20.0225,0.382984,803.406,5783.87,0.613146
106.638,38.6069,2.76576,811.860,20.00,656.425,0.927999,20.0123,0.440408,811.860,6030.24,0.671759
111.646,42.2686,2.63700,820.249,20.00,585.035,0.827074,20.0295,0.327451,820.249,6313.41,0.735472
116.215,46.2773,2.51694,828.637,20.00,805.697,1.13903,20.0217,0.376214,828.637,6571.81,0.805224
121.529,50.6661,2.40226,837.026,20.00,735.026,1.03912,20.0121,0.286330,837.026,6872.30,0.881589
127.499,55.4714,2.29144,845.414,20.00,835.063,1.18054,20.0276,0.271382,845.414,7209.88,0.965201
132.908,60.7759,2.18428,853.869,20.00,906.689,1.28180,20.0139,0.245469,853.869,7515.78,1.05750
138.784,66.5864,2.08068,862.323,20.00,966.034,1.36570,20.0224,0.217882,862.323,7848.08,1.15860
144.249,72.9015,1.97930,870.711,20.00,995.388,1.40720,20.0061,0.187292,870.711,8157.12,1.26848
150.324,79.8155,1.88180,879.100,20.00,1075.88,1.52100,20.0201,0.168885,879.100,8500.60,1.38879
156.339,87.3850,1.78814,887.489,20.00,1113.22,1.57378,20.0124,0.145783,887.489,8840.75,1.52050
162.411,95.6040,1.69902,895.812,20.00,1163.77,1.64525,20.0205,0.127326,895.812,9184.12,1.66351