File: Viscosity/csv/pvk_dcm_00_3.csv
Filename,pvk_dcm_3
Instrument name,5333-0457
Operator,Osamu Katagiri
rundate,13/12/2019
Sample name,_3_PVK_DCM
Geometry name,60.0mm 0.996944° cone plate, Peltier plate Steel
Procedure name,Sample
,Flow ramp
proceduresegments,Flow ramp
[step]
Flow ramp - 1
Stress,Shear rate,Viscosity,Step time,Temperature,Normal stress
Pa,1/s,Pa.s,s,°C,Pa
0.0775388,6.57094e-3,11.8003,4.19434,19.99,-165.888
-4.20055e-3,6.89697e-3,-0.609043,12.7521,19.99,-165.579
-4.30741e-3,7.57451e-3,-0.568672,21.2071,19.99,-167.082
-4.02227e-3,8.27715e-3,-0.485949,29.6223,19.99,-167.387
-4.74950e-3,9.01926e-3,-0.526595,38.0109,20.00,-166.202
-3.95164e-3,9.88922e-3,-0.399591,46.3995,19.99,-166.580
-4.47039e-3,0.0108840,-0.410731,54.7881,20.00,-166.435
-4.59471e-3,0.0118388,-0.388107,63.1767,20.00,-164.769
-3.85342e-3,0.0129965,-0.296496,71.6309,20.00,-163.496
-4.48271e-3,0.0142339,-0.314933,80.0850,20.00,-170.455
-4.61213e-3,0.0156286,-0.295107,88.4736,20.00,-166.615
-4.69751e-3,0.0170626,-0.275311,96.8622,20.00,-165.692
-3.78973e-3,0.0186867,-0.202804,105.251,20.00,-164.698
-3.47633e-3,0.0204844,-0.169706,113.639,20.00,-167.160
-3.64308e-3,0.0224386,-0.162357,122.094,20.00,-171.580
-3.99094e-3,0.0245925,-0.162283,130.548,20.00,-168.562
-4.37588e-3,0.0269166,-0.162572,138.936,20.00,-167.954
-4.30051e-3,0.0294523,-0.146016,147.325,20.00,-166.795
-3.83333e-3,0.0322406,-0.118897,155.714,20.00,-165.876
-3.41992e-3,0.0353126,-0.0968469,164.102,20.00,-165.122
-3.34974e-3,0.0386970,-0.0865632,172.556,20.00,-164.681
-3.33535e-3,0.0423928,-0.0786773,181.010,20.00,-165.068
-3.93094e-3,0.0464236,-0.0846754,189.399,20.00,-173.587
-4.04398e-3,0.0508235,-0.0795691,197.788,20.00,-170.337
-4.23404e-3,0.0556445,-0.0760908,206.176,20.00,-169.016
-4.51066e-3,0.0608378,-0.0741423,214.565,20.00,-168.496
-4.72985e-3,0.0666649,-0.0709496,223.019,20.00,-167.476
-4.83512e-3,0.0730424,-0.0661961,231.473,20.00,-167.287
-4.92967e-3,0.0799818,-0.0616349,239.862,20.00,-167.453
-5.00991e-3,0.0875732,-0.0572082,248.250,20.00,-167.178
-5.15503e-3,0.0959027,-0.0537528,256.639,20.00,-167.103
-5.38318e-3,0.105075,-0.0512319,265.093,20.00,-166.274
-5.57394e-3,0.115131,-0.0484139,273.547,20.00,-166.024
-5.84792e-3,0.126067,-0.0463876,281.936,20.00,-165.994
-6.24347e-3,0.138029,-0.0452330,290.325,20.00,-165.098
-6.57346e-3,0.151125,-0.0434968,298.713,20.00,-165.087
-6.87535e-3,0.165459,-0.0415533,307.102,20.00,-164.659
-7.11322e-3,0.181301,-0.0392343,315.556,20.00,-164.351
-7.45239e-3,0.198634,-0.0375182,324.010,20.00,-164.506
-7.72918e-3,0.217496,-0.0355371,332.399,20.00,-165.131
-7.39908e-3,0.238143,-0.0310699,340.787,20.00,-168.374
-8.46791e-3,0.260680,-0.0324839,349.176,20.00,-174.409
-8.30323e-3,0.285453,-0.0290879,357.564,20.00,-173.046
-8.65507e-3,0.312757,-0.0276735,366.019,20.00,-172.192
-8.97550e-3,0.342618,-0.0261968,374.473,20.00,-171.314
-9.49210e-3,0.375174,-0.0253005,382.861,20.00,-170.761
-0.0102777,0.410762,-0.0250209,391.250,20.00,-170.186
-0.0105767,0.449693,-0.0235197,399.639,20.00,-169.395
-0.0103182,0.492347,-0.0209571,408.027,20.00,-169.313
-9.41557e-3,0.539410,-0.0174553,416.481,20.00,-168.894
-6.75143e-3,0.590943,-0.0114248,424.935,20.00,-167.646
-2.99450e-3,0.647014,-4.62819e-3,433.324,20.00,-167.474
2.12624e-4,0.708263,3.00205e-4,441.713,20.00,-166.568
2.09643e-3,0.775631,2.70287e-3,450.101,20.00,-166.949
2.42946e-3,0.849169,2.86099e-3,458.490,20.00,-166.974
9.81883e-4,0.930673,1.05503e-3,466.944,20.00,-166.893
-6.83538e-4,1.01945,-6.70497e-4,475.398,20.00,-166.661
4.43775e-4,1.11588,3.97690e-4,483.787,20.00,-166.687
2.61234e-3,1.22187,2.13799e-3,492.175,20.00,-166.757
4.60865e-3,1.33772,3.44516e-3,500.564,20.00,-166.397
3.62611e-3,1.46609,2.47331e-3,509.018,20.00,-166.352
2.99491e-3,1.60567,1.86521e-3,517.472,20.00,-165.989
8.32146e-3,1.75812,4.73315e-3,525.861,20.00,-166.317
4.85372e-3,1.92522,2.52113e-3,534.250,20.00,-165.327
-4.45145e-4,2.10757,-2.11213e-4,542.638,20.00,-165.416
9.62468e-4,2.30749,4.17107e-4,551.027,20.00,-165.012
-3.83224e-3,2.52844,-1.51566e-3,559.481,20.00,-165.986
-3.40280e-3,2.76948,-1.22868e-3,567.935,20.00,-165.594
8.33430e-4,3.03218,2.74862e-4,576.324,20.00,-166.116
1.83103e-3,3.32001,5.51515e-4,584.712,20.00,-166.163
1.25741e-3,3.63523,3.45895e-4,593.101,20.00,-165.547
-2.27155e-3,3.98009,-5.70729e-4,601.489,20.00,-165.358
-6.94240e-3,4.35989,-1.59234e-3,609.944,20.00,-164.967
2.35238e-3,4.77694,4.92445e-4,618.398,20.00,-165.268
3.72136e-3,5.22997,7.11545e-4,626.786,20.00,-165.838
5.99679e-3,5.72640,1.04722e-3,635.175,20.00,-165.369
7.31026e-4,6.26971,1.16597e-4,643.564,20.00,-164.992
1.64283e-3,6.86318,2.39369e-4,651.952,20.00,-165.366
1.62078e-3,7.52039,2.15518e-4,660.406,20.00,-164.996
-2.74573e-3,8.23868,-3.33273e-4,668.860,20.00,-163.912
5.33244e-3,9.02063,5.91138e-4,677.249,20.00,-164.371
6.43579e-3,9.87638,6.51635e-4,685.638,20.00,-164.291
3.71094e-3,10.8123,3.43216e-4,694.026,20.00,-164.782
3.57372e-4,11.8382,3.01881e-5,702.415,20.00,-164.793
8.12449e-3,12.9698,6.26416e-4,710.869,20.00,-164.735
5.33278e-3,14.2103,3.75275e-4,719.323,20.00,-164.767
4.16172e-3,15.5578,2.67501e-4,727.712,20.00,-170.472
0.0107454,17.0335,6.30839e-4,736.100,20.00,-174.159
7.46571e-3,18.6489,4.00330e-4,744.489,20.00,-173.453
8.85179e-3,20.4315,4.33242e-4,752.943,20.00,-171.387
0.0100066,22.3859,4.47002e-4,761.397,20.00,-170.815
0.0112776,24.5083,4.60156e-4,769.786,20.00,-169.875
0.0102211,26.8325,3.80921e-4,778.174,20.00,-169.960
0.0153447,29.3779,5.22322e-4,786.563,20.00,-169.349
0.0151618,32.1639,4.71393e-4,794.952,20.00,-169.083
0.0161189,35.2390,4.57417e-4,803.406,20.00,-169.015
0.0180292,38.6086,4.66973e-4,811.860,20.00,-168.487
0.0204184,42.2702,4.83043e-4,820.249,20.00,-167.414
0.0228771,46.2790,4.94330e-4,828.637,20.00,-167.028
0.0256259,50.6682,5.05759e-4,837.026,20.00,-167.525
0.0275713,55.4733,4.97018e-4,845.414,20.00,-167.449
0.0303414,60.7782,4.99214e-4,853.869,20.00,-166.983
0.0342864,66.5887,5.14899e-4,862.323,20.00,-166.611
0.0369345,72.9041,5.06618e-4,870.711,20.00,-166.184
0.0401256,79.8180,5.02713e-4,879.100,20.00,-166.802
0.0447315,87.3880,5.11872e-4,887.489,20.00,-166.179
0.0492193,95.6073,5.14807e-4,895.812,20.00,-166.741